File: Data/Thesis_Samples_Data/Notched_Cast_5/Notched_Cast_5.csv
"File Path: C:\Users\Lab User\Desktop\Will\Thesis Tests\Test Run 12 04-9-22 14 37 15 PM\DAQ- Crosshead, … - (Timed).csv   ",,,
Test: MTS EM Tension (Extensometer) - Will 1,,,
Test Run: Test Run 12,,,
Date: 4/9/2022 2:29:01 PM,,,
,,,
,,,
Crosshead ,Load ,Time ,Extensometer
mm,N,sec,mm
0,-0.735322654,0.02,-4.64E-05
0,-0.755903304,0.079999998,-4.72E-05
-4.88E-05,-0.803270519,0.140000001,-4.46E-05
-9.77E-05,-0.752112567,0.200000003,-3.67E-05
-0.000146484,-0.949496448,0.25999999,-2.88E-05
-0.000195312,-0.889098227,0.319999993,-2.97E-05
-0.000292969,-0.92175293,0.379999995,-3.15E-05
-0.000341797,-1.026045799,0.439999998,-3.11E-05
-0.000439453,-0.866016746,0.5,-2.70E-05
-0.000537109,-1.173108816,0.560000002,-7.29E-07
-0.000634766,-1.117032886,0.620000005,1.82E-05
-0.000732422,-1.30674386,0.680000007,2.01E-05
-0.000830078,-1.398996711,0.74000001,3.09E-05
-0.000927734,-1.489091158,0.800000012,2.19E-05
-0.001025391,-1.783265948,0.860000014,5.33E-05
-0.001171875,-1.849854946,0.920000017,7.09E-05
-0.001269531,-1.994253397,0.980000019,7.16E-05
-0.001416016,-2.172872066,1.039999962,0.000102014
-0.0015625,-2.220536232,1.100000024,0.00013018
-0.001708984,-2.515883923,1.159999967,0.000143893
-0.001855469,-2.464883089,1.220000029,0.000131174
-0.001953125,-2.557910442,1.279999971,0.000160597
-0.002099609,-2.618542194,1.340000033,0.000200421
-0.002197266,-2.623259306,1.399999976,0.000217153
-0.00234375,-2.782705069,1.460000038,0.000232578
-0.002441406,-2.612901926,1.519999981,0.000195314
-0.002587891,-2.849114895,1.580000043,0.000196182
-0.002685547,-2.991913319,1.639999986,0.000178964
-0.002783203,-2.980829954,1.700000048,0.000148962
-0.002880859,-3.126220703,1.75999999,0.000156712
-0.003027344,-3.02135849,1.820000052,0.000182746
-0.003125,-3.123045921,1.879999995,0.000197797
-0.003222656,-3.253851652,1.940000057,0.000228402
-0.003320313,-3.274341106,2,0.00024332
-0.003417969,-3.395720005,2.059999943,0.000257204
-0.003564453,-3.380582571,2.119999886,0.000267869
-0.003662109,-3.597532034,2.180000067,0.000296304
-0.003759766,-3.497606993,2.24000001,0.000295911
-0.003857422,-3.664348125,2.299999952,0.000326941
-0.003955078,-3.789470911,2.359999895,0.000333745
-0.004052734,-3.72992754,2.420000076,0.000334593
-0.004150391,-4.0471735,2.480000019,0.000337988
-0.004248047,-4.016618252,2.539999962,0.000324814
-0.004345703,-4.225106716,2.599999905,0.00030337
-0.00444336,-4.32624197,2.660000086,0.000313813
-0.004589844,-4.228954792,2.720000029,0.000328546
-0.0046875,-4.44616127,2.779999971,0.000327024
-0.004785156,-4.546039104,2.839999914,0.00033362
-0.004882812,-4.72938776,2.900000095,0.000332747
-0.004980469,-4.884356022,2.960000038,0.000325207
-0.005078125,-4.949967861,3.019999981,0.000341518
-0.005175781,-5.106271267,3.079999924,0.000343134
-0.005273438,-5.151477814,3.140000105,0.000336866
-0.005371094,-5.40017271,3.200000048,0.000354729
-0.00546875,-5.494765282,3.25999999,0.000368002
-0.005566406,-5.621773243,3.319999933,0.000342629
-0.005664062,-5.889220238,3.380000114,0.000346861
-0.005761719,-5.846330166,3.440000057,0.00033828
-0.005859375,-6.04035902,3.5,0.000323998
-0.005957031,-6.13343811,3.559999943,0.00033415
-0.006054688,-6.248987198,3.619999886,0.000332293
-0.006152344,-6.410367012,3.680000067,0.000358069
-0.00625,-6.503093243,3.74000001,0.000348596
-0.006347656,-6.766714096,3.799999952,0.000362965
-0.006445312,-6.821678638,3.859999895,0.000349926
-0.006542969,-7.07083416,3.920000076,0.000357137
-0.006640625,-7.263145924,3.980000019,0.000377515
-0.006738281,-7.130489826,4.039999962,0.000357818
-0.006835938,-7.536713123,4.099999905,0.000383983
-0.006933594,-7.504513741,4.159999847,0.000390465
-0.006982422,-7.743369102,4.21999979,0.000383272
-0.007080078,-8.003959656,4.28000021,0.000378586
-0.007177734,-8.09573555,4.340000153,0.000382237
-0.007275391,-8.450873375,4.400000095,0.000387297
-0.007373047,-8.33729744,4.460000038,0.000381962
-0.007470703,-8.537338257,4.519999981,0.000379849
-0.007568359,-8.772985458,4.579999924,0.000398995
-0.007666015,-8.958679199,4.639999866,0.000402116
-0.007763672,-9.257411003,4.699999809,0.000407787
-0.007861328,-9.134322166,4.760000229,0.000380911
-0.007958984,-9.53585434,4.820000172,0.000397352
-0.008056641,-9.656673431,4.880000114,0.00041255
-0.008154297,-9.813638687,4.940000057,0.000399945
-0.008251953,-10.01065254,5,0.000411317
-0.00834961,-10.07826519,5.059999943,0.000400065
-0.008447266,-10.41370678,5.119999886,0.000420397
-0.008544922,-10.62287903,5.179999828,0.000422928
-0.008642578,-10.73385048,5.239999771,0.000422516
-0.008789062,-11.03652287,5.300000191,0.000420888
-0.008886719,-10.96560574,5.360000134,0.000427386
-0.008984375,-11.41505623,5.420000076,0.000442499
-0.009082031,-11.59615707,5.480000019,0.000438327
-0.009179687,-11.85609722,5.539999962,0.000426649
-0.009326171,-12.07396984,5.599999905,0.000454584
-0.009423828,-12.1531992,5.659999847,0.000436847
-0.009521485,-12.49057579,5.71999979,0.000447885
-0.009619141,-12.54481125,5.78000021,0.000447353
-0.009716797,-12.91843987,5.840000153,0.000445884
-0.009863281,-13.11962223,5.900000095,0.000444383
-0.009960938,-13.32009792,5.960000038,0.000451987
-0.010058594,-13.62840939,6.019999981,0.000465805
-0.01015625,-13.763484,6.079999924,0.000454081
-0.010253906,-14.06596851,6.139999866,0.000457896
-0.010351562,-14.1424675,6.199999809,0.000477645
-0.010449219,-14.32599068,6.260000229,0.000473301
-0.010595703,-14.69327927,6.320000172,0.000499775
-0.010693359,-14.75068283,6.380000114,0.000504637
-0.010791015,-15.07518005,6.440000057,0.00051404
-0.010888672,-15.29215336,6.5,0.000528616
-0.010986329,-15.55574512,6.559999943,0.000528856
-0.011083985,-15.78628349,6.619999886,0.000546265
-0.011181641,-15.83787727,6.679999828,0.000558455
-0.011279297,-16.25853539,6.739999771,0.000577819
-0.011376953,-16.31756973,6.800000191,0.00057449
-0.011474609,-16.54076385,6.860000134,0.000584728
-0.011572266,-16.82092857,6.920000076,0.000584301
-0.011669922,-16.96310234,6.980000019,0.000583309
-0.011816406,-17.29891777,7.039999962,0.00060664
-0.011914062,-17.42732811,7.099999905,0.000598073
-0.012011718,-17.62852478,7.159999847,0.000607949
-0.012109375,-17.93242073,7.21999979,0.000618199
-0.012207031,-18.08328056,7.28000021,0.000613138
-0.012304688,-18.42518806,7.340000153,0.00060873
-0.012402344,-18.56215096,7.400000095,0.000618591
-0.0125,-18.80711555,7.460000038,0.000621406
-0.012597657,-18.99135208,7.519999981,0.000620032
-0.012695313,-19.12645721,7.579999924,0.000614742
-0.012792969,-19.52375221,7.639999866,0.000617915
-0.012890625,-19.6334362,7.699999809,0.000627539
-0.012988281,-20.00748062,7.760000229,0.000646284
-0.013085937,-20.0974865,7.820000172,0.000646567
-0.013183594,-20.33399391,7.880000114,0.000637814
-0.01328125,-20.66924477,7.940000057,0.000662708
-0.013378906,-20.68925095,8,0.000657156
-0.013427734,-21.04116249,8.06000042,0.00066042
-0.01352539,-21.20906067,8.119999886,0.000680992
-0.013623046,-21.41422081,8.180000305,0.00067894
-0.013720703,-21.71404457,8.239999771,0.000691071
-0.01381836,-21.84959984,8.300000191,0.000698298
-0.013916016,-22.24711418,8.359999657,0.000706331
-0.014013672,-22.313591,8.420000076,0.000709171
-0.014111328,-22.61288071,8.479999542,0.000709747
-0.014208985,-22.87163353,8.539999962,0.00072426
-0.014306641,-23.0679245,8.600000381,0.000724806
-0.014404297,-23.26018906,8.659999847,0.000735208
-0.014501953,-23.55655289,8.720000267,0.000719747
-0.014599609,-23.81040001,8.779999733,0.000724651
-0.014697265,-24.09334373,8.840000153,0.000757903
-0.014794922,-24.23202515,8.899999619,0.000751383
-0.014892578,-24.60315514,8.960000038,0.000754574
-0.014990234,-24.78532982,9.020000458,0.000771337
-0.01508789,-25.14872742,9.079999924,0.000803023
-0.015185547,-25.43027306,9.140000343,0.000801627
-0.015283204,-25.55187607,9.199999809,0.000810278
-0.01538086,-25.92849159,9.260000229,0.000816589
-0.015478516,-26.0494194,9.319999695,0.000824706
-0.015625001,-26.36930847,9.380000114,0.00084106
-0.015722657,-26.63227272,9.43999958,0.000833668
-0.015820313,-26.88830948,9.5,0.000827406
-0.015917969,-27.37356758,9.56000042,0.000854312
-0.016015625,-27.4547863,9.619999886,0.000848809
-0.01616211,-27.80518913,9.680000305,0.00084516
-0.016259766,-28.08951569,9.739999771,0.000865222
-0.016357422,-28.32658768,9.800000191,0.000865043
-0.016455078,-28.79555511,9.859999657,0.000883722
-0.016552734,-28.84612274,9.920000076,0.00089009
-0.016650391,-29.31264877,9.979999542,0.000886994
-0.016748047,-29.52870369,10.03999996,0.000894008
-0.016894532,-29.76534462,10.10000038,0.000898192
-0.016992188,-30.07719231,10.15999985,0.000890748
-0.017089844,-30.20616341,10.22000027,0.000894523
-0.0171875,-30.76000977,10.27999973,0.000927807
-0.017285156,-30.88944244,10.34000015,0.000936226
-0.017382812,-31.24966431,10.39999962,0.000931424
-0.017480468,-31.58659363,10.46000004,0.000948617
-0.017578124,-31.69104004,10.52000046,0.000945832
-0.017675782,-32.203228,10.57999992,0.000957416
-0.017773438,-32.24420166,10.64000034,0.000955106
-0.017871094,-32.59114838,10.69999981,0.000955401
-0.01796875,-32.94396973,10.76000023,0.0009754
-0.018066406,-33.14965439,10.81999969,0.000971232
-0.018164063,-33.62321854,10.88000011,0.00097605
-0.018261719,-33.67408752,10.93999958,0.000974359
-0.018359375,-34.09843445,11,0.000971543
-0.018457031,-34.35401535,11.06000042,0.000977867
-0.018554687,-34.56306839,11.11999989,0.000976781
-0.018652343,-34.97877121,11.18000031,0.000986776
-0.018750001,-35.06639481,11.23999977,0.000990691
-0.018847657,-35.53520203,11.30000019,0.001000158
-0.018945313,-35.65867233,11.35999966,0.00099827
-0.019042969,-35.9912529,11.42000008,0.00100033
-0.019140625,-36.6877594,11.47999954,0.00101469
-0.019238281,-36.46840668,11.53999996,0.001006929
-0.019335937,-36.84199142,11.60000038,0.001026349
-0.019433593,-37.16915512,11.65999985,0.001033163
-0.01953125,-37.45106125,11.72000027,0.001043189
-0.019628906,-37.83517838,11.77999973,0.001049263
-0.019726562,-37.94136047,11.84000015,0.001045215
-0.01982422,-38.37142181,11.89999962,0.001064967
-0.019921876,-38.63090134,11.96000004,0.001083244
-0.020019532,-38.81537628,12.02000046,0.001084752
-0.020117188,-39.13155746,12.07999992,0.00110138
-0.020214844,-39.42902756,12.14000034,0.001116282
-0.0203125,-39.83760452,12.19999981,0.001127178
-0.020410156,-39.98438263,12.26000023,0.001117699
-0.020507812,-40.33522034,12.31999969,0.00113357
-0.020605468,-40.57830429,12.38000011,0.001144194
-0.020654297,-40.77102661,12.43999958,0.001144288
-0.020751953,-41.19681168,12.5,0.001154301
-0.020849609,-41.36528015,12.56000042,0.00116465
-0.020947266,-41.79798508,12.61999989,0.001175353
-0.021044922,-42.11116791,12.68000031,0.001179721
-0.021142578,-42.39435577,12.73999977,0.001169978
-0.021240234,-42.79553604,12.80000019,0.001185275
-0.02133789,-42.9635849,12.85999966,0.001193131
-0.021435548,-43.29590988,12.92000008,0.001200821
-0.021533204,-43.5981369,12.97999954,0.00120246
-0.02163086,-43.89941406,13.03999996,0.001208138
-0.021728516,-44.31417084,13.10000038,0.001213244
-0.021826172,-44.4582901,13.15999985,0.001218575
-0.021923828,-45.03741455,13.22000027,0.001226155
-0.022021484,-45.19493484,13.27999973,0.001231219
-0.022167969,-45.54893112,13.34000015,0.001261648
-0.022265625,-45.91656494,13.39999962,0.001280411
-0.022363281,-46.13051605,13.46000004,0.001268766
-0.022460938,-46.69445801,13.52000046,0.001293279
-0.022558594,-46.91087723,13.57999992,0.001308028
-0.02265625,-47.26377106,13.64000034,0.001298304
-0.022753906,-47.64612579,13.69999981,0.001320445
-0.022900391,-47.89582825,13.76000023,0.001317837
-0.022998047,-48.32784271,13.81999969,0.001333678
-0.023095703,-48.63245392,13.88000011,0.001349967
-0.023193359,-49.10684967,13.93999958,0.00135203
-0.023291015,-49.47935104,14,0.001357335
-0.023388671,-49.62060547,14.06000042,0.001343433
-0.023535156,-50.00863266,14.11999989,0.001361806
-0.023632812,-50.31539154,14.18000031,0.001355761
-0.023730468,-50.81433487,14.23999977,0.001374712
-0.023828125,-51.14065933,14.30000019,0.001376453
-0.023925781,-51.35072708,14.35999966,0.001364721
-0.024023437,-51.92201614,14.42000008,0.001381
-0.024121095,-52.09716034,14.47999954,0.00136856
-0.024218751,-52.52866364,14.53999996,0.001364736
-0.024365234,-52.76047134,14.60000038,0.001385101
-0.02446289,-53.01600647,14.65999985,0.001378885
-0.024560546,-53.57822037,14.72000027,0.00138799
-0.024658204,-53.75388718,14.77999973,0.001380853
-0.02475586,-54.26753998,14.84000015,0.001384592
-0.024853516,-54.57324219,14.89999962,0.001391014
-0.024951172,-54.82407379,14.96000004,0.001409526
-0.025048828,-55.32202911,15.02000046,0.001419233
-0.025146484,-55.36469269,15.07999992,0.001420813
-0.02524414,-56.03117752,15.14000034,0.001441754
-0.025341797,-56.26018143,15.19999981,0.001454458
-0.025439453,-56.60774231,15.26000023,0.001456956
-0.025537109,-57.05013275,15.31999969,0.001469498
-0.025634765,-57.3001976,15.38000011,0.001471337
-0.025732423,-57.67995453,15.43999958,0.001486192
-0.025830079,-57.96210861,15.5,0.001498131
-0.025927735,-58.3360939,15.56000042,0.001492561
-0.026025391,-58.64213562,15.61999989,0.001514123
-0.026123047,-58.84704971,15.68000031,0.001516295
-0.026220703,-59.42798233,15.73999977,0.001529246
-0.026318359,-59.59941483,15.80000019,0.001519172
-0.026416015,-59.92224884,15.85999966,0.001540413
-0.026513671,-60.25567627,15.92000008,0.001564812
-0.026611327,-60.57403564,15.97999954,0.00154505
-0.026708984,-61.04541779,16.04000092,0.001575633
-0.026806641,-61.20915222,16.10000038,0.001568106
-0.026904298,-61.70587158,16.15999985,0.001582951
-0.027001954,-62.03841782,16.21999931,0.001591016
-0.02709961,-62.25840378,16.28000069,0.001588621
-0.027197266,-62.6517868,16.34000015,0.001602795
-0.027294922,-62.78552628,16.39999962,0.001602707
-0.027392578,-63.28276443,16.45999908,0.001617191
-0.027490234,-63.50630188,16.52000046,0.001629244
-0.02758789,-63.91260147,16.57999992,0.00162187
-0.027685546,-64.3924942,16.63999939,0.001630555
-0.027734375,-64.52906036,16.70000076,0.001630965
-0.027832031,-65.00448608,16.76000023,0.001642998
-0.027929687,-65.34745026,16.81999969,0.001662268
-0.028027343,-65.71033478,16.87999916,0.001655034
-0.028173828,-66.08968353,16.94000053,0.001660022
-0.028271485,-66.33370972,17,0.001651088
-0.028369141,-66.93657684,17.05999947,0.001673285
-0.028466797,-67.25035095,17.12000084,0.001657835
-0.028564453,-67.528862,17.18000031,0.001668207
-0.028662109,-67.9962616,17.23999977,0.001684234
-0.028759765,-68.31981659,17.29999924,0.001684488
-0.028857421,-68.92321777,17.36000061,0.001704462
-0.028955079,-69.13754272,17.42000008,0.00168732
-0.029101562,-69.59293365,17.47999954,0.0016967
-0.029199218,-70.0348053,17.54000092,0.001715529
-0.029296874,-70.39341736,17.60000038,0.00171097
-0.02939453,-70.95331573,17.65999985,0.001713458
-0.029492188,-71.13632965,17.71999931,0.001715369
-0.029638672,-71.64839172,17.78000069,0.001752266
-0.029736328,-72.00795746,17.84000015,0.001746533
-0.029833984,-72.40606689,17.89999962,0.001745568
-0.02993164,-72.96826935,17.95999908,0.001754193
-0.030029298,-73.23960876,18.02000046,0.001768557
-0.030175781,-73.74315643,18.07999992,0.001782304
-0.030273437,-74.04639435,18.13999939,0.001779261
-0.030371093,-74.39974213,18.20000076,0.001786868
-0.030468749,-74.88768768,18.26000023,0.00181802
-0.030566407,-75.15682983,18.31999969,0.001810913
-0.030664061,-75.59947205,18.37999916,0.00182286
-0.030761719,-75.99906158,18.44000053,0.001832619
-0.030859374,-76.4280777,18.5,0.001838616
-0.030957031,-76.89466858,18.55999947,0.001860928
-0.031103515,-77.1372757,18.62000084,0.001869695
-0.031201173,-77.7009201,18.68000031,0.001883597
-0.031298827,-77.98596954,18.73999977,0.001886749
-0.031396485,-78.42614746,18.79999924,0.001894911
-0.031494139,-78.92324066,18.86000061,0.001916709
-0.031591797,-79.154953,18.92000008,0.001914215
-0.031689455,-79.6828537,18.97999954,0.001931802
-0.031787109,-79.87023163,19.04000092,0.001924397
-0.031884767,-80.46714783,19.10000038,0.001940316
-0.031982421,-80.93028259,19.15999985,0.001965527
-0.032080079,-81.2771759,19.21999931,0.001950766
-0.032177733,-81.78253174,19.28000069,0.001956418
-0.032275391,-82.04679871,19.34000015,0.001960467
-0.032373046,-82.44035339,19.39999962,0.001985658
-0.032470703,-82.81806946,19.45999908,0.00198323
-0.032568358,-83.10443878,19.52000046,0.001977368
-0.032666016,-83.66575623,19.57999992,0.001994864
-0.032763674,-83.96871948,19.63999939,0.002011537
-0.032861328,-84.50046539,19.70000076,0.002025849
-0.032958986,-84.80482483,19.76000023,0.002017725
-0.03305664,-85.14363861,19.81999969,0.00201663
-0.033154298,-85.59667969,19.87999916,0.002045964
-0.033251952,-85.85183716,19.94000053,0.002042626
-0.03334961,-86.37137604,20,0.002061604
-0.033447264,-86.70290375,20.05999947,0.002077824
-0.033544922,-87.13243103,20.12000084,0.002081446
-0.033642576,-87.62870026,20.18000031,0.002095
-0.033740234,-87.87330627,20.23999977,0.002095196
-0.033789063,-88.43489838,20.29999924,0.002107112
-0.033886718,-88.71380615,20.36000061,0.002122016
-0.033984375,-89.2088623,20.42000008,0.002138212
-0.03408203,-89.64997864,20.47999954,0.002151027
-0.034179688,-89.96529388,20.54000092,0.002155579
-0.034277346,-90.57723236,20.60000038,0.002166702
-0.034375,-90.79438019,20.65999985,0.00217068
-0.034472658,-91.34311676,20.71999931,0.002178725
-0.034570312,-91.74071503,20.78000069,0.002203787
-0.03466797,-92.08132172,20.84000015,0.002200533
-0.034765624,-92.73391724,20.89999962,0.00221533
-0.034863282,-93.06595612,20.95999908,0.002234146
-0.034960936,-93.60748291,21.02000046,0.00223915
-0.035058594,-94.00471497,21.07999992,0.002257021
-0.035156248,-94.37866974,21.13999939,0.002260183
-0.035302735,-94.89633942,21.20000076,0.002285227
-0.03540039,-95.1279068,21.26000023,0.002293193
-0.035498048,-95.8366394,21.31999969,0.002307504
-0.035595702,-96.26067352,21.37999916,0.002309873
-0.03569336,-96.75048828,21.44000053,0.002335238
-0.035791014,-97.33137512,21.5,0.002355431
-0.035888672,-97.63746643,21.55999947,0.002348139
-0.036035155,-98.22317505,21.62000084,0.002369886
-0.036132813,-98.55051422,21.68000031,0.002380448
-0.036230467,-99.10804749,21.73999977,0.00239354
-0.036328125,-99.80380249,21.79999924,0.002409604
-0.036425783,-100.1618118,21.86000061,0.002407935
-0.036523437,-100.6437073,21.92000008,0.002419644
-0.036669921,-100.9924164,21.97999954,0.002431898
-0.036767578,-101.5867996,22.04000092,0.002441205
-0.036865233,-102.1420135,22.10000038,0.002448647
-0.036962891,-102.5024033,22.15999985,0.002455856
-0.037060548,-103.1136932,22.21999931,0.002477266
-0.037158203,-103.5017624,22.28000069,0.002482461
-0.037255861,-103.9884033,22.34000015,0.00248811
-0.037353515,-104.5055695,22.39999962,0.002506499
-0.037500002,-104.8920364,22.45999908,0.002503772
-0.037597656,-105.5279236,22.52000046,0.002520245
-0.037695314,-105.7735367,22.57999992,0.0025185
-0.037792968,-106.3363571,22.63999939,0.002537425
-0.037890626,-106.9045486,22.70000076,0.002550891
-0.03798828,-107.3574753,22.76000023,0.002549982
-0.038085938,-107.8972244,22.81999969,0.002560624
-0.038183593,-108.1697693,22.87999916,0.002554352
-0.03828125,-108.8355179,22.94000053,0.002581463
-0.038378905,-109.1754456,23,0.002583048
-0.038476563,-109.5574646,23.05999947,0.002598974
-0.038574221,-110.2204285,23.12000084,0.002612262
-0.038671875,-110.6203613,23.18000031,0.002620232
-0.038769533,-111.2198715,23.23999977,0.002632533
-0.038867187,-111.5920258,23.29999924,0.002630511
-0.038964845,-112.0303421,23.36000061,0.002648461
-0.039062499,-112.5574722,23.42000008,0.002667279
-0.039160157,-112.9027176,23.47999954,0.002658595
-0.039257811,-113.5406876,23.54000092,0.002682411
-0.039355469,-113.9545746,23.60000038,0.002697881
-0.039453123,-114.5548019,23.65999985,0.002704342
-0.039550781,-114.9539795,23.71999931,0.002725876
-0.039648439,-115.2574387,23.78000069,0.002717963
-0.039746094,-115.8339996,23.84000015,0.002734774
-0.039843751,-116.198288,23.89999962,0.002752045
-0.039941406,-116.6845016,23.95999908,0.002767387
-0.040039064,-117.1694946,24.02000046,0.002788183
-0.040136718,-117.6215439,24.07999992,0.002790231
-0.040234376,-118.2035522,24.13999939,0.002797783
-0.04033203,-118.5040359,24.20000076,0.0028042
-0.040380859,-119.0572662,24.26000023,0.002820497
-0.040478517,-119.5214691,24.31999969,0.002820908
-0.040576171,-120.0356903,24.37999916,0.0028439
-0.040673829,-120.6424255,24.44000053,0.002868957
-0.040771483,-120.9608154,24.5,0.00285894
-0.040869141,-121.5946884,24.55999947,0.002884531
-0.040966795,-122.0682678,24.62000084,0.002887439
-0.041064453,-122.4989471,24.68000031,0.002878641
-0.041162108,-123.055603,24.73999977,0.002907973
-0.041259766,-123.4257736,24.79999924,0.002923997
-0.041357423,-124.0901337,24.86000061,0.002924821
-0.041455078,-124.5351791,24.92000008,0.002935875
-0.041552736,-125.0711746,24.97999954,0.002951871
-0.04165039,-125.6252899,25.04000092,0.002961983
-0.041748048,-125.9673538,25.10000038,0.002966693
-0.041845702,-126.5635452,25.15999985,0.002981012
-0.04194336,-126.9876022,25.21999931,0.00298306
-0.042089843,-127.6026764,25.28000069,0.00300687
-0.042187501,-128.1763153,25.34000015,0.003022976
-0.042285155,-128.5974731,25.39999962,0.003011251
-0.042382813,-129.3808899,25.45999908,0.003040787
-0.042480468,-129.8471832,25.52000046,0.003043979
-0.042578125,-130.5025024,25.57999992,0.003051056
-0.042724609,-130.9709778,25.63999939,0.003059294
-0.042822267,-131.4252319,25.70000076,0.003070184
-0.042919921,-132.2458649,25.76000023,0.00309058
-0.043017579,-132.6909485,25.81999969,0.003097739
-0.043164062,-133.3252411,25.87999916,0.003098184
-0.04326172,-133.8674316,25.94000053,0.003111283
-0.043359374,-134.317215,26,0.003127972
-0.043457032,-134.9746094,26.05999947,0.003147326
-0.043554686,-135.4872437,26.12000084,0.003141891
-0.043652344,-136.1371002,26.18000031,0.003151753
-0.043798827,-136.5886383,26.23999977,0.003157286
-0.043896485,-137.2311707,26.29999924,0.003165974
-0.04399414,-137.8263702,26.36000061,0.003168347
-0.044091797,-138.1706085,26.42000008,0.003182266
-0.044189452,-138.838623,26.47999954,0.003183968
-0.04428711,-139.4150543,26.54000092,0.003205123
-0.044384764,-139.9075165,26.60000038,0.003215128
-0.044482422,-140.5910187,26.65999985,0.003231507
-0.04458008,-140.9640961,26.71999931,0.003225649
-0.044677734,-141.6783752,26.78000069,0.003230182
-0.044775392,-142.0485992,26.84000015,0.003240433
-0.044921875,-142.6139069,26.89999962,0.003251482
-0.045019533,-143.2118988,26.95999908,0.003271857
-0.045117187,-143.6144257,27.02000046,0.0032773
-0.045214845,-144.355484,27.07999992,0.003291831
-0.045312499,-144.7989502,27.13999939,0.00329608
-0.045410157,-145.4285278,27.20000076,0.003307437
-0.045507812,-145.9158478,27.26000023,0.003309686
-0.045605469,-146.312851,27.31999969,0.003317758
-0.045703124,-147.0072632,27.37999916,0.003348966
-0.045800782,-147.3759308,27.44000053,0.003353661
-0.045898436,-148.010437,27.5,0.003354752
-0.045996094,-148.5369415,27.55999947,0.003377101
-0.046093752,-148.986145,27.62000084,0.003378447
-0.046191406,-149.694809,27.68000031,0.003398078
-0.046289064,-150.0309296,27.73999977,0.00339879
-0.046386718,-150.6856842,27.79999924,0.00340551
-0.046484376,-151.0971222,27.86000061,0.003433082
-0.04658203,-151.5874939,27.92000008,0.00343324
-0.046679688,-152.2049103,27.97999954,0.003433174
-0.046728517,-152.5083618,28.04000092,0.003445267
-0.046875,-153.2257233,28.10000038,0.003469439
-0.046923829,-153.7410889,28.15999985,0.00347334
-0.047021484,-154.1409912,28.21999931,0.003470362
-0.047119142,-154.744339,28.28000069,0.003489731
-0.047216796,-155.2459564,28.34000015,0.003497816
-0.047314454,-155.9786377,28.39999962,0.003520592
-0.047412108,-156.3852997,28.45999908,0.003530851
-0.047509766,-156.8573761,28.52000046,0.003531051
-0.04760742,-157.4294128,28.57999992,0.003542528
-0.047705078,-157.8842926,28.63999939,0.003550125
-0.047802736,-158.5122833,28.70000076,0.003564049
-0.04790039,-158.9365387,28.76000023,0.00358693
-0.047998048,-159.5953827,28.81999969,0.00359931
-0.048095702,-160.1756287,28.87999916,0.00361553
-0.04819336,-160.7149048,28.94000053,0.003615517
-0.048291015,-161.4101868,29,0.003631796
-0.048388672,-161.7029877,29.05999947,0.003635707
-0.048486327,-162.3475342,29.12000084,0.003642782
-0.048583985,-162.9903107,29.18000031,0.003660055
-0.048681639,-163.4681244,29.23999977,0.003656967
-0.048779297,-164.3206024,29.29999924,0.003691818
-0.048876955,-164.6985016,29.36000061,0.003684085
-0.049023438,-165.3448639,29.42000008,0.003691114
-0.049121092,-166.1329956,29.47999954,0.003721892
-0.04921875,-166.6232147,29.54000092,0.003710531
-0.049316408,-167.4595032,29.60000038,0.003715714
-0.049462891,-167.8758698,29.65999985,0.003734631
-0.049560545,-168.6537933,29.71999931,0.003763801
-0.049658203,-169.3224335,29.78000069,0.003776663
-0.049755858,-169.8458862,29.84000015,0.003771896
-0.049853516,-170.585907,29.89999962,0.003788964
-0.049951173,-170.9903412,29.95999908,0.003785949
-0.050048828,-171.8235321,30.02000046,0.003811434
-0.050195311,-172.2534637,30.07999992,0.003811965
-0.050292969,-172.887085,30.13999939,0.003822569
-0.050390627,-173.7356567,30.20000076,0.003859531
-0.050488281,-174.1791229,30.26000023,0.003856511
-0.050585939,-174.8959808,30.31999969,0.003855027
-0.050683593,-175.3291473,30.37999916,0.003874048
-0.050781251,-176.0903625,30.44000053,0.003885811
-0.050878905,-176.6596527,30.5,0.003905831
-0.050976563,-177.0620728,30.55999947,0.003900325
-0.051074217,-177.9667664,30.62000084,0.003913294
-0.051171875,-178.4349365,30.68000031,0.003941029
-0.05126953,-179.0232697,30.73999977,0.00395119
-0.051367188,-179.5390167,30.79999924,0.003965059
-0.051513671,-180.1732788,30.86000061,0.00396199
-0.051611329,-180.9314423,30.92000008,0.00400786
-0.051708983,-181.3019104,30.97999954,0.003993562
-0.051806641,-182.1156464,31.04000092,0.004022478
-0.051904295,-182.7315369,31.10000038,0.004053128
-0.052001953,-183.2773285,31.15999985,0.004053556
-0.052099611,-184.0110931,31.21999931,0.004075735
-0.052197265,-184.5094299,31.28000069,0.004081866
-0.052294923,-185.2257385,31.34000015,0.004110899
-0.052392577,-185.7019348,31.39999962,0.004134834
-0.052490235,-186.2612762,31.45999908,0.004133254
-0.05258789,-186.9494476,31.52000046,0.004163086
-0.052685547,-187.4921265,31.57999992,0.004171082
-0.052783202,-188.1657257,31.63999939,0.004185977
-0.05288086,-188.7664032,31.70000076,0.004190098
-0.052929689,-189.3862915,31.76000023,0.004201254
-0.053027343,-190.0629883,31.81999969,0.004233426
-0.053125001,-190.4687042,31.87999916,0.004231469
-0.053222655,-191.3068848,31.94000053,0.004254269
-0.053320313,-191.8693848,32,0.004273666
-0.053417967,-192.4881287,32.06000137,0.00429472
-0.053515625,-193.1492157,32.11999893,0.00431131
-0.053613283,-193.6598663,32.18000031,0.004317216
-0.053710937,-194.3543243,32.24000168,0.004340424
-0.053808595,-194.8005676,32.29999924,0.004380679
-0.053906249,-195.3098145,32.36000061,0.004383309
-0.054003907,-196.0197144,32.41999817,0.004395599
-0.054101562,-196.5367584,32.47999954,0.004404966
-0.054199219,-197.3287201,32.54000092,0.004446007
-0.054248048,-197.8275757,32.59999847,0.004446369
-0.054345703,-198.446991,32.65999985,0.004461633
-0.054443361,-199.1224976,32.72000122,0.00450102
-0.054589844,-199.6606293,32.77999878,0.00452531
-0.054687502,-200.4309845,32.84000015,0.004552707
-0.054785156,-200.8862152,32.90000153,0.004552679
-0.054833985,-201.6941376,32.95999908,0.00457354
-0.054931639,-202.2166748,33.02000046,0.004591326
-0.055078126,-202.8166199,33.08000183,0.00460108
-0.05517578,-203.5428619,33.13999939,0.004628364
-0.055273438,-204.0517883,33.20000076,0.00464947
-0.055371092,-204.9568329,33.25999832,0.004667849
-0.05546875,-205.6884003,33.31999969,0.004682111
-0.055566405,-206.4065247,33.38000107,0.004690348
-0.055664063,-207.0588074,33.43999863,0.004713384
-0.05576172,-207.6660309,33.5,0.004719237
-0.055859375,-208.4955597,33.56000137,0.004735527
-0.056005858,-209.0825958,33.61999893,0.004748492
-0.056103516,-209.8718567,33.68000031,0.00477632
-0.05620117,-210.6142426,33.74000168,0.004812579
-0.056298828,-211.2557526,33.79999924,0.004808973
-0.056396486,-212.0157928,33.86000061,0.004829523
-0.05649414,-212.5488129,33.91999817,0.004836368
-0.056640623,-213.2137756,33.97999954,0.004860115
-0.056738281,-214.0090332,34.04000092,0.004883665
-0.056835939,-214.5139618,34.09999847,0.004876407
-0.056933593,-215.489624,34.15999985,0.004911898
-0.057031251,-216.0150452,34.22000122,0.004938675
-0.057128906,-216.8052216,34.27999878,0.004936325
-0.057226564,-217.4535522,34.34000015,0.004953588
-0.057324218,-217.9161377,34.40000153,0.004958919
-0.057470705,-218.7190399,34.45999908,0.00498581
-0.057568359,-219.2782135,34.52000046,0.005008846
-0.057666017,-219.9811707,34.58000183,0.005032263
-0.057763671,-220.6612854,34.63999939,0.005049952
-0.057861329,-221.359436,34.70000076,0.005061852
-0.057958983,-222.1391296,34.75999832,0.005088521
-0.058056641,-222.5935516,34.81999969,0.005099017
-0.058154295,-223.5084229,34.88000107,0.005135391
-0.058251953,-224.0347595,34.93999863,0.005145808
-0.058349608,-224.6506653,35,0.005164624
-0.058447265,-225.3954315,35.06000137,0.00521578
-0.058544923,-225.9203033,35.11999893,0.005228046
-0.058642578,-226.640564,35.18000031,0.005226031
-0.058740236,-227.2258759,35.24000168,0.00525238
-0.05883789,-227.793869,35.29999924,0.005272561
-0.058935548,-228.5002899,35.36000061,0.005307606
-0.059033202,-229.0357361,35.41999817,0.005307793
-0.05913086,-229.8260193,35.47999954,0.005322334
-0.059228514,-230.3252106,35.54000092,0.005357787
-0.059326172,-231.05867,35.59999847,0.005364502
-0.059423826,-231.621582,35.65999985,0.005383888
-0.059521484,-232.0789185,35.72000122,0.005383595
-0.059619142,-232.825119,35.77999878,0.005425752
-0.059716796,-233.3346558,35.84000015,0.005445749
-0.059814454,-234.1137085,35.90000153,0.005471874
-0.059912109,-234.7885132,35.95999908,0.005486324
-0.060009766,-235.2583008,36.02000046,0.005495875
-0.060107421,-236.0823517,36.08000183,0.005519865
-0.06015625,-236.5064392,36.13999939,0.005530161
-0.060253908,-237.1438293,36.20000076,0.005552775
-0.060351562,-237.7818146,36.25999832,0.005571904
-0.06044922,-238.4057617,36.31999969,0.005601575
-0.060546874,-239.2644958,36.38000107,0.005615662
-0.060644532,-239.7602692,36.43999863,0.005615713
-0.060742186,-240.553421,36.5,0.005651641
-0.060839844,-241.0666504,36.56000137,0.005662453
-0.060937498,-241.7096863,36.61999893,0.005671848
-0.061035156,-242.3667297,36.68000031,0.00570858
-0.061132814,-242.8982239,36.74000168,0.005711432
-0.061230472,-243.6452332,36.79999924,0.005732839
-0.061328123,-244.3886566,36.86000061,0.005767369
-0.061425781,-245.0401001,36.91999817,0.005784852
-0.061523438,-245.760376,36.97999954,0.005801796
-0.061621096,-246.0944824,37.04000092,0.005830116
-0.061718747,-246.9695435,37.09999847,0.005846997
-0.061816405,-247.6655579,37.15999985,0.005873003
-0.061914063,-248.3429718,37.22000122,0.005896068
-0.062011721,-248.9975281,37.27999878,0.005909666
-0.062109379,-249.5962982,37.34000015,0.005927943
-0.062255858,-250.5202332,37.40000153,0.005954464
-0.062353516,-251.118515,37.45999908,0.005968534
-0.062451174,-251.9442902,37.52000046,0.005993081
-0.062548825,-252.6239166,37.58000183,0.006025497
-0.062646483,-253.252121,37.63999939,0.006033871
-0.062792969,-254.0966644,37.70000076,0.006068654
-0.062890627,-254.7327728,37.75999832,0.006090684
-0.062988278,-255.6508484,37.81999969,0.006097627
-0.063085936,-256.4367065,37.88000107,0.006133101
-0.063232423,-256.9822388,37.93999863,0.00617105
-0.063330081,-257.7934265,38,0.006199686
-0.063427731,-258.409729,38.06000137,0.006203798
-0.063525389,-259.2361145,38.11999893,0.006241264
-0.063623047,-260.0335693,38.18000031,0.006274
-0.063769534,-260.6522217,38.24000168,0.006283014
-0.063867185,-261.3105774,38.29999924,0.006319774
-0.063964842,-261.8020325,38.36000061,0.006335665
-0.0640625,-262.6254272,38.41999817,0.006362434
-0.064160158,-263.2337341,38.47999954,0.006397703
-0.064257816,-263.9997864,38.54000092,0.006411593
-0.064355467,-264.7013245,38.59999847,0.006440092
-0.064453125,-265.2612305,38.65999985,0.006451351
-0.064550783,-266.0739136,38.72000122,0.006495728
-0.06464844,-266.7080078,38.77999878,0.006513266
-0.06479492,-267.2618103,38.84000015,0.006542577
-0.064892578,-267.9454956,38.90000153,0.006576406
-0.064990236,-268.4183044,38.95999908,0.0066031
-0.065039065,-269.1413879,39.02000046,0.006631819
-0.065136715,-269.7106628,39.08000183,0.006639141
-0.065283202,-270.3254089,39.13999939,0.006669276
-0.06538086,-271.0006409,39.20000076,0.00670042
-0.065478518,-271.4587097,39.25999832,0.006727385
-0.065576169,-272.3173218,39.31999969,0.006759661
-0.065673827,-272.7434998,39.38000107,0.006780873
-0.065771485,-273.5097656,39.43999863,0.006806729
-0.065869142,-274.0629578,39.5,0.006846877
-0.0659668,-274.7094727,39.56000137,0.006866121
-0.066064451,-275.4789734,39.61999893,0.006895181
-0.066162109,-275.9299316,39.68000031,0.006900458
-0.066259767,-276.5863342,39.74000168,0.006941333
-0.066357425,-277.1308899,39.79999924,0.006975482
-0.066455075,-277.7138062,39.86000061,0.006994755
-0.066552733,-278.4247131,39.91999817,0.007014688
-0.066650391,-278.8494873,39.97999954,0.007025818
-0.066748049,-279.7149658,40.04000092,0.007054256
-0.0668457,-280.2184448,40.09999847,0.007083332
-0.066943358,-280.8287964,40.15999985,0.007094792
-0.067041015,-281.4547424,40.22000122,0.007123962
-0.067138673,-281.9327393,40.27999878,0.007139523
-0.067187502,-282.7376099,40.34000015,0.007182902
-0.067285153,-283.2616882,40.40000153,0.007190396
-0.067382811,-283.8560486,40.45999908,0.007210909
-0.067480469,-284.4602356,40.52000046,0.007265766
-0.067578127,-284.8591614,40.58000183,0.007274884
-0.067675785,-285.5427551,40.63999939,0.007312494
-0.067773435,-286.0207214,40.70000076,0.00735529
-0.067871093,-286.6526184,40.75999832,0.007389461
-0.067968751,-287.2013245,40.81999969,0.007424782
-0.068066409,-287.6722412,40.88000107,0.007446868
-0.068164059,-288.3657837,40.93999863,0.007483113
-0.068261717,-288.8071594,41,0.007524442
-0.068359375,-289.4957275,41.06000137,0.007567516
-0.068457033,-289.915863,41.11999893,0.00761104
-0.068603513,-290.3450317,41.18000031,0.007643858
-0.068701171,-291.0640564,41.24000168,0.007716686
-0.068798829,-291.3760376,41.29999924,0.007748989
-0.068896486,-292.0861816,41.36000061,0.007786463
-0.068994137,-292.7604065,41.41999817,0.007829468
-0.069091795,-293.2615356,41.47999954,0.007878143
-0.069189453,-293.9234009,41.54000092,0.007930063
-0.06933594,-294.3289185,41.59999847,0.007965279
-0.06943359,-294.9687805,41.65999985,0.0080233
-0.069531248,-295.6490784,41.72000122,0.008072095
-0.069628906,-296.1022949,41.77999878,0.008105196
-0.069775393,-296.5482178,41.84000015,0.008146771
-0.069873044,-296.8564453,41.90000153,0.008215205
-0.069970702,-297.4485474,41.95999908,0.008283298
-0.070068359,-297.6030579,42.02000046,0.008328599
-0.070166017,-298.0544739,42.08000183,0.008412929
-0.070263675,-298.4482727,42.13999939,0.008485948
-0.070361326,-298.5570679,42.20000076,0.008528136
-0.070458984,-298.9132996,42.25999832,0.008609876
-0.070605471,-298.7495728,42.31999969,0.008700009
-0.070703129,-298.6271362,42.38000107,0.008790831
-0.070800779,-298.5490112,42.43999863,0.008913899
-0.070898437,-298.0316772,42.5,0.009007561
-0.070996095,-297.1239014,42.56000137,0.00917333
-0.071093753,-295.0926514,42.61999893,0.009438275
-0.071191404,-292.0186157,42.68000031,0.009752512
-0.071289061,-281.4577942,42.74000168,0.010665173
-0.071386719,-266.8905029,42.79999924,0.011961992
-0.071484377,-256.3514709,42.86000061,0.013009379
-0.071582028,-248.6378021,42.91999817,0.013823354
-0.071679686,-240.7395325,42.97999954,0.014708821
-0.071826173,-225.542511,43.04000092,0.016264145
-0.071923831,-202.1131287,43.09999847,0.018738925
-0.072021481,-189.4775391,43.15999985,0.020278638
-0.072119139,-180.8310547,43.22000122,0.021312107
-0.072216797,-174.796051,43.27999878,0.022139495
-0.072314455,-169.3087158,43.34000015,0.022918695
-0.072412113,-164.7436066,43.40000153,0.023559602
-0.072509763,-160.8213806,43.45999908,0.024184723
-0.072558592,-157.8622284,43.52000046,0.024658708
-0.072705079,-156.1443176,43.58000183,0.025032132
-0.072802737,-154.8870392,43.63999939,0.02530456
-0.072851566,-153.815155,43.70000076,0.025556383
-0.072949217,-153.0354462,43.75999832,0.025805857
-0.073046875,-152.347702,43.81999969,0.02600826
-0.073144533,-151.7652435,43.88000107,0.026218439
-0.07324219,-151.1229248,43.93999863,0.026408514
-0.073339841,-150.6572266,44,0.026590107
-0.073437499,-150.2800446,44.06000137,0.026774378
-0.073535157,-149.7679138,44.11999893,0.026919013
-0.073632815,-149.5827179,44.18000031,0.027082877
-0.073730465,-149.099472,44.24000168,0.027251295
-0.073828123,-148.7697906,44.29999924,0.027418966
-0.073925781,-148.6489258,44.36000061,0.027569256
-0.07397461,-148.1212311,44.41999817,0.027723168
-0.074072268,-147.9151001,44.47999954,0.027877024
-0.074169919,-147.5660095,44.54000092,0.028025888
-0.074267577,-147.374115,44.59999847,0.028176577
-0.074365234,-147.0913544,44.65999985,0.028359329
-0.074462892,-145.7001648,44.72000122,0.028661718
-0.07456055,-144.7238159,44.77999878,0.028970871
-0.074658201,-143.3655853,44.84000015,0.029264917
-0.074755859,-142.5192108,44.90000153,0.029540815
-0.074853517,-141.6040955,44.95999908,0.029802688
-0.075000004,-140.6129913,45.02000046,0.030037554
-0.075097654,-139.9202423,45.08000183,0.030308338
-0.075195312,-138.8014069,45.13999939,0.030575666
-0.07529297,-138.1654968,45.20000076,0.030828534
-0.075390628,-137.3269501,45.25999832,0.031059652
-0.075488279,-136.4973145,45.31999969,0.031292722
-0.075585936,-135.5298615,45.38000107,0.031592015
-0.075683594,-134.017868,45.43999863,0.031924716
-0.075781252,-132.71138,45.5,0.032265449
-0.075927732,-131.2920074,45.56000137,0.03259378
-0.07602539,-129.7061615,45.61999893,0.032988235
-0.076123048,-128.0308228,45.68000031,0.033431057
-0.076220706,-125.9191666,45.74000168,0.033864013
-0.076367185,-123.5802078,45.79999924,0.034397613
-0.076464843,-120.8936768,45.86000061,0.034955789
-0.076562501,-118.3339005,45.91999817,0.035553763
-0.076660159,-115.8436661,45.97999954,0.036123361
-0.076757809,-113.1389389,46.04000092,0.036723013
-0.076855467,-110.5052414,46.09999847,0.037387257
-0.076953125,-107.6678772,46.15999985,0.038045084
-0.077099612,-105.0656586,46.22000122,0.038700266
-0.077197263,-102.4677811,46.27999878,0.03937685
-0.077294921,-100.2463837,46.34000015,0.039948751
-0.077392579,-97.83522034,46.40000153,0.040639734
-0.077490236,-94.56970215,46.45999908,0.041482745
-0.077587887,-91.43988037,46.52000046,0.042376207
-0.077685545,-87.73065948,46.58000183,0.043387627
-0.077783203,-83.02362823,46.63999939,0.044705397
-0.077880861,-76.68266296,46.70000076,0.046518166
-0.077978519,-70.68200684,46.75999832,0.048270653
-0.078076169,-66.18550873,46.81999969,0.049736373
-0.078222656,-62.8395462,46.88000107,0.050871251
-0.078320314,-59.71300888,46.93999863,0.051910458
-0.078417972,-57.30273819,47,0.052860956
-0.078515623,-54.77379608,47.06000137,0.05376252
-0.07861328,-52.77419281,47.11999893,0.054612683
-0.078710938,-50.88715363,47.18000031,0.05541644
-0.078808596,-48.92022324,47.24000168,0.056248035
-0.078906247,-47.21852493,47.29999924,0.057064924
-0.079003905,-45.5693779,47.36000061,0.057784455
-0.079101563,-44.31915665,47.41999817,0.058465721
-0.079199221,-42.89805222,47.47999954,0.059142643
-0.07924805,-41.5148468,47.54000092,0.059855964
-0.0793457,-40.12219238,47.59999847,0.060576422
-0.079443358,-38.7338829,47.65999985,0.061247243
-0.079541016,-37.81433105,47.72000122,0.061900493
-0.079638674,-36.80514908,47.77999878,0.062462823
-0.079736325,-36.01063156,47.84000015,0.062991166
-0.079833982,-35.11778259,47.90000153,0.063525978
-0.07993164,-34.31833267,47.95999908,0.064040265
-0.080029298,-33.50240326,48.02000046,0.064631233
-0.080126956,-32.48775482,48.08000183,0.065203785
-0.080224607,-31.44499779,48.13999939,0.065786349
-0.080322265,-30.40631485,48.20000076,0.066490335
-0.080419923,-29.01164436,48.25999832,0.067270419
-0.08051758,-27.76946068,48.31999969,0.068033762
-0.080615231,-25.8719368,48.38000107,0.068990848
-0.080712889,-24.10658264,48.43999863,0.070019625
-0.080810547,-21.33070183,48.5,0.071032409
-0.080908205,-18.41373825,48.56000137,0.072620896
-0.081005863,-14.82502651,48.61999893,0.07475551
-0.081103513,-11.43305874,48.68000031,0.076618751
-0.081201171,-8.67125988,48.74000168,0.078504752
-0.081298829,-6.465506077,48.79999924,0.080038531
-0.081396487,-4.891450405,48.86000061,0.081310034
-0.081494138,-3.421950102,48.91999817,0.082758874
-0.081591796,-1.681047678,48.97999954,0.084230691
-0.081689454,-0.507296324,49.04000092,0.085902422
-0.081787111,0.39173162,49.09999847,5.942543037
-0.081884762,0.470140934,49.15999985,5.651686341
-0.08198242,0.418463111,49.22000122,5.694843363
-0.082080078,0.580158532,49.27999878,5.682774819
-0.082177736,0.357338369,49.34000015,5.693650339
-0.082275394,0.450700372,49.40000153,5.694976076
-0.082421873,0.454681784,49.45999908,5.693745334
-0.082519531,0.435355633,49.52000046,5.694093648
-0.082617189,0.559723139,49.58000183,5.69432741
-0.082714847,0.37833631,49.63999939,5.693756975
-0.082812498,0.491747022,49.70000076,5.694553722
-0.082958984,0.39161405,49.75999832,5.694608204
-0.083056642,0.405959606,49.81999969,0.68528566
-0.0831543,0.50214982,49.88000107,0.675467716
-0.083251951,0.366750389,49.93999863,0.675487099
-0.083349609,0.496227264,50,0.675487448
-0.083447267,0.400509298,50.06000137,0.675490359
-0.083544925,0.416243762,50.11999893,0.675488089
-0.083691404,0.556218207,50.18000031,0.675491116
-0.083789062,0.362499028,50.24000168,0.675500662
-0.08388672,0.545296311,50.29999924,0.675499672
-0.083984378,0.446516991,50.36000061,0.675506948
-0.084082028,0.445242018,50.41999817,0.675500312
-0.084179686,0.577492118,50.47999954,0.675497053
-0.084277344,0.355428398,50.54000092,0.67550852
-0.084375002,0.514067709,50.59999847,0.675501011
-0.084472653,0.353495419,50.65999985,0.675506191
-0.084570311,0.460074216,50.72000122,0.675503397
-0.084667969,0.43319124,50.77999878,0.675502117
-0.084814455,0.328912884,50.84000015,0.675514049
-0.084912106,0.484536499,50.90000153,0.67549682
-0.085009764,0.355055422,50.95999908,0.675511023
-0.085107422,0.403697997,51.02000046,0.675508811
-0.08520508,0.47459814,51.08000183,0.675510557
-0.085302738,0.386182994,51.13999939,0.675507821
-0.085400388,0.546585739,51.20000076,0.675505958
-0.085498046,0.331964523,51.25999832,0.675516319
-0.085595704,0.424701065,51.31999969,0.675505202
-0.085693362,0.365171462,51.38000107,0.675507879
-0.085791013,0.431661069,51.43999863,0.675512129
-0.085888671,0.475361228,51.5,0.675503805
-0.085986328,0.253873169,51.56000137,0.675507938
-0.086083986,0.475151926,51.61999893,0.675504329
-0.086181637,0.420603395,51.68000031,0.67550427
-0.086230466,0.500401139,51.72000122,0.675512769