File: Data/Thesis_Samples_Data/Notched_Cast_6/Notched_Cast_6.csv
"File Path: C:\Users\Lab User\Desktop\Will\Thesis Tests\Test Run 13 04-9-22 14 36 21 PM\DAQ- Crosshead, … - (Timed).csv   ",,,
Test: MTS EM Tension (Extensometer) - Will 1,,,
Test Run: Test Run 13,,,
Date: 4/9/2022 2:34:50 PM,,,
,,,
,,,
Crosshead ,Load ,Time ,Extensometer
mm,N,sec,mm
0,-0.299609661,0.02,-6.75E-05
0,-0.349657714,0.059999999,-6.78E-05
-4.88E-05,-0.256271869,0.100000001,-6.95E-05
-4.88E-05,-0.39860177,0.140000001,-6.26E-05
-4.88E-05,-0.295326114,0.180000007,-7.04E-05
-9.77E-05,-0.319560647,0.219999999,-5.27E-05
-0.000146484,-0.363168776,0.25999999,-5.29E-05
-0.000195312,-0.299156308,0.300000012,-4.80E-05
-0.000195312,-0.556164861,0.340000004,-4.76E-05
-0.000244141,-0.420908809,0.379999995,-4.85E-05
-0.000292969,-0.476435214,0.419999987,-2.79E-05
-0.000341797,-0.63945806,0.460000008,-2.16E-05
-0.000439453,-0.495130807,0.5,-2.96E-05
-0.000488281,-0.719841123,0.540000021,-2.56E-05
-0.000537109,-0.733800411,0.579999983,-3.04E-05
-0.000634766,-0.849874914,0.620000005,-3.13E-06
-0.000683594,-0.871655822,0.660000026,-2.95E-06
-0.00078125,-0.914038777,0.699999988,-8.21E-06
-0.000830078,-1.104496837,0.74000001,5.50E-07
-0.000927734,-1.085376024,0.779999971,1.67E-06
-0.000976563,-1.255141377,0.819999993,1.30E-05
-0.001074219,-1.4330796,0.860000014,1.77E-05
-0.001171875,-1.391948223,0.899999976,2.00E-05
-0.001269531,-1.682874918,0.939999998,3.52E-05
-0.001367187,-1.630597591,0.980000019,2.85E-05
-0.001464844,-1.694993138,1.019999981,4.23E-05
-0.0015625,-1.859138727,1.059999943,4.36E-05
-0.001660156,-1.790814519,1.100000024,4.65E-05
-0.001757812,-2.03005147,1.139999986,6.06E-05
-0.001855469,-2.059422493,1.179999948,6.13E-05
-0.001904297,-2.056480408,1.220000029,7.16E-05
-0.002001953,-2.221967697,1.25999999,6.93E-05
-0.002050781,-2.126327991,1.299999952,7.26E-05
-0.002148437,-2.367178202,1.340000033,8.79E-05
-0.002197266,-2.308081865,1.379999995,7.87E-05
-0.002294922,-2.547491074,1.419999957,8.12E-05
-0.00234375,-2.585433006,1.460000038,9.05E-05
-0.002441406,-2.513608694,1.5,9.06E-05
-0.002490234,-2.708266497,1.539999962,0.000100454
-0.002539063,-2.746824741,1.580000043,9.14E-05
-0.002636719,-2.736156464,1.620000005,9.33E-05
-0.002685547,-2.912806273,1.659999967,0.000100559
-0.002734375,-2.832484722,1.700000048,9.43E-05
-0.002832031,-3.072402,1.74000001,0.000109363
-0.002880859,-3.090580702,1.779999971,9.67E-05
-0.002929688,-3.087198496,1.820000052,0.000116287
-0.003027344,-3.183357954,1.860000014,0.000110696
-0.003076172,-3.269486904,1.899999976,0.000109551
-0.003125,-3.391212225,1.940000057,0.000131369
-0.003173828,-3.324385166,1.980000019,0.000123628
-0.003271484,-3.343848944,2.019999981,0.000125493
-0.003320313,-3.599731684,2.059999943,0.000132692
-0.003369141,-3.508224487,2.099999905,0.000128149
-0.003466797,-3.701953411,2.140000105,0.000146189
-0.003515625,-3.726433277,2.180000067,0.000134239
-0.003564453,-3.829100847,2.220000029,0.000144113
-0.003662109,-4.011885166,2.25999999,0.00014734
-0.003710938,-3.950245142,2.299999952,0.000133047
-0.003759766,-4.045521259,2.339999914,0.000157066
-0.003857422,-4.188979626,2.380000114,0.000153695
-0.00390625,-4.251612663,2.420000076,0.00014851
-0.004003906,-4.428931713,2.460000038,0.000156302
-0.004052734,-4.400669098,2.5,0.000151831
-0.004101562,-4.466425896,2.539999962,0.000170847
-0.004199219,-4.578035355,2.579999924,0.000163914
-0.004248047,-4.570596218,2.619999886,0.000166242
-0.004345703,-4.81827116,2.660000086,0.000173743
-0.004394531,-4.783508301,2.700000048,0.000165075
-0.004492188,-4.964275837,2.74000001,0.00018306
-0.004541016,-5.108834267,2.779999971,0.000174936
-0.004638672,-5.075879097,2.819999933,0.000175716
-0.0046875,-5.263712883,2.859999895,0.000183533
-0.004736328,-5.308780193,2.900000095,0.000179321
-0.004833984,-5.512094498,2.940000057,0.00019176
-0.00493164,-5.59387064,2.980000019,0.000196493
-0.004980469,-5.579718113,3.019999981,0.000197962
-0.005029297,-5.884126663,3.059999943,0.000199033
-0.005126953,-5.756936073,3.099999905,0.000192734
-0.005175781,-5.903204441,3.140000105,0.000206259
-0.005273438,-6.147807121,3.180000067,0.000202748
-0.005322266,-6.127444267,3.220000029,0.000213322
-0.005419922,-6.353460312,3.25999999,0.000215499
-0.00546875,-6.338650227,3.299999952,0.000214573
-0.005566406,-6.411488056,3.339999914,0.000223314
-0.005615234,-6.687910557,3.380000114,0.000233709
-0.00571289,-6.61820364,3.420000076,0.000228082
-0.005761719,-6.84437561,3.460000038,0.000238351
-0.005810547,-6.777153492,3.5,0.000235134
-0.005908203,-6.943995953,3.539999962,0.000244668
-0.005957031,-7.187703609,3.579999924,0.000248372
-0.006054688,-7.112710476,3.619999886,0.000256971
-0.006103516,-7.364834309,3.660000086,0.000261987
-0.006201172,-7.364724636,3.700000048,0.00026264
-0.00625,-7.484126091,3.74000001,0.000282777
-0.006298828,-7.613510609,3.779999971,0.000274786
-0.006396484,-7.563399792,3.819999933,0.000272507
-0.006445312,-7.905629635,3.859999895,0.000293898
-0.006494141,-7.989592075,3.900000095,0.000282924
-0.006591797,-8.087061882,3.940000057,0.000288782
-0.006640625,-8.137566566,3.980000019,0.000289027
-0.006738281,-8.208415031,4.019999981,0.000285008
-0.006787109,-8.512822151,4.059999943,0.000298611
-0.006835938,-8.511533737,4.099999905,0.000295669
-0.006933594,-8.528243065,4.139999866,0.000294145
-0.006982422,-8.809762955,4.179999828,0.000304081
-0.007080078,-8.749638557,4.21999979,0.000301746
-0.007128906,-9.000548363,4.260000229,0.000315765
-0.007226563,-9.114474297,4.300000191,0.000305584
-0.007275391,-9.083545685,4.340000153,0.000313709
-0.007324219,-9.50398159,4.380000114,0.000322224
-0.007421875,-9.380504608,4.420000076,0.000311177
-0.007470703,-9.566900253,4.460000038,0.000331181
-0.007519531,-9.660471916,4.5,0.000326901
-0.007617187,-9.796185493,4.539999962,0.000338341
-0.007666015,-9.977417946,4.579999924,0.000341412
-0.007763672,-9.938136101,4.619999886,0.000343821
-0.0078125,-10.19419098,4.659999847,0.000354086
-0.007861328,-10.32906151,4.699999809,0.000348234
-0.007958984,-10.29349804,4.739999771,0.000353104
-0.008007813,-10.63954639,4.78000021,0.000357984
-0.008056641,-10.60361767,4.820000172,0.000358085
-0.008154297,-10.8602047,4.860000134,0.00037384
-0.008203125,-10.87883377,4.900000095,0.000370566
-0.008251953,-10.96762943,4.940000057,0.000378782
-0.00834961,-11.14946938,4.980000019,0.000386003
-0.008398438,-11.21413898,5.019999981,0.00037928
-0.008447266,-11.36069775,5.059999943,0.000393711
-0.008544922,-11.57766914,5.099999905,0.000394103
-0.00859375,-11.53210449,5.139999866,0.000402863
-0.008642578,-11.82152367,5.179999828,0.000402618
-0.008740234,-11.76233768,5.21999979,0.000396873
-0.008789062,-11.93517017,5.260000229,0.000409954
-0.008837891,-12.01349163,5.300000191,0.000415511
-0.008886719,-12.01447773,5.340000153,0.000423467
-0.008984375,-12.3259306,5.380000114,0.000427782
-0.009033203,-12.33977318,5.420000076,0.00042623
-0.009082031,-12.46105766,5.460000038,0.000424838
-0.009179687,-12.65262032,5.5,0.000422671
-0.009228515,-12.75679588,5.539999962,0.000427407
-0.009277343,-12.99062443,5.579999924,0.000431172
-0.009326171,-13.00076294,5.619999886,0.000421651
-0.009423828,-13.13703442,5.659999847,0.000438917
-0.009472657,-13.28862762,5.699999809,0.000441278
-0.009521485,-13.27716637,5.739999771,0.000441347
-0.009619141,-13.52927399,5.78000021,0.000451089
-0.009667969,-13.6676712,5.820000172,0.00044391
-0.009716797,-13.83049107,5.860000134,0.00046061
-0.009814453,-13.96862316,5.900000095,0.000459596
-0.009863281,-13.88518238,5.940000057,0.000466637
-0.00991211,-14.20834637,5.980000019,0.000477207
-0.009960938,-14.32003212,6.019999981,0.000468557
-0.010058594,-14.43537045,6.059999943,0.000489874
-0.010107422,-14.58025551,6.099999905,0.000489816
-0.01015625,-14.49941158,6.139999866,0.000483957
-0.010253906,-14.81368732,6.179999828,0.000509524
-0.010302734,-14.89984226,6.21999979,0.000499914
-0.010351562,-15.01043701,6.260000229,0.000511452
-0.010449219,-15.26561069,6.300000191,0.00051816
-0.010498047,-15.34023476,6.340000153,0.000517411
-0.010546875,-15.52409077,6.380000114,0.000526969
-0.010644531,-15.63279152,6.420000076,0.000522597
-0.010693359,-15.6707058,6.460000038,0.000525137
-0.010791015,-15.97010899,6.5,0.000537849
-0.010839844,-15.93147755,6.539999962,0.000531846
-0.010888672,-16.17543602,6.579999924,0.000546546
-0.010986329,-16.19814301,6.619999886,0.000538154
-0.011035157,-16.39140701,6.659999847,0.000542425
-0.011132813,-16.62185669,6.699999809,0.00055367
-0.011181641,-16.69594574,6.739999771,0.000549863
-0.011279297,-16.80972672,6.78000021,0.00056375
-0.011328125,-16.94927216,6.820000172,0.000563938
-0.011376953,-17.06585693,6.860000134,0.000567386
-0.011474609,-17.40447426,6.900000095,0.000572329
-0.011523438,-17.31468391,6.940000057,0.000570565
-0.011621094,-17.56797028,6.980000019,0.00058773
-0.011669922,-17.75130653,7.019999981,0.000585481
-0.011767578,-17.86179543,7.059999943,0.000585286
-0.011816406,-18.14207268,7.099999905,0.000586467
-0.011914062,-18.13591576,7.139999866,0.000580545
-0.01196289,-18.3918457,7.179999828,0.000599456
-0.012060547,-18.5650959,7.21999979,0.000604242
-0.012109375,-18.51079941,7.260000229,0.000603968
-0.012158203,-18.84309578,7.300000191,0.000606891
-0.012255859,-18.8799057,7.340000153,0.000612844
-0.012304688,-19.16784668,7.380000114,0.000613664
-0.012402344,-19.25721359,7.420000076,0.000620364
-0.012451172,-19.32356071,7.460000038,0.000625276
-0.0125,-19.67736244,7.5,0.00063459
-0.012597657,-19.7226696,7.539999962,0.000625907
-0.012646485,-19.91523361,7.579999924,0.000636843
-0.012744141,-19.97112846,7.619999886,0.000650503
-0.012792969,-20.30609512,7.659999847,0.000650198
-0.012841797,-20.35224342,7.699999809,0.000656366
-0.012939453,-20.35079956,7.739999771,0.000656251
-0.012988281,-20.57514763,7.78000021,0.000663213
-0.013085937,-20.80587387,7.820000172,0.000675293
-0.013134766,-20.95710373,7.860000134,0.000675284
-0.013183594,-21.1648922,7.900000095,0.000689301
-0.01328125,-21.07176208,7.940000057,0.000680145
-0.013330078,-21.33252907,7.980000019,0.000687899
-0.013427734,-21.54310417,8.020000458,0.000691053
-0.013476562,-21.56289291,8.06000042,0.000685221
-0.01352539,-21.8216629,8.100000381,0.000696584
-0.013623046,-21.80719566,8.140000343,0.000697845
-0.013671875,-22.05013657,8.180000305,0.000706204
-0.013720703,-22.29639626,8.220000267,0.000702491
-0.01381836,-22.30136681,8.260000229,0.000709824
-0.013867188,-22.63194656,8.300000191,0.000730335
-0.013916016,-22.66345406,8.340000153,0.000720205
-0.014013672,-22.82756805,8.380000114,0.000727304
-0.0140625,-22.9689846,8.420000076,0.000741195
-0.014160156,-22.97761345,8.460000038,0.000723821
-0.014208985,-23.34575272,8.5,0.000746521
-0.014257813,-23.44602394,8.539999962,0.000745105
-0.014355469,-23.54560089,8.579999924,0.000747664
-0.014404297,-23.84481621,8.619999886,0.000759124
-0.014453125,-23.80109215,8.659999847,0.000747393
-0.014550781,-24.08099747,8.699999809,0.000763439
-0.014599609,-24.17085838,8.739999771,0.000756196
-0.014648437,-24.31642914,8.779999733,0.000760797
-0.014746094,-24.55469131,8.819999695,0.000777359
-0.014794922,-24.58087158,8.859999657,0.000768138
-0.01484375,-24.78875732,8.899999619,0.000781044
-0.014892578,-24.87044525,8.93999958,0.000778245
-0.014990234,-24.99844742,8.979999542,0.000788864
-0.015039062,-25.34202385,9.020000458,0.000791226
-0.01508789,-25.31470108,9.06000042,0.000785431
-0.015185547,-25.44167709,9.100000381,0.000806356
-0.015234375,-25.66791916,9.140000343,0.000799403
-0.015283204,-25.79302406,9.180000305,0.00081026
-0.01538086,-26.11623764,9.220000267,0.000818186
-0.015429687,-26.05932617,9.260000229,0.000814062
-0.015478516,-26.37672043,9.300000191,0.000829124
-0.015576172,-26.48411369,9.340000153,0.000825723
-0.015625001,-26.56682777,9.380000114,0.000829529
-0.015673828,-26.82375336,9.420000076,0.000839138
-0.015722657,-26.84975815,9.460000038,0.00084374
-0.015820313,-27.12366295,9.5,0.000843814
-0.01586914,-27.21299171,9.539999962,0.000848812
-0.015917969,-27.19612122,9.579999924,0.000853461
-0.016015625,-27.6288681,9.619999886,0.000861773
-0.016064454,-27.55537415,9.659999847,0.000857111
-0.016113281,-27.82673264,9.699999809,0.000872667
-0.01616211,-27.9486599,9.739999771,0.000873793
-0.016259766,-28.01606941,9.779999733,0.000873189
-0.016308593,-28.37675285,9.819999695,0.00088659
-0.016357422,-28.37459755,9.859999657,0.000877313
-0.016406249,-28.54411125,9.899999619,0.000891219
-0.016503905,-28.74256706,9.93999958,0.000892318
-0.016552734,-28.89213371,9.979999542,0.000898718
-0.016601563,-29.11067772,10.02000046,0.000897298
-0.016699219,-29.17035294,10.06000042,0.000882383
-0.016748047,-29.38849068,10.10000038,0.000898739
-0.016796876,-29.57470322,10.14000034,0.000899297
-0.016894532,-29.63156128,10.18000031,0.000900014
-0.016943359,-29.93340111,10.22000027,0.000914229
-0.016992188,-30.03610229,10.26000023,0.000913853
-0.017089844,-30.26893806,10.30000019,0.000919293
-0.017138673,-30.4821167,10.34000015,0.000916362
-0.0171875,-30.43706894,10.38000011,0.00091531
-0.017285156,-30.79016113,10.42000008,0.000927394
-0.017333985,-30.88657761,10.46000004,0.000928522
-0.017431641,-31.07159805,10.5,0.000931585
-0.017480468,-31.3377285,10.53999996,0.000939802
-0.017529297,-31.39126015,10.57999992,0.000941019
-0.017626953,-31.72802734,10.61999989,0.000949781
-0.017675782,-31.74555969,10.65999985,0.000946889
-0.017773438,-31.94331551,10.69999981,0.00095996
-0.017822265,-32.19161606,10.73999977,0.000963271
-0.017871094,-32.26181412,10.77999973,0.000963887
-0.01796875,-32.49505997,10.81999969,0.000974433
-0.018017578,-32.73963547,10.85999966,0.000979198
-0.018115234,-32.83837891,10.89999962,0.000974664
-0.018164063,-33.15616989,10.93999958,0.000990473
-0.018261719,-33.19355011,10.97999954,0.000977122
-0.018310548,-33.53693008,11.02000046,0.000998875
-0.018408204,-33.61755753,11.06000042,0.000992401
-0.018457031,-33.87404251,11.10000038,0.000993745
-0.018554687,-34.1632309,11.14000034,0.00100744
-0.018603516,-34.23176956,11.18000031,0.00100087
-0.018701172,-34.45740891,11.22000027,0.001007359
-0.018750001,-34.62994766,11.26000023,0.001011216
-0.018798828,-34.74487686,11.30000019,0.00101742
-0.018896484,-35.08753586,11.34000015,0.001034805
-0.018945313,-35.07736588,11.38000011,0.001017197
-0.019042969,-35.40270996,11.42000008,0.00104023
-0.019091796,-35.56461716,11.46000004,0.001036681
-0.019189452,-35.76452637,11.5,0.001043951
-0.019238281,-36.00946045,11.53999996,0.001045189
-0.019335937,-36.01411438,11.57999992,0.00104196
-0.019384766,-36.35577011,11.61999989,0.001054074
-0.019433593,-36.57663345,11.65999985,0.001043249
-0.01953125,-36.71052933,11.69999981,0.001044047
-0.019580079,-37.02441788,11.73999977,0.001055815
-0.019677735,-37.00883865,11.77999973,0.001054091
-0.019726562,-37.28344345,11.81999969,0.001058071
-0.019775391,-37.46087265,11.85999966,0.001062143
-0.019873047,-37.60031128,11.89999962,0.001070558
-0.019921876,-37.97548676,11.93999958,0.001079203
-0.020019532,-38.07772827,11.97999954,0.001075394
-0.020068359,-38.30178833,12.02000046,0.001089442
-0.020166015,-38.5143013,12.06000042,0.001088071
-0.020214844,-38.58306885,12.10000038,0.001085014
-0.020263671,-38.98817825,12.14000034,0.001094211
-0.020361329,-38.89067078,12.18000031,0.001086117
-0.020410156,-39.24282837,12.22000027,0.001104056
-0.020507812,-39.4951973,12.26000023,0.001096699
-0.020556641,-39.52267075,12.30000019,0.001100414
-0.020605468,-39.88535309,12.34000015,0.001107334
-0.020703124,-39.89456558,12.38000011,0.001108636
-0.020751953,-40.27048111,12.42000008,0.001115582
-0.02080078,-40.47153854,12.46000004,0.001129054
-0.020898438,-40.48470306,12.5,0.001125956
-0.020947266,-40.79308319,12.53999996,0.001124825
-0.021044922,-40.90144348,12.57999992,0.001130643
-0.021093751,-41.11732483,12.61999989,0.00114248
-0.021142578,-41.40589905,12.65999985,0.001145359
-0.021240234,-41.35442352,12.69999981,0.001140042
-0.021289063,-41.84002304,12.73999977,0.001153431
-0.02133789,-41.86250305,12.77999973,0.001157687
-0.021435548,-42.05323029,12.81999969,0.00116677
-0.021484375,-42.34273148,12.85999966,0.001161807
-0.021533204,-42.36656189,12.89999962,0.001170594
-0.02163086,-42.75818253,12.93999958,0.001182078
-0.021679687,-42.87057877,12.97999954,0.001182669
-0.021728516,-42.96391296,13.02000046,0.001184993
-0.021826172,-43.29304123,13.06000042,0.001190474
-0.021874999,-43.30664444,13.10000038,0.001190249
-0.021923828,-43.6819191,13.14000034,0.001201954
-0.021972657,-43.7138443,13.18000031,0.001197043
-0.022070313,-43.9432373,13.22000027,0.001203625
-0.02211914,-44.26167679,13.26000023,0.001211061
-0.022167969,-44.26719666,13.30000019,0.001211715
-0.022265625,-44.49728394,13.34000015,0.001220677
-0.022314453,-44.68647766,13.38000011,0.001216635
-0.022363281,-44.83475494,13.42000008,0.001231915
-0.022460938,-45.24106979,13.46000004,0.001238411
-0.022509766,-45.16059875,13.5,0.001232532
-0.022558594,-45.49067307,13.53999996,0.00124808
-0.022607423,-45.70957947,13.57999992,0.001243112
-0.022705079,-45.8468895,13.61999989,0.001250308
-0.022753906,-46.11780548,13.65999985,0.001264189
-0.022802735,-46.25233459,13.69999981,0.001255618
-0.022900391,-46.4585762,13.73999977,0.001269471
-0.022949218,-46.69779968,13.77999973,0.001278096
-0.022998047,-46.73466873,13.81999969,0.001267545
-0.023095703,-47.07400513,13.85999966,0.001284312
-0.023144532,-47.3311348,13.89999962,0.001282347
-0.023193359,-47.57014847,13.93999958,0.001298486
-0.023291015,-47.67713165,13.97999954,0.001296346
-0.023339844,-47.82167435,14.02000046,0.001290727
-0.023388671,-48.11177063,14.06000042,0.001290737
-0.023486327,-48.16648483,14.10000038,0.001296177
-0.023535156,-48.55783463,14.14000034,0.0012962
-0.023583985,-48.73004532,14.18000031,0.001312209
-0.023681641,-48.73381424,14.22000027,0.001314419
-0.023730468,-49.18904114,14.26000023,0.001320184
-0.023779297,-49.20871353,14.30000019,0.001314517
-0.023876953,-49.47730637,14.34000015,0.001331707
-0.023925781,-49.78771591,14.38000011,0.001328064
-0.02397461,-49.8278656,14.42000008,0.001333493
-0.024072266,-50.22407532,14.46000004,0.001339472
-0.024121095,-50.18650818,14.5,0.00134364
-0.024218751,-50.53769302,14.53999996,0.001341897
-0.024267578,-50.83462524,14.57999992,0.00134483
-0.024316407,-50.95172119,14.61999989,0.001356099
-0.024414063,-51.27537155,14.65999985,0.001364137
-0.02446289,-51.38343811,14.69999981,0.001372025
-0.024560546,-51.68309021,14.73999977,0.001375173
-0.024609375,-52.02894211,14.77999973,0.001375861
-0.024707031,-52.01676178,14.81999969,0.001372682
-0.02475586,-52.39996719,14.85999966,0.001395784
-0.024853516,-52.544487,14.89999962,0.001403797
-0.024902343,-52.88485336,14.93999958,0.001399748
-0.024999999,-53.10956192,14.97999954,0.001405341
-0.025048828,-53.26739502,15.02000046,0.0014034
-0.025146484,-53.5770874,15.06000042,0.00142319
-0.025195313,-53.84249115,15.10000038,0.001418197
-0.025292969,-54.01412201,15.14000034,0.00142922
-0.025341797,-54.31508255,15.18000031,0.001444923
-0.025390626,-54.26295853,15.22000027,0.001438762
-0.025488282,-54.73479843,15.26000023,0.001447868
-0.025537109,-54.9152832,15.30000019,0.001449889
-0.025634765,-55.08271027,15.34000015,0.001462307
-0.025683594,-55.44543076,15.38000011,0.001465527
-0.025732423,-55.54712677,15.42000008,0.001465243
-0.025830079,-55.78347778,15.46000004,0.001484648
-0.025878906,-55.9877243,15.5,0.001473014
-0.025976562,-56.1798172,15.53999996,0.001483379
-0.026025391,-56.63955688,15.57999992,0.001492108
-0.026123047,-56.65046692,15.61999989,0.001483878
-0.026171874,-56.90720749,15.65999985,0.001506629
-0.026220703,-57.25048065,15.69999981,0.001495699
-0.026318359,-57.38282394,15.73999977,0.001502569
-0.026367188,-57.84408188,15.77999973,0.001513524
-0.026416015,-57.82850647,15.81999969,0.001513937
-0.026513671,-58.03232574,15.85999966,0.00152861
-0.0265625,-58.29073715,15.89999962,0.001527932
-0.026611327,-58.38503265,15.93999958,0.00153842
-0.026708984,-58.73286438,15.97999954,0.00154533
-0.026757813,-58.86919022,16.02000046,0.001540431
-0.026806641,-59.15250778,16.05999947,0.001551036
-0.026904298,-59.45362854,16.10000038,0.001549532
-0.026953125,-59.57579041,16.13999939,0.001562786
-0.027050781,-59.85970688,16.18000031,0.001569351
-0.02709961,-59.96037674,16.21999931,0.001563281
-0.027148437,-60.23872757,16.26000023,0.001575183
-0.027246093,-60.43356705,16.29999924,0.001579326
-0.027294922,-60.67598724,16.34000015,0.001593619
-0.027392578,-61.06942749,16.37999916,0.001599215
-0.027441407,-61.11546707,16.42000008,0.001591365
-0.027490234,-61.3800087,16.45999908,0.001602701
-0.02758789,-61.58468246,16.5,0.001612373
-0.027636719,-61.79448318,16.54000092,0.001611703
-0.027685546,-62.13121033,16.57999992,0.001634993
-0.027783202,-62.22192764,16.62000084,0.001627946
-0.027832031,-62.56774902,16.65999985,0.001645183
-0.02788086,-62.73962021,16.70000076,0.001637571
-0.027978516,-62.79177475,16.73999977,0.001636823
-0.028027343,-63.25497055,16.78000069,0.001655409
-0.028076172,-63.28813553,16.81999969,0.001637165
-0.028173828,-63.49571609,16.86000061,0.001667452
-0.028222656,-63.90975189,16.89999962,0.001668392
-0.028271485,-63.92625809,16.94000053,0.001665848
-0.028369141,-64.33069611,16.97999954,0.001682037
-0.02841797,-64.44776917,17.02000046,0.00167224
-0.028466797,-64.78276825,17.05999947,0.001678281
-0.028564453,-64.97045898,17.10000038,0.001687518
-0.028613282,-65.07479095,17.13999939,0.001687707
-0.028662109,-65.36068726,17.18000031,0.001698638
-0.028710938,-65.56092072,17.21999931,0.001699165
-0.028808594,-65.77510834,17.26000023,0.001698841
-0.028857421,-65.97909546,17.29999924,0.001706931
-0.02890625,-66.07402802,17.34000015,0.001719513
-0.029003906,-66.45558167,17.37999916,0.001741736
-0.029052735,-66.64422607,17.42000008,0.001734485
-0.029101562,-66.86574554,17.45999908,0.001736269
-0.029150391,-67.15963745,17.5,0.001743433
-0.029248047,-67.27797699,17.54000092,0.001739513
-0.029296874,-67.68663025,17.57999992,0.001762061
-0.029345703,-67.67597961,17.62000084,0.001761241
-0.029443359,-67.94197845,17.65999985,0.001766841
-0.029492188,-68.28437805,17.70000076,0.001772482
-0.029541015,-68.34619141,17.73999977,0.001771741
-0.029589844,-68.62010193,17.78000069,0.001790535
-0.029687501,-68.81532288,17.81999969,0.001787723
-0.029736328,-68.98110199,17.86000061,0.001798645
-0.029785157,-69.39385986,17.89999962,0.001799669
-0.029833984,-69.39673615,17.94000053,0.001803766
-0.02993164,-69.6767807,17.97999954,0.001821029
-0.029980469,-69.96450043,18.02000046,0.001812476
-0.030029298,-70.24051666,18.05999947,0.001825534
-0.030126954,-70.63719177,18.10000038,0.001837877
-0.030175781,-70.72431183,18.13999939,0.00182667
-0.03022461,-70.93140411,18.18000031,0.001849656
-0.030322266,-71.20824432,18.21999931,0.001844782
-0.030371093,-71.40568542,18.26000023,0.001857947
-0.030419922,-71.71333313,18.29999924,0.00187112
-0.030517578,-71.7884903,18.34000015,0.001868639
-0.030566407,-72.17917633,18.37999916,0.00188312
-0.030615236,-72.34915924,18.42000008,0.001894961
-0.03071289,-72.49445343,18.45999908,0.001892861
-0.030761719,-72.9550705,18.5,0.001901773
-0.030859374,-73.08821106,18.54000092,0.001895311
-0.030908202,-73.43107605,18.57999992,0.001915625
-0.030957031,-73.67267609,18.62000084,0.00191554
-0.031054689,-73.61780548,18.65999985,0.001910334
-0.031103515,-74.13609314,18.70000076,0.001933387
-0.031152344,-74.27910614,18.73999977,0.001914755
-0.031250001,-74.64196777,18.78000069,0.001948986
-0.031298827,-74.94229889,18.81999969,0.001948843
-0.031396485,-75.09936523,18.86000061,0.001937034
-0.031445314,-75.54214478,18.89999962,0.001954503
-0.031542968,-75.65594482,18.94000053,0.001960027
-0.031591797,-75.99699402,18.97999954,0.001961075
-0.031689455,-76.31506348,19.02000046,0.001972436
-0.03173828,-76.40883636,19.05999947,0.001979581
-0.031787109,-76.80387878,19.10000038,0.001988806
-0.031884767,-76.9709549,19.13999939,0.001989173
-0.031933592,-77.33472443,19.18000031,0.0019995
-0.03203125,-77.51753998,19.21999931,0.002001206
-0.032080079,-77.75340271,19.26000023,0.00201376
-0.032177733,-78.06278229,19.29999924,0.002022726
-0.032226562,-78.37399292,19.34000015,0.002022701
-0.032275391,-78.63432312,19.37999916,0.002036021
-0.032373046,-78.91580963,19.42000008,0.00203714
-0.032421874,-79.08940125,19.45999908,0.002041206
-0.032519532,-79.4708786,19.5,0.002049759
-0.032568358,-79.72774506,19.54000092,0.00206355
-0.032617187,-79.96908569,19.57999992,0.002062581
-0.032714845,-80.33187103,19.62000084,0.002061484
-0.032763674,-80.42655182,19.65999985,0.002070867
-0.032861328,-80.78945923,19.70000076,0.00209245
-0.032910157,-80.97844696,19.73999977,0.002085358
-0.032958986,-81.25785828,19.78000069,0.00208709
-0.03305664,-81.66342163,19.81999969,0.002095875
-0.033105469,-81.83898163,19.86000061,0.002090519
-0.033203127,-82.05957794,19.89999962,0.002109982
-0.033251952,-82.44682312,19.94000053,0.002104088
-0.033300781,-82.58921814,19.97999954,0.002109496
-0.033398439,-83.06434631,20.02000046,0.002124256
-0.033447264,-83.18106079,20.05999947,0.002124693
-0.033544922,-83.53839111,20.10000038,0.00213648
-0.033593751,-83.70635986,20.13999939,0.002132778
-0.033642576,-83.98217773,20.18000031,0.002134851
-0.033740234,-84.39138794,20.21999931,0.002146572
-0.033789063,-84.4858551,20.26000023,0.002143823
-0.033837892,-84.82047272,20.29999924,0.002156709
-0.033935547,-85.14256287,20.34000015,0.002167789
-0.033984375,-85.24607086,20.37999916,0.002160015
-0.034033204,-85.75175476,20.42000008,0.002171955
-0.034130859,-85.75276184,20.45999908,0.00217072
-0.034179688,-86.19286346,20.5,0.002194001
-0.034228517,-86.41856384,20.54000092,0.002194791
-0.034326171,-86.59124756,20.57999992,0.002201224
-0.034375,-87.01107788,20.62000084,0.002207313
-0.034423829,-87.10281372,20.65999985,0.002204389
-0.034521483,-87.50935364,20.70000076,0.002219348
-0.034570312,-87.84015656,20.73999977,0.002235871
-0.034619141,-87.84445953,20.78000069,0.00223033
-0.034716795,-88.40551758,20.81999969,0.002244079
-0.034765624,-88.49526978,20.86000061,0.002244348
-0.034814453,-88.83932495,20.89999962,0.00226154
-0.034912111,-89.08136749,20.94000053,0.002264456
-0.034960936,-89.26587677,20.97999954,0.002266342
-0.035009765,-89.61766052,21.02000046,0.002280129
-0.035107423,-89.78543091,21.05999947,0.002265468
-0.035156248,-90.07040405,21.10000038,0.002291508
-0.035205077,-90.47009277,21.13999939,0.002292639
-0.035253906,-90.62542725,21.18000031,0.002295654
-0.035351564,-91.10215759,21.21999931,0.002312393
-0.03540039,-91.21893311,21.26000023,0.002309939
-0.035449219,-91.46589661,21.29999924,0.002325862
-0.035546876,-91.89299774,21.34000015,0.002316347
-0.035595702,-92.00111389,21.37999916,0.002326922
-0.035644531,-92.32551575,21.42000008,0.002341364
-0.035742189,-92.50469971,21.45999908,0.002341849
-0.035791014,-92.87089539,21.5,0.002348874
-0.035839843,-93.23165131,21.54000092,0.002363873
-0.035888672,-93.29759979,21.57999992,0.002350548
-0.03598633,-93.65415192,21.62000084,0.002364161
-0.036035155,-93.97975159,21.65999985,0.002362337
-0.036083984,-94.20230865,21.70000076,0.002382226
-0.036181642,-94.57675171,21.73999977,0.002389894
-0.036230467,-94.7039566,21.78000069,0.00238915
-0.036279296,-95.21789551,21.81999969,0.002407369
-0.036376954,-95.33602142,21.86000061,0.002412389
-0.036425783,-95.50570679,21.89999962,0.002413597
-0.036474608,-95.86193085,21.94000053,0.002422502
-0.036523437,-96.11255646,21.97999954,0.002426915
-0.036621095,-96.52055359,22.02000046,0.002437599
-0.036669921,-96.76477051,22.05999947,0.002441062
-0.036718749,-96.91034698,22.10000038,0.002447763
-0.036816407,-97.30323029,22.13999939,0.002458851
-0.036865233,-97.57003021,22.18000031,0.002460429
-0.036914062,-97.98047638,22.21999931,0.002481464
-0.03701172,-98.19794464,22.26000023,0.002477558
-0.037060548,-98.48200989,22.29999924,0.002481238
-0.037109374,-98.87445068,22.34000015,0.002493934
-0.037207032,-98.95079041,22.37999916,0.002486716
-0.037255861,-99.4485321,22.42000008,0.002511408
-0.037304686,-99.75504303,22.45999908,0.002511581
-0.037402344,-99.98258972,22.5,0.002518479
-0.037451173,-100.4679565,22.54000092,0.002527897
-0.037548827,-100.563797,22.57999992,0.002530107
-0.037597656,-100.9598541,22.62000084,0.002552464
-0.037646485,-101.3762894,22.65999985,0.002544834
-0.037744139,-101.5238419,22.70000076,0.002557578
-0.037792968,-102.0467834,22.73999977,0.00257182
-0.037890626,-102.2949829,22.78000069,0.002565172
-0.037939451,-102.6998215,22.81999969,0.00257692
-0.038037109,-102.9307404,22.86000061,0.002590185
-0.038085938,-103.2140884,22.89999962,0.002592913
-0.038183593,-103.6347046,22.94000053,0.002613937
-0.038232422,-103.996582,22.97999954,0.002611476
-0.038330079,-104.3156509,23.02000046,0.002623629
-0.038378905,-104.7590332,23.05999947,0.002623075
-0.038476563,-104.8688889,23.10000038,0.002628891
-0.038525392,-105.4530563,23.13999939,0.002643934
-0.038623046,-105.5548477,23.18000031,0.002643657
-0.038671875,-105.9953384,23.21999931,0.002646255
-0.038769533,-106.2953491,23.26000023,0.0026622
-0.038818358,-106.5842209,23.29999924,0.00265809
-0.038867187,-106.9861679,23.34000015,0.002674864
-0.038964845,-107.29039,23.37999916,0.002670389
-0.03901367,-107.5890198,23.42000008,0.002689221
-0.039111328,-108.0746536,23.45999908,0.002697134
-0.039160157,-108.2675781,23.5,0.002705824
-0.039257811,-108.7720795,23.54000092,0.002720748
-0.03930664,-108.951767,23.57999992,0.002709243
-0.039404298,-109.2833176,23.62000084,0.002717413
-0.039453123,-109.6988297,23.65999985,0.002734715
-0.039550781,-109.8953018,23.70000076,0.00273704
-0.03959961,-110.3213272,23.73999977,0.002748571
-0.039648439,-110.6260757,23.78000069,0.002756527
-0.039746094,-110.9848785,23.81999969,0.002759884
-0.039794922,-111.4847412,23.86000061,0.002776171
-0.039892577,-111.4554214,23.89999962,0.002775002
-0.039941406,-111.9791183,23.94000053,0.002790758
-0.039990235,-112.3045425,23.97999954,0.002787265
-0.040087889,-112.5437012,24.02000046,0.002811375
-0.040136718,-112.9585037,24.05999947,0.002817828
-0.040234376,-113.0942993,24.10000038,0.002817828
-0.040283205,-113.6932831,24.13999939,0.00283478
-0.040380859,-113.9314346,24.18000031,0.002841586
-0.040429688,-114.1493149,24.21999931,0.002846202
-0.040478517,-114.6796417,24.26000023,0.002855206
-0.040576171,-114.8030624,24.29999924,0.00285098
-0.040625,-115.1579285,24.34000015,0.00287209
-0.040673829,-115.5338821,24.37999916,0.00287473
-0.040771483,-115.7118378,24.42000008,0.002883648
-0.040820312,-116.2889481,24.45999908,0.002896045
-0.040869141,-116.365242,24.5,0.002895665
-0.040966795,-116.8595123,24.54000092,0.002910066
-0.041015624,-117.1317291,24.57999992,0.002912665
-0.041113282,-117.3974686,24.62000084,0.002919345
-0.041162108,-117.8979797,24.65999985,0.002937061
-0.041210937,-118.109787,24.70000076,0.002930767
-0.041308595,-118.3988876,24.73999977,0.002952025
-0.041357423,-118.7777557,24.78000069,0.002950226
-0.041406249,-119.0746231,24.81999969,0.002960574
-0.041503907,-119.4123764,24.86000061,0.002974994
-0.041552736,-119.5875244,24.89999962,0.002976939
-0.041601561,-120.0534286,24.94000053,0.002985953
-0.04165039,-120.324852,24.97999954,0.003000453
-0.041748048,-120.5198593,25.02000046,0.002999549
-0.041796877,-121.0174484,25.05999947,0.003015425
-0.041845702,-121.2028198,25.10000038,0.003011849
-0.04194336,-121.6437912,25.13999939,0.003026019
-0.041992189,-122.0038605,25.18000031,0.003038451
-0.042041014,-121.994812,25.21999931,0.003037656
-0.042138672,-122.6197357,25.26000023,0.003053514
-0.042187501,-122.9305954,25.29999924,0.003057147
-0.042236326,-123.308075,25.34000015,0.0030652
-0.042333984,-123.6100998,25.37999916,0.003078559
-0.042382813,-123.7812958,25.42000008,0.003076188
-0.042431642,-124.2112885,25.45999908,0.003087925
-0.042529296,-124.4477158,25.5,0.003096312
-0.042578125,-124.7702484,25.54000092,0.003111083
-0.042626954,-125.3080673,25.57999992,0.003119303
-0.042724609,-125.3305511,25.62000084,0.003126875
-0.042773438,-125.8035583,25.65999985,0.00313935
-0.042822267,-126.1140137,25.70000076,0.0031444
-0.042871096,-126.4334869,25.73999977,0.003155969
-0.04296875,-126.8229141,25.78000069,0.003163557
-0.043017579,-126.9715805,25.81999969,0.003168348
-0.043066408,-127.4491577,25.86000061,0.003186962
-0.043115233,-127.6499252,25.89999962,0.003180897
-0.043212891,-128.012146,25.94000053,0.003194097
-0.04326172,-128.4617767,25.97999954,0.003208391
-0.043310545,-128.6007996,26.02000046,0.003208973
-0.043408203,-129.010025,26.05999947,0.003224629
-0.043457032,-129.3902435,26.10000038,0.003231268
-0.043505861,-129.6708374,26.13999939,0.003231384
-0.043603515,-130.1036224,26.18000031,0.003244885
-0.043652344,-130.3318634,26.21999931,0.003250635
-0.043701173,-130.7599487,26.26000023,0.003263142
-0.043798827,-131.0857849,26.29999924,0.003268993
-0.043847656,-131.3528748,26.34000015,0.003277321
-0.043896485,-131.7949219,26.37999916,0.003287182
-0.04399414,-132.0391541,26.42000008,0.003286632
-0.044042969,-132.5469055,26.45999908,0.003303405
-0.044140626,-132.8041992,26.5,0.003303967
-0.044189452,-133.0173035,26.54000092,0.003314892
-0.044238281,-133.6002808,26.57999992,0.003332466
-0.044335939,-133.7926331,26.62000084,0.003337652
-0.044384764,-134.2836609,26.65999985,0.003348474
-0.044482422,-134.6107788,26.70000076,0.003353946
-0.044531251,-134.8787384,26.73999977,0.003363926
-0.044628905,-135.4413147,26.78000069,0.00338743
-0.044677734,-135.6474457,26.81999969,0.003380099
-0.044726563,-136.0480194,26.86000061,0.003405867
-0.044824217,-136.4915466,26.89999962,0.003407969
-0.044873046,-136.694519,26.94000053,0.003425532
-0.044970704,-137.3171844,26.97999954,0.003430127
-0.045019533,-137.5198822,27.02000046,0.003427102
-0.045117187,-137.9407501,27.05999947,0.003445961
-0.045166016,-138.467392,27.10000038,0.003456895
-0.04526367,-138.6259308,27.13999939,0.003465081
-0.045312499,-139.1000671,27.18000031,0.003478402
-0.045410157,-139.3334351,27.21999931,0.003476573
-0.045458983,-139.8692474,27.26000023,0.003496207
-0.045556641,-140.2639008,27.29999924,0.00350572
-0.045605469,-140.5309906,27.34000015,0.003509092
-0.045654298,-141.0332794,27.37999916,0.003526588
-0.045751953,-141.1873016,27.42000008,0.003533559
-0.045800782,-141.5912933,27.45999908,0.003548121
-0.045849611,-141.9962006,27.5,0.003565407
-0.045947265,-142.1698608,27.54000092,0.003561288
-0.045996094,-142.7531128,27.57999992,0.003586117
-0.046093752,-142.9046783,27.62000084,0.00357708
-0.046142577,-143.281723,27.65999985,0.003590847
-0.046191406,-143.7117615,27.70000076,0.00360868
-0.046289064,-143.9143524,27.73999977,0.003609396
-0.046337889,-144.5422211,27.78000069,0.003630842
-0.046435547,-144.7068481,27.81999969,0.003626197
-0.046484376,-145.0864563,27.86000061,0.003644722
-0.046533201,-145.5672607,27.89999962,0.003654852
-0.046630859,-145.6655731,27.94000053,0.003659089
-0.046679688,-146.199173,27.97999954,0.003677964
-0.046728517,-146.4584198,28.02000046,0.00367861
-0.046826171,-146.7456512,28.05999947,0.003696301
-0.046875,-147.3497162,28.10000038,0.003707646
-0.046972655,-147.5778046,28.13999939,0.00369652
-0.047021484,-148.0759277,28.18000031,0.00372636
-0.047070313,-148.3774414,28.21999931,0.003731826
-0.04716797,-148.6730194,28.26000023,0.003725833
-0.047216796,-149.2284851,28.29999924,0.003746695
-0.047265625,-149.2706604,28.34000015,0.003746549
-0.047363283,-149.8057404,28.37999916,0.003768201
-0.047412108,-150.2907562,28.42000008,0.003777014
-0.047460937,-150.5163727,28.45999908,0.003784232
-0.047558595,-150.9476776,28.5,0.003796805
-0.04760742,-151.1723022,28.54000092,0.003797637
-0.047705078,-151.7008057,28.57999992,0.003815373
-0.047753907,-152.0542145,28.62000084,0.003829807
-0.047802736,-152.2597656,28.65999985,0.003825798
-0.047851561,-152.6617432,28.70000076,0.00384672
-0.047949219,-152.8816528,28.73999977,0.003843913
-0.047998048,-153.4527588,28.78000069,0.003868363
-0.048046873,-153.7044983,28.81999969,0.003875816
-0.048144531,-153.9653473,28.86000061,0.003887378
-0.04819336,-154.4341278,28.89999962,0.003900993
-0.048242189,-154.6962738,28.94000053,0.003899486
-0.048339843,-155.0373535,28.97999954,0.003912243
-0.048388672,-155.490509,29.02000046,0.00392793
-0.048437501,-155.7173004,29.05999947,0.003925456
-0.048535156,-156.185318,29.10000038,0.003947402
-0.048583985,-156.4223175,29.13999939,0.003948813
-0.048632814,-156.7763672,29.18000031,0.0039669
-0.048730468,-157.2059021,29.21999931,0.003974608
-0.048779297,-157.4517975,29.26000023,0.003986576
-0.048828126,-157.9155731,29.29999924,0.004012469
-0.048876955,-158.0941467,29.34000015,0.00400498
-0.048974609,-158.4229279,29.37999916,0.004028097
-0.049023438,-158.9046173,29.42000008,0.004040294
-0.049072267,-159.0133514,29.45999908,0.004048647
-0.049121092,-159.4683075,29.5,0.004068047
-0.04921875,-159.8287201,29.54000092,0.004066119
-0.049267579,-160.2419281,29.57999992,0.004072133
-0.049316408,-160.6059723,29.62000084,0.004086348
-0.049414062,-160.7110138,29.65999985,0.004101487
-0.049462891,-161.3995972,29.70000076,0.004117155
-0.04951172,-161.6604767,29.73999977,0.004118308
-0.049560545,-161.9212036,29.78000069,0.004131573
-0.049658203,-162.3075867,29.81999969,0.004157661
-0.049707032,-162.6212616,29.86000061,0.004152276
-0.049755858,-163.0569611,29.89999962,0.004180828
-0.049853516,-163.3819427,29.94000053,0.004177957
-0.049902344,-163.6660919,29.97999954,0.004199472
-0.049951173,-164.1957397,30.02000046,0.004203049
-0.050048828,-164.4330444,30.05999947,0.004206538
-0.050097657,-164.9822388,30.10000038,0.004236996
-0.050146486,-165.2092896,30.13999939,0.004233417
-0.05024414,-165.5726929,30.18000031,0.004249065
-0.050292969,-166.0003662,30.21999931,0.004272517
-0.050341798,-166.2969055,30.26000023,0.004265504
-0.050439452,-166.7459717,30.29999924,0.00429899
-0.050488281,-167.174469,30.34000015,0.004309552
-0.05053711,-167.384201,30.37999916,0.004322314
-0.050634764,-167.8846436,30.42000008,0.004341499
-0.050683593,-168.1416931,30.45999908,0.004336546
-0.050781251,-168.5572968,30.5,0.004364542
-0.050830076,-169.0176086,30.54000092,0.004376256
-0.050878905,-169.4151917,30.57999992,0.004384106
-0.050976563,-169.9028015,30.62000084,0.004398821
-0.051025392,-170.1701355,30.65999985,0.004408295
-0.051123046,-170.611145,30.70000076,0.004433835
-0.051171875,-171.1558075,30.73999977,0.004431568
-0.051220704,-171.3441162,30.78000069,0.004441294
-0.051318359,-172.0467682,30.81999969,0.004466533
-0.051367188,-172.2686157,30.86000061,0.004474661
-0.051464845,-172.8145294,30.89999962,0.004499003
-0.051513671,-173.1779785,30.94000053,0.00451609
-0.051611329,-173.332901,30.97999954,0.004522333
-0.051660158,-174.0765686,31.02000046,0.00454824
-0.051757812,-174.3632813,31.05999947,0.004555797
-0.051806641,-174.8409424,31.10000038,0.00457198
-0.05185547,-175.2222595,31.13999939,0.004593257
-0.051953124,-175.545929,31.18000031,0.004602443
-0.052001953,-176.1229401,31.21999931,0.004633522
-0.052099611,-176.3526306,31.26000023,0.004639158
-0.052148436,-176.8428345,31.29999924,0.004668427
-0.052246094,-177.2211304,31.34000015,0.004686195
-0.052294923,-177.6433868,31.37999916,0.004705008
-0.052392577,-178.1439972,31.42000008,0.004739441
-0.052441406,-178.5096893,31.45999908,0.004744142
-0.052490235,-178.934082,31.5,0.004753489
-0.05258789,-179.4963074,31.54000092,0.004778505
-0.052636718,-179.735672,31.57999992,0.004781863
-0.052734376,-180.1570892,31.62000084,0.004820248
-0.052783202,-180.6531525,31.65999985,0.004820815
-0.052832031,-180.9329529,31.70000076,0.004845378
-0.052929689,-181.5960236,31.73999977,0.004861701
-0.052978514,-181.8219299,31.78000069,0.004872743
-0.053076172,-182.3458405,31.81999969,0.004908326
-0.053125001,-182.808609,31.86000061,0.004920116
-0.053222655,-183.0565186,31.89999962,0.004937394
-0.053271484,-183.6383972,31.94000053,0.004956891
-0.053320313,-183.7944031,31.97999954,0.004958137
-0.053417967,-184.3290405,32.02000046,0.004991271
-0.053466796,-184.8645325,32.06000137,0.005008964
-0.053515625,-185.0521393,32.09999847,0.005027487
-0.053613283,-185.7171021,32.13999939,0.005047682
-0.053662108,-185.9706268,32.18000031,0.005058031
-0.053759766,-186.4730988,32.22000122,0.005085283
-0.053808595,-186.9721222,32.25999832,0.005092376
-0.05385742,-187.2719269,32.29999924,0.005108361
-0.053955078,-187.8176117,32.34000015,0.005138708
-0.054003907,-188.1074677,32.38000107,0.005150339
-0.054101562,-188.5108643,32.41999817,0.005173799
-0.05415039,-188.964859,32.45999908,0.005186682
-0.054199219,-189.4385986,32.5,0.005196925
-0.054296874,-190.0335236,32.54000092,0.005228341
-0.054345703,-190.2487488,32.58000183,0.005232441
-0.054394532,-190.5710449,32.61999893,0.005265578
-0.054492186,-191.0205383,32.65999985,0.005283694
-0.054541015,-191.4215851,32.70000076,0.005297123
-0.054589844,-191.7803802,32.74000168,0.005327158
-0.054687502,-192.118576,32.77999878,0.005338105
-0.054736327,-192.5434875,32.81999969,0.005368561
-0.054785156,-192.8719482,32.86000061,0.005387374
-0.054882814,-193.1501465,32.90000153,0.005409936
-0.054931639,-193.6145325,32.93999863,0.005438627
-0.054980468,-193.8820496,32.97999954,0.0054459
-0.055078126,-194.3572083,33.02000046,0.005488596
-0.055126951,-194.6897583,33.06000137,0.005509008
-0.05517578,-194.7932892,33.09999847,0.005533419
-0.055273438,-195.3717957,33.13999939,0.005570026
-0.055322267,-195.6750031,33.18000031,0.00557962
-0.055371092,-195.9726868,33.22000122,0.005613133
-0.05546875,-196.2679443,33.25999832,0.005652162
-0.055517579,-196.4222717,33.29999924,0.005674899
-0.055566405,-196.8325043,33.34000015,0.005707686
-0.055664063,-196.9697876,33.38000107,0.005731179
-0.055712891,-197.2854767,33.41999817,0.005775466
-0.05576172,-197.6213989,33.45999908,0.005819661
-0.055859375,-197.5835571,33.5,0.005852265
-0.055908204,-197.9630737,33.54000092,0.005903378
-0.055957033,-198.028656,33.58000183,0.005938219
-0.056005858,-198.0913849,33.61999893,0.005990798
-0.056103516,-198.212265,33.65999985,0.006048353
-0.056152345,-198.2476349,33.70000076,0.006099465
-0.05620117,-198.2580719,33.74000168,0.006171044
-0.056249999,-198.3425293,33.77999878,0.006228187
-0.056347657,-198.2825928,33.81999969,0.006295346
-0.056396486,-198.5213928,33.86000061,0.006361186
-0.056445311,-198.2671814,33.90000153,0.006404349
-0.056542969,-198.3591766,33.93999863,0.00647136
-0.056591798,-198.4346008,33.97999954,0.006527321
-0.056640623,-198.4346924,34.02000046,0.00659435
-0.056738281,-198.134552,34.06000137,0.006682912
-0.05678711,-197.7375336,34.09999847,0.006755208
-0.056835939,-197.5690613,34.13999939,0.006860778
-0.056933593,-197.1398163,34.18000031,0.006971818
-0.056982422,-196.4845734,34.22000122,0.007081641
-0.057031251,-196.1439056,34.25999832,0.007200994
-0.057128906,-195.4688873,34.29999924,0.007297269
-0.057177735,-195.0178223,34.34000015,0.007436209
-0.057226564,-194.3541107,34.38000107,0.007542535
-0.057324218,-193.6628876,34.41999817,0.007670877
-0.057373047,-193.0106659,34.45999908,0.007843887
-0.057421876,-191.6212616,34.5,0.008046348
-0.05751953,-190.3323975,34.54000092,0.008287172
-0.057568359,-188.5739746,34.58000183,0.008523128
-0.057666017,-186.8965149,34.61999893,0.008764156
-0.057714842,-185.1782532,34.65999985,0.00906
-0.0578125,-182.5335693,34.70000076,0.009385274
-0.057861329,-176.7937164,34.74000168,0.010024533
-0.057958983,-165.0787354,34.77999878,0.011297228
-0.058007812,-153.8487549,34.81999969,0.01263829
-0.05810547,-145.1851501,34.86000061,0.013771232
-0.058154295,-139.0375977,34.90000153,0.01464387
-0.058251953,-135.667038,34.93999863,0.015181245
-0.058300782,-133.1226807,34.97999954,0.015662685
-0.058398437,-130.2519226,35.02000046,0.016131227
-0.058447265,-128.8209839,35.06000137,0.016446291
-0.058496094,-127.3950195,35.09999847,0.016717438
-0.058593749,-126.2170029,35.13999939,0.016977952
-0.058642578,-125.462471,35.18000031,0.017209857
-0.058740236,-124.4345856,35.22000122,0.017419034
-0.058789061,-123.8507233,35.25999832,0.017622675
-0.058886719,-122.9946594,35.29999924,0.017812068
-0.058935548,-122.5769501,35.34000015,0.017971797
-0.058984377,-122.1700745,35.38000107,0.018121282
-0.059082031,-121.5381851,35.41999817,0.018261464
-0.05913086,-121.3787613,35.45999908,0.018427891
-0.059228514,-120.9474182,35.5,0.018548262
-0.059277343,-120.6985626,35.54000092,0.018677085
-0.059375001,-120.4744492,35.58000183,0.018815002
-0.059423826,-120.1621017,35.61999893,0.018920206
-0.059472655,-120.2085876,35.65999985,0.019040446
-0.059570313,-119.9171143,35.70000076,0.019125355
-0.059619142,-119.8968964,35.74000168,0.019221839
-0.059716796,-120.1959763,35.77999878,0.01930502
-0.059765625,-119.7610474,35.81999969,0.019386733
-0.05986328,-119.7939072,35.86000061,0.019494
-0.059912109,-119.6963882,35.90000153,0.019576721
-0.059960938,-119.4353638,35.93999863,0.019675499
-0.060058595,-119.3784714,35.97999954,0.019782441
-0.060107421,-118.9821701,36.02000046,0.019873829
-0.06015625,-118.8748169,36.06000137,0.019999778
-0.060253908,-118.6122665,36.09999847,0.020105846
-0.060302733,-118.364624,36.13999939,0.020207475
-0.060351562,-118.3340683,36.18000031,0.02031893
-0.06044922,-117.7892227,36.22000122,0.020425532
-0.060498045,-117.6996002,36.25999832,0.02054859
-0.060546874,-117.4023895,36.29999924,0.020673502
-0.060644532,-117.0046844,36.34000015,0.020772961
-0.060693361,-116.9920959,36.38000107,0.0208823
-0.060742186,-116.5799561,36.41999817,0.020985277
-0.060839844,-116.4465179,36.45999908,0.021105679
-0.060888673,-116.3785553,36.5,0.021210464
-0.060937498,-115.9400406,36.54000092,0.021324431
-0.061035156,-115.7619629,36.58000183,0.021441096
-0.061083985,-115.6514816,36.61999893,0.021544838
-0.061181643,-115.4490662,36.65999985,0.021636735
-0.061230472,-115.4354706,36.70000076,0.021741429
-0.061279294,-115.1802292,36.74000168,0.021830983
-0.061376952,-115.1365433,36.77999878,0.021937301
-0.061425781,-114.9483719,36.81999969,0.022026741
-0.06147461,-114.7380676,36.86000061,0.022135917
-0.061523438,-114.5911179,36.90000153,0.022224473
-0.061621096,-114.3705826,36.93999863,0.022304946
-0.061669925,-114.3843231,36.97999954,0.022422371
-0.061718747,-113.9604187,37.02000046,0.022522463
-0.061816405,-113.7232513,37.06000137,0.022632496
-0.061865234,-113.4848175,37.09999847,0.022748894
-0.061914063,-113.1169968,37.13999939,0.022868522
-0.062011721,-112.8747635,37.18000031,0.022981092
-0.06206055,-112.481514,37.22000122,0.023108505
-0.062109379,-112.0689163,37.25999832,0.023240082
-0.062207029,-111.7897568,37.29999924,0.02336784
-0.062255858,-111.1883316,37.34000015,0.02350565
-0.062304687,-110.6417542,37.38000107,0.023709161
-0.062353516,-109.2979126,37.41999817,0.02393352
-0.062451174,-107.1488113,37.45999908,0.024353856
-0.062500003,-104.0810242,37.5,0.02495041
-0.062548825,-100.9702835,37.54000092,0.025529502
-0.062646483,-97.33031464,37.58000183,0.026283844
-0.062695311,-93.27385712,37.61999893,0.027161641
-0.06274414,-87.41951752,37.65999985,0.02843014
-0.062792969,-80.09001923,37.70000076,0.030203695
-0.062890627,-75.57363892,37.74000168,0.031389151
-0.062939456,-71.77468872,37.77999878,0.032541033
-0.062988278,-64.79241943,37.81999969,0.034502285
-0.063085936,-55.82256699,37.86000061,0.037224923
-0.063134765,-45.53408813,37.90000153,0.040494786
-0.063183594,-17.27143288,37.93999863,0.061729639
-0.063281252,0.310083896,37.97999954,5.634059664
-0.063330081,0.364643365,38.02000046,5.614290014
-0.06337891,0.447971702,38.06000137,0.34600377
-0.06347656,0.325455248,38.09999847,0.687281194
-0.063525389,0.54594171,38.13999939,0.687426422
-0.063574218,0.101288803,38.18000031,0.687416003
-0.063623047,0.440654844,38.22000122,0.687406806
-0.063720705,0.474458843,38.25999832,5.123237614
-0.063769534,0.343637824,38.29999924,5.686043296
-0.063818363,0.415738344,38.34000015,4.904926289
-0.063916013,0.451396137,38.38000107,0.688222062
-0.063964842,0.439617723,38.41999817,0.687319611
-0.064013671,0.429009795,38.45999908,0.687409076
-0.064111329,0.257915258,38.5,0.687417574
-0.064160158,0.459433734,38.54000092,0.687406049
-0.064208987,0.422051579,38.58000183,0.687410007
-0.064306638,0.429969877,38.61999893,0.687412044
-0.064355467,0.576634884,38.65999985,0.687404361
-0.064453125,0.356603205,38.70000076,0.687416061
-0.064501954,0.388550311,38.74000168,0.687408086
-0.064599612,0.387503445,38.77999878,0.687409891
-0.06464844,0.36927101,38.81999969,0.687411521
-0.064697262,0.519659877,38.86000061,0.687417574
-0.06479492,0.347791702,38.90000153,0.687417109
-0.064843749,0.461558193,38.93999863,0.687409309
-0.064941407,0.476348639,38.97999954,0.687421008
-0.064990236,0.356743544,39.02000046,0.687416992
-0.065087894,0.534762442,39.06000137,0.687409891
-0.065136715,0.302438051,39.09999847,0.687419379
-0.065185544,0.458990484,39.13999939,0.687407155
-0.065283202,0.418988794,39.18000031,0.687415071
-0.065332031,0.356675357,39.22000122,0.687414198
-0.065429689,0.506715417,39.25999832,0.687413733
-0.065478518,0.397515476,39.29999924,0.687413558
-0.065576169,0.456452638,39.34000015,0.687405991
-0.065624998,0.395289391,39.38000107,0.687417516
-0.065722656,0.250959754,39.41999817,0.687413791
-0.065771485,0.435918272,39.45999908,0.687402266
-0.065820313,0.369487315,39.5,0.687416003
-0.065917971,0.519016802,39.54000092,0.68741024
-0.0659668,0.423614264,39.58000183,0.687417632
-0.066064451,0.342765719,39.61999893,0.687403488
-0.06611328,0.477565676,39.65999985,0.687406631
-0.066162109,0.457375467,39.70000076,0.687414955
-0.066259767,0.412886262,39.74000168,0.68741088
-0.066308596,0.368481666,39.77999878,0.687407388
-0.066406254,0.28414607,39.81999969,0.687417225
-0.066455075,0.502232492,39.86000061,0.687414315
-0.066503904,0.404802442,39.90000153,0.687426073
-0.066601562,0.384436041,39.93999863,0.687420135
-0.066650391,0.511824727,39.97999954,0.687418971
-0.06669922,0.334187597,40.02000046,0.687414606
-0.066796878,0.512313962,40.06000137,0.687405234
-0.0668457,0.332138598,40.09999847,0.687412801
-0.066943358,0.370754808,40.13999939,0.687412859
-0.066992186,0.447727323,40.18000031,0.687418273
-0.067041015,0.290333182,40.22000122,0.687415071
-0.067138673,0.470344722,40.25999832,0.687405292
-0.067187502,0.346058488,40.29999924,0.687420368
-0.067236331,0.518726945,40.34000015,0.687413209
-0.067333982,0.499047458,40.38000107,0.687415712
-0.067382811,0.387596428,40.41999817,0.687421649