File: Data/Thesis_Samples_Data/Notched_Layered_6/Notched_Layered_6.csv
"File Path: C:\Users\Lab User\Desktop\Will\Thesis Tests\Test Run 10 04-8-22 20 51 46 PM\DAQ- Crosshead, … - (Timed).csv   ",,,
Test: MTS EM Tension (Extensometer) - Will 1,,,
Test Run: Test Run 10,,,
Date: 4/8/2022 8:40:40 PM,,,
,,,
,,,
Crosshead ,Load ,Time ,Extensometer
mm,N,sec,mm
-0.000292969,-0.697750509,0.02,6.80E-05
-0.000927734,-0.701476216,0.639999986,8.81E-05
-0.002001953,-0.961276174,1.25999999,0.000131496
-0.002978516,-0.80083549,1.879999995,0.000130114
-0.004052734,-0.935922265,2.5,0.000146306
-0.005175781,-0.950824797,3.119999886,0.000167427
-0.006201172,-1.097116232,3.74000001,0.000182213
-0.007275391,-0.996470153,4.360000134,0.000184974
-0.008251953,-0.905302763,4.980000019,0.000191121
-0.009228515,-0.90269208,5.599999905,0.000203294
-0.010253906,-0.90035814,6.21999979,0.000229059
-0.011376953,-0.959874511,6.840000153,0.000236306
-0.012451172,-1.103151321,7.460000038,0.000258984
-0.01352539,-1.12326622,8.079999924,0.000273801
-0.014501953,-1.018998504,8.699999809,0.000264832
-0.015527345,-0.973221242,9.319999695,0.000271827
-0.016503905,-0.966575444,9.93999958,0.000279769
-0.017578124,-0.927338898,10.56000042,0.000293391
-0.018652343,-0.977795124,11.18000031,0.000311534
-0.019726562,-0.925537586,11.80000019,0.000318888
-0.020751953,-1.000896692,12.42000008,0.000341741
-0.021728516,-1.135653973,13.03999996,0.000351728
-0.022705079,-1.157982588,13.65999985,0.000357907
-0.023730468,-1.093008757,14.27999973,0.000365852
-0.024853516,-1.07491231,14.89999962,0.00038209
-0.025927735,-1.073215604,15.52000046,0.000372133
-0.026953125,-1.207472324,16.13999939,0.000403024
-0.027978516,-1.252624393,16.76000023,0.000413921
-0.028955079,-1.366885185,17.37999916,0.000431732
-0.02993164,-1.442913175,18,0.000435255
-0.031054689,-1.290224314,18.62000084,0.000442763
-0.032128908,-1.23261416,19.23999977,0.000449907
-0.033154298,-1.312936068,19.86000061,0.000460448
-0.034179688,-1.176878452,20.47999954,0.000470219
-0.035156248,-1.27874577,21.10000038,0.00046771
-0.036132813,-1.28308928,21.71999931,0.000463691
-0.037158203,-1.335733175,22.34000015,0.000474998
-0.038232422,-1.296101928,22.95999908,0.00047263
-0.03930664,-1.257327199,23.57999992,0.00047893
-0.04033203,-1.262475491,24.20000076,0.000490568
-0.041357423,-1.351729512,24.81999969,0.000496716
-0.042285155,-1.32711494,25.44000053,0.000505508
-0.043310545,-1.341086626,26.05999947,0.00052297
-0.044433593,-1.705744267,26.68000031,0.000559027
-0.045507812,-2.140073538,27.29999924,0.000602252
-0.04658203,-2.392599821,27.92000008,0.000640813
-0.04760742,-2.778682947,28.54000092,0.00070874
-0.048583985,-2.968187332,29.15999985,0.000733358
-0.049560545,-3.328469753,29.78000069,0.000764085
-0.050634764,-3.731770515,30.39999962,0.000827075
-0.051757812,-4.058452129,31.02000046,0.000871655
-0.052783202,-4.586448193,31.63999939,0.00092656
-0.053808595,-4.919720173,32.25999832,0.000971574
-0.054833985,-5.302355766,32.88000107,0.001021207
-0.05576172,-5.533139229,33.5,0.001062468
-0.056835939,-5.896312237,34.11999893,0.001108777
-0.057910158,-6.147342205,34.74000168,0.001163854
-0.058984377,-6.584342957,35.36000061,0.001198657
-0.060009766,-7.008691311,35.97999954,0.001256855
-0.061035156,-7.67445755,36.59999847,0.001298412
-0.062011721,-7.767339706,37.22000122,0.001356314
-0.062988278,-8.065186501,37.84000015,0.001401218
-0.0640625,-8.437857628,38.45999908,0.001447411
-0.065185544,-8.768992424,39.08000183,0.001498009
-0.066210938,-9.026114464,39.70000076,0.001544252
-0.067285153,-9.452181816,40.31999969,0.001598086
-0.068261717,-9.896777153,40.93999863,0.001655782
-0.069238282,-10.24331093,41.56000137,0.001716979
-0.070214846,-10.59588337,42.18000031,0.001778675
-0.07133789,-10.93798637,42.79999924,0.001836348
-0.072363284,-11.32064342,43.41999817,0.001890571
-0.073437499,-11.60612965,44.04000092,0.001956601
-0.074414063,-11.86539364,44.65999985,0.00201436
-0.075390628,-12.16235447,45.27999878,0.002055337
-0.076416014,-12.57695961,45.90000153,0.002115384
-0.077441407,-13.04070377,46.52000046,0.002180663
-0.078564452,-13.36871243,47.13999939,0.00224675
-0.079638674,-13.75075531,47.75999832,0.002319846
-0.08066406,-14.00406742,48.38000107,0.00237843
-0.081640625,-14.29192543,49,0.002440272
-0.082617189,-14.52327061,49.61999893,0.002502732
-0.083691404,-14.90726948,50.24000168,0.002571489
-0.084765627,-15.33459759,50.86000061,0.002663704
-0.085839842,-15.64834976,51.47999954,0.002733485
-0.086865235,-15.96682549,52.09999847,0.002816736
-0.087890628,-16.31357956,52.72000122,0.002877251
-0.088867186,-16.5219059,53.34000015,0.002941249
-0.089892579,-16.81393051,53.95999908,0.002994487
-0.090966794,-17.15006256,54.58000183,0.003056764
-0.092041017,-17.64201736,55.20000076,0.003130051
-0.093115232,-17.9451561,55.81999969,0.003207119
-0.094140625,-18.28876877,56.43999863,0.003263534
-0.09511719,-18.64382935,57.06000137,0.00332307
-0.096093747,-18.90923691,57.68000031,0.003391435
-0.097167969,-19.20504951,58.29999924,0.0034571
-0.098242184,-19.47096825,58.91999817,0.003518553
-0.099316407,-19.88866997,59.54000092,0.003592448
-0.1003418,-20.27664185,60.15999985,0.003661021
-0.101318357,-20.56988716,60.77999878,0.003738435
-0.102294922,-20.9119091,61.40000153,0.003815456
-0.103271486,-21.10388756,62.02000046,0.003910107
-0.104345701,-21.37649536,62.63999939,0.004016753
-0.105468753,-21.68030357,63.25999832,0.0041016
-0.106494139,-21.97213936,63.88000107,0.004199169
-0.107519532,-22.27994347,64.5,0.004313078
-0.108496097,-22.52611923,65.12000275,0.004401474
-0.109472654,-22.91135216,65.73999786,0.004486648
-0.110498047,-23.26729202,66.36000061,0.004580579
-0.111621091,-23.48802567,66.98000336,0.00467903
-0.112695314,-23.78710175,67.59999847,0.004772905
-0.1137207,-23.91420937,68.22000122,0.004873113
-0.114746093,-24.22358322,68.83999634,0.004977911
-0.115722658,-24.42168045,69.45999908,0.005081979
-0.116748044,-24.73859978,70.08000183,0.005222224
-0.117822266,-25.07523346,70.69999695,0.005328753
-0.118896482,-25.33524323,71.31999969,0.005469175
-0.119970704,-25.40487862,71.94000244,0.005615204
-0.120947268,-25.5175209,72.55999756,0.005766773
-0.121923826,-25.68357277,73.18000031,0.00588742
-0.122900397,-25.83262062,73.80000305,0.006015435
-0.123974605,-26.05467606,74.41999817,0.006175753
-0.125048828,-26.19700813,75.04000092,0.00634457
-0.12612305,-26.51612091,75.66000366,0.006506681
-0.127197272,-26.75875282,76.27999878,0.006659738
-0.128222659,-26.79794884,76.90000153,0.006836333
-0.129150387,-26.92831612,77.51999664,0.006967253
-0.130224609,-27.07714081,78.13999939,0.007124841
-0.131298832,-27.24939537,78.76000214,0.007296318
-0.132373054,-27.43956566,79.37999725,0.007470798
-0.133447262,-27.63610268,80,0.007653161
-0.134423826,-27.75715828,80.62000275,0.007862489
-0.135351569,-27.59751892,81.23999786,0.008173029
-0.136376955,-27.26749802,81.86000061,0.008684129
-0.137402341,-11.24849987,82.48000336,0.019965484
-0.138476564,-11.42365074,83.09999847,0.02097055
-0.139550786,-11.43299294,83.72000122,0.021516817
-0.140576172,-11.60762596,84.33999634,0.021983047
-0.141552737,-11.75546551,84.95999908,0.022389017
-0.142529301,-11.95494938,85.58000183,0.022706374
-0.143554687,-12.13432026,86.19999695,0.023004433
-0.144677731,-12.35074043,86.81999969,0.023300128
-0.145751954,-12.24670219,87.44000244,0.023626717
-0.146826176,-12.51447392,88.05999756,0.040125335
-0.147851562,-12.53202915,88.68000031,0.042984673
-0.148828127,-12.7791481,89.30000305,0.044310935
-0.149804691,-12.97643852,89.91999817,0.045259265
-0.150878899,-13.27072048,90.54000092,0.046023488
-0.151953122,-13.43970966,91.16000366,0.04667871
-0.152978522,-13.53817177,91.77999878,0.047224537
-0.15405273,-13.69721985,92.40000153,0.047727615
-0.155029295,-13.87144852,93.01999664,0.048172893
-0.156005859,-13.97714424,93.63999939,0.048592188
-0.157031245,-14.17594528,94.26000214,0.048979862
-0.158105468,-14.53061676,94.87999725,0.049355887
-0.159228512,-14.69387341,95.5,0.049718408
-0.160253912,-14.87585163,96.12000275,0.05003508
-0.161279298,-14.85599899,96.73999786,0.050343973
-0.162255863,-14.91949081,97.36000061,0.050644157
-0.163232427,-14.78699112,97.98000336,0.050923863
-0.164306635,-14.45641041,98.59999847,0.051276991
-0.165380858,-14.69530487,99.22000122,0.051603791
-0.16645508,-14.92448711,99.83999634,0.051889179
-0.167480466,-15.12776661,100.4599991,0.05215501
-0.168457031,-15.34777832,101.0800018,0.052402818
-0.169433595,-15.57155037,101.6999969,0.052644806
-0.170458981,-15.7689991,102.3199997,0.052884028
-0.171533204,-15.92106628,102.9400024,0.053131014
-0.172607426,-16.09379005,103.5599976,0.053369218
-0.173632812,-16.21725845,104.1800003,0.053611486
-0.174658198,-16.47712708,104.8000031,0.053834538
-0.175634763,-16.69106102,105.4199982,0.054047123
-0.176660149,-16.88838387,106.0400009,0.054278917
-0.177734371,-17.19610977,106.6600037,0.054497516
-0.178857415,-17.35493851,107.2799988,0.054731474
-0.179882816,-17.45818901,107.9000015,0.054947763
-0.180908202,-17.59669304,108.5199966,0.055160213
-0.181884767,-17.67679405,109.1399994,0.055370168
-0.182861331,-17.9542141,109.7600021,0.055564644
-0.183886717,-18.11723137,110.3799973,0.055774679
-0.185009761,-18.4342823,111,0.056004075
-0.186083984,-18.64610672,111.6200027,0.05622183
-0.18710937,-18.70129395,112.2399979,0.056435532
-0.188085934,-18.65026665,112.8600006,0.056619134
-0.189111335,-18.71917534,113.4800034,0.056797737
-0.190087885,-18.77483177,114.0999985,0.056993631
-0.191210944,-18.89581108,114.7200012,0.057197878
-0.192285152,-19.15828514,115.3399963,0.057416361
-0.193359374,-19.45577621,115.9599991,0.057613899
-0.194335938,-19.58511162,116.5800018,0.057822046
-0.195361325,-19.70973969,117.1999969,0.058019748
-0.196289067,-19.8954258,117.8199997,0.05821856
-0.197412111,-20.07047272,118.4400024,0.058426875
-0.198486334,-20.21337891,119.0599976,0.058625028
-0.19951172,-20.46160507,119.6800003,0.058833142
-0.200537106,-20.70627975,120.3000031,0.05903262
-0.201513671,-20.93231583,120.9199982,0.059233276
-0.202490235,-21.20982933,121.5400009,0.059416674
-0.203515621,-21.30770111,122.1600037,0.05960503
-0.204589844,-21.49375153,122.7799988,0.059817008
-0.205664066,-21.7390728,123.4000015,0.060005848
-0.206689452,-21.79251099,124.0199966,0.060202849
-0.207763675,-22.06288528,124.6399994,0.060400413
-0.208740239,-22.38710594,125.2600021,0.060585538
-0.209716804,-22.56445122,125.8799973,0.060784769
-0.210791011,-22.7111702,126.5,0.060992152
-0.211914055,-22.98302841,127.1200027,0.061215454
-0.212939456,-22.9876976,127.7399979,0.061436469
-0.213964842,-23.15662384,128.3600006,0.061643397
-0.214941407,-23.24029732,128.9799957,0.061839462
-0.215966793,-23.48500443,129.6000061,0.062038773
-0.216992194,-23.69399071,130.2200012,0.062241954
-0.218066401,-23.89806747,130.8399963,0.06245626
-0.219140624,-24.15154457,131.4600067,0.062663094
-0.220214846,-24.27983665,132.0800018,0.062849038
-0.221191411,-24.44941139,132.6999969,0.063037391
-0.222167975,-24.50665665,133.3200073,0.063229061
-0.223144525,-24.61625862,133.9400024,0.063398387
-0.224218747,-24.84771156,134.5599976,0.063594533
-0.225341792,-25.05676651,135.1799927,0.063799074
-0.226416014,-25.27028847,135.8000031,0.063989421
-0.2274414,-25.55250931,136.4199982,0.064183114
-0.228417965,-25.68501282,137.0399933,0.064350337
-0.229394529,-25.79529381,137.6600037,0.064533779
-0.230419915,-25.87215996,138.2799988,0.06471487
-0.231542974,-26.08974838,138.8999939,0.064906679
-0.23256836,-26.26965141,139.5200043,0.065099608
-0.233642582,-26.56853485,140.1399994,0.065288885
-0.234619147,-26.70721436,140.7599945,0.06547098
-0.235595697,-26.97448158,141.3800049,0.065651897
-0.236572261,-27.1905098,142,0.065842702
-0.237646484,-27.22328758,142.6199951,0.066031818
-0.238720706,-27.41973495,143.2400055,0.066217341
-0.239794928,-27.54876328,143.8600006,0.066385837
-0.240771478,-27.72397614,144.4799957,0.066570188
-0.241796879,-27.90943527,145.1000061,0.066755754
-0.242773443,-28.15280724,145.7200012,0.066930275
-0.24379883,-28.39822769,146.3399963,0.067124354
-0.244921888,-28.6173172,146.9600067,0.06731342
-0.245996082,-28.72484207,147.5800018,0.067501402
-0.247021497,-28.7600193,148.1999969,0.067681489
-0.248046883,-28.94531631,148.8200073,0.06784514
-0.249023433,-29.15947723,149.4400024,0.068022469
-0.250048819,-29.21464348,150.0599976,0.0682018
-0.251123041,-29.58167839,150.6799927,0.068397167
-0.252197264,-29.79566956,151.3000031,0.068588306
-0.253271486,-30.1158123,151.9199982,0.068777328
-0.254296872,-30.23801613,152.5399933,0.06895182
-0.255273451,-30.40730286,153.1600037,0.069125963
-0.256250001,-30.50277328,153.7799988,0.069309528
-0.257275387,-30.69510651,154.3999939,0.069494381
-0.258398446,-30.86544418,155.0200043,0.069686241
-0.259472668,-31.0365696,155.6399994,0.069879112
-0.260498055,-31.31393814,156.2599945,0.07007135
-0.261474604,-31.54550362,156.8800049,0.070252943
-0.262451184,-31.70908737,157.5,0.070426831
-0.26347657,-31.85286713,158.1199951,0.070602277
-0.264550792,-32.04848862,158.7400055,0.07079573
-0.265673822,-32.15291977,159.3600006,0.070979091
-0.266699208,-32.30561066,159.9799957,0.071166338
-0.267724623,-32.56532669,160.6000061,0.071361697
-0.268701173,-32.82184219,161.2200012,0.071542279
-0.269677723,-32.96481323,161.8399963,0.071735158
-0.270703138,-33.19657135,162.4600067,0.071942413
-0.271826168,-33.42940903,163.0800018,0.072144714
-0.272851554,-33.49107742,163.6999969,0.07233701
-0.27387694,-33.69735718,164.3200073,0.072521565
-0.274853519,-33.73397827,164.9400024,0.072703035
-0.275878905,-33.99475098,165.5599976,0.072889226
-0.276855455,-34.2293663,166.1799927,0.073081785
-0.277978514,-34.4595871,166.8000031,0.073284056
-0.279052736,-34.65345383,167.4199982,0.073499679
-0.280126958,-34.88035965,168.0399933,0.07369712
-0.281103508,-34.98323441,168.6600037,0.073894102
-0.282080087,-35.09505463,169.2799988,0.074085772
-0.283105473,-35.15502548,169.8999939,0.074272335
-0.284179696,-35.39734268,170.5200043,0.074471609
-0.285253918,-35.67742157,171.1399994,0.074669748
-0.286328112,-35.91585541,171.7599945,0.074853131
-0.287353527,-36.15998459,172.3800049,0.075040698
-0.288330077,-36.2902565,173,0.075224532
-0.289306627,-36.38158035,173.6199951,0.075407013
-0.290332042,-36.45392227,174.2400055,0.075587435
-0.291455071,-36.7417717,174.8600006,0.075787299
-0.292529294,-36.92775726,175.4799957,0.075981479
-0.29355468,-37.11243439,176.1000061,0.076190656
-0.294580066,-37.26395416,176.7200012,0.076390279
-0.295556645,-37.46536255,177.3399963,0.076566736
-0.296533195,-37.67887878,177.9600067,0.076772041
-0.297656254,-37.80744934,178.5800018,0.076964192
-0.298730476,-37.9665184,179.1999969,0.077148892
-0.299804698,-38.0675087,179.8200073,0.077333716
-0.300781248,-38.2530098,180.4400024,0.077531244
-0.301757798,-38.47055054,181.0599976,0.077717908
-0.302734377,-38.60998154,181.6799927,0.077890822
-0.303759763,-38.83465195,182.3000031,0.07808864
-0.304833986,-38.98291016,182.9199982,0.078290737
-0.305908208,-39.06533813,183.5399933,0.078492085
-0.306933594,-39.15238953,184.1600037,0.078685262
-0.307958981,-39.32817459,184.7799988,0.078869933
-0.30893556,-39.47562408,185.3999939,0.079043595
-0.30991211,-39.54620743,186.0200043,0.07924885
-0.311035168,-39.68113327,186.6399994,0.079449084
-0.312109361,-39.76166916,187.2599945,0.079638099
-0.313183584,-39.83195877,187.8800049,0.079827369
-0.31420897,-39.90488815,188.5,0.080016405
-0.315185549,-39.99526978,189.1199951,0.080189544
-0.316162099,-40.08572388,189.7400055,0.080387181
-0.317236321,-40.33105087,190.3600006,0.080582984
-0.318310544,-40.55434036,190.9799957,0.080783313
-0.319384766,-40.79652023,191.6000061,0.080971615
-0.320410152,-40.97603989,192.2200012,0.081162718
-0.321386731,-41.02358246,192.8399963,0.081349339
-0.322363281,-41.16657257,193.4600067,0.081524056
-0.323388667,-41.21720505,194.0800018,0.08172074
-0.32446289,-41.54053879,194.6999969,0.081919199
-0.325537112,-41.79363632,195.3200073,0.082124192
-0.326611334,-41.95640945,195.9400024,0.082311693
-0.327636721,-42.22231293,196.5599976,0.082488121
-0.328662107,-42.26622009,197.1799927,0.082662656
-0.329638686,-42.40808487,197.8000031,0.082840728
-0.330712879,-42.45551682,198.4199982,0.083029758
-0.331787101,-42.63527679,199.0399933,0.083214611
-0.332861324,-42.98133469,199.6600037,0.08342127
-0.33388671,-43.12451553,200.2799988,0.083599858
-0.334863289,-43.39716721,200.8999939,0.083783525
-0.335791003,-43.477211,201.5200043,0.083963881
-0.336816418,-43.50767136,202.1399994,0.084159052
-0.337890611,-43.68769836,202.7599945,0.084346415
-0.338964834,-43.82697678,203.3800049,0.084548861
-0.339990249,-44.03558731,204,0.084735373
-0.341015635,-44.27963638,204.6199951,0.084924715
-0.341992185,-44.5127449,205.2400055,0.085108324
-0.343017571,-44.66975021,205.8600006,0.085280983
-0.344042957,-44.7544136,206.4799957,0.085479267
-0.345166016,-44.91016769,207.1000061,0.085668478
-0.346240238,-44.97434235,207.7200012,0.085868305
-0.347265624,-45.1612587,208.3399963,0.086063439
-0.348291011,-45.3385582,208.9600067,0.086264605
-0.34926759,-45.55614853,209.5800018,0.086444255
-0.350292976,-45.68931198,210.1999969,0.086642707
-0.351367198,-45.83277893,210.8200073,0.086852495
-0.352441421,-46.00322723,211.4400024,0.087051267
-0.353466807,-45.94573593,212.0599976,0.087235159
-0.354492193,-46.15307236,212.6799927,0.087435386
-0.355468743,-46.33768082,213.3000031,0.08761746
-0.356445322,-46.66196442,213.9199982,0.087816683
-0.357519544,-46.85335159,214.5399933,0.088016604
-0.358593737,-47.06045914,215.1600037,0.088218934
-0.35966796,-47.08259964,215.7799988,0.088422385
-0.360693346,-47.22342682,216.3999939,0.088617489
-0.361718761,-47.37342834,217.0200043,0.088816902
-0.362695311,-47.6087265,217.6399994,0.089001558
-0.363720697,-47.75553894,218.2599945,0.089203269
-0.364843756,-48.07806396,218.8800049,0.089416062
-0.365869142,-48.11878204,219.5,0.089624285
-0.366943364,-48.2361412,220.1199951,0.089822162
-0.367919914,-48.47600555,220.7400055,0.090015965
-0.368896493,-48.49581528,221.3600006,0.090200847
-0.369873043,-48.66618729,221.9799957,0.090399837
-0.370947266,-48.89387894,222.6000061,0.090597845
-0.372021488,-40.45129013,223.2200012,0.089422174
-0.373095711,-40.61519623,223.8399963,0.089491296
-0.374121097,-40.76117706,224.4600067,0.089609472
-0.375097647,-40.79311371,225.0800018,0.089747649
-0.376074226,-40.79526901,225.6999969,0.0898996
-0.377099612,-40.99828339,226.3200073,0.090069407
-0.37822267,-41.19879913,226.9400024,0.090235342
-0.379296864,-41.41929245,227.5599976,0.090416477
-0.380371086,-41.63380051,228.1799927,0.090597852
-0.381347665,-41.71601105,228.8000031,0.090773465
-0.382324215,-41.6975708,229.4199982,0.090940033
-0.383349601,-41.82306671,230.0399933,0.091113674
-0.384423824,-42.03512573,230.6600037,0.091313741
-0.385498046,-42.297966,231.2799988,0.09151065
-0.386523432,-42.43040848,231.8999939,0.091699789
-0.387548818,-42.65611267,232.5200043,0.09188721
-0.388574204,-42.71203613,233.1399994,0.092069095
-0.389550783,-42.74403381,233.7599945,0.092252405
-0.39057617,-42.89072037,234.3800049,0.092456037
-0.391699228,-43.14768219,235,0.092655449
-0.392773451,-43.27210617,235.6199951,0.092860784
-0.393798837,-43.32225037,236.2400055,0.093085204
-0.394824223,-43.45818329,236.8600006,0.093262723
-0.395800773,-43.53881454,237.4799957,0.093454888
-0.396777352,-43.4466629,238.1000061,0.093649993
-0.397851574,-43.36179352,238.7200012,0.09384536
-0.398974604,-43.48845291,239.3399963,0.094059949
-0.39999999,-43.53796005,239.9600067,0.094258467
-0.400976569,-43.55205154,240.5800018,0.094446739
-0.401953119,-43.52460861,241.1999969,0.094648683
-0.402929698,-43.50234222,241.8200073,0.094848983
-0.403955084,-43.38452148,242.4400024,0.095039512
-0.405078114,-43.29225159,243.0599976,0.095277835
-0.406152336,-43.34722519,243.6799927,0.095499432
-0.407177722,-43.4152565,244.3000031,0.095713927
-0.408203137,-43.45890808,244.9199982,0.095914889
-0.409179687,-43.45558548,245.5399933,0.096104275
-0.410156237,-43.5054245,246.1600037,0.096304211
-0.411279296,-43.53794861,246.7799988,0.096509291
-0.412402354,-43.48038101,247.3999939,0.096727417
-0.413427741,-43.70544434,248.0200043,0.096933538
-0.414453127,-43.885849,248.6399994,0.09714187
-0.415429677,-43.93669891,249.2599945,0.097339143
-0.416406256,-43.89107895,249.8800049,0.097539167
-0.417480478,-43.86068726,250.5,0.097739103
-0.4185547,-43.90284348,251.1199951,0.097953423
-0.419628894,-43.80025101,251.7400055,0.098162876
-0.420654309,-43.91266251,252.3600006,0.09837863
-0.421630859,-44.1131134,252.9799957,0.098579039
-0.422607409,-44.12478256,253.6000061,0.09877063
-0.423632824,-44.16217804,254.2200012,0.098964076
-0.424755854,-44.25527573,254.8399963,0.099184785
-0.425830076,-44.27718353,255.4600067,0.099390723
-0.426855462,-44.24969101,256.0799866,0.099575474
-0.427880848,-44.52053452,256.7000122,0.09977389
-0.428857427,-44.63351059,257.3200073,0.09997977
-0.429882813,-44.78746033,257.9400024,0.100179721
-0.4309082,-44.72336578,258.5599976,0.100387049
-0.432031258,-44.68953705,259.1799927,0.100594523
-0.433056644,-44.6349144,259.7999878,0.100803467
-0.434082031,-44.52796936,260.4200134,0.100986945
-0.43505858,-44.67643738,261.0400085,0.101155303
-0.43603516,-44.12726212,261.6600037,0.101265359
-0.437060546,-44.10015488,262.2799988,0.101442507
-0.438134768,-38.89578629,262.8999939,0.10155057
-0.43920899,-38.55737686,263.519989,0.101712045
-0.440234377,-36.56079865,264.1400146,0.102104728
-0.441259763,-36.4739418,264.7600098,0.102325248
-0.442236342,-36.48433685,265.3800049,0.102528109
-0.443212892,-36.52057648,266,0.102722355
-0.444287114,-36.51932907,266.6199951,0.102928818
-0.445410144,-31.26926994,267.2399902,0.103256767
-0.446484366,-31.13519478,267.8599854,0.103453523
-0.447509752,-31.21442986,268.480011,0.103624508
-0.448486331,-31.18074226,269.1000061,0.103801547
-0.449462881,-31.22959137,269.7200012,0.103974329
-0.450537103,-31.37464714,270.3399963,0.104152001
-0.451660162,-31.42574501,270.9599915,0.104354294
-0.452685548,-30.52586937,271.5799866,0.105598199
-0.453710934,-17.58973122,272.2000122,0.120156801
-0.454736321,-17.44729996,272.8200073,0.121268946
-0.4557129,-17.3321476,273.4400024,0.122059231
-0.456689449,-17.30776978,274.0599976,0.122767815
-0.457812508,-17.13976479,274.6799927,0.123422491
-0.45888673,-11.61506176,275.2999878,0.125543404
-0.459912117,-11.70164967,275.9200134,0.126128813
-0.460937503,-11.72569847,276.5400085,0.12670568
-0.461914053,-11.62577248,277.1600037,0.127265739
-0.462890632,-11.66930294,277.7799988,0.127807376
-0.463964854,-11.61465645,278.3999939,0.128337691
-0.465039077,-11.71675682,279.019989,0.128892832
-0.46611327,-11.69527054,279.6400146,0.129459018
-0.467138685,-11.84969044,280.2600098,0.129991575
-0.468164071,-11.87713051,280.8800049,0.130532862
-0.469140621,-11.79501152,281.5,0.131131223
-0.4701172,-11.71722031,282.1199951,0.131722423
-0.47124023,-11.72217846,282.7399902,0.132251938
-0.472265616,-11.76071548,283.3599854,0.132795132
-0.473339838,-11.79678154,283.980011,0.133329173
-0.474316417,-11.87073898,284.6000061,0.133842448
-0.475292967,-11.9142828,285.2200012,0.13433944
-0.476318353,-11.83123016,285.8399963,0.134814778
-0.477343739,-11.79519558,286.4599915,0.135307404
-0.478466798,-11.71264935,287.0799866,0.135804992
-0.47954102,-11.77988338,287.7000122,0.136286413
-0.480566407,-11.89872169,288.3200073,0.136787246
-0.481542957,-11.8781662,288.9400024,0.137311057
-0.482519536,-11.91964722,289.5599976,0.138011324
-0.483544922,-11.88305283,290.1799927,0.138457792
-0.48466798,-11.84003448,290.7999878,0.138927615
-0.485742174,-11.85539341,291.4200134,0.139386728
-0.486816396,-11.85210228,292.0400085,0.139842145
-0.487792975,-11.89345264,292.6600037,0.140345146
-0.488769554,-11.89959431,293.2799988,0.140824093
-0.489746104,-11.99242687,293.8999939,0.141319426
-0.490820326,-11.94848824,294.519989,0.141798591
-0.491943385,-11.93562698,295.1400146,0.142285309
-0.492968771,-11.87494564,295.7600098,0.142763325
-0.494042994,-11.83127022,296.3800049,0.143249286
-0.495019543,-11.8661747,297,0.143731435
-0.495996093,-11.90346336,297.6199951,0.144218109
-0.49702148,-12.03830814,298.2399902,0.144705773
-0.498144538,-11.97930622,298.8599854,0.145219281
-0.499218761,-12.00263882,299.480011,0.145714905
-0.500244147,-11.92182732,300.1000061,0.146208637
-0.501220697,-11.98395824,300.7200012,0.146694772
-0.502197247,-12.00033188,301.3399963,0.147182465
-0.503173855,-12.02932358,301.9599915,0.147663144
-0.504248019,-12.14773941,302.5799866,0.14815497
-0.505322241,-12.0881319,303.2000122,0.148665786
-0.506396464,-12.07667637,303.8200073,0.149180269
-0.507373072,-11.97840023,304.4400024,0.14967582
-0.508398458,-11.98462391,305.0599976,0.150179068
-0.509375008,-12.06035805,305.6799927,0.150676729
-0.510400394,-12.11526966,306.2999878,0.15118008
-0.511523453,-12.18661785,306.9200134,0.151692278
-0.512597675,-12.29128933,307.5400085,0.15219432
-0.513671897,-12.24695778,308.1600037,0.152703651
-0.514648447,-12.10091591,308.7799988,0.153188346
-0.515624997,-12.0615778,309.3999939,0.153685716
-0.516650383,-12.15434933,310.019989,0.154182999
-0.517724606,-12.12337875,310.6400146,0.154711757
-0.518798828,-12.20532608,311.2600098,0.155222398
-0.519824214,-12.29496288,311.8800049,0.155750677
-0.5208496,-12.28661156,312.5,0.1562666
-0.52182615,-12.17904282,313.1199951,0.156766589
-0.522802758,-12.09374046,313.7399902,0.157279079
-0.523876981,-12.15688419,314.3599854,0.157802409
-0.524951145,-12.27707863,314.980011,0.158350842
-0.526074204,-12.22699261,315.6000061,0.158894429
-0.52709959,-12.24508095,316.2200012,0.159429008
-0.528076198,-12.31739902,316.8399963,0.159976495
-0.529052748,-12.37357426,317.4599915,0.160528216
-0.53012697,-12.22451305,318.0799866,0.161058648
-0.531201193,-12.10176468,318.7000122,0.161629039
-0.532275415,-12.17022705,319.3200073,0.162171884
-0.533300801,-12.26841736,319.9400024,0.162735989
-0.534326187,-12.28833008,320.5599976,0.163314311
-0.535302737,-12.37115002,321.1799927,0.16387034
-0.536279287,-12.30700111,321.7999878,0.164423618
-0.537304673,-12.25352669,322.4200134,0.164997211
-0.538378896,-12.24316692,323.0400085,0.165548001
-0.539453118,-12.26387215,323.6600037,0.166113605
-0.540478504,-12.20487309,324.2799988,0.16665952
-0.541455054,-12.42199039,324.8999939,0.167202612
-0.542431662,-12.27910805,325.519989,0.16776986
-0.543457048,-12.35253716,326.1400146,0.168332073
-0.544580107,-12.48998642,326.7600098,0.168899787
-0.545654271,-12.39054966,327.3800049,0.169494495
-0.546728494,-12.36355686,328,0.170089028
-0.54775388,-12.26473999,328.6199951,0.170730214
-0.548730488,-12.32965279,329.2399902,0.171347812
-0.549707038,-12.409235,329.8599854,0.172017608
-0.55078126,-12.40714264,330.480011,0.172701228
-0.551855483,-12.49937248,331.1000061,0.173390261
-0.552929705,-12.47787952,331.7200012,0.174057102
-0.553955091,-12.44357586,332.3399963,0.174692352
-0.554931641,-12.52832508,332.9599915,0.175318055
-0.555908191,-12.49116898,333.5799866,0.175933324
-0.556933577,-12.56990528,334.2000122,0.17655034
-0.5580078,-12.57276917,334.8200073,0.177157985
-0.559082022,-12.72771835,335.4400024,0.177768117
-0.560156244,-12.7416811,336.0599976,0.178378177
-0.56118163,-12.71462536,336.6799927,0.178995309
-0.56215818,-12.75885677,337.2999878,0.179609546
-0.563134789,-12.71781445,337.9200134,0.180258343
-0.564209011,-12.82883644,338.5400085,0.18094301
-0.565332011,-12.93291855,339.1600037,0.181627271
-0.566357397,-13.01304245,339.7799988,0.18228509
-0.567382784,-12.96977043,340.3999939,0.182939402
-0.568359392,-12.94441032,341.019989,0.183626602
-0.569335942,-12.96294975,341.6400146,0.184308985
-0.570361328,-12.89417648,342.2600098,0.18496043
-0.571484386,-13.0788784,342.8800049,0.185627112
-0.572509773,-13.10838509,343.5,0.186298872
-0.573535159,-13.1999712,344.1199951,0.186963589
-0.574560545,-13.31353378,344.7399902,0.187620564
-0.575537095,-13.27199459,345.3599854,0.18828352
-0.576562481,-13.12366009,345.980011,0.188928141
-0.577636703,-13.12633419,346.6000061,0.189587547
-0.578710926,-13.21675873,347.2200012,0.190238366
-0.579785148,-13.30424786,347.8399963,0.190919032
-0.580810534,-13.40944004,348.4599915,0.191582862
-0.581787084,-13.47383308,349.0799866,0.192250722
-0.582763692,-13.40451431,349.7000122,0.192922613
-0.583789079,-13.38495731,350.3200073,0.193571177
-0.584912137,-13.41073227,350.9400024,0.194270833
-0.585986301,-13.55366707,351.5599976,0.194967302
-0.587011746,-13.53961754,352.1799927,0.195686109
-0.588037132,-13.66434669,352.7999878,0.196398862
-0.589013682,-13.67911816,353.4200134,0.197107729
-0.589990232,-13.68514156,354.0400085,0.197832996
-0.59111329,-13.69855022,354.6600037,0.198575712
-0.592187513,-13.57992554,355.2799988,0.199339149
-0.593212899,-13.68506718,355.8999939,0.200104943
-0.594238285,-13.80108356,356.519989,0.200885523
-0.595263671,-13.86515045,357.1400146,0.201670031
-0.596240221,-13.88486767,357.7600098,0.202479889
-0.597265607,-13.78036118,358.3800049,0.203357733
-0.59833983,-13.82186985,359,0.204228665
-0.599414052,-13.80175877,359.6199951,0.20509545
-0.600439438,-13.8420105,360.2399902,0.205967197
-0.601415988,-13.96581745,360.8599854,0.206870958
-0.602392596,-13.99205017,361.480011,0.207785401
-0.603417982,-13.95348644,362.1000061,0.208727419
-0.604492205,-13.99021244,362.7200012,0.209767444
-0.605566427,-13.93779182,363.3399963,0.210693644
-0.606640649,-14.01603889,363.9599915,0.211617749
-0.607617199,-14.09574127,364.5799866,0.212536892
-0.608642586,-14.14497471,365.2000122,0.213611842
-0.609619136,-14.24631214,365.8200073,0.214542219
-0.610693358,-14.15671349,366.4400024,0.215476583
-0.611816416,-14.09217262,367.0599976,0.216430097
-0.612841803,-14.08702946,367.6799927,0.217351044
-0.613916025,-14.1323576,368.2999878,0.21826895
-0.614892575,-14.18128014,368.9200134,0.219195397
-0.615869125,-14.25353336,369.5400085,0.22011211
-0.616894511,-14.37044621,370.1600037,0.221049137
-0.617968733,-14.17321682,370.7799988,0.222141229
-0.619042956,-14.16276932,371.3999939,0.223295399
-0.620068342,-14.15788078,372.019989,0.224444884
-0.621093728,-14.20831776,372.6400146,0.225480006
-0.622070336,-14.32155037,373.2600098,0.226451361
-0.623046886,-14.48932076,373.8800049,0.227398385
-0.624121109,-14.26918125,374.5,0.228398319
-0.625244167,-14.21315765,375.1199951,0.229424055
-0.626318331,-14.21895218,375.7399902,0.230433085
-0.627343776,-14.33038139,376.3599854,0.231430589
-0.628320326,-14.285676,376.980011,0.232469567
-0.629296876,-14.40982533,377.6000061,0.23349555
-0.630322262,-14.40291691,378.2200012,0.234460342
-0.631396484,-14.32180405,378.8399963,0.235427899
-0.632470706,-14.35431671,379.4599915,0.23638866
-0.633544929,-14.27673149,380.0799866,0.237317421
-0.634521479,-14.37962723,380.7000122,0.238191788
-0.635498029,-14.38618946,381.3200073,0.239079483
-0.636474637,-14.48215294,381.9400024,0.239958725
-0.637548801,-14.54933167,382.5599976,0.240851907
-0.638623023,-14.40517616,383.1799927,0.241755668
-0.639697246,-14.43570232,383.7999878,0.242682072
-0.640673854,-14.47389317,384.4200134,0.243636285
-0.64169924,-14.60020065,385.0400085,0.244537339
-0.64267579,-14.59088326,385.6600037,0.245439383
-0.643701176,-14.60642433,386.2799988,0.246238342
-0.644824235,-14.61155224,386.8999939,0.247013813
-0.645898457,-14.52149868,387.519989,0.247782533
-0.646923843,-14.50148487,388.1400146,0.248533062
-0.647949229,-14.50702,388.7600098,0.249291508
-0.648925779,-14.67546749,389.3800049,0.250036479
-0.649951166,-14.74012566,390,0.250782265
-0.651025388,-14.7424593,390.6199951,0.251549267
-0.65209961,-14.75450706,391.2399902,0.252326397
-0.653173833,-14.65253639,391.8599854,0.253099453
-0.654150383,-14.62381649,392.480011,0.253910373
-0.655175769,-14.70113182,393.1000061,0.25472304
-0.656152319,-14.76531792,393.7200012,0.255510793
-0.657177763,-14.83795929,394.3399963,0.256303087
-0.658300763,-14.78567123,394.9599915,0.257113279
-0.659374986,-14.77560997,395.5799866,0.257920852
-0.660400372,-14.7036171,396.2000122,0.258734333
-0.66137698,-14.7417984,396.8200073,0.259556022
-0.66235353,-14.73812389,397.4400024,0.260373461
-0.663378916,-14.78330326,398.0599976,0.2611948
-0.664453139,-14.91576099,398.6799927,0.262063462
-0.665527361,-14.83578396,399.2999878,0.262942223
-0.666601583,-14.7749567,399.9200134,0.263843685
-0.66762697,-14.73635387,400.5400085,0.264715607
-0.668603519,-14.76463223,401.1600037,0.265595358
-0.669580069,-14.86397362,401.7799988,0.266456947
-0.670605456,-14.87203217,402.3999939,0.267330965
-0.671679678,-14.98765469,403.019989,0.268189266
-0.6727539,-14.8560648,403.6400146,0.269178679
-0.673779286,-14.85889816,404.2600098,0.270149845
-0.674804673,-14.76927376,404.8800049,0.27111292
-0.675732445,-14.78979492,405.5,0.272031553
-0.676757831,-14.82544994,406.1199951,0.272958074
-0.677832053,-14.91258812,406.7399902,0.273891725
-0.678955053,-14.95074368,407.3599854,0.274837395
-0.679980498,-14.8674221,407.980011,0.275787723
-0.681005884,-14.78561783,408.6000061,0.276721606
-0.681982434,-14.74442387,409.2200012,0.277690997
-0.68300782,-14.82312012,409.8399963,0.278671301
-0.684033206,-14.86523724,410.4599915,0.279650994
-0.685156265,-14.94240761,411.0799866,0.280656066
-0.686230487,-14.99379158,411.7000122,0.281651854
-0.687255873,-14.85757446,412.3200073,0.282649649
-0.688232423,-14.80568314,412.9400024,0.283709611
-0.689208973,-14.72707367,413.5599976,0.284836395
-0.690234359,-14.8093853,414.1799927,0.285936345
-0.691357418,-14.79165363,414.7999878,0.287087605
-0.69243164,-14.81332397,415.4200134,0.288230571
-0.693457027,-14.89033127,416.0400085,0.28937211
-0.694482413,-14.78947067,416.6600037,0.290563796
-0.695458963,-14.73278427,417.2799988,0.291794451
-0.696435571,-14.66189098,417.8999939,0.293068995
-0.697509793,-14.671628,418.519989,0.294417056
-0.698632794,-14.80738926,419.1400146,0.295846228
-0.69965818,-14.70322609,419.7600098,0.2973394
-0.700683566,-14.69687653,420.3800049,0.29872125
-0.701660174,-14.71835136,421,0.300052023
-0.702636724,-14.69464588,421.6199951,0.301369902
-0.70366211,-14.50324917,422.2399902,0.302694913
-0.704736332,-14.45452023,422.8599854,0.304056593
-0.705810555,-14.57209206,423.480011,0.305452792
-0.706835941,-14.53207588,424.1000061,0.306816364
-0.707861327,-14.61619473,424.7200012,0.308340415
-0.708837877,-14.68541622,425.3399963,0.30985623
-0.709814427,-14.48670483,425.9599915,0.311400509
-0.710888649,-14.40441513,426.5799866,0.312891993
-0.712011708,-14.33708572,427.2000122,0.31439052
-0.71308593,-14.37686062,427.8200073,0.315916259
-0.714111316,-14.44004345,428.4400024,0.317438564
-0.715087866,-14.43194771,429.0599976,0.318977429
-0.716064475,-14.44506073,429.6799927,0.32050247
-0.717138697,-14.34441853,430.2999878,0.322061562
-0.718212919,-14.30706406,430.9200134,0.323632848
-0.719287083,-14.21968651,431.5400085,0.325193221
-0.720312528,-14.14274406,432.1600037,0.326749636
-0.721289078,-14.25969696,432.7799988,0.328340713
-0.722265628,-14.17467308,433.3999939,0.329928851
-0.723242178,-14.1774683,434.019989,0.33154065
-0.724365236,-14.32068348,434.6400146,0.333136908
-0.725439459,-14.17357922,435.2600098,0.33472263
-0.726513681,-14.04573441,435.8800049,0.336231198
-0.727539067,-13.97447681,436.5,0.337875652
-0.728515617,-13.9657917,437.1199951,0.339500926
-0.729541003,-14.01903057,437.7399902,0.341160485
-0.730566389,-14.0502739,438.3599854,0.342838292
-0.731689448,-14.0998888,438.980011,0.344526983
-0.732714834,-14.03000546,439.6000061,0.346257671
-0.733789057,-14.01194382,440.2200012,0.348018861
-0.734765606,-13.85271263,440.8399963,0.349812181
-0.735742215,-13.85433865,441.4599915,0.351699622
-0.736718765,-13.8452034,442.0799866,0.353609037
-0.737792987,-13.89664555,442.7000122,0.355523429
-0.738867209,-13.17014408,443.3200073,0.363111059
-0.739892595,-13.19774342,443.9400024,0.366343098
-0.740917982,-13.06545162,444.5599976,0.369627
-0.741894532,-12.98433018,445.1799927,0.372732524
-0.742919918,-12.86831665,445.7999878,0.375727133
-0.743945304,-12.81836319,446.4200134,0.378614845
-0.745068362,-12.74910259,447.0400085,0.381497608
-0.746142585,-12.80016041,447.6600037,0.38432228
-0.747216807,-12.7903471,448.2799988,0.387058884
-0.748193357,-12.74095726,448.8999939,0.389855995
-0.749169907,-12.5596714,449.519989,0.392748276
-0.750195293,-12.48458099,450.1400146,0.39562484
-0.751269516,-12.40512371,450.7600098,0.398397271
-0.752343738,-12.35224056,451.3800049,0.401115278
-0.753369124,-12.25283432,452,0.403813523
-0.75439451,-12.21912193,452.6199951,0.406470761
-0.755371118,-12.26049614,453.2399902,0.409118977
-0.756347668,-12.20812988,453.8599854,0.411672052
-0.757421891,-12.07483768,454.480011,0.414209033
-0.758496113,-11.93818951,455.1000061,0.416694966
-0.759570336,-11.85758972,455.7200012,0.419192482
-0.760595722,-11.84831905,456.3399963,0.421570934
-0.761621108,-11.78475857,456.9599915,0.423856865
-0.762597658,-11.81863976,457.5799866,0.426038372
-0.763623044,-11.79345989,458.2000122,0.428172731
-0.764746103,-11.68839931,458.8200073,0.430275395
-0.765820325,-11.61214256,459.4400024,0.432349014
-0.766845711,-11.52480412,460.0599976,0.434401241
-0.767822261,-11.47862148,460.6799927,0.436373753
-0.768798811,-11.4699564,461.2999878,0.438296003
-0.769824197,-11.52402687,461.9200134,0.440160104
-0.770849583,-11.57660103,462.5400085,0.442001852
-0.771923806,-11.46137333,463.1600037,0.443850819
-0.772998028,-11.40841007,463.7799988,0.445648649
-0.774023414,-11.35443592,464.3999939,0.447412051
-0.775000022,-11.33528805,465.019989,0.449142099
-0.775976572,-11.37190437,465.6400146,0.450855558
-0.777001958,-11.35906029,466.2600098,0.452537002
-0.778125017,-11.50318336,466.8800049,0.454237976
-0.779199239,-11.40177345,467.5,0.455920352
-0.780273462,-11.2985363,468.1199951,0.457575894
-0.781250012,-11.2029562,468.7399902,0.459191157
-0.782226562,-11.14822292,469.3599854,0.460811716
-0.783251948,-11.12024307,469.980011,0.462425029
-0.78432617,-11.10219479,470.6000061,0.464040466
-0.785400392,-11.25419617,471.2200012,0.465667603
-0.786425779,-11.18140507,471.8399963,0.467264384
-0.787500001,-11.12897205,472.4599915,0.468857063
-0.788476551,-11.06890297,473.0799866,0.470403582
-0.789404323,-10.95174408,473.7000122,0.471908337
-0.790478487,-11.04675961,474.3200073,0.473396329
-0.791601546,-11.01330471,474.9400024,0.474907021
-0.792626932,-11.0727272,475.5599976,0.476390851
-0.793701154,-10.95058823,476.1799927,0.477832364
-0.79472654,-11.01934719,476.7999878,0.479278999
-0.795703148,-10.96478939,477.4200134,0.480711664
-0.796679698,-10.76932335,478.0400085,0.482129166
-0.797753921,-10.89340878,478.6600037,0.483563548
-0.798828143,-10.92356777,479.2799988,0.485000666
-0.799902366,-10.84039783,479.8999939,0.486398319
-0.800878915,-10.89305019,480.519989,0.487765763
-0.801904302,-10.91824055,481.1400146,0.489126774
-0.802832015,-10.79081631,481.7600098,0.490473583
-0.803906238,-10.77250481,482.3800049,0.491830986
-0.80498046,-10.79005146,483,0.493180181
-0.806054682,-10.84008312,483.6199951,0.494524371
-0.807080069,-10.92045593,484.2399902,0.495875953
-0.808105455,-10.95193768,484.8599854,0.497196044
-0.809082005,-10.89932442,485.480011,0.49852283
-0.810107449,-10.80495358,486.1000061,0.499859219
-0.811181613,-10.67533684,486.7200012,0.501210045
-0.812304672,-10.75936604,487.3399963,0.502566691
-0.813330058,-10.75652027,487.9599915,0.503930729
-0.814355444,-10.85159874,488.5799866,0.505299773
-0.815332052,-10.79218197,489.2000122,0.506642973
-0.816308602,-10.69525719,489.8200073,0.507987104
-0.817382825,-10.66393566,490.4400024,0.509357022
-0.818457047,-10.53711987,491.0599976,0.510736194
-0.819531269,-10.51199913,491.6799927,0.512080442
-0.820556656,-10.64754963,492.2999878,0.513418403
-0.821533205,-10.684762,492.9200134,0.514757587
-0.822509755,-10.75642681,493.5400085,0.51605812
-0.823535142,-10.59672642,494.1600037,0.517377921
-0.8246582,-10.6044178,494.7799988,0.5186731
-0.825732423,-10.51936722,495.3999939,0.519989
-0.826757809,-10.55062675,496.019989,0.521292444
-0.827783195,-10.62674713,496.6400146,0.522588147
-0.828759745,-10.6773653,497.2600098,0.523872557
-0.829736353,-10.73537445,497.8800049,0.525156327
-0.830810575,-10.56737804,498.5,0.526437361
-0.831884739,-10.58514214,499.1199951,0.527740573
-0.832958962,-10.59339619,499.7399902,0.529031502
-0.833984348,-10.65007114,500.3599854,0.530300371
-0.834960956,-10.63441181,500.980011,0.531575351
-0.835937506,-10.63124657,501.6000061,0.532823207
-0.836962892,-10.72490311,502.2200012,0.534070714
-0.838037115,-10.60485649,502.8399963,0.535352039
-0.839111337,-10.54257298,503.4599915,0.536620151
-0.840136723,-10.54850674,504.0799866,0.537857995
-0.841162109,-10.55455589,504.7000122,0.539105327
-0.842138659,-10.71914673,505.3200073,0.540359644
-0.843115209,-10.53486156,505.9400024,0.541609479
-0.844189432,-10.57698059,506.5599976,0.542907743
-0.84531249,-10.39496803,507.1799927,0.544196868
-0.846386713,-10.47864532,507.7999878,0.545470044
-0.847412099,-10.62347221,508.4200134,0.546735246
-0.848388649,-10.6132021,509.0400085,0.547979085
-0.849365257,-10.63964176,509.6600037,0.549216638
-0.850439479,-10.55164433,510.2799988,0.55044092
-0.851513643,-10.40421677,510.8999939,0.551706587
-0.852587866,-10.47606087,511.519989,0.55291655
-0.85361331,-10.52528286,512.1400146,0.554150494
-0.854638696,-10.53676605,512.7600098,0.555372797
-0.855615246,-10.62119579,513.3800049,0.556578278
-0.856591796,-10.61603832,514,0.557781954
-0.857666018,-10.55285454,514.6199951,0.558996806
-0.858789077,-10.51208305,515.2399902,0.560204149
-0.859814463,-10.54229832,515.8599854,0.561404799
-0.860839849,-10.62878132,516.4799805,0.56262163
-0.861816399,-10.69181538,517.0999756,0.563818205
-0.862792949,-10.65893364,517.7199707,0.565022754
-0.863867172,-10.62242413,518.3400269,0.566285278
-0.864941394,-10.61728668,518.960022,0.567484996
-0.866015616,-10.54574203,519.5800171,0.56872383
-0.867041002,-10.55975246,520.2000122,0.569959113
-0.868066389,-10.61110592,520.8200073,0.571190496
-0.869042997,-10.6941061,521.4400024,0.572405756
-0.870019547,-10.660779,522.0599976,0.573595578
-0.871093769,-10.51583958,522.6799927,0.574815378
-0.872167991,-10.51281548,523.2999878,0.575997808
-0.873242214,-10.55457592,523.9199829,0.577190658
-0.874218764,-10.56801796,524.539978,0.578368607
-0.875195314,-10.58074188,525.1599731,0.57953858
-0.8762207,-10.65638638,525.7800293,0.580710883
-0.877246086,-10.56563854,526.4000244,0.581895642
-0.878369145,-10.47572708,527.0200195,0.583078363
-0.879394531,-10.5053196,527.6400146,0.584268651
-0.880468753,-10.65515995,528.2600098,0.585450965
-0.881445303,-10.62645626,528.8800049,0.586616981
-0.882421853,-10.66414642,529.5,0.587782881
-0.883447239,-10.71379852,530.1199951,0.588925846
-0.884570298,-10.59260941,530.7399902,0.590106414
-0.88564452,-10.58322716,531.3599854,0.591279706
-0.886718743,-10.55288219,531.9799805,0.592435885
-0.887695292,-10.63698006,532.5999756,0.593598816
-0.888671901,-10.64965153,533.2199707,0.594748708
-0.889648451,-10.71012211,533.8400269,0.595896447
-0.890722673,-10.64863873,534.460022,0.59706514
-0.891845732,-10.6360569,535.0800171,0.598216779
-0.892871118,-10.55290699,535.7000122,0.599387626
-0.89394534,-10.56218052,536.3200073,0.60050789
-0.89492189,-10.63517857,536.9400024,0.601643929
-0.89589844,-10.73206329,537.5599976,0.60278544
-0.896923826,-10.77370167,538.1799927,0.60392305
-0.897998048,-10.74127579,538.7999878,0.605083827
-0.899121107,-10.70914173,539.4199829,0.606243848
-0.900146493,-10.66568089,540.039978,0.60742459
-0.901171879,-10.55951118,540.6599731,0.608579023
-0.902099593,-10.71229553,541.2800293,0.609739101
-0.903076143,-10.73732662,541.9000244,0.610878458
-0.904150365,-10.83125114,542.5200195,0.612034346
-0.905224588,-10.70619011,543.1400146,0.613221666
-0.90629881,-10.69402027,543.7600098,0.614406425
-0.907324196,-10.66611862,544.3800049,0.615570287
-0.908300804,-10.68379307,545,0.616736361
-0.909277354,-10.74429035,545.6199951,0.617903483
-0.910302741,-10.76053238,546.2399902,0.619090046
-0.911425799,-10.80827618,546.8599854,0.620262988
-0.912500022,-10.7799263,547.4799805,0.62147784
-0.913574244,-10.66088581,548.0999756,0.622675463
-0.914550794,-10.76067352,548.7199707,0.623863772
-0.91557618,-10.63498116,549.3400269,0.625021057
-0.91655273,-10.79514027,549.960022,0.626192952
-0.917626952,-10.8394022,550.5800171,0.62737189
-0.918701175,-10.79233074,551.2000122,0.628542795
-0.919775397,-10.74314022,551.8200073,0.629699731
-0.920751947,-10.64493465,552.4400024,0.630851428
-0.921728497,-10.70540905,553.0599976,0.631988107
-0.922705105,-10.73812389,553.6799927,0.633119256
-0.923730491,-10.8114233,554.2999878,0.634281663
-0.924853492,-10.89775181,554.9199829,0.635433302
-0.925927714,-10.80680943,555.539978,0.636578712
-0.927001936,-10.8327589,556.1599731,0.637721969
-0.928027323,-10.78709412,556.7800293,0.638827099
-0.929003931,-10.76248646,557.4000244,0.63993677
-0.929980481,-10.83395004,558.0200195,0.641040271
-0.931103539,-10.93515873,558.6400146,0.642156985
-0.932177762,-10.91770363,559.2600098,0.64327888
-0.933203148,-10.98279858,559.8800049,0.644375046
-0.934228534,-10.91464424,560.5,0.645473134
-0.935205084,-10.78713989,561.1199951,0.646548928
-0.936181634,-10.84354401,561.7399902,0.647627341
-0.93720702,-10.95818329,562.3599854,0.648701563
-0.938281242,-10.87660599,562.9799805,0.649800815
-0.939355465,-10.9625206,563.5999756,0.650862756
-0.940380851,-10.90036011,564.2199707,0.651948212
-0.941357401,-10.83089733,564.8400269,0.653055089
-0.942334009,-10.81652737,565.460022,0.654147356
-0.943359395,-10.91971874,566.0800171,0.65521861
-0.944482395,-10.95834827,566.7000122,0.656325428
-0.945556618,-10.96489239,567.3200073,0.657420198
-0.94663084,-11.0216589,567.9400024,0.658509438
-0.947656226,-11.01159382,568.5599976,0.65957784
-0.948632834,-10.88673306,569.1799927,0.660613354
-0.949609384,-10.89913464,569.7999878,0.661659404
-0.950683607,-10.9891367,570.4199829,0.662713603
-0.951757829,-11.02486515,571.039978,0.66377403
-0.952783215,-11.08883381,571.6599731,0.664826948
-0.953857438,-10.96467304,572.2800293,0.665874046
-0.954833988,-10.9602623,572.9000244,0.666897278
-0.955810538,-10.94715786,573.5200195,0.667927379
-0.956835924,-10.98455524,574.1400146,0.668959168
-0.957910146,-11.0814991,574.7600098,0.670025009
-0.958984368,-11.13396358,575.3800049,0.671067275
-0.960058591,-11.22594643,576,0.672097551
-0.961083977,-11.1294508,576.6199951,0.673111004
-0.962060527,-11.11701012,577.2399902,0.674142968
-0.963037135,-11.02297688,577.8599854,0.67518506
-0.964111299,-11.10558891,578.4799805,0.676238444
-0.965234358,-11.12117386,579.0999756,0.677298289
-0.966259744,-11.19106388,579.7199707,0.678352371
-0.96728513,-11.2371645,580.3400269,0.679387827
-0.968261738,-11.12219715,580.960022,0.680415484
-0.969238288,-11.01906109,581.5800171,0.681430101
-0.970263674,-11.07931042,582.2000122,0.682467362
-0.971337897,-10.99071407,582.8200073,0.683504972
-0.972412119,-11.18337059,583.4400024,0.684556318
-0.973437505,-11.23945045,584.0599976,0.685590669
-0.974462891,-11.20158482,584.6799927,0.686626125
-0.975439441,-11.15110874,585.2999878,0.687653315
-0.976464828,-11.07270908,585.9199829,0.688689819
-0.977539108,-11.09143162,586.539978,0.689725624
-0.978613272,-11.17206097,587.1599731,0.690786866
-0.979687553,-11.22771358,587.7800293,0.691834255
-0.980712939,-11.37713337,588.4000244,0.692876463
-0.981689431,-11.2577076,589.0200195,0.693908543
-0.982666039,-11.19661236,589.6400146,0.694930553
-0.983691425,-11.16181755,590.2600098,0.695956172
-0.984814484,-11.15480328,590.8800049,0.696998439
-0.985888648,-11.27956486,591.5,0.698050251
-0.986914034,-11.30621815,592.1199951,0.699091644
-0.98793942,-11.30968475,592.7399902,0.700117846
-0.988916028,-11.29311752,593.3599854,0.701134384
-0.98989252,-11.2463274,593.9799805,0.70213963
-0.990966801,-11.20777035,594.5999756,0.70318958
-0.992089859,-11.1789341,595.2199707,0.704238191
-0.993115245,-11.26274776,595.8400269,0.70527877
-0.99418941,-11.32579708,596.460022,0.706308405
-0.995166018,-11.3763485,597.0800171,0.707326573
-0.996142626,-11.29018211,597.7000122,0.708330364
-0.997168012,-11.27633286,598.3200073,0.709339161
-0.998242176,-11.17331123,598.9400024,0.71035896
-0.999316457,-11.23483753,599.5599976,0.711373927
-1.000341843,-11.32186127,600.1799927,0.712412701
-1.001318335,-11.38219166,600.7999878,0.713422371
-1.002294943,-11.4459753,601.4199829,0.714409805
-1.003320329,-11.34572601,602.039978,0.715383212
-1.004345715,-11.32507992,602.6599731,0.716405397
-1.005468774,-11.31282234,603.2800293,0.717443239
-1.006542938,-11.26270199,603.9000244,0.718453142
-1.007519546,-11.40450096,604.5200195,0.719463453
-1.008544932,-11.39341831,605.1400146,0.720475335
-1.00952154,-11.48077202,605.7600098,0.721488032
-1.010595704,-11.4935379,606.3800049,0.722492521
-1.011669869,-11.46097565,607,0.723525707
-1.012744149,-11.33946991,607.6199951,0.724582875
-1.013769535,-11.34148312,608.2399902,0.725710066
-1.014794922,-11.41066551,608.8599854,0.72676508
-1.01577153,-11.44204426,609.4799805,0.727839128
-1.016748021,-11.52305031,610.0999756,0.72890037
-1.01787108,-11.3950758,610.7199707,0.729967491
-1.018945361,-11.37439728,611.3400269,0.731048931
-1.019970747,-11.38617611,611.960022,0.732117973
-1.020996133,-11.34051228,612.5800171,0.733158435
-1.021972625,-11.49783707,613.2000122,0.734183413
-1.022949233,-11.51639175,613.8200073,0.735226495
-1.024023397,-11.54254818,614.4400024,0.736280519
-1.025146456,-11.49079037,615.0599976,0.737334776
-1.026220736,-11.48856163,615.6799927,0.738389324
-1.027246122,-11.44406986,616.2999878,0.739423733
-1.028222614,-11.40619755,616.9199829,0.740450283
-1.029199222,-11.45240593,617.539978,0.741487427
-1.030224608,-11.51248264,618.1599731,0.742500415
-1.031298772,-11.53030491,618.7800293,0.743512355
-1.032373053,-11.53170586,619.4000244,0.744537276
-1.033447217,-11.55739307,620.0200195,0.7455452
-1.034423825,-11.62546253,620.6400146,0.746549165
-1.035400433,-11.52505493,621.2600098,0.747543643
-1.036376925,-11.5446291,621.8800049,0.748509308
-1.037451206,-11.534729,622.5,0.749496394
-1.03852537,-11.58583355,623.1199951,0.750522246
-1.038574264,-11.63057041,623.1400146,0.75054809