File: Data/Thesis_Samples_Data/Notched_Solid_6/Notched_Solid_6.csv
"File Path: C:\Users\Lab User\Desktop\Will\Thesis Tests\Test Run 4 04-8-22 16 15 28 PM\DAQ- Crosshead, … - (Timed).csv   ",,,
Test: MTS EM Tension (Extensometer) - Will 1,,,
Test Run: Test Run 4,,,
Date: 4/8/2022 4:13:51 PM,,,
,,,
,,,
Crosshead ,Load ,Time ,Extensometer
mm,N,sec,mm
4.88E-05,-1.568293214,0.02,2.17E-06
0,-1.40722084,0.100000001,-4.17E-06
-4.88E-05,-1.556377769,0.180000007,-2.56E-06
-9.77E-05,-1.640481472,0.25999999,-4.32E-06
-0.000195312,-1.741601586,0.340000004,-2.56E-06
-0.000244141,-1.721136093,0.419999987,-7.73E-06
-0.000390625,-1.826813936,0.5,-1.23E-05
-0.000537109,-2.121628284,0.579999983,-5.57E-06
-0.000683594,-2.469558716,0.660000026,-1.19E-05
-0.000830078,-2.65979743,0.74000001,-3.33E-06
-0.000976563,-2.840589285,0.819999993,-2.07E-05
-0.001171875,-3.087749481,0.899999976,-1.01E-05
-0.001318359,-3.398643732,0.980000019,-1.63E-05
-0.001513672,-3.828264236,1.059999943,-2.31E-06
-0.001660156,-4.016044617,1.139999986,-8.50E-06
-0.001855469,-4.243388653,1.220000029,-9.19E-06
-0.002050781,-4.485605717,1.299999952,-1.17E-05
-0.002197266,-4.828725815,1.379999995,-1.53E-05
-0.00234375,-5.085068226,1.460000038,-3.61E-06
-0.002490234,-5.331557751,1.539999962,-4.48E-06
-0.002587891,-5.358355522,1.620000005,-2.01E-05
-0.002734375,-5.630494595,1.700000048,-1.14E-05
-0.002880859,-5.937422276,1.779999971,-1.11E-05
-0.003027344,-6.267305374,1.860000014,-1.02E-05
-0.003173828,-6.269589901,1.940000057,-2.06E-06
-0.003271484,-6.352743149,2.019999981,-1.35E-05
-0.003417969,-6.618479729,2.099999905,-8.03E-06
-0.003564453,-7.053470135,2.180000067,-5.76E-06
-0.003710938,-7.212433815,2.25999999,1.87E-06
-0.003808594,-7.322795868,2.339999914,-5.32E-06
-0.003955078,-7.43046093,2.420000076,-1.06E-05
-0.004101562,-7.873101234,2.5,-1.37E-06
-0.004248047,-8.141067505,2.579999924,9.33E-06
-0.004394531,-8.372747421,2.660000086,8.41E-06
-0.004541016,-8.445668221,2.74000001,5.56E-07
-0.0046875,-8.667961121,2.819999933,-1.15E-05
-0.004833984,-8.970366478,2.900000095,-1.20E-07
-0.004980469,-9.346487999,2.980000019,2.15E-06
-0.005126953,-9.477125168,3.059999943,1.15E-05
-0.005273438,-9.57579422,3.140000105,-4.65E-06
-0.005419922,-9.834988594,3.220000029,8.25E-07
-0.005517578,-10.15987301,3.299999952,-6.16E-07
-0.005664062,-10.44440365,3.380000114,-7.57E-07
-0.005810547,-10.610425,3.460000038,4.47E-06
-0.005957031,-10.73335266,3.539999962,4.60E-06
-0.006103516,-10.99635792,3.619999886,1.02E-05
-0.00625,-11.43132305,3.700000048,8.89E-06
-0.006347656,-11.67859936,3.779999971,8.93E-06
-0.006494141,-11.79937553,3.859999895,1.52E-05
-0.006640625,-11.97245884,3.940000057,1.27E-05
-0.006787109,-12.28645611,4.019999981,5.66E-06
-0.006884766,-12.56350994,4.099999905,1.88E-05
-0.00703125,-12.83369923,4.179999828,2.24E-05
-0.007177734,-12.98458099,4.260000229,2.27E-05
-0.007275391,-13.20869637,4.340000153,1.90E-05
-0.007421875,-13.55260563,4.420000076,2.20E-05
-0.007568359,-13.80974865,4.5,2.28E-05
-0.007666015,-13.94742298,4.579999924,2.97E-05
-0.0078125,-14.20016384,4.659999847,2.82E-05
-0.007958984,-14.31650162,4.739999771,2.89E-05
-0.008056641,-14.65212154,4.820000172,2.83E-05
-0.008203125,-15.01021957,4.900000095,3.87E-05
-0.00834961,-15.13064861,4.980000019,2.65E-05
-0.008447266,-15.21219444,5.059999943,3.25E-05
-0.00859375,-15.53201485,5.139999866,2.85E-05
-0.008691406,-15.74662971,5.21999979,4.43E-05
-0.008837891,-16.15165901,5.300000191,4.49E-05
-0.008935547,-16.27321815,5.380000114,4.48E-05
-0.009082031,-16.40758133,5.460000038,4.16E-05
-0.009228515,-16.66413307,5.539999962,4.02E-05
-0.009326171,-17.04794502,5.619999886,5.16E-05
-0.009472657,-17.3088131,5.699999809,4.12E-05
-0.009619141,-17.39801788,5.78000021,3.52E-05
-0.009716797,-17.65129471,5.860000134,4.47E-05
-0.009863281,-18.00248337,5.940000057,4.88E-05
-0.010009766,-18.34545708,6.019999981,4.98E-05
-0.010107422,-18.53159142,6.099999905,4.84E-05
-0.010253906,-18.74810791,6.179999828,5.09E-05
-0.01040039,-18.84505081,6.260000229,4.74E-05
-0.010546875,-19.13089561,6.340000153,4.68E-05
-0.010693359,-19.65373421,6.420000076,7.19E-05
-0.010791015,-19.93818283,6.5,6.51E-05
-0.0109375,-19.96655655,6.579999924,6.01E-05
-0.011083985,-20.3244133,6.659999847,5.65E-05
-0.011230469,-20.62142372,6.739999771,6.69E-05
-0.011376953,-20.94633102,6.820000172,6.31E-05
-0.011523438,-21.1580925,6.900000095,7.36E-05
-0.011669922,-21.35411453,6.980000019,6.00E-05
-0.011816406,-21.65775299,7.059999943,5.56E-05
-0.01196289,-22.10106087,7.139999866,7.03E-05
-0.012060547,-22.20348167,7.21999979,6.59E-05
-0.012207031,-22.50754929,7.300000191,6.80E-05
-0.012353516,-22.6303997,7.380000114,7.76E-05
-0.012451172,-23.04313278,7.460000038,7.78E-05
-0.012597657,-23.41913605,7.539999962,8.34E-05
-0.012744141,-23.74838448,7.619999886,8.64E-05
-0.012890625,-23.84017754,7.699999809,8.53E-05
-0.012988281,-24.07579613,7.78000021,7.16E-05
-0.013134766,-24.32803154,7.860000134,8.64E-05
-0.01328125,-24.83195305,7.940000057,9.40E-05
-0.013427734,-25.04339981,8.020000458,8.37E-05
-0.013574218,-25.21817017,8.100000381,8.24E-05
-0.013671875,-25.49136353,8.180000305,9.37E-05
-0.01381836,-25.95046997,8.260000229,0.000101876
-0.013916016,-26.23981094,8.340000153,0.000101181
-0.0140625,-26.47667694,8.420000076,9.82E-05
-0.014208985,-26.61880875,8.5,0.000107057
-0.014306641,-26.96972084,8.579999924,0.000101883
-0.014453125,-27.37520027,8.659999847,0.000115636
-0.014599609,-27.68738365,8.739999771,0.000114388
-0.014697265,-27.94752693,8.819999695,0.000108016
-0.01484375,-28.1962471,8.899999619,0.000117284
-0.014941406,-28.46813202,8.979999542,0.000110583
-0.01508789,-28.92365265,9.06000042,0.000127109
-0.015185547,-29.2042942,9.140000343,0.00013068
-0.015332031,-29.42372131,9.220000267,0.000124286
-0.015478516,-29.72878456,9.300000191,0.000126994
-0.015576172,-30.05847168,9.380000114,0.00013693
-0.015722657,-30.52007675,9.460000038,0.000132813
-0.015820313,-30.70956802,9.539999962,0.000142827
-0.015966796,-31.01346779,9.619999886,0.000140805
-0.016113281,-31.20690346,9.699999809,0.000140924
-0.016210937,-31.69469643,9.779999733,0.000141969
-0.016357422,-32.17339325,9.859999657,0.000146524
-0.016455078,-32.40358353,9.93999958,0.000151856
-0.016601563,-32.704216,10.02000046,0.000156006
-0.016748047,-33.07221222,10.10000038,0.000156388
-0.016845703,-33.34637451,10.18000031,0.000154691
-0.016992188,-33.93047714,10.26000023,0.000172376
-0.017138673,-34.19348145,10.34000015,0.000166483
-0.017285156,-34.53778458,10.42000008,0.000163972
-0.017431641,-34.91407776,10.5,0.000166283
-0.017578124,-35.40517807,10.57999992,0.000170876
-0.017724609,-35.6786499,10.65999985,0.000188617
-0.017822265,-36.03967285,10.73999977,0.000188441
-0.01796875,-36.42694855,10.81999969,0.000186166
-0.018115234,-36.90714264,10.89999962,0.000184375
-0.018261719,-37.50652313,10.97999954,0.000205836
-0.018408204,-37.76879883,11.06000042,0.000201849
-0.018554687,-38.15059662,11.14000034,0.00020528
-0.018701172,-38.49777603,11.22000027,0.00021263
-0.018847657,-38.97018051,11.30000019,0.000206592
-0.01899414,-39.45256042,11.38000011,0.000208895
-0.019140625,-39.86577225,11.46000004,0.00022956
-0.019238281,-40.12402725,11.53999996,0.000228648
-0.019384766,-40.51462936,11.61999989,0.000224287
-0.01953125,-40.90813065,11.69999981,0.000233186
-0.019628906,-41.64727402,11.77999973,0.000236968
-0.019775391,-41.71902466,11.85999966,0.000244889
-0.019921876,-42.09050751,11.93999958,0.000246504
-0.020068359,-42.41642761,12.02000046,0.00024728
-0.020166015,-42.96903229,12.10000038,0.000256515
-0.0203125,-43.38628387,12.18000031,0.000265538
-0.020458985,-43.67211533,12.26000023,0.000264342
-0.020605468,-44.01916504,12.34000015,0.000261987
-0.020703124,-44.56674957,12.42000008,0.000263943
-0.020849609,-44.95772934,12.5,0.000276069
-0.020996094,-45.37375641,12.57999992,0.000272471
-0.021093751,-45.7203598,12.65999985,0.000273296
-0.021240234,-46.19374847,12.73999977,0.000286122
-0.021386719,-46.54447174,12.81999969,0.000286356
-0.021484375,-47.06539536,12.89999962,0.000293104
-0.02163086,-47.36938477,12.97999954,0.000308365
-0.021728516,-47.65286255,13.06000042,0.000306849
-0.021874999,-48.06114578,13.14000034,0.000297991
-0.022021484,-48.56311035,13.22000027,0.000306572
-0.02211914,-49.01887512,13.30000019,0.000319419
-0.022265625,-49.36735153,13.38000011,0.000314665
-0.022363281,-49.66944504,13.46000004,0.000315373
-0.022509766,-50.09460831,13.53999996,0.00031676
-0.02265625,-50.61193848,13.61999989,0.000330112
-0.022753906,-51.05817032,13.69999981,0.000336273
-0.022900391,-51.41309357,13.77999973,0.000337648
-0.022998047,-51.73493958,13.85999966,0.000341142
-0.023144532,-52.30219269,13.93999958,0.000345181
-0.023291015,-52.84506989,14.02000046,0.000351521
-0.0234375,-53.27629089,14.10000038,0.000364808
-0.023535156,-53.57977295,14.18000031,0.000356911
-0.023681641,-53.95452881,14.26000023,0.00035939
-0.023828125,-54.59134293,14.34000015,0.000378666
-0.02397461,-55.08642197,14.42000008,0.000375039
-0.024121095,-55.46791458,14.5,0.000379774
-0.024267578,-55.989151,14.57999992,0.000386721
-0.024414063,-56.41815948,14.65999985,0.000392629
-0.024560546,-57.00367737,14.73999977,0.000392247
-0.024707031,-57.55519104,14.81999969,0.000398211
-0.024853516,-57.94350815,14.89999962,0.000406622
-0.024999999,-58.29438782,14.97999954,0.000408805
-0.025097655,-58.85172272,15.06000042,0.000403794
-0.02524414,-59.36632919,15.14000034,0.000419872
-0.025390626,-59.92539978,15.22000027,0.000426739
-0.025537109,-60.3134613,15.30000019,0.000428764
-0.025683594,-60.74274445,15.38000011,0.000428543
-0.025830079,-61.25909042,15.46000004,0.000436972
-0.025927735,-61.72653198,15.53999996,0.000443213
-0.026074218,-62.27490616,15.61999989,0.00044908
-0.026220703,-62.65304947,15.69999981,0.000450637
-0.026367188,-62.95910263,15.77999973,0.000447555
-0.026464844,-63.62734985,15.85999966,0.000454492
-0.026611327,-64.11083984,15.93999958,0.000463087
-0.026757813,-64.46941376,16.02000046,0.000470156
-0.026855469,-64.87883759,16.10000038,0.000469383
-0.027001954,-65.45433044,16.18000031,0.000471107
-0.027148437,-65.95858002,16.26000023,0.000474463
-0.027294922,-66.42420959,16.34000015,0.000479946
-0.027441407,-66.83573914,16.42000008,0.000483997
-0.027539063,-67.17230225,16.5,0.000488263
-0.027685546,-67.62866211,16.57999992,0.000495757
-0.027783202,-68.13708496,16.65999985,0.000502522
-0.027929687,-68.6750946,16.73999977,0.000516273
-0.028027343,-69.07386017,16.81999969,0.000524212
-0.028173828,-69.46722412,16.89999962,0.000526084
-0.028320312,-69.97149658,16.97999954,0.000530196
-0.02841797,-70.48286438,17.05999947,0.000533822
-0.028564453,-70.8890152,17.13999939,0.0005436
-0.028710938,-71.3735733,17.21999931,0.000539565
-0.028808594,-71.72051239,17.29999924,0.000544795
-0.028955079,-72.21146393,17.37999916,0.000557192
-0.029052735,-72.78006744,17.45999908,0.000568302
-0.029199218,-73.26168823,17.54000092,0.000576706
-0.029296874,-73.49551392,17.62000084,0.000573755
-0.029443359,-73.9708786,17.70000076,0.000573365
-0.029589844,-74.58883667,17.78000069,0.000583983
-0.029736328,-75.15422821,17.86000061,0.000584814
-0.029833984,-75.47298431,17.94000053,0.000601469
-0.029980469,-75.93738556,18.02000046,0.000608821
-0.030126954,-76.45013428,18.10000038,0.000606934
-0.03022461,-76.97373199,18.18000031,0.000609871
-0.030371093,-77.68011475,18.26000023,0.000633426
-0.030517578,-77.92897797,18.34000015,0.00062633
-0.030664061,-78.40433502,18.42000008,0.000627869
-0.030810548,-79.02983093,18.5,0.000640333
-0.030957031,-79.69638824,18.57999992,0.000656657
-0.031103515,-80.15063477,18.65999985,0.000664215
-0.031250001,-80.69817352,18.73999977,0.00066531
-0.031347656,-81.2372818,18.81999969,0.000674018
-0.031494139,-81.71331787,18.89999962,0.000675663
-0.031640626,-82.35075378,18.97999954,0.00068415
-0.031787109,-82.76480103,19.05999947,0.000690431
-0.031933592,-83.28900909,19.13999939,0.000698354
-0.032080079,-83.79223633,19.21999931,0.000707862
-0.032226562,-84.29206848,19.29999924,0.000709728
-0.03232422,-85.01526642,19.37999916,0.000716738
-0.032470703,-85.39047241,19.45999908,0.000726671
-0.032617187,-85.91402435,19.54000092,0.000718271
-0.032763674,-86.36264801,19.62000084,0.000732779
-0.032910157,-86.96326447,19.70000076,0.000740459
-0.033007811,-87.55706024,19.78000069,0.000749573
-0.033154298,-88.02632904,19.86000061,0.000755497
-0.033300781,-88.48569489,19.94000053,0.000763287
-0.033447264,-88.99893188,20.02000046,0.000766959
-0.033544922,-89.60715485,20.10000038,0.000773521
-0.033691405,-90.22995758,20.18000031,0.000790955
-0.033837892,-90.50874329,20.26000023,0.000790944
-0.033935547,-91.04116821,20.34000015,0.000788851
-0.03408203,-91.56726074,20.42000008,0.000801314
-0.034228517,-92.07942963,20.5,0.000808196
-0.034326171,-92.60153198,20.57999992,0.000816011
-0.034472658,-93.02566528,20.65999985,0.00082393
-0.034619141,-93.46557617,20.73999977,0.000829637
-0.034716795,-94.08969879,20.81999969,0.000832969
-0.034863282,-94.69463348,20.89999962,0.000837479
-0.034960936,-95.1612854,20.97999954,0.000866204
-0.035107423,-95.56439209,21.05999947,0.000864643
-0.035205077,-96.03835297,21.13999939,0.000870639
-0.035351564,-96.55414581,21.21999931,0.000878816
-0.035449219,-97.0920105,21.29999924,0.000882813
-0.035595702,-97.33153534,21.37999916,0.000890508
-0.035742189,-97.79149628,21.45999908,0.000910093
-0.035839843,-98.37532043,21.54000092,0.000900124
-0.03598633,-98.91265869,21.62000084,0.000911364
-0.036132813,-99.56809235,21.70000076,0.000922748
-0.036230467,-99.852211,21.78000069,0.000926608
-0.036376954,-100.4177704,21.86000061,0.000935834
-0.036474608,-100.8949966,21.94000053,0.000944125
-0.036621095,-101.723732,22.02000046,0.000951407
-0.036767578,-102.0647659,22.10000038,0.000964843
-0.036914062,-102.596405,22.18000031,0.00096437
-0.03701172,-103.1339569,22.26000023,0.000985064
-0.037158203,-103.7978134,22.34000015,0.000995268
-0.037304686,-104.4228134,22.42000008,0.001005045
-0.037451173,-105.1102982,22.5,0.001014913
-0.037597656,-105.4910278,22.57999992,0.00102748
-0.037744139,-106.0382919,22.65999985,0.001016931
-0.037890626,-106.7364578,22.73999977,0.001048027
-0.038037109,-107.4181061,22.81999969,0.001054792
-0.038183593,-107.894989,22.89999962,0.001071957
-0.038330079,-108.4996109,22.97999954,0.001080736
-0.038476563,-109.0784683,23.05999947,0.00109008
-0.038574221,-109.7123032,23.13999939,0.001104106
-0.038720704,-110.4003372,23.21999931,0.001125083
-0.038867187,-110.9103088,23.29999924,0.001130098
-0.03901367,-111.4364777,23.37999916,0.001143679
-0.039160157,-112.0203018,23.45999908,0.001138138
-0.03930664,-112.7090302,23.54000092,0.001168483
-0.039404298,-113.1228714,23.62000084,0.001191004
-0.039550781,-113.8369064,23.70000076,0.001193057
-0.039697265,-114.2913666,23.78000069,0.001212149
-0.039843751,-114.9315567,23.86000061,0.001215417
-0.039990235,-115.4959564,23.94000053,0.001240786
-0.040087889,-115.9916229,24.02000046,0.001255929
-0.040234376,-116.4979782,24.10000038,0.001271459
-0.040380859,-117.0923843,24.18000031,0.001277987
-0.040478517,-117.7187805,24.26000023,0.001300268
-0.040625,-118.384491,24.34000015,0.001322052
-0.040771483,-118.7703705,24.42000008,0.001339595
-0.040869141,-119.2840424,24.5,0.001352376
-0.041015624,-119.8566208,24.57999992,0.001359457
-0.041162108,-120.4799042,24.65999985,0.00138428
-0.041308595,-121.0207672,24.73999977,0.001408962
-0.041406249,-121.56147,24.81999969,0.001429667
-0.041552736,-121.9985962,24.89999962,0.001442136
-0.04165039,-122.5526886,24.97999954,0.001463409
-0.041796877,-123.1047134,25.05999947,0.001497457
-0.04194336,-123.6208267,25.13999939,0.001516277
-0.042041014,-124.0450592,25.21999931,0.001541564
-0.042187501,-124.5716858,25.29999924,0.001562485
-0.042285155,-125.0404434,25.37999916,0.001577558
-0.042431642,-125.6888123,25.45999908,0.001597748
-0.042529296,-126.2057419,25.54000092,0.001622119
-0.04267578,-126.7556,25.62000084,0.001643245
-0.042822267,-127.2977905,25.70000076,0.001654998
-0.042919921,-127.8575516,25.78000069,0.001679359
-0.043066408,-128.5004272,25.86000061,0.00169912
-0.043212891,-129.1020203,25.94000053,0.001720373
-0.043310545,-129.4963989,26.02000046,0.001746516
-0.043457032,-130.1558228,26.10000038,0.001759531
-0.043603515,-130.8309479,26.18000031,0.001787601
-0.043701173,-131.3846588,26.26000023,0.001808433
-0.043847656,-131.9440613,26.34000015,0.001837945
-0.04399414,-132.5113525,26.42000008,0.001859816
-0.044140626,-133.2234344,26.5,0.001881755
-0.04428711,-133.9087524,26.57999992,0.001903862
-0.044433593,-134.6660767,26.65999985,0.001942675
-0.04458008,-135.3529358,26.73999977,0.001958729
-0.044726563,-135.8039551,26.81999969,0.001997116
-0.044873046,-136.5386353,26.89999962,0.002023642
-0.045019533,-137.3410339,26.97999954,0.002062916
-0.045117187,-137.9470673,27.05999947,0.002087845
-0.04526367,-138.5033569,27.13999939,0.002110043
-0.045410157,-139.1227417,27.21999931,0.00214332
-0.045556641,-139.867569,27.29999924,0.002168842
-0.045654298,-140.5101471,27.37999916,0.00220948
-0.045800782,-141.1615906,27.45999908,0.002254275
-0.045947265,-141.7596893,27.54000092,0.002400397
-0.046093752,-142.4313354,27.62000084,0.002432657
-0.046240235,-143.1186218,27.70000076,0.002473921
-0.046386718,-143.8937073,27.78000069,0.002511754
-0.046484376,-144.470871,27.86000061,0.002545095
-0.046630859,-145.0316772,27.94000053,0.002583583
-0.046777343,-145.4373016,28.02000046,0.002624119
-0.046875,-146.1459198,28.10000038,0.00267824
-0.047021484,-146.7097473,28.18000031,0.002721564
-0.04716797,-147.2062988,28.26000023,0.002766018
-0.047265625,-147.6122284,28.34000015,0.002807605
-0.047412108,-148.3101044,28.42000008,0.00285809
-0.047558595,-148.7934265,28.5,0.002927126
-0.047656249,-149.0927887,28.57999992,0.002983333
-0.047802736,-149.4932098,28.65999985,0.003035648
-0.047949219,-149.7384186,28.73999977,0.003114458
-0.048046873,-149.9615326,28.81999969,0.003192058
-0.04819336,-150.1841278,28.89999962,0.003278157
-0.048291015,-150.0978394,28.97999954,0.00337756
-0.048437501,-149.9102936,29.05999947,0.003479831
-0.048583985,-149.2391357,29.13999939,0.00363061
-0.048681639,-148.1729126,29.21999931,0.003817633
-0.048828126,-146.4884796,29.29999924,0.004070595
-0.04892578,-144.8508301,29.37999916,0.004288655
-0.049072267,-143.3368988,29.45999908,0.004508714
-0.049169921,-142.3827972,29.54000092,0.004692813
-0.049316408,-141.902359,29.62000084,0.004867789
-0.049414062,-141.2719269,29.70000076,0.005010432
-0.049560545,-141.0934448,29.78000069,0.005129785
-0.049707032,-140.8781433,29.86000061,0.005246822
-0.049804687,-140.9414063,29.94000053,0.005366126
-0.049951173,-141.1197968,30.02000046,0.005467974
-0.050097657,-141.314682,30.10000038,0.005575851
-0.05024414,-141.4576721,30.18000031,0.005654744
-0.050341798,-141.8498688,30.26000023,0.0057393
-0.050488281,-142.3409119,30.34000015,0.005815685
-0.050634764,-142.8087158,30.42000008,0.005906098
-0.050781251,-143.0997925,30.5,0.005995209
-0.050927734,-143.5537872,30.57999992,0.00606348
-0.051074217,-143.9388428,30.65999985,0.006161143
-0.051171875,-144.4071045,30.73999977,0.006243135
-0.051318359,-144.8597565,30.81999969,0.006321131
-0.051464845,-145.3148193,30.89999962,0.006417547
-0.051611329,-145.6636505,30.97999954,0.006494783
-0.051757812,-146.15979,31.05999947,0.006553706
-0.051904295,-146.6233826,31.13999939,0.006634557
-0.052050782,-147.2167664,31.21999931,0.006713635
-0.052197265,-147.6408386,31.29999924,0.006781688
-0.052294923,-147.7537079,31.37999916,0.006873751
-0.052441406,-148.1148529,31.45999908,0.006957503
-0.05258789,-148.4953766,31.54000092,0.007052579
-0.052734376,-148.7530212,31.62000084,0.0071408
-0.052832031,-148.8190918,31.70000076,0.007226977
-0.052978514,-149.0814819,31.78000069,0.007299989
-0.053125001,-149.4641266,31.86000061,0.007401078
-0.053271484,-149.6848755,31.94000053,0.007489018
-0.053369142,-149.8093414,32.02000046,0.007592219
-0.053515625,-149.9911041,32.09999847,0.00768793
-0.053662108,-149.7639923,32.18000031,0.007784805
-0.053759766,-149.8335266,32.25999832,0.007901301
-0.053906249,-149.8028259,32.34000015,0.008024574
-0.054052733,-149.3569946,32.41999817,0.008149403
-0.05415039,-148.8522644,32.5,0.008287328
-0.054296874,-148.6537018,32.58000183,0.008416288
-0.054443361,-148.3718262,32.65999985,0.008560166
-0.054541015,-148.2471313,32.74000168,0.0086792
-0.054687502,-147.8254395,32.81999969,0.008815301
-0.054785156,-147.4085541,32.90000153,0.008945094
-0.054931639,-147.3003845,32.97999954,0.009070532
-0.055078126,-147.2829132,33.06000137,0.009192881
-0.05517578,-147.2009583,33.13999939,0.009300356
-0.055322267,-147.1020966,33.22000122,0.009414813
-0.055419921,-146.9394836,33.29999924,0.009516976
-0.055566405,-147.0776062,33.38000107,0.009625012
-0.055712891,-147.2318726,33.45999908,0.009727157
-0.055810546,-147.3974457,33.54000092,0.009831672
-0.055957033,-147.4158783,33.61999893,0.009924662
-0.056054687,-147.4230957,33.70000076,0.010021153
-0.05620117,-147.585495,33.77999878,0.01012636
-0.056347657,-147.8202515,33.86000061,0.010212367
-0.056445311,-148.1072845,33.93999863,0.010305002
-0.056591798,-148.3266449,34.02000046,0.010388412
-0.056738281,-148.8345337,34.09999847,0.010461568
-0.056884764,-149.3005829,34.18000031,0.010552247
-0.056982422,-149.7540588,34.25999832,0.010624166
-0.057128906,-150.0834351,34.34000015,0.010709117
-0.057275389,-150.3459015,34.41999817,0.010802229
-0.057421876,-150.6967926,34.5,0.010889419
-0.057568359,-151.1164093,34.58000183,0.010980168
-0.057714842,-151.2131805,34.65999985,0.011105377
-0.057861329,-151.5171814,34.74000168,0.011221277
-0.058007812,-151.5910797,34.81999969,0.011412107
-0.058154295,-151.9808044,34.90000153,0.011523356
-0.058300782,-152.1379089,34.97999954,0.011628653
-0.058398437,-152.3504791,35.06000137,0.011726878
-0.058544923,-152.3086395,35.13999939,0.011860669
-0.058691407,-152.2042847,35.22000122,0.011960827
-0.05883789,-152.0924072,35.29999924,0.012102581
-0.058984377,-151.9709473,35.38000107,0.012230044
-0.05913086,-151.6753387,35.45999908,0.012367394
-0.059277343,-151.4334564,35.54000092,0.012490078
-0.059423826,-151.2250366,35.61999893,0.012632718
-0.059521484,-151.0848389,35.70000076,0.012768758
-0.059667967,-150.6869812,35.77999878,0.012922318
-0.059814454,-149.8788147,35.86000061,0.013092225
-0.059960938,-148.6056976,35.93999863,0.013292805
-0.060058595,-147.7397614,36.02000046,0.013474411
-0.060205079,-147.0911102,36.09999847,0.013655615
-0.060351562,-146.4862518,36.18000031,0.013828373
-0.060498045,-145.56633,36.25999832,0.014003587
-0.060595703,-145.051712,36.34000015,0.014164177
-0.060742186,-144.8975525,36.41999817,0.01428928
-0.060888673,-144.5667114,36.5,0.014421829
-0.060986327,-144.436554,36.58000183,0.014557667
-0.061132814,-144.1713715,36.65999985,0.01466898
-0.061230472,-143.993988,36.74000168,0.014782213
-0.061376952,-144.0545807,36.81999969,0.014901459
-0.061523438,-144.0824738,36.90000153,0.015021294
-0.061621096,-144.0161743,36.97999954,0.015144014
-0.061767576,-144.053009,37.06000137,0.015261003
-0.061914063,-143.9651947,37.13999939,0.015352131
-0.062011721,-144.2325745,37.22000122,0.015457799
-0.0621582,-144.3512573,37.29999924,0.015574318
-0.062255858,-144.3714142,37.38000107,0.01567385
-0.062402345,-144.411438,37.45999908,0.015781226
-0.062548825,-144.3937988,37.54000092,0.015887608
-0.062646483,-144.5128784,37.61999893,0.015985905
-0.062792969,-144.7835388,37.70000076,0.016104326
-0.062939456,-144.7973328,37.77999878,0.016203629
-0.063037107,-144.9088287,37.86000061,0.01630535
-0.063183594,-145.0503998,37.93999863,0.016415535
-0.063330081,-145.1569519,38.02000046,0.016524325
-0.063427731,-145.2861176,38.09999847,0.016639797
-0.063574218,-145.4153137,38.18000031,0.016763976
-0.063720705,-145.4619904,38.25999832,0.016878445
-0.063867185,-145.694519,38.34000015,0.017013677
-0.064013671,-145.8736877,38.41999817,0.017133369
-0.064160158,-146.1236115,38.5,0.017245411
-0.064257816,-146.2446747,38.58000183,0.017360826
-0.064404296,-146.4372559,38.65999985,0.017460146
-0.064550783,-146.5790863,38.74000168,0.017577548
-0.064697262,-146.8659363,38.81999969,0.017696671
-0.064843749,-146.8525543,38.90000153,0.017811139
-0.064990236,-146.8065186,38.97999954,0.017936707
-0.065136715,-146.6645966,39.06000137,0.018064447
-0.065283202,-146.5611572,39.13999939,0.018184239
-0.065429689,-146.6524658,39.22000122,0.018307406
-0.065527347,-146.4992371,39.29999924,0.018416978
-0.065673827,-146.50354,39.38000107,0.018544697
-0.065820313,-146.4268494,39.45999908,0.018667744
-0.0659668,-146.3493958,39.54000092,0.018788807
-0.06611328,-146.2712555,39.61999893,0.018925484
-0.066210938,-146.168335,39.70000076,0.019044788
-0.066357425,-145.9319611,39.77999878,0.019182178
-0.066503904,-145.8551178,39.86000061,0.019300145
-0.066650391,-145.6361847,39.93999863,0.019438452
-0.066748049,-145.4031219,40.02000046,0.019579642
-0.066894529,-145.1023712,40.09999847,0.019717307
-0.067041015,-144.9448242,40.18000031,0.019839583
-0.067187502,-144.6094666,40.25999832,0.01999386
-0.067285153,-144.4236145,40.34000015,0.020144573
-0.06743164,-144.054657,40.41999817,0.020284846
-0.067529298,-143.6700287,40.5,0.02041136
-0.067675785,-143.3411713,40.58000183,0.020552425
-0.067822264,-143.1905975,40.65999985,0.020698288
-0.067919922,-142.9217224,40.74000168,0.020837024
-0.068066409,-142.6722107,40.81999969,0.020974403
-0.068164059,-142.2849579,40.90000153,0.021104273
-0.068310546,-142.0189056,40.97999954,0.021254386
-0.068457033,-141.7674713,41.06000137,0.021399068
-0.068554691,-141.5479279,41.13999939,0.021549584
-0.068701171,-140.8807983,41.22000122,0.021713275
-0.068798829,-140.466217,41.29999924,0.021926715
-0.068945315,-140.1056213,41.38000107,0.022085091
-0.069042966,-139.8972931,41.45999908,0.022233215
-0.069189453,-139.7370758,41.54000092,0.02237041
-0.06933594,-139.5385742,41.61999893,0.022492892
-0.06943359,-139.4013367,41.70000076,0.022622467
-0.069580077,-139.3942871,41.77999878,0.022739441
-0.069726564,-139.2835999,41.86000061,0.022868811
-0.069824222,-139.175354,41.93999863,0.023007626
-0.069970702,-139.0723267,42.02000046,0.023129109
-0.070117188,-138.7379761,42.09999847,0.023257331
-0.070214846,-138.7300873,42.18000031,0.023386145
-0.070361326,-138.4808502,42.25999832,0.023551565
-0.070507813,-138.3911438,42.34000015,0.023699789
-0.0706543,-138.0018616,42.41999817,0.023838889
-0.070800779,-137.8479462,42.5,0.023976061
-0.070947266,-137.7119751,42.58000183,0.024119163
-0.071093753,-137.6693878,42.65999985,0.024253985
-0.071240233,-137.5244446,42.74000168,0.024413654
-0.071386719,-137.3162842,42.81999969,0.024544937
-0.071533206,-137.1794434,42.90000153,0.024691819
-0.071630857,-137.2785034,42.97999954,0.024825415
-0.071777344,-137.2961273,43.06000137,0.024953899
-0.071923831,-137.1891327,43.13999939,0.025098036
-0.07207031,-137.0390015,43.22000122,0.025223806
-0.072216797,-137.1236725,43.29999924,0.025352621
-0.072363284,-137.0745239,43.38000107,0.025470552
-0.072460934,-137.1251373,43.45999908,0.025596972
-0.072607421,-137.0210724,43.54000092,0.025722782
-0.072753908,-136.9761963,43.61999893,0.025837013
-0.072900388,-137.0245972,43.70000076,0.025959213
-0.073046875,-137.21138,43.77999878,0.026083491
-0.073193361,-137.1210175,43.86000061,0.026210655
-0.073291012,-136.9952698,43.93999863,0.026334115
-0.073437499,-136.6804199,44.02000046,0.026470301
-0.073583986,-136.6135864,44.09999847,0.026622944
-0.073681644,-136.2980957,44.18000031,0.026768324
-0.073828123,-135.824234,44.25999832,0.026942002
-0.073925781,-134.5048065,44.34000015,0.02717172
-0.074072268,-133.3916016,44.41999817,0.027386292
-0.074218748,-132.7841034,44.5,0.02757943
-0.074316406,-132.041153,44.58000183,0.027762853
-0.074462892,-131.1155548,44.65999985,0.027965874
-0.074609372,-129.9661255,44.74000168,0.02819869
-0.07470703,-128.7383423,44.81999969,0.028440802
-0.074853517,-127.5320969,44.90000153,0.028698139
-0.075000004,-126.0670395,44.97999954,0.02897165
-0.075097654,-123.9940109,45.06000137,0.029321953
-0.075244141,-122.073616,45.13999939,0.029717094
-0.075341799,-120.6198044,45.22000122,0.030027872
-0.075488279,-119.4752426,45.29999924,0.030309458
-0.075634765,-118.4683075,45.38000107,0.030581996
-0.075732423,-117.336731,45.45999908,0.030841777
-0.075878903,-115.7286377,45.54000092,0.031136678
-0.075976561,-114.9345932,45.61999893,0.031377211
-0.076123048,-114.4165192,45.70000076,0.031597832
-0.076220706,-113.6843567,45.77999878,0.03181606
-0.076367185,-113.0622025,45.86000061,0.032011725
-0.076513672,-112.5385513,45.93999863,0.032198986
-0.076660159,-112.2780762,46.02000046,0.032364816
-0.076757809,-112.1151428,46.09999847,0.032537962
-0.076904296,-111.8374252,46.18000031,0.032693446
-0.077050783,-111.6213074,46.25999832,0.032844771
-0.077197263,-111.4246445,46.34000015,0.03298798
-0.07734375,-111.4542694,46.41999817,0.033131171
-0.077441407,-111.4956665,46.5,0.033295673
-0.077587887,-111.2472153,46.58000183,0.033447694
-0.077734374,-111.0569305,46.65999985,0.033598288
-0.077880861,-110.8812027,46.74000168,0.033747878
-0.07802734,-110.836525,46.81999969,0.033894561
-0.078173827,-110.8066406,46.90000153,0.034058045
-0.078320314,-110.6233749,46.97999954,0.034206376
-0.078466794,-110.2898026,47.06000137,0.03435064
-0.07861328,-110.3536682,47.13999939,0.034496887
-0.078759767,-110.3931961,47.22000122,0.034639706
-0.078857425,-110.3754654,47.29999924,0.034775261
-0.079003905,-110.2422791,47.38000107,0.034899716
-0.079150392,-110.2529068,47.45999908,0.03503442
-0.079296879,-110.1807251,47.54000092,0.035169251
-0.079443358,-110.3026886,47.61999893,0.035297046
-0.079541016,-110.1612625,47.70000076,0.03543216
-0.079687503,-109.9733353,47.77999878,0.035580408
-0.079833982,-109.7590866,47.86000061,0.035718127
-0.079980469,-109.6963272,47.93999863,0.035873436
-0.080078127,-109.4714661,48.02000046,0.036053894
-0.080224607,-109.1266174,48.09999847,0.036229139
-0.080371094,-108.7602539,48.18000031,0.036376798
-0.08051758,-108.5585327,48.25999832,0.036539201
-0.080615231,-108.2073212,48.34000015,0.036706948
-0.080761718,-108.019371,48.41999817,0.036887388
-0.080908205,-107.6506195,48.5,0.037059719
-0.081005863,-107.2344055,48.58000183,0.037205726
-0.081152342,-106.7306519,48.65999985,0.037393896
-0.08125,-106.2624054,48.74000168,0.037609665
-0.081396487,-105.8292084,48.81999969,0.037809394
-0.081542967,-105.2807083,48.90000153,0.038000766
-0.081640625,-104.6908875,48.97999954,0.038187896
-0.081787111,-104.3665085,49.06000137,0.038391212
-0.081884762,-103.7794189,49.13999939,0.038611306
-0.082031249,-103.1138229,49.22000122,0.03883494
-0.082177736,-102.4603119,49.29999924,0.03904874
-0.082275394,-101.8703995,49.38000107,0.039268773
-0.082421873,-101.3388367,49.45999908,0.039474755
-0.082519531,-100.9166794,49.54000092,0.039685445
-0.082666018,-100.2798691,49.61999893,0.039906296
-0.082763669,-99.61464691,49.70000076,0.04012998
-0.082910155,-99.04647064,49.77999878,0.040342617
-0.083056642,-98.57406616,49.86000061,0.040553979
-0.0831543,-98.2124176,49.93999863,0.040761057
-0.08330078,-97.6724472,50.02000046,0.040969004
-0.083447267,-97.25952148,50.09999847,0.04116795
-0.083544925,-96.69773865,50.18000031,0.041369673
-0.083691404,-96.33277893,50.25999832,0.041577743
-0.083837891,-96.06676483,50.34000015,0.041770949
-0.083984378,-95.56001282,50.41999817,0.041979831
-0.084130857,-95.04058838,50.5,0.042182
-0.084228515,-94.51053619,50.58000183,0.042392327
-0.084375002,-93.78359985,50.65999985,0.042666663
-0.084521482,-93.2763443,50.74000168,0.043034332
-0.084667969,-92.60549164,50.81999969,0.043293308
-0.084814455,-91.95215607,50.90000153,0.043536475
-0.084960935,-91.45993805,50.97999954,0.043753826
-0.085107422,-91.18664551,51.06000137,0.043984553
-0.085253909,-90.66913605,51.13999939,0.044181492
-0.085400388,-90.2950592,51.22000122,0.044384567
-0.085498046,-89.93836212,51.29999924,0.044579374
-0.085644533,-89.64576721,51.38000107,0.044766057
-0.085791013,-89.28954315,51.45999908,0.044968416
-0.0859375,-89.006073,51.54000092,0.04517012
-0.086035157,-88.54673004,51.61999893,0.045354645
-0.086181637,-88.16578674,51.70000076,0.045542361
-0.086328124,-87.88135529,51.77999878,0.045729623
-0.086474611,-87.80696106,51.86000061,0.045921741
-0.08662109,-87.44890594,51.93999863,0.046108013
-0.086718748,-87.13593292,52.02000046,0.046281813
-0.086865235,-86.8572998,52.09999847,0.046460082
-0.087011722,-86.77209473,52.18000031,0.046624555
-0.087109373,-86.58894348,52.25999832,0.04679403
-0.087255859,-86.26390839,52.34000015,0.046984023
-0.087402346,-85.62243652,52.41999817,0.047204114
-0.087499997,-85.13915253,52.5,0.047418926
-0.087646484,-84.88922119,52.58000183,0.047636397
-0.087744142,-84.42932129,52.65999985,0.047844092
-0.087890628,-83.88247681,52.74000168,0.048071252
-0.088037108,-83.33615112,52.81999969,0.048280199
-0.088134766,-83.06256866,52.90000153,0.048484897
-0.088281253,-82.66955566,52.97999954,0.048707108
-0.088378903,-82.24388885,53.06000137,0.04891081
-0.08852539,-81.86856079,53.13999939,0.049095881
-0.088671877,-81.4672699,53.22000122,0.049295355
-0.088769528,-81.28121948,53.29999924,0.049480619
-0.088916015,-81.03137207,53.38000107,0.049668088
-0.089013673,-80.64247894,53.45999908,0.049869948
-0.089160159,-80.25255585,53.54000092,0.050054659
-0.08925781,-79.80698395,53.61999893,0.050249113
-0.089404297,-79.53357697,53.70000076,0.050449449
-0.089550784,-79.17305756,53.77999878,0.050694252
-0.089648434,-78.55396271,53.86000061,0.050931936
-0.089794921,-64.07542419,53.93999863,0.054324944
-0.089941408,-54.91525269,54.02000046,0.056877925
-0.090087888,-50.56491089,54.09999847,0.058173104
-0.090185546,-48.31336975,54.18000031,0.058997037
-0.090332032,-46.6844368,54.25999832,0.059574315
-0.090478512,-45.54213715,54.34000015,0.060045237
-0.090624999,-44.83351517,54.41999817,0.06043856
-0.090771486,-44.17956161,54.5,0.060801485
-0.090917965,-43.61273956,54.58000183,0.061135601
-0.091064452,-43.0846405,54.65999985,0.061446415
-0.09116211,-42.39517593,54.74000168,0.061746337
-0.091308597,-42.04056931,54.81999969,0.062057567
-0.091455076,-41.54239655,54.90000153,0.062356179
-0.091601563,-41.19886017,54.97999954,0.062618827
-0.09174805,-40.82445145,55.06000137,0.062898223
-0.09189453,-40.32904434,55.13999939,0.063151427
-0.092041017,-40.04640961,55.22000122,0.063416315
-0.092187503,-39.73200226,55.29999924,0.063678221
-0.092333983,-39.32452393,55.38000107,0.063923799
-0.092431641,-38.98587799,55.45999908,0.064189728
-0.092578128,-38.49445724,55.54000092,0.064444204
-0.092724607,-38.15335083,55.61999893,0.064703396
-0.092871094,-37.93522263,55.70000076,0.064956228
-0.092968752,-37.54223633,55.77999878,0.065216118
-0.093115232,-37.04463959,55.86000061,0.065484339
-0.093261719,-36.75087357,55.93999863,0.065733431
-0.093408205,-36.47895432,56.02000046,0.065989763
-0.093505856,-36.09420013,56.09999847,0.06623524
-0.093652343,-35.75947952,56.18000031,0.066502835
-0.09379883,-35.31428528,56.25999832,0.066766748
-0.093945309,-34.99562836,56.34000015,0.067005647
-0.094042967,-34.684021,56.41999817,0.067253721
-0.094189454,-34.52900314,56.5,0.06750082
-0.094335941,-34.11209488,56.58000183,0.067740068
-0.094433592,-33.67956924,56.65999985,0.067999019
-0.094580078,-33.41057968,56.74000168,0.068247384
-0.094726565,-33.17133713,56.81999969,0.068504247
-0.094824216,-32.81321335,56.90000153,0.068753048
-0.094970703,-32.33993912,56.97999954,0.069025606
-0.095068361,-31.87657547,57.06000137,0.069273476
-0.09521484,-31.62369728,57.13999939,0.069552152
-0.095361327,-31.29036903,57.22000122,0.069829475
-0.095458985,-30.91654015,57.29999924,0.070116621
-0.095605472,-30.36820221,57.38000107,0.070396214
-0.095703122,-30.00520515,57.45999908,0.070692811
-0.095849609,-29.62656212,57.54000092,0.070990034
-0.095996096,-29.32871437,57.61999893,0.071281451
-0.096093747,-28.7702179,57.70000076,0.071581853
-0.096240234,-28.28672409,57.77999878,0.071908966
-0.096386721,-27.84650421,57.86000061,0.07225111
-0.096484378,-27.42823792,57.93999863,0.072605908
-0.096630858,-27.10891342,58.02000046,0.072954281
-0.096777345,-26.49929237,58.09999847,0.073322393
-0.096875003,-25.90675926,58.18000031,0.073703974
-0.097021482,-25.32653809,58.25999832,0.074100222
-0.097167969,-24.82019997,58.34000015,0.07454661
-0.097314456,-22.26403999,58.41999817,0.075880591
-0.097460936,-20.46032906,58.5,0.076962831
-0.097607423,-18.65926361,58.58000183,0.078020981
-0.097753909,-17.26465034,58.65999985,0.078959485
-0.097900389,-13.27593708,58.74000168,0.080955622
-0.098046876,-10.05270958,58.81999969,0.082892155
-0.098193363,-6.585932732,58.90000153,0.084182546
-0.098291013,-5.234543324,58.97999954,0.084521365
-0.0984375,-4.543158054,59.06000137,0.085075073
-0.098583987,-3.987788916,59.13999939,0.08554793
-0.098730467,-3.374063969,59.22000122,0.08599156
-0.098876953,-2.882215023,59.29999924,0.08641043
-0.09902344,-2.373253107,59.38000107,0.086803353
-0.09916992,-2.139317036,59.45999908,0.087202628
-0.099316407,-1.693919778,59.54000092,0.087609107
-0.099414065,-1.319954753,59.61999893,0.088039124
-0.099560544,-0.869460166,59.70000076,0.088485969
-0.099707031,-0.480335504,59.77999878,0.08897981
-0.099853518,-0.157385394,59.86000061,0.08951388
-0.099951169,0.082728028,59.93999863,0.09017541
-0.100097655,0.447185904,60.02000046,0.091561255
-0.100244142,0.839183927,60.09999847,5.1798122
-0.1003418,0.88772434,60.18000031,5.73772192
-0.10048828,0.723408759,60.25999832,5.760897882
-0.100634767,0.737953424,60.34000015,5.79006644
-0.100732424,0.746465027,60.41999817,5.818066653
-0.100878904,0.953273535,60.5,5.81817003
-0.100976562,0.83065486,60.58000183,5.818232894
-0.101123049,0.770913005,60.65999985,5.818285514
-0.101269528,0.76050657,60.74000168,5.818323232
-0.101367186,0.828779578,60.81999969,5.818354432
-0.101513673,0.854455173,60.90000153,5.818374455
-0.101660153,0.84789443,60.97999954,5.818385631
-0.101757811,0.777978182,61.06000137,5.818397738
-0.101904297,0.776458025,61.13999939,5.818403792
-0.102001955,0.847869813,61.22000122,5.818410311
-0.102148435,0.913444221,61.29999924,5.818414036
-0.102294922,0.823720694,61.38000107,5.818417296
-0.10239258,0.806427181,61.45999908,5.81842009
-0.102539059,0.850193679,61.54000092,5.818424281
-0.102636717,0.880449533,61.61999893,5.818422884
-0.102783204,0.911616623,61.70000076,5.818422884
-0.102929691,0.833708823,61.77999878,5.818425212
-0.103027342,0.720399261,61.86000061,5.818424281
-0.103173828,0.758048415,61.93999863,5.818428006
-0.103320315,0.906629801,62.02000046,5.81842754
-0.103417966,0.767230272,62.09999847,5.818425212
-0.103564453,0.788447857,62.18000031,5.818428472
-0.10371094,0.708718956,62.25999832,5.818426609