File: Data/Thesis_Samples_Data/Notched_Layered_5_(precracked)/Notched_Layered_5_(precracked).csv
"File Path: C:\Users\Lab User\Desktop\Will\Thesis Tests\Test Run 8 04-8-22 20 29 41 PM\DAQ- Crosshead, … - (Timed).csv   ",,,
Test: MTS EM Tension (Extensometer) - Will 1,,,
Test Run: Test Run 8,,,
Date: 4/8/2022 8:21:13 PM,,,
,,,
,,,
Crosshead ,Load ,Time ,Extensometer
mm,N,sec,mm
0,-0.832297564,0.02,-2.08E-05
-0.000341797,-0.854936004,0.419999987,8.33E-05
-0.001025391,-1.138742924,0.819999993,0.000216105
-0.001855469,-1.420139194,1.220000029,0.000429866
-0.002587891,-1.662373185,1.620000005,0.000593143
-0.003271484,-1.896333098,2.019999981,0.000735462
-0.00390625,-2.162777662,2.420000076,0.000869899
-0.004589844,-2.463897228,2.819999933,0.001013825
-0.005273438,-2.77023077,3.220000029,0.001181741
-0.006005859,-3.066208839,3.619999886,0.00134592
-0.006689453,-3.310992241,4.019999981,0.001523445
-0.007421875,-3.559587717,4.420000076,0.001679037
-0.008056641,-3.782953024,4.820000172,0.001826959
-0.008740234,-4.115243435,5.21999979,0.001986958
-0.009375,-4.326021671,5.619999886,0.002136563
-0.010009766,-4.519230843,6.019999981,0.002287655
-0.010644531,-4.798106194,6.420000076,0.002428275
-0.011328125,-4.992542267,6.820000172,0.002578708
-0.012011718,-5.294100761,7.21999979,0.002742836
-0.012744141,-5.52216959,7.619999886,0.002905326
-0.013427734,-5.725390911,8.020000458,0.003066791
-0.0140625,-5.896044731,8.420000076,0.00320792
-0.014746094,-6.137992859,8.819999695,0.003386063
-0.015429687,-6.359669685,9.220000267,0.003541879
-0.016064454,-6.513284206,9.619999886,0.003687622
-0.016650391,-6.803283215,10.02000046,0.003845087
-0.017333985,-6.931296349,10.42000008,0.00400426
-0.01796875,-7.15662384,10.81999969,0.004162683
-0.018652343,-7.455461025,11.22000027,0.004328636
-0.019384766,-7.662693024,11.61999989,0.004522228
-0.020068359,-8.008298874,12.02000046,0.004682086
-0.020751953,-8.227941513,12.42000008,0.00487146
-0.021435548,-8.43842411,12.81999969,0.005043939
-0.022070313,-8.669728279,13.22000027,0.005212529
-0.022705079,-8.887659073,13.61999989,0.005369386
-0.023339844,-9.169916153,14.02000046,0.005528592
-0.02397461,-9.266898155,14.42000008,0.005705213
-0.024658204,-9.5977211,14.81999969,0.005872976
-0.025341797,-9.794427872,15.22000027,0.006070539
-0.026074218,-9.990800858,15.61999989,0.006259017
-0.026757813,-10.18454742,16.02000046,0.006461139
-0.027441407,-10.26064301,16.42000008,0.006698694
-0.028076172,-10.41533661,16.81999969,0.006975382
-0.028759765,-10.52998257,17.21999931,0.007248657
-0.02939453,-10.85195255,17.62000084,0.007499893
-0.030029298,-10.82388306,18.02000046,0.007733418
-0.030664061,-10.96529388,18.42000008,0.007961908
-0.031298827,-11.09541035,18.81999969,0.008196645
-0.031982421,-11.30617428,19.21999931,0.008452155
-0.032714845,-11.50502682,19.62000084,0.008699402
-0.033398439,-11.74548435,20.02000046,0.008940876
-0.03408203,-11.98014832,20.42000008,0.009173152
-0.034716795,-12.12650394,20.81999969,0.00939134
-0.035351564,-12.30542278,21.21999931,0.009634888
-0.03598633,-12.4624567,21.62000084,0.009873987
-0.036621095,-12.6382494,22.02000046,0.010117081
-0.037255861,-12.86882782,22.42000008,0.01036966
-0.037939451,-12.97714138,22.81999969,0.010631626
-0.038623046,-13.20018387,23.21999931,0.01089955
-0.039355469,-13.34978962,23.62000084,0.011164393
-0.040039064,-13.57619286,24.02000046,0.011425725
-0.040722658,-13.73320103,24.42000008,0.01167802
-0.041406249,-13.79270172,24.81999969,0.011936702
-0.042041014,-13.99321938,25.21999931,0.012184805
-0.04267578,-14.06037426,25.62000084,0.012458272
-0.043310545,-14.19673824,26.02000046,0.012771879
-0.043945314,-14.25095749,26.42000008,0.013077171
-0.044628905,-14.33853531,26.81999969,0.013406801
-0.045312499,-14.49846649,27.21999931,0.013731604
-0.046044923,-14.56443024,27.62000084,0.01410635
-0.046777343,-14.6539669,28.02000046,0.014459039
-0.047412108,-14.55144882,28.42000008,0.014866325
-0.048095702,-14.71972275,28.81999969,0.015260261
-0.048730468,-11.18426704,29.21999931,0.033292217
-0.049365233,-9.750427246,29.62000084,0.035233978
-0.049999999,0.711549461,30.02000046,0.088039247
-0.050634764,0.673993647,30.42000008,0.090652618
-0.051318359,0.607496023,30.81999969,0.092073591
-0.052001953,0.598665118,31.21999931,0.093106908
-0.052734376,0.550141633,31.62000084,0.093936855
-0.053417967,0.561471105,32.02000046,0.094651827
-0.054101562,0.522377551,32.41999817,0.09528669
-0.054736327,0.56421262,32.81999969,0.095865384
-0.055419921,0.586586535,33.22000122,0.096371376
-0.056054687,0.598901868,33.61999893,0.096837713
-0.056689452,0.563342392,34.02000046,0.097274511
-0.057324218,0.627722859,34.41999817,0.097679993
-0.058007812,0.634880841,34.81999969,0.098074859
-0.058691407,0.610234916,35.22000122,0.098431388
-0.059423826,0.656066298,35.61999893,0.098790857
-0.060107421,0.679321289,36.02000046,0.099119155
-0.060791015,0.626684666,36.41999817,0.099436438
-0.061425781,0.75646317,36.81999969,0.099742123
-0.06206055,0.709580481,37.22000122,0.100032303
-0.062695311,0.796157777,37.61999893,0.100334742
-0.063330081,0.762231112,38.02000046,0.100617108
-0.063964842,0.760165453,38.41999817,0.100890014
-0.064599612,0.67634213,38.81999969,0.101145226
-0.065283202,0.761500239,39.22000122,0.101386649
-0.066015622,0.76460284,39.61999893,0.101629979
-0.06669922,0.646701753,40.02000046,0.101860649
-0.067382811,0.69556874,40.41999817,0.102093152
-0.068066409,0.705118775,40.81999969,0.102321646
-0.068701171,0.708306789,41.22000122,0.102533748
-0.06933594,0.667041123,41.61999893,0.102752027
-0.069970702,0.603822589,42.02000046,0.102953869
-0.070605471,0.613104343,42.41999817,0.103165024
-0.071289061,0.595384061,42.81999969,0.103380909
-0.071972659,0.654037893,43.22000122,0.103572587
-0.072705079,0.676895082,43.61999893,0.103775921
-0.07338867,0.600311399,44.02000046,0.103965343
-0.074072268,0.541697085,44.41999817,0.104192499
-0.074755859,0.554042995,44.81999969,0.104457577
-0.075390628,0.51855886,45.22000122,0.104752668
-0.076074219,0.449617565,45.61999893,0.105074912
-0.076660159,0.449076325,46.02000046,0.105350307
-0.077294921,0.386455655,46.41999817,0.10565808
-0.077978519,0.209591568,46.81999969,0.10593851
-0.078662109,0.242264628,47.22000122,0.106221538
-0.079394529,0.041800417,47.61999893,0.106536987
-0.080078127,-0.034643423,48.02000046,0.106852291
-0.080761718,-0.171487376,48.41999817,0.107209875
-0.081396487,-0.107539564,48.81999969,0.107752065
-0.082031249,-0.004679768,49.22000122,0.108501255
-0.082666018,-0.117441133,49.61999893,0.109044311
-0.08330078,-0.259842157,50.02000046,0.109422341
-0.083935549,-0.32192409,50.41999817,0.109804183
-0.08461914,-0.499568492,50.81999969,0.110162648
-0.085302738,-0.610907853,51.22000122,0.110544213
-0.086035157,-0.763276458,51.61999893,0.110896042
-0.086718748,-0.854355156,52.02000046,0.111275011
-0.087402346,-1.016304851,52.41999817,0.111658199
-0.088085937,-1.025374413,52.81999969,0.112030764
-0.088769528,-1.172357917,53.22000122,0.112432885
-0.089404297,-1.296137214,53.61999893,0.112784008
-0.090039066,-1.307867408,54.02000046,0.113145601
-0.090673828,-1.398306727,54.41999817,0.113519091
-0.091357419,-1.464179039,54.81999969,0.113907729
-0.092041017,-1.493532062,55.22000122,0.114323295
-0.092773436,-1.59790051,55.61999893,0.11474709
-0.093457034,-1.722045064,56.02000046,0.115119292
-0.094091796,-1.886513948,56.41999817,0.115503477
-0.094775394,-1.981750965,56.81999969,0.11591021
-0.095410156,-1.917778015,57.22000122,0.116269977
-0.096044925,-2.213802576,57.61999893,0.116641088
-0.096679687,-2.335657835,58.02000046,0.117008327
-0.097314456,-2.38364768,58.41999817,0.117380136
-0.097949218,-2.484104395,58.81999969,0.117763026
-0.098632816,-2.612587214,59.22000122,0.118153323
-0.099365236,-2.851554155,59.61999893,0.118556993
-0.100048826,-2.999577522,60.02000046,0.118976182
-0.100732424,-3.06249404,60.41999817,0.119386495
-0.101367186,-3.235565424,60.81999969,0.11977867
-0.102050784,-3.281294823,61.22000122,0.120176745
-0.102685546,-3.310482979,61.61999893,0.120559365
-0.103271486,-3.338850975,62.02000046,0.120915356
-0.103955077,-3.41369462,62.41999817,0.121305311
-0.104589846,-3.584154606,62.81999969,0.121689365
-0.105273437,-3.628608227,63.22000122,0.122068355
-0.106005857,-3.756517649,63.61999893,0.122507001
-0.106738284,-3.776288986,64.01999664,0.122913523
-0.107421874,-3.912626743,64.41999817,0.123328035
-0.108105465,-3.968216896,64.81999969,0.123723847
-0.108740234,-3.998783827,65.22000122,0.124138052
-0.109375003,-4.066086769,65.62000275,0.124559956
-0.110009765,-4.236111164,66.01999664,0.124964135
-0.110644534,-4.171666622,66.41999817,0.125715276
-0.111328125,-4.311767101,66.81999969,0.126116414
-0.112011716,-4.461435795,67.22000122,0.126531086
-0.112744143,-4.532982349,67.62000275,0.126941013
-0.113427734,-4.746617794,68.01999664,0.127321153
-0.114062503,-4.90334034,68.41999817,0.127718478
-0.114746093,-4.997481346,68.81999969,0.128152577
-0.115380863,-5.054101467,69.22000122,0.128566331
-0.116015624,-4.686441422,69.62000275,0.129566644
-0.116650393,-4.661696434,70.01999664,0.130496221
-0.117285155,-4.754277706,70.41999817,0.131005625
-0.117968753,-4.821201324,70.81999969,0.131469875
-0.118652344,-4.931030273,71.22000122,0.131935842
-0.119384764,-4.982214451,71.62000275,0.132397006
-0.120068362,-5.072041512,72.01999664,0.132824091
-0.120751953,-5.186370373,72.41999817,0.133243506
-0.121435543,-5.274936676,72.81999969,0.133669717
-0.122070313,-5.328752041,73.22000122,0.134080678
-0.122705082,-5.415047169,73.62000275,0.134480186
-0.123339851,-5.463655949,74.01999664,0.134904069
-0.123974605,-5.577650547,74.41999817,0.135302078
-0.124658196,-5.781984806,74.81999969,0.135723763
-0.125341801,-5.868252277,75.22000122,0.136166258
-0.126074214,-6.072598934,75.62000275,0.136624818
-0.126757819,-6.209204197,76.01999664,0.137077979
-0.12744141,-6.173400402,76.41999817,0.137537645
-0.128076179,-6.382452011,76.81999969,0.137967188
-0.128710933,-6.485216141,77.22000122,0.138376185
-0.129394524,-6.602462769,77.62000275,0.138822841
-0.129980472,-6.704158783,78.01999664,0.139236727
-0.130615241,-6.642691612,78.41999817,0.139809592
-0.131298832,-6.766583443,78.81999969,0.140329968
-0.131982422,-6.852496147,79.22000122,0.140778779
-0.132714849,-6.977838039,79.62000275,0.141234108
-0.13339844,-6.991754055,80.01999664,0.141688928
-0.134082031,-7.108664513,80.41999817,0.142144825
-0.1347168,-7.093254566,80.81999969,0.142575635
-0.135351569,0.241787791,81.22000122,0.155911359
-0.135986324,0.725484073,81.62000275,0.15938461
-0.136669929,0.764317572,82.01999664,0.160828058
-0.137304683,0.740755856,82.41999817,0.174195826
-0.137939453,0.790640056,82.81999969,0.182918564
-0.13867188,0.727763236,83.22000122,0.187083016
-0.13935547,0.751707613,83.62000275,0.189077153
-0.140087897,0.779068112,84.01999664,0.190582534
-0.140771488,0.673041165,84.41999817,0.191780491
-0.141406257,0.703995407,84.81999969,0.192831954
-0.142089848,0.608635664,85.22000122,0.19373589
-0.142724602,0.654758692,85.62000275,0.194593755
-0.143359372,0.66388315,86.01999664,0.195325338
-0.143994141,0.584789157,86.41999817,0.19599557
-0.14462891,0.609872222,86.81999969,0.196583685
-0.145312501,0.555844247,87.22000122,0.197125119
-0.146044928,0.691071451,87.62000275,0.197645466
-0.146728518,0.653484285,88.01999664,0.198155249
-0.147412109,0.64071244,88.41999817,0.198987342
-0.1480957,0.702584267,88.81999969,0.200677343
-0.148730469,0.685639799,89.22000122,0.203609627
-0.149365238,0.664240718,89.62000275,0.204849828
-0.150000007,0.644231141,90.01999664,0.205775068
-0.150634762,0.75044328,90.41999817,0.206617231
-0.151318352,0.71909529,90.81999969,0.207375517
-0.152001958,0.795434237,91.22000122,0.208065612
-0.15273437,0.761256516,91.62000275,0.208758938
-0.153417976,0.776312411,92.01999664,0.209432095
-0.154101566,0.762689471,92.41999817,0.210083701
-0.154785157,0.677700341,92.81999969,0.21068778
-0.155419926,0.711193204,93.22000122,0.211267601
-0.156054681,0.695477366,93.62000275,0.211831139
-0.15668945,0.645628989,94.01999664,0.212378232
-0.157324219,0.650467753,94.41999817,0.212936269
-0.15800781,0.557974756,94.81999969,0.213506195
-0.1586914,0.572907925,95.22000122,0.214045271
-0.159375006,0.596347868,95.62000275,0.214553598
-0.160058597,0.635433972,96.01999664,0.215036285
-0.160742187,0.630895257,96.41999817,0.215516149
-0.161425778,0.602734506,96.81999969,0.215967855
-0.162060547,0.6228773,97.22000122,0.216394677
-0.162695316,0.662972331,97.62000275,0.216802262
-0.163330085,0.68086642,98.01999664,0.217198802
-0.16396484,0.667271137,98.41999817,0.217668407
-0.164599609,0.690523148,98.81999969,0.218179615
-0.1652832,0.751169443,99.22000122,0.218691363
-0.166015627,0.758948743,99.62000275,0.219340218
-0.166699218,0.775429964,100.0199966,0.219974914
-0.167382808,0.813057899,100.4199982,0.220639791
-0.168066399,0.722098351,100.8199997,0.222353498
-0.168701168,0.714722753,101.2200012,0.225019219
-0.169335937,0.620895505,101.6200027,0.226433884
-0.169970706,0.608121574,102.0199966,0.227493816
-0.170605475,0.664322376,102.4199982,0.228301607
-0.171289066,0.568630934,102.8199997,0.228984529
-0.172021479,0.552093446,103.2200012,0.229596393
-0.172705084,0.656359971,103.6200027,0.230160513
-0.173437496,0.50603652,104.0199966,0.230709105
-0.174072266,0.541453063,104.4199982,0.231234342
-0.174755856,0.613756597,104.8199997,0.231743965
-0.175390625,0.619763076,105.2200012,0.232222665
-0.176025394,0.652441978,105.6200027,0.232679304
-0.176660149,0.628199339,106.0199966,0.233134255
-0.177294918,0.618106663,106.4199982,0.233604616
-0.177978509,0.677613676,106.8199997,0.23405737
-0.178662114,0.671812594,107.2200012,0.234487932
-0.179394527,0.750804067,107.6200027,0.234920371
-0.180078132,0.768935204,108.0199966,0.235319269
-0.180761723,0.734459102,108.4199982,0.235726664
-0.181445314,0.686331332,108.8199997,0.236123873
-0.182080083,0.661047041,109.2200012,0.236505657
-0.182714837,0.724236727,109.6200027,0.236883425
-0.183349606,0.665828586,110.0199966,0.237259737
-0.183984375,0.677796423,110.4199982,0.237619854
-0.184619144,0.585036159,110.8199997,0.237966888
-0.185302735,0.674452484,111.2200012,0.238327339
-0.186035162,0.638642669,111.6200027,0.238655848
-0.186767575,0.566333234,112.0199966,0.238989232
-0.187451165,0.537033141,112.4199982,0.239303496
-0.188085934,0.565094948,112.8199997,0.23963346
-0.188769525,0.604751945,113.2200012,0.239956134
-0.189404294,0.601660192,113.6200027,0.240266323
-0.190039063,0.626720905,114.0199966,0.240564492
-0.190673833,0.691427171,114.4199982,0.240879643
-0.191308587,0.672509432,114.8199997,0.241201604
-0.192041014,0.731817961,115.2200012,0.241524322
-0.192724605,0.770089269,115.6200027,0.241841102
-0.19340821,0.793409109,116.0199966,0.242151451
-0.194091801,0.674813867,116.4199982,0.242455848
-0.194775392,0.752691329,116.8199997,0.242758644
-0.195410161,0.715906799,117.2200012,0.243059039
-0.196044915,0.787286818,117.6200027,0.243344912
-0.196679684,0.735825002,118.0199966,0.243640534
-0.197314454,0.688212037,118.4199982,0.243917326
-0.197949223,0.739918828,118.8199997,0.244209543
-0.198632813,0.70176059,119.2200012,0.244480761
-0.19936524,0.753432274,119.6200027,0.244745141
-0.200048831,0.637732685,120.0199966,0.245008239
-0.200732422,0.702691913,120.4199982,0.245260278
-0.201367191,0.561879933,120.8199997,0.245516305
-0.20200196,0.635457933,121.2200012,0.245765754
-0.202685551,0.602507889,121.6200027,0.246024545
-0.203271484,0.61633724,122.0199966,0.246275624
-0.203906253,0.608468056,122.4199982,0.246506504
-0.204589844,0.650415301,122.8199997,0.246758718
-0.205273434,0.646815002,123.2200012,0.24699705
-0.206005861,0.721767306,123.6200027,0.247231306
-0.206738288,0.753724337,124.0199966,0.247490418
-0.207421879,0.698075175,124.4199982,0.247732532
-0.20810547,0.703140974,124.8199997,0.247993041
-0.208740239,0.718455434,125.2200012,0.248263183
-0.209374994,0.773130298,125.6200027,0.248503289
-0.210009763,0.763216019,126.0199966,0.248754222
-0.210644532,0.768799067,126.4199982,0.248993834
-0.211328123,0.756184757,126.8199997,0.2492473
-0.212011713,0.785994828,127.2200012,0.249492616
-0.21274414,0.791287422,127.6200027,0.249723904
-0.213427731,0.653108358,128.0200043,0.249965262
-0.2140625,0.658121407,128.4199982,0.250194658
-0.214746091,0.610734999,128.8200073,0.250452344
-0.215429682,0.60511148,129.2200012,0.25069309
-0.216064451,0.602086782,129.6199951,0.250932411
-0.216650384,0.586843252,130.0200043,0.251183868
-0.217333989,0.530709147,130.4199982,0.25162255
-0.217968744,0.503823817,130.8200073,0.252089987
-0.218652349,0.501225531,131.2200012,0.252613449
-0.219384761,0.410813779,131.6199951,0.253164209
-0.220068367,0.425498486,132.0200043,0.25367309
-0.220751957,0.323650956,132.4199982,0.25433948
-0.221435548,0.356945753,132.8200073,0.254926243
-0.222070317,0.422585905,133.2200012,0.255423074
-0.222705072,0.320268661,133.6199951,0.255902356
-0.223339841,0.27399981,134.0200043,0.256418571
-0.22397461,0.252560139,134.4199982,0.256883766
-0.224658201,0.260054737,134.8200073,0.257355976
-0.225341792,0.143377081,135.2200012,0.257946056
-0.226074219,0.095042937,135.6199951,0.258414628
-0.226757809,0.038907651,136.0200043,0.258960994
-0.2274414,-0.022689892,136.4199982,0.259493856
-0.228076169,-0.052267689,136.8200073,0.260053144
-0.22875976,-0.170483187,137.2200012,0.260572793
-0.229394529,-0.23561193,137.6199951,0.261140201
-0.230029298,-0.315521359,138.0200043,0.261729001
-0.230664067,-0.313577086,138.4199982,0.262291316
-0.231298822,-0.368198901,138.8200073,0.262825313
-0.231982427,-0.403331876,139.2200012,0.263349939
-0.23271484,-0.482137978,139.6199951,0.263878872
-0.23339843,-0.46705541,140.0200043,0.264460687
-0.234082036,-0.518494666,140.4199982,0.264991715
-0.23471679,-0.53750962,140.8200073,0.265560462
-0.235351559,-0.55577296,141.2200012,0.266097864
-0.235986328,-0.653154314,141.6199951,0.266603776
-0.236621097,-0.619252264,142.0200043,0.267161638
-0.237255867,-0.568989635,142.4199982,0.267714553
-0.237939457,-0.661355793,142.8200073,0.268298289
-0.238623048,-0.597510695,143.2200012,0.268894015
-0.239355475,-0.700278223,143.6199951,0.26954044
-0.240039066,-0.708218873,144.0200043,0.270218094
-0.240722657,-0.754756212,144.4199982,0.270830205
-0.241406247,-0.735506773,144.8200073,0.271487777
-0.242041016,-0.766924798,145.2200012,0.27213298
-0.242675786,-0.748676956,145.6199951,0.272821315
-0.24331054,-0.751971126,146.0200043,0.273427315
-0.243945309,-0.782952607,146.4199982,0.274117687
-0.2446289,-0.737991452,146.8200073,0.274822698
-0.245312491,-0.673236728,147.2200012,0.275890343
-0.246044918,-0.523065805,147.6199951,0.276905484
-0.246728509,-0.5729177,148.0200043,0.27776527
-0.247412099,-0.512301147,148.4199982,0.278548105
-0.24809569,0.663294613,148.8200073,0.317727507
-0.248730474,0.67737639,149.2200012,0.337323931
-0.249365228,0.655004561,149.6199951,0.346900168
-0.250000012,0.656334758,150.0200043,0.351885654
-0.250634766,0.672134399,150.4199982,0.355712371
-0.251318357,0.737141788,150.8200073,0.359066646
-0.252001948,0.682626963,151.2200012,0.362116523
-0.252734375,0.772591293,151.6199951,0.364887062
-0.253417966,0.742626131,152.0200043,0.367317727
-0.254101556,0.679460227,152.4199982,0.385932304
-0.25473634,0.746129274,152.8200073,0.393298571
-0.255419931,0.642401338,153.2200012,0.551700883
-0.256054685,0.820845902,153.6199951,0.592641649
-0.25668944,0.731945515,154.0200043,0.623341068
-0.257324224,0.607301235,154.4199982,0.651566195
-0.258007814,0.64074111,154.8200073,0.675950781
-0.258691405,0.642718673,155.2200012,0.696569157
-0.259423832,0.575299203,155.6199951,0.715595554
-0.260107423,0.538958907,156.0200043,0.73213107
-0.260791014,0.601030588,156.4199982,0.747647602
-0.261425768,0.612753093,156.8200073,0.76282816
-0.262060552,0.696580231,157.2200012,0.776472501
-0.262695306,0.675616264,157.6199951,0.789724407
-0.26333009,0.68640095,158.0200043,0.802121824
-0.263964845,0.844290793,158.4199982,0.81355439
-0.264599599,0.74222517,158.8200073,0.824300805
-0.26528319,0.687100351,159.2200012,0.834646402
-0.266015617,0.750682056,159.6199951,0.844477734
-0.266699208,0.809541345,160.0200043,0.853754696
-0.267382798,0.755648077,160.4199982,0.862751447
-0.268066418,0.713987648,160.8200073,0.871269091
-0.268701173,0.77455312,161.2200012,0.879681553
-0.269335927,0.616585076,161.6199951,0.887496164
-0.269970711,0.744472861,162.0200043,0.895466947
-0.270605466,0.734607935,162.4199982,0.90304215
-0.271289056,0.650523126,162.8200073,0.910442497
-0.271972647,0.617994905,163.2200012,0.917338708
-0.272705074,0.632743478,163.6199951,0.923905929
-0.273388665,0.690165758,164.0200043,0.93101809
-0.274072256,0.625576556,164.4199982,0.937588804
-0.274755846,0.59941566,164.8200073,0.944104977
-0.27539063,0.595713854,165.2200012,0.950540591
-0.276025385,0.62557739,165.6199951,0.956922246
-0.276660168,0.714848697,166.0200043,0.963193073
-0.277294923,0.619293988,166.4199982,0.969082699
-0.277978514,0.648384452,166.8200073,0.975256029
-0.278662104,0.645124078,167.2200012,0.981290592
-0.279394531,0.710954189,167.6199951,0.987186562
-0.280078122,0.798800647,168.0200043,0.993346563
-0.280761713,0.778034091,168.4199982,0.999105396
-0.281396497,0.774282277,168.8200073,1.004755846
-0.282031251,0.806251466,169.2200012,1.010388252
-0.282714842,0.783305883,169.6199951,1.016024151
-0.283300789,0.682454824,170.0200043,1.021319418
-0.283935544,0.685393035,170.4199982,1.026725629
-0.284619135,0.604886472,170.8200073,1.031709136
-0.285302725,0.695053756,171.2200012,1.036465983
-0.286035152,0.635912001,171.6199951,1.041082432
-0.286718743,0.688071907,172.0200043,1.0456132
-0.287402334,0.685041487,172.4199982,1.050149789
-0.288085925,0.629009604,172.8200073,1.054842724
-0.288720708,0.542222798,173.2200012,1.059105503
-0.289404299,0.612346947,173.6199951,1.063212403
-0.290039054,0.48189795,174.0200043,1.067286939
-0.290673837,0.628353179,174.4199982,1.071216189
-0.291308592,0.70083338,174.8200073,1.075026346
-0.292041019,0.734113455,175.2200012,1.07893243
-0.292773446,0.7633757,175.6199951,1.082503586
-0.293457037,0.689144552,176.0200043,1.085982658
-0.294091791,0.7970047,176.4199982,1.089312602
-0.294775382,0.775912166,176.8200073,1.092530787
-0.295410166,0.841916621,177.2200012,1.095751417
-0.29604492,0.820879102,177.6199951,1.099029323
-0.296679675,0.778944671,178.0200043,1.102344831
-0.297314458,0.771972656,178.4199982,1.105657779
-0.297949213,0.740665138,178.8200073,1.108841388
-0.298632804,0.734636486,179.2200012,1.111978898
-0.299365231,0.679994345,179.6199951,1.115093357
-0.300048821,0.719049931,180.0200043,1.118138433
-0.300732412,0.688860893,180.4199982,1.121365
-0.301367196,0.721449852,180.8200073,1.12458074
-0.302050787,0.605251312,181.2200012,1.127695548
-0.302685541,0.635151625,181.6199951,1.130696735
-0.303271489,0.758414149,182.0200043,1.133800019
-0.303906243,0.68761307,182.4199982,1.136939274
-0.304589834,0.681643665,182.8200073,1.140029868
-0.305322261,0.674701989,183.2200012,1.143000321
-0.306005852,0.700222135,183.6199951,1.145936432
-0.306738279,0.695023239,184.0200043,1.148691867
-0.307421869,0.763431668,184.4199982,1.151526929
-0.30810546,0.841724157,184.8200073,1.154335332
-0.308740244,0.776565611,185.2200012,1.15697307
-0.309374998,0.855994999,185.6199951,1.159664942
-0.310009753,0.834003448,186.0200043,1.16233388
-0.310644537,0.780300736,186.4199982,1.164913177
-0.311328127,0.747299135,186.8200073,1.167539624
-0.312011718,0.699746192,187.2200012,1.169908093
-0.312744145,0.742038012,187.6199951,1.17230427
-0.313427736,0.72191,188.0200043,1.174762729
-0.31406249,0.786772907,188.4199982,1.177291851
-0.314746081,0.732391834,188.8200073,1.179764862
-0.315380865,0.661814928,189.2200012,1.182184904
-0.316015619,0.687884986,189.6199951,1.184590044
-0.316650403,0.620447814,190.0200043,1.186838141
-0.317285158,0.630671144,190.4199982,1.189123723
-0.317968748,0.552661955,190.8200073,1.19129417
-0.318652339,0.670579791,191.2200012,1.193426782
-0.319384766,0.609179258,191.6199951,1.195698977
-0.320068357,0.612911284,192.0200043,1.197766745
-0.320751948,0.727075279,192.4199982,1.199793303
-0.321435538,0.680232882,192.8200073,1.201806823
-0.322070322,0.656976402,193.2200012,1.203806256
-0.322705077,0.593172431,193.6199951,1.205940265
-0.323339831,0.680400014,194.0200043,1.208063448
-0.323974615,0.769413829,194.4199982,1.210244605
-0.324658205,0.811890543,194.8200073,1.212448929
-0.325341796,0.814208448,195.2200012,1.21453905
-0.326074223,0.86359334,195.6199951,1.216568751
-0.326757814,0.739728689,196.0200043,1.218721271
-0.327441405,0.778004527,196.4199982,1.22064352
-0.328076159,0.761127412,196.8200073,1.222523744
-0.328759779,0.67557317,197.2200012,1.224482432
-0.329394534,0.809589803,197.6199951,1.226504915
-0.330029288,0.717720509,198.0200043,1.228362555
-0.330664072,0.781504869,198.4199982,1.23020052
-0.331298826,0.712411642,198.8200073,1.231994131
-0.331982417,0.666264355,199.2200012,1.233808813
-0.332714844,0.643014431,199.6199951,1.235588337
-0.333398435,0.638251066,200.0200043,1.237284858
-0.33403319,0.65865624,200.4199982,1.239095582
-0.334716809,0.569361329,200.8200073,1.240869169
-0.335351564,0.60723877,201.2200012,1.242610975
-0.336035155,0.56625098,201.6199951,1.24436547
-0.336669909,0.670067251,202.0200043,1.246177009
-0.337304693,0.764625251,202.4199982,1.247998676
-0.337939447,0.582142591,202.8200073,1.24964898
-0.338671874,0.761163354,203.2200012,1.251286711
-0.339355465,0.738824189,203.6199951,1.252964605
-0.340087892,0.72070235,204.0200043,1.254600007
-0.340771483,0.663679242,204.4199982,1.256175456
-0.341455074,0.690268576,204.8200073,1.257661614
-0.342089857,0.711941361,205.2200012,1.259188983
-0.342724612,0.764560997,205.6199951,1.260669669
-0.343359367,0.787072718,206.0200043,1.262074686
-0.34399415,0.859926641,206.4199982,1.263620914
-0.344628905,0.744847238,206.8200073,1.265195315
-0.345312495,0.709228814,207.2200012,1.266746665
-0.346044922,0.598745883,207.6199951,1.268246328
-0.346728513,0.756428421,208.0200043,1.269752975
-0.347412104,0.666544378,208.4199982,1.271218294
-0.348095695,0.716871917,208.8200073,1.27269933
-0.348730478,0.738265336,209.2200012,1.274283743
-0.349365233,0.589301825,209.6199951,1.275825896
-0.349999988,0.63285768,210.0200043,1.277255476
-0.350634771,0.656247497,210.4199982,1.278628944
-0.351318362,0.615340054,210.8200073,1.280164113
-0.352001953,0.641783655,211.2200012,1.281619887
-0.35273438,0.66227138,211.6199951,1.283040154
-0.35341797,0.618186653,212.0200043,1.284443424
-0.354101561,0.649080753,212.4199982,1.285780803
-0.354785152,0.724187434,212.8200073,1.28719036
-0.355419936,0.729736447,213.2200012,1.288577449
-0.35605469,0.783994734,213.6199951,1.290028798
-0.356689445,0.746656835,214.0200043,1.29139307
-0.357324228,0.818688989,214.4199982,1.292776084
-0.358007819,0.765765071,214.8200073,1.294126734
-0.35869141,0.776314735,215.2200012,1.295398106
-0.359375001,0.783626318,215.6199951,1.296771225
-0.360107428,0.774902999,216.0200043,1.298108837
-0.360742182,0.706237495,216.4199982,1.299462398
-0.361425773,0.792975962,216.8200073,1.300844247
-0.362060557,0.712171316,217.2200012,1.302170334
-0.362695311,0.727437854,217.6199951,1.303505735
-0.363330066,0.724027991,218.0200043,1.304850797
-0.363964849,0.683138967,218.4199982,1.306316815
-0.364599604,0.531236053,218.8200073,1.307733473
-0.365283195,0.666398287,219.2200012,1.309010433
-0.366015622,0.528750479,219.6199951,1.310332329
-0.366699212,0.568055749,220.0200043,1.311861444
-0.367382803,0.703768194,220.4199982,1.313224784
-0.368066394,0.650764227,220.8200073,1.314521069
-0.368701178,0.693855345,221.2200012,1.315820846
-0.369335932,0.653064311,221.6199951,1.317114918
-0.369970716,0.666224122,222.0200043,1.318379189
-0.37060547,0.719081044,222.4199982,1.319574309
-0.371289061,0.771041393,222.8200073,1.320723328
-0.372021488,0.756077707,223.2200012,1.321849762
-0.372705079,0.747215152,223.6199951,1.323018572
-0.37338867,0.741474926,224.0200043,1.324228011
-0.37407226,0.716746449,224.4199982,1.325441408
-0.374755851,0.701628447,224.8200073,1.326584374
-0.375390635,0.730823159,225.2200012,1.327756094
-0.376025389,0.65873152,225.6199951,1.328888698
-0.376660144,0.676675916,226.0200043,1.329971245
-0.377294928,0.642847717,226.4199982,1.331091509
-0.377978518,0.562157452,226.8200073,1.332170796
-0.378662109,0.558835208,227.2200012,1.333258115
-0.379394536,0.578450859,227.6199951,1.334330649
-0.380078127,0.567053437,228.0200043,1.335325418
-0.380761718,0.551456571,228.4199982,1.336337766
-0.381445308,0.60112381,228.8200073,1.337403199
-0.382080092,0.668096542,229.2200012,1.338391448
-0.382714847,0.704030752,229.6199951,1.339399605
-0.383300794,0.706243455,230.0200043,1.340506715
-0.383984385,0.636218429,230.4199982,1.341587282
-0.384619139,0.707826078,230.8200073,1.342688687
-0.38530273,0.713313878,231.2200012,1.343802665
-0.386035157,0.756804883,231.6199951,1.344868913
-0.386767584,0.739777565,232.0200043,1.345975325
-0.387451175,0.73596257,232.4199982,1.347098732
-0.388085929,0.673396528,232.8200073,1.348148449
-0.38876952,0.734510958,233.2200012,1.349140657
-0.389404304,0.698165238,233.6199951,1.350053935
-0.390039058,0.65496397,234.0200043,1.351073268
-0.390673842,0.694773197,234.4199982,1.352059771
-0.391308597,0.531860471,234.8200073,1.353017869
-0.392041024,0.528331161,235.2200012,1.353953267
-0.392724614,0.615478098,235.6199951,1.354870968
-0.393408205,0.572776675,236.0200043,1.355859567
-0.394091796,0.636727571,236.4199982,1.356768305
-0.394775387,0.609671712,236.8200073,1.35770021
-0.39541017,0.694839716,237.2200012,1.358680194
-0.396044925,0.637936473,237.6199951,1.359631773
-0.396679679,0.700819254,238.0200043,1.360589755
-0.397314463,0.676272511,238.4199982,1.361533534
-0.397949218,0.748937607,238.8200073,1.362492214
-0.398632808,0.809642196,239.2200012,1.363447518
-0.399365235,0.707431197,239.6199951,1.364382682
-0.400048826,0.754680336,240.0200043,1.365371165
-0.400732417,0.682505727,240.4199982,1.366344746
-0.401367201,0.627012312,240.8200073,1.367283985
-0.402050791,0.657379448,241.2200012,1.368213561
-0.402685546,0.619239986,241.6199951,1.369113219
-0.403271493,0.637215495,242.0200043,1.370034763
-0.403906248,0.605905473,242.4199982,1.370960614
-0.404589839,0.623740256,242.8200073,1.371855964
-0.405273429,0.517731845,243.2200012,1.372749917
-0.406005856,0.556773067,243.6199951,1.373574953
-0.406738283,0.606408656,244.0200043,1.374411513
-0.407421874,0.586647868,244.4199982,1.375237945
-0.408056629,0.620124638,244.8200073,1.376092085
-0.408740249,0.609579623,245.2200012,1.37691549
-0.409375003,0.708512604,245.6199951,1.377718174
-0.410009758,0.683096409,246.0200043,1.378516783
-0.410644541,0.681673765,246.4199982,1.379325869
-0.411328132,0.856856585,246.8200073,1.380115515
-0.412011723,0.67722255,247.2200012,1.380887115
-0.41274415,0.727724493,247.6199951,1.381659531
-0.413427741,0.727252483,248.0200043,1.382420887
-0.414111331,0.712440848,248.4199982,1.383305294
-0.414746086,0.675233006,248.8200073,1.384189469
-0.415429677,0.588811278,249.2200012,1.385015086
-0.41606446,0.714541614,249.6199951,1.385826967
-0.416650379,0.654653192,250.0200043,1.386617892
-0.417285162,0.583361208,250.4199982,1.387414988
-0.417968753,0.532291889,250.8200073,1.388263307
-0.418652344,0.583302677,251.2200012,1.389140729
-0.419384771,0.598121881,251.6199951,1.389934099
-0.420068362,0.58034867,252.0200043,1.390763558
-0.420751952,0.615064561,252.4199982,1.391601982
-0.421435543,0.746843755,252.8200073,1.392403501
-0.422070327,0.644376993,253.2200012,1.393216779
-0.422705081,0.712505281,253.6199951,1.394013758
-0.423339836,0.701711357,254.0200043,1.394785941
-0.423974619,0.70616287,254.4199982,1.395699452
-0.424609374,0.72207284,254.8200073,1.396507025
-0.425341801,0.782209337,255.2200012,1.397298765
-0.426025392,0.700567663,255.6199951,1.398035442
-0.426757819,0.702038348,256.019989,1.398766646
-0.42744141,0.736838102,256.4200134,1.399481553
-0.428076164,0.678753018,256.8200073,1.400258974
-0.428759755,0.654135942,257.2200012,1.40099728
-0.429394539,0.703717947,257.6199951,1.401686575
-0.430029293,0.654854298,258.019989,1.40238984
-0.430664077,0.607826054,258.4200134,1.403117087
-0.431298831,0.566195607,258.8200073,1.403850736
-0.431982422,0.548861027,259.2200012,1.404548297
-0.432714849,0.532567024,259.6199951,1.405248884
-0.43339844,0.654568315,260.019989,1.40597939
-0.434033194,0.679445982,260.4200134,1.406679046
-0.434716785,0.754146099,260.8200073,1.407375559
-0.435351569,0.753841937,261.2200012,1.40809326
-0.435986323,0.666460037,261.6199951,1.408851589
-0.436621107,0.741985917,262.019989,1.409568591
-0.437255861,0.776696384,262.4200134,1.410250552
-0.437939452,0.774444997,262.8200073,1.410964527
-0.438623043,0.784372926,263.2200012,1.411625301
-0.43935547,0.704773724,263.6199951,1.412376179
-0.440039061,0.69759357,264.019989,1.413075835
-0.440722652,0.685317934,264.4200134,1.413747435
-0.441406242,0.630998433,264.8200073,1.41439971
-0.442041026,0.59627986,265.2200012,1.41505152
-0.442675781,0.694441438,265.6199951,1.415721024
-0.443310535,0.595837057,266.019989,1.416440355
-0.443945319,0.601789773,266.4200134,1.417177613
-0.444628909,0.548358858,266.8200073,1.417905791
-0.4453125,0.590821743,267.2200012,1.418609289
-0.446044927,0.597268164,267.6199951,1.4192987
-0.446728518,0.610840082,268.019989,1.419916283
-0.447412109,0.667777658,268.4200134,1.420594985
-0.4480957,0.685483396,268.8200073,1.421308494
-0.448730483,0.645888448,269.2200012,1.421987079
-0.449365238,0.606325746,269.6199951,1.422656467
-0.449999992,0.624504507,270.019989,1.423315378
-0.450634776,0.646984041,270.4200134,1.42399373
-0.451318367,0.711626828,270.8200073,1.424642862
-0.452001957,0.815556347,271.2200012,1.425297814
-0.452685548,0.723033071,271.6199951,1.425905153
-0.453417975,0.735259414,272.019989,1.426517847
-0.454101566,0.754626513,272.4200134,1.427188166
-0.454736321,0.751879573,272.8200073,1.427834737
-0.455419911,0.662792742,273.2200012,1.42849132
-0.456054695,0.725090146,273.6199951,1.429192722
-0.456689449,0.654808939,274.019989,1.429922995
-0.457324233,0.667304456,274.4200134,1.43068959
-0.458007824,0.57366991,274.8200073,1.431404147
-0.458691415,0.603193283,275.2200012,1.432111254
-0.459423842,0.652028739,275.6199951,1.432834542
-0.460107432,0.637437582,276.019989,1.433488098
-0.460791023,0.631213665,276.4200134,1.434143167
-0.461425778,0.689459741,276.8200073,1.434844104
-0.462109369,0.634696305,277.2200012,1.43552816
-0.462695316,0.644641042,277.6199951,1.436183462
-0.46333007,0.661035836,278.019989,1.436821884
-0.463964854,0.637919426,278.4200134,1.437454019
-0.464599609,0.72902441,278.8200073,1.438080915
-0.465283199,0.739693701,279.2200012,1.438710606
-0.466015626,0.745082319,279.6199951,1.43931713
-0.466699217,0.777556241,280.019989,1.439916901
-0.467382808,0.763099968,280.4200134,1.440557884
-0.468066399,0.800254166,280.8200073,1.44115719
-0.468701182,0.728933573,281.2200012,1.441754168
-0.469335937,0.760269582,281.6199951,1.442345791
-0.469970691,0.73198545,282.019989,1.442937646
-0.470605475,0.65930295,282.4200134,1.443580491
-0.471289066,0.654293954,282.8200073,1.444227761
-0.471972657,0.653814495,283.2200012,1.444820315
-0.472705084,0.600279689,283.6199951,1.445462811
-0.473388674,0.58883059,284.019989,1.44613185
-0.474072265,0.593385994,284.4200134,1.446799375
-0.474755856,0.564530134,284.8200073,1.447458519
-0.475390611,0.640688062,285.2200012,1.448080409
-0.476025394,0.644323766,285.6199951,1.44868379
-0.476660149,0.667731583,286.019989,1.44926901
-0.477294932,0.664357066,286.4200134,1.449833391
-0.477978523,0.687657297,286.8200073,1.450382406
-0.478662114,0.699503422,287.2200012,1.450904296
-0.479394541,0.742508173,287.6199951,1.45147997
-0.480078132,0.722716153,288.019989,1.452074619
-0.480761722,0.713907659,288.4200134,1.452632598
-0.481396477,0.686080754,288.8200073,1.453202683
-0.482031261,0.778232634,289.2200012,1.453778823
-0.482666015,0.79272449,289.6199951,1.454335637
-0.48330077,0.805303812,290.019989,1.45491038
-0.483935553,0.807282746,290.4200134,1.455496997
-0.484619144,0.757211268,290.8200073,1.456067548
-0.485302735,0.759978354,291.2200012,1.456659986
-0.486035162,0.768449545,291.6199951,1.45727559
-0.486718753,0.712361395,292.019989,1.457951614
-0.487402343,0.696798861,292.4200134,1.458606683
-0.488085934,0.607720971,292.8200073,1.459225896
-0.488769554,0.650171101,293.2200012,1.459811814
-0.489404309,0.689899743,293.6199951,1.460381551
-0.490039063,0.615835011,294.019989,1.460949075
-0.490673818,0.65492934,294.4200134,1.46152568
-0.491357408,0.712724805,294.8200073,1.462114044
-0.492040999,0.620714068,295.2200012,1.462661894
-0.492773426,0.740241408,295.6199951,1.463189605
-0.493457017,0.655945837,296.019989,1.463704859
-0.494091772,0.602785647,296.4200134,1.464256202
-0.494775362,0.641973138,296.8200073,1.464762143
-0.495410175,0.719520032,297.2200012,1.465310459
-0.49604493,0.691284895,297.6199951,1.465862966
-0.496679684,0.69990015,298.019989,1.466401271
-0.497314439,0.710307002,298.4200134,1.466908609
-0.497949193,0.673101544,298.8200073,1.467409427
-0.498632784,0.775185764,299.2200012,1.467935625
-0.499365211,0.697851002,299.6199951,1.468455303
-0.500048802,0.764598846,300.019989,1.468975679
-0.500732451,0.733131528,300.4200134,1.469478011
-0.501416042,0.748324156,300.8200073,1.469964511
-0.502050796,0.784767926,301.2200012,1.470537158
-0.502685551,0.793480158,301.6199951,1.471076393
-0.503271469,0.696350038,302.019989,1.471609343
-0.50395506,0.737521589,302.4200134,1.472192467
-0.504589872,0.673677325,302.8200073,1.472788863
-0.505322241,0.816084862,303.2200012,1.473532408
-0.506005832,0.683121741,303.6199951,1.474078279
-0.506738259,0.61208415,304.019989,1.474643592
-0.50742185,0.674438953,304.4200134,1.475156168
-0.508105441,0.597714126,304.8200073,1.475680852
-0.508740253,0.628623188,305.2200012,1.476198086
-0.509375008,0.561457932,305.6199951,1.476757228
-0.510009762,0.638845146,306.019989,1.47728622
-0.510644517,0.668402433,306.4200134,1.477813814
-0.511328108,0.634484112,306.8200073,1.478340011
-0.512011698,0.657615721,307.2200012,1.478901948
-0.512744125,0.733112633,307.6199951,1.479446655
-0.513427716,0.711190581,308.019989,1.47998624
-0.514062529,0.75399673,308.4200134,1.480513834
-0.51474612,0.731995702,308.8200073,1.481049112
-0.515380874,0.700864553,309.2200012,1.481593936
-0.516015629,0.735045612,309.6199951,1.482119435
-0.516650383,0.670656621,310.019989,1.482638647
-0.517285138,0.780542552,310.4200134,1.483162516
-0.517968729,0.650375068,310.8200073,1.483703847
-0.518652319,0.73071754,311.2200012,1.484266832
-0.519384746,0.735107005,311.6199951,1.484854147
-0.520068337,0.711858749,312.019989,1.485395012
-0.520751928,0.74772191,312.4200134,1.485919231
-0.521435519,0.578751743,312.8200073,1.486477675
-0.522070331,0.672009706,313.2200012,1.487013651
-0.522705086,0.640641153,313.6199951,1.487547182
-0.523339841,0.512456357,314.019989,1.488070353
-0.523974595,0.53372556,314.4200134,1.488568028
-0.524658186,0.543366849,314.8200073,1.489033573
-0.525341777,0.526363611,315.2200012,1.489564311
-0.526074204,0.538002551,315.6199951,1.490133931
-0.526757794,0.669528246,316.019989,1.490668044
-0.527441385,0.588182509,316.4200134,1.491167117
-0.528076198,0.586387932,316.8200073,1.491676667
-0.528710952,0.626245618,317.2200012,1.492174924
-0.529394543,0.676423669,317.6199951,1.492667128
-0.529980462,0.653443813,318.019989,1.493154909
-0.530615216,0.662254572,318.4200134,1.493640128
-0.531298807,0.681683123,318.8200073,1.494170749
-0.531982398,0.736885846,319.2200012,1.49466272
-0.532714825,0.809153318,319.6199951,1.495174016
-0.533398415,0.747764349,320.019989,1.495673321
-0.534033228,0.714568615,320.4200134,1.496118144
-0.534716819,0.660155773,320.8200073,1.496599638
-0.535351573,0.711497068,321.2200012,1.497073681
-0.536035164,0.640652001,321.6199951,1.497525722
-0.536669919,0.657228172,322.019989,1.498017809
-0.537304673,0.609683692,322.4200134,1.498530619
-0.537939428,0.639468014,322.8200073,1.499079051
-0.538671855,0.628902853,323.2200012,1.499554259
-0.539355446,0.623113632,323.6199951,1.50002155
-0.540087873,0.472396553,324.019989,1.500525861
-0.540771463,0.536887228,324.4200134,1.501008053
-0.541406276,0.6020751,324.8200073,1.501487452
-0.542089867,0.545947611,325.2200012,1.501955558
-0.542724621,0.644211352,325.6199951,1.502440544
-0.543359376,0.624761939,326.019989,1.502894214
-0.543994131,0.611750364,326.4200134,1.503361622
-0.544628885,0.603899837,326.8200073,1.503844163
-0.545312476,0.687613726,327.2200012,1.504335902
-0.546044903,0.724475563,327.6199951,1.504840329
-0.546728494,0.709136188,328.019989,1.505344058
-0.547412084,0.709816992,328.4200134,1.505853259
-0.548095675,0.694630682,328.8200073,1.506349072
-0.548730488,0.763314486,329.2200012,1.5068457
-0.549365242,0.626144588,329.6199951,1.507340115
-0.549999997,0.597012937,330.019989,1.507827546
-0.550634752,0.626520097,330.4200134,1.508318004
-0.551318342,0.603530645,330.8200073,1.508799847
-0.552001933,0.693700254,331.2200012,1.509283553
-0.55273436,0.606916189,331.6199951,1.509738504
-0.553417951,0.541754305,332.019989,1.510192058
-0.554101542,0.594524324,332.4200134,1.510603121
-0.554785132,0.547753453,332.8200073,1.511054579
-0.555419945,0.569031775,333.2200012,1.511514769
-0.5560547,0.605903625,333.6199951,1.511982176
-0.556689454,0.648511469,334.019989,1.512474497
-0.557324209,0.570240855,334.4200134,1.51294691
-0.5580078,0.670445979,334.8200073,1.513413037
-0.55869139,0.674826145,335.2200012,1.513908384
-0.559374981,0.769553959,335.6199951,1.51436124
-0.560107408,0.695378959,336.019989,1.514847856
-0.560742163,0.761601508,336.4200134,1.515312935
-0.561425753,0.834261,336.8200073,1.515803044
-0.562060566,0.744304001,337.2200012,1.51626463
-0.562695321,0.684576869,337.6199951,1.516758231
-0.563330075,0.737154067,338.019989,1.517292345
-0.56396483,0.726781368,338.4200134,1.517808298
-0.564599584,0.747311831,338.8200073,1.518300967
-0.565283175,0.694762766,339.2200012,1.518820296
-0.566015602,0.706721365,339.6199951,1.519308076
-0.566699193,0.71096009,340.019989,1.519798185
-0.567382784,0.675562084,340.4200134,1.520310179
-0.568066433,0.624905527,340.8200073,1.520829857
-0.568701187,0.620337546,341.2200012,1.521433238
-0.569335942,0.693223894,341.6199951,1.522046747
-0.569970696,0.60042721,342.019989,1.522607752
-0.570605451,0.751037896,342.4200134,1.523122191
-0.571289042,0.715324938,342.8200073,1.523601823
-0.572021469,0.720477462,343.2200012,1.52413547
-0.572705059,0.711145282,343.6199951,1.524664811
-0.573437486,0.676497579,344.019989,1.52514514
-0.574072241,0.783019006,344.4200134,1.525618602
-0.574755832,0.809034765,344.8200073,1.526079839
-0.575390644,0.829750597,345.2200012,1.526560518
-0.576025399,0.686345041,345.6199951,1.527045853
-0.576660153,0.698093712,346.019989,1.52754155
-0.577294908,0.728129566,346.4200134,1.528066932
-0.577978499,0.667676806,346.8200073,1.528579625
-0.57866209,0.670057058,347.2200012,1.529082074
-0.579394517,0.71570456,347.6199951,1.529559144
-0.580078107,0.705813825,348.019989,1.530007808
-0.580761698,0.668151557,348.4200134,1.530475449
-0.581396511,0.648174405,348.8200073,1.530948328
-0.582080102,0.631508231,349.2200012,1.531415968
-0.582714856,0.643938482,349.6199951,1.531888265
-0.583349611,0.635454595,350.019989,1.532351249
-0.583935529,0.657877386,350.4200134,1.532817958
-0.58461912,0.640181661,350.8200073,1.533262897
-0.585302711,0.676967084,351.2200012,1.533723203
-0.586035138,0.700034678,351.6199951,1.534169656
-0.586718728,0.767888784,352.019989,1.534619601
-0.587451155,0.755438626,352.4200134,1.535069663
-0.58808591,0.838154376,352.8200073,1.535507734
-0.588769559,0.739660382,353.2200012,1.535948599
-0.589404313,0.764059603,353.6199951,1.536361175
-0.590039068,0.736314714,354.019989,1.536799013
-0.590673822,0.736354172,354.4200134,1.53720798
-0.591308577,0.765995502,354.8200073,1.537604141
-0.592041004,0.72161299,355.2200012,1.538003213
-0.592724595,0.713962317,355.6199951,1.538410899
-0.593408186,0.626665413,356.019989,1.538825338
-0.594091776,0.660223007,356.4200134,1.539248042
-0.594775367,0.511333704,356.8200073,1.539681572
-0.59541018,0.567182481,357.2200012,1.540105673
-0.596044934,0.620981574,357.6199951,1.540513127
-0.596679689,0.572522104,358.019989,1.540934201
-0.597314443,0.64762634,358.4200134,1.541347359
-0.597949198,0.685092688,358.8200073,1.541781938
-0.598632789,0.709980607,359.2200012,1.542184968
-0.599365216,0.685667336,359.6199951,1.542576589
-0.600048807,0.712092757,360.019989,1.542985672
-0.600732397,0.790714741,360.4200134,1.543390332
-0.60136721,0.794597089,360.8200073,1.543752616
-0.602001965,0.718784392,361.2200012,1.544143772
-0.602685555,0.838073015,361.6199951,1.544551342
-0.60332031,0.725784957,362.019989,1.544981147
-0.603906228,0.712898135,362.4200134,1.545385225
-0.604589819,0.678104818,362.8200073,1.545769861
-0.60527341,0.725076854,363.2200012,1.546144718
-0.606005837,0.736238241,363.6199951,1.546537154
-0.606738264,0.69658196,364.019989,1.546925283
-0.607421855,0.683897793,364.4200134,1.547322609
-0.608056667,0.585245371,364.8200073,1.547756605
-0.608740258,0.642619431,365.2200012,1.548194676
-0.609375013,0.602148831,365.6199951,1.548628439
-0.610009767,0.60741061,366.019989,1.549044973
-0.610644522,0.643034995,366.4200134,1.549407723
-0.611328112,0.682418525,366.8200073,1.549799461
-0.612011703,0.685189068,367.2200012,1.550200279
-0.61274413,0.716367781,367.6199951,1.550579676
-0.613427721,0.730633974,368.019989,1.550958841
-0.614111312,0.62489289,368.4200134,1.551366295
-0.614746066,0.766294718,368.8200073,1.551734982
-0.615429715,0.788326561,369.2200012,1.552110887
-0.61606447,0.761105895,369.6199951,1.55250472
-0.616699224,0.741525412,370.019989,1.552879694
-0.617333979,0.769346833,370.4200134,1.553235692
-0.617968733,0.809049129,370.8200073,1.553602517
-0.618652324,0.776922762,371.2200012,1.553966198
-0.619384751,0.728547096,371.6199951,1.554366201
-0.620068342,0.659770489,372.019989,1.554753399
-0.620751933,0.704003394,372.4200134,1.555130701
-0.621435523,0.705653131,372.8200073,1.555530704
-0.622070336,0.653011918,373.2200012,1.555918949
-0.622705091,0.708767474,373.6199951,1.556300791
-0.623339845,0.612475932,374.019989,1.556674717
-0.6239746,0.600813627,374.4200134,1.557055395
-0.624658191,0.617094696,374.8200073,1.557413139
-0.625341781,0.682246268,375.2200012,1.557762153
-0.626074208,0.730558455,375.6199951,1.558113727
-0.626757799,0.70724225,376.019989,1.558472868
-0.62744139,0.708188176,376.4200134,1.558821648
-0.628076144,0.724691927,376.8200073,1.55915611
-0.628759793,0.709008038,377.2200012,1.559502445
-0.629394548,0.82740736,377.6199951,1.559857163
-0.630029303,0.84849453,378.019989,1.560220844
-0.630664057,0.455518574,378.4200134,1.56059349
-0.631298812,0.790611446,378.8200073,1.560973004
-0.631982402,0.782912612,379.2200012,1.561350655
-0.632714829,0.779591203,379.6199951,1.561689074
-0.63339842,0.643897593,380.019989,1.562032849
-0.634033175,0.749041438,380.4200134,1.562362653
-0.634716824,0.680247605,380.8200073,1.56272843
-0.635400414,0.763264298,381.2200012,1.563083497
-0.635986333,0.691644788,381.6199951,1.563408645
-0.636621087,0.60947907,382.019989,1.563766156
-0.637255842,0.63913691,382.4200134,1.564114122
-0.637939433,0.63575995,382.8200073,1.56445126
-0.638623023,0.621170998,383.2200012,1.564811217
-0.63935545,0.724364936,383.6199951,1.565185376
-0.640039041,0.6256392,384.019989,1.565537183
-0.640722632,0.651869297,384.4200134,1.565891667
-0.641406223,0.677079618,384.8200073,1.566236489
-0.642041035,0.701398015,385.2200012,1.566607505
-0.64267579,0.700459898,385.6199951,1.56696036
-0.643310545,0.789717019,386.019989,1.567346742
-0.643945299,0.840133429,386.4200134,1.567729167
-0.64462889,0.800643265,386.8200073,1.568088075
-0.645312481,0.817226231,387.2200012,1.568425447
-0.646044908,0.817932367,387.6199951,1.568751992
-0.646777335,0.813568711,388.019989,1.569114276
-0.647412089,0.709136248,388.4200134,1.569485292
-0.64809568,0.757045448,388.8200073,1.569884014
-0.648730493,0.718158007,389.2200012,1.57026411
-0.649365247,0.789874375,389.6199951,1.570606255
-0.650000002,0.740381241,390.019989,1.570931403
-0.650634756,0.718823075,390.4200134,1.571278903
-0.651318347,0.729775071,390.8200073,1.571597299
-0.652001938,0.642584026,391.2200012,1.571918838
-0.652734365,0.68798399,391.6199951,1.572251203
-0.653417956,0.641899049,392.019989,1.572629088
-0.654101546,0.646801591,392.4200134,1.573005458
-0.654736301,0.60439986,392.8200073,1.573369605
-0.65541995,0.71664089,393.2200012,1.573710586
-0.656054704,0.750583112,393.6199951,1.574033638
-0.656689459,0.712936997,394.019989,1.574385911
-0.657324214,0.631020129,394.4200134,1.574725844
-0.658007804,0.673983455,394.8200073,1.575034112
-0.658691395,0.779072821,395.2200012,1.57535763
-0.659423822,0.742936373,395.6199951,1.57566485
-0.660107413,0.773018658,396.019989,1.575965085
-0.660791004,0.746170223,396.4200134,1.576270326
-0.661425758,0.777657628,396.8200073,1.576581853
-0.662109349,0.865154445,397.2200012,1.576898154
-0.662695325,0.745427251,397.6199951,1.577206654
-0.66333008,0.774733245,398.019989,1.577555202
-0.663964835,0.69972378,398.4200134,1.57788943
-0.664599589,0.731195092,398.8200073,1.578295371
-0.66528318,0.706577122,399.2200012,1.578644034
-0.666015607,0.596257865,399.6199951,1.578993746
-0.666699198,0.667875648,400.019989,1.579332049
-0.667382788,0.610243857,400.4200134,1.57966651
-0.667675806,0.720015824,400.6000061,1.579827513