File: Data/Thesis_Samples_Data/Notched_Solid_5/Notched_Solid_5.csv
"File Path: C:\Users\Lab User\Desktop\Will\Thesis Tests\Test Run 3 04-8-22 16 07 51 PM\DAQ- Crosshead, … - (Timed).csv   ",,,
Test: MTS EM Tension (Extensometer) - Will 1,,,
Test Run: Test Run 3,,,
Date: 4/8/2022 4:06:06 PM,,,
,,,
,,,
Crosshead ,Load ,Time ,Extensometer
mm,N,sec,mm
-4.88E-05,-2.566328526,0.02,-5.06E-06
-4.88E-05,-2.66408515,0.100000001,-4.61E-07
-9.77E-05,-2.60405159,0.180000007,-1.03E-05
-0.000195312,-2.503619909,0.25999999,-8.14E-06
-0.000244141,-2.606727123,0.340000004,-5.89E-06
-0.000341797,-2.734592438,0.419999987,4.74E-06
-0.000439453,-2.950540543,0.5,6.41E-06
-0.000585938,-3.060746193,0.579999983,4.73E-06
-0.00078125,-3.386425257,0.660000026,-4.30E-07
-0.000927734,-3.588652849,0.74000001,2.94E-06
-0.001074219,-4.077354908,0.819999993,1.59E-05
-0.001269531,-4.517456055,0.899999976,1.91E-05
-0.001416016,-4.780029774,0.980000019,2.59E-05
-0.0015625,-4.955502033,1.059999943,2.01E-05
-0.001708984,-5.372724533,1.139999986,1.66E-05
-0.001855469,-5.849962234,1.220000029,3.98E-05
-0.002050781,-6.363688469,1.299999952,3.42E-05
-0.002197266,-6.598568439,1.379999995,2.82E-05
-0.00234375,-6.959878445,1.460000038,3.67E-05
-0.002490234,-7.49861908,1.539999962,3.81E-05
-0.002685547,-7.945951462,1.620000005,4.73E-05
-0.002832031,-8.38693428,1.700000048,5.87E-05
-0.002978516,-8.720959663,1.779999971,5.89E-05
-0.003125,-8.987787247,1.860000014,5.25E-05
-0.003271484,-9.439731598,1.940000057,6.35E-05
-0.003369141,-9.905637741,2.019999981,6.97E-05
-0.003515625,-10.35507679,2.099999905,6.69E-05
-0.003662109,-10.60428619,2.180000067,6.25E-05
-0.003808594,-10.85631466,2.25999999,7.37E-05
-0.003955078,-11.37904644,2.339999914,8.12E-05
-0.004052734,-11.81065273,2.420000076,9.52E-05
-0.004199219,-12.27736568,2.5,8.79E-05
-0.004345703,-12.48535633,2.579999924,8.43E-05
-0.004492188,-12.85199261,2.660000086,8.63E-05
-0.004589844,-13.27877617,2.74000001,9.48E-05
-0.004736328,-13.80331421,2.819999933,0.000108542
-0.004882812,-14.07970238,2.900000095,0.000108272
-0.005029297,-14.40973663,2.980000019,9.72E-05
-0.005126953,-14.79968834,3.059999943,9.78E-05
-0.005273438,-15.30002975,3.140000105,0.000113127
-0.005419922,-15.657444,3.220000029,0.000115198
-0.005517578,-16.01802063,3.299999952,0.000111043
-0.005664062,-16.29844666,3.380000114,0.00011056
-0.005810547,-16.67643929,3.460000038,0.000111038
-0.005908203,-17.07582283,3.539999962,0.000123161
-0.006054688,-17.53191185,3.619999886,0.00012026
-0.006201172,-17.88362694,3.700000048,0.000119665
-0.006298828,-18.19083595,3.779999971,0.000125532
-0.006445312,-18.58572388,3.859999895,0.000128267
-0.006542969,-19.06430435,3.940000057,0.000138363
-0.006689453,-19.35238647,4.019999981,0.000139255
-0.006835938,-19.80331421,4.099999905,0.000128753
-0.006933594,-20.07789421,4.179999828,0.00012672
-0.007080078,-20.4629612,4.260000229,0.000141994
-0.007177734,-20.99953842,4.340000153,0.000148644
-0.007324219,-21.38640594,4.420000076,0.0001531
-0.007470703,-21.62598801,4.5,0.000143013
-0.007568359,-21.94550323,4.579999924,0.000158753
-0.007714843,-22.48644829,4.659999847,0.000156875
-0.007861328,-22.86621284,4.739999771,0.000161311
-0.007958984,-23.2468853,4.820000172,0.000160387
-0.008105469,-23.69265938,4.900000095,0.000158368
-0.008251953,-23.96109009,4.980000019,0.000168069
-0.008398438,-24.44523048,5.059999943,0.000172809
-0.008496094,-24.96351433,5.139999866,0.00017414
-0.008642578,-25.38235474,5.21999979,0.000179446
-0.008789062,-25.7599926,5.300000191,0.000181689
-0.008935547,-26.10677338,5.380000114,0.000181743
-0.009082031,-26.68427658,5.460000038,0.000190765
-0.009228515,-27.19794083,5.539999962,0.000198576
-0.009375,-27.63980865,5.619999886,0.000202841
-0.009521485,-27.90406799,5.699999809,0.000207449
-0.009667969,-28.2808075,5.78000021,0.000204895
-0.009814453,-28.78262138,5.860000134,0.000220175
-0.00991211,-29.24571991,5.940000057,0.000217816
-0.010058594,-29.75346375,6.019999981,0.000220715
-0.010205078,-29.97852325,6.099999905,0.000220062
-0.010351562,-30.40252304,6.179999828,0.000222055
-0.010498047,-30.91190147,6.260000229,0.00023656
-0.010644531,-31.40928459,6.340000153,0.000232226
-0.010742187,-31.73353577,6.420000076,0.000238776
-0.010888672,-32.12339401,6.5,0.000248297
-0.011035157,-32.62989807,6.579999924,0.000247759
-0.011181641,-32.97489929,6.659999847,0.000247969
-0.011279297,-33.48222733,6.739999771,0.000258431
-0.011425781,-33.82282257,6.820000172,0.00025649
-0.011572266,-34.18258667,6.900000095,0.000263077
-0.01171875,-34.61328888,6.980000019,0.000263411
-0.011816406,-35.12690353,7.059999943,0.000271556
-0.01196289,-35.4901123,7.139999866,0.00027418
-0.012060547,-35.85424423,7.21999979,0.000274074
-0.012207031,-36.1267395,7.300000191,0.000280303
-0.012353516,-36.56098938,7.380000114,0.000288581
-0.012451172,-37.19102859,7.460000038,0.000290648
-0.012597657,-37.45777512,7.539999962,0.000291846
-0.012695313,-37.82116318,7.619999886,0.000305403
-0.012841797,-38.10964203,7.699999809,0.000307075
-0.012988281,-38.60635757,7.78000021,0.000307169
-0.013085937,-39.0712738,7.860000134,0.000302836
-0.013232422,-39.36296844,7.940000057,0.000316901
-0.013330078,-39.69692612,8.020000458,0.000329855
-0.013476562,-40.06857681,8.100000381,0.000327681
-0.013574218,-40.5234642,8.180000305,0.00032965
-0.013720703,-41.04403687,8.260000229,0.000339738
-0.01381836,-41.28039169,8.340000153,0.000340819
-0.013964844,-41.62690353,8.420000076,0.00033938
-0.014111328,-41.99180222,8.5,0.000352937
-0.014208985,-42.55607986,8.579999924,0.000342782
-0.014355469,-42.91952133,8.659999847,0.000353011
-0.014501953,-43.26825333,8.739999771,0.000359523
-0.014599609,-43.58222198,8.819999695,0.000357927
-0.014746094,-43.98955536,8.899999619,0.000360125
-0.014892578,-44.4880867,8.979999542,0.000361838
-0.014990234,-44.92990494,9.06000042,0.000372924
-0.015136719,-45.33040237,9.140000343,0.000373575
-0.015283204,-45.74295807,9.220000267,0.000378831
-0.015429687,-46.09641266,9.300000191,0.000390999
-0.015576172,-46.69933319,9.380000114,0.000389991
-0.015722657,-47.00926208,9.460000038,0.000387692
-0.01586914,-47.37538147,9.539999962,0.0003981
-0.016015625,-47.71177292,9.619999886,0.000406332
-0.01616211,-48.23665619,9.699999809,0.000402585
-0.016259766,-48.75258255,9.779999733,0.000410825
-0.016406249,-49.26028824,9.859999657,0.00041014
-0.016552734,-49.53219986,9.93999958,0.000413007
-0.016699219,-49.86004639,10.02000046,0.000422
-0.016845703,-50.42386246,10.10000038,0.000430596
-0.016992188,-50.83410645,10.18000031,0.000431114
-0.017089844,-51.15974045,10.26000023,0.000444447
-0.017236329,-51.52758408,10.34000015,0.000429932
-0.017382812,-51.94023132,10.42000008,0.000440238
-0.017529297,-52.33830643,10.5,0.000444579
-0.017626953,-52.81745911,10.57999992,0.000451268
-0.017773438,-53.10759735,10.65999985,0.000469211
-0.017919921,-53.51104355,10.73999977,0.000459229
-0.018066406,-53.8190918,10.81999969,0.000466029
-0.018164063,-54.39096069,10.89999962,0.000472644
-0.018310548,-54.83011627,10.97999954,0.000471484
-0.018457031,-55.11269379,11.06000042,0.000494813
-0.018603516,-55.36211777,11.14000034,0.000497032
-0.018701172,-55.83507919,11.22000027,0.000493753
-0.018847657,-56.29898071,11.30000019,0.000491186
-0.01899414,-56.78890991,11.38000011,0.000500002
-0.019091796,-57.06954575,11.46000004,0.000501529
-0.019238281,-57.36309814,11.53999996,0.000512209
-0.019335937,-57.75020218,11.61999989,0.000504016
-0.019482422,-58.33041,11.69999981,0.000516185
-0.019580079,-58.65491867,11.77999973,0.000519953
-0.019726562,-59.00869751,11.85999966,0.000526205
-0.019873047,-59.33946228,11.93999958,0.000517554
-0.019970703,-59.7867775,12.02000046,0.00053112
-0.020117188,-60.27556992,12.10000038,0.000539107
-0.020214844,-60.68051147,12.18000031,0.000551235
-0.020361329,-60.97925949,12.26000023,0.000546342
-0.020507812,-61.29859924,12.34000015,0.000546995
-0.020605468,-61.75387955,12.42000008,0.000554763
-0.020751953,-62.21858597,12.5,0.00056181
-0.020849609,-62.57849121,12.57999992,0.00057463
-0.020996094,-62.93606567,12.65999985,0.000567481
-0.021142578,-63.28922272,12.73999977,0.000574838
-0.021289063,-63.84587479,12.81999969,0.000584183
-0.021386719,-64.37577057,12.89999962,0.0005994
-0.021533204,-64.68940735,12.97999954,0.000600035
-0.021679687,-65.09672546,13.06000042,0.000611088
-0.021826172,-65.50601959,13.14000034,0.000604571
-0.021923828,-66.03549194,13.22000027,0.000617225
-0.022070313,-66.56351471,13.30000019,0.000617452
-0.022216796,-66.9227066,13.38000011,0.000625505
-0.022363281,-67.25082397,13.46000004,0.00062891
-0.022509766,-67.78704071,13.53999996,0.000640306
-0.02265625,-68.31959534,13.61999989,0.000649647
-0.022802735,-68.94885254,13.69999981,0.000655955
-0.022949218,-69.2021637,13.77999973,0.000662424
-0.023095703,-69.54786682,13.85999966,0.000671629
-0.023242188,-70.02848053,13.93999958,0.000655282
-0.023388671,-70.61164093,14.02000046,0.000683668
-0.023486327,-70.94905853,14.10000038,0.000683327
-0.023632812,-71.46567535,14.18000031,0.000682541
-0.023779297,-71.83927155,14.26000023,0.000694679
-0.023925781,-72.45022583,14.34000015,0.000696779
-0.024072266,-72.84986115,14.42000008,0.000701717
-0.024218751,-73.33950806,14.5,0.000723263
-0.024365234,-73.63091278,14.57999992,0.000722425
-0.02446289,-74.13362885,14.65999985,0.000722126
-0.024609375,-74.64891815,14.73999977,0.000728558
-0.02475586,-75.14161682,14.81999969,0.000745075
-0.024853516,-75.51000977,14.89999962,0.000755259
-0.024999999,-75.95127869,14.97999954,0.000754855
-0.025146484,-76.18438721,15.06000042,0.000753875
-0.025292969,-76.73558807,15.14000034,0.000758136
-0.025390626,-77.28189087,15.22000027,0.00077229
-0.025537109,-77.64459229,15.30000019,0.000782889
-0.025683594,-77.98999786,15.38000011,0.00079643
-0.025830079,-78.3229599,15.46000004,0.000791449
-0.025927735,-78.94141388,15.53999996,0.000796718
-0.026074218,-79.38690186,15.61999989,0.000814327
-0.026171874,-79.75553894,15.69999981,0.000806846
-0.026318359,-80.08873749,15.77999973,0.000819669
-0.026416015,-80.5302887,15.85999966,0.000818724
-0.0265625,-80.90036011,15.93999958,0.000835099
-0.026660156,-81.47093201,16.02000046,0.000838345
-0.026806641,-81.79566193,16.10000038,0.000847683
-0.026953125,-82.15802765,16.18000031,0.000847447
-0.027050781,-82.52767944,16.26000023,0.000860228
-0.027197266,-83.14072418,16.34000015,0.000859613
-0.027343751,-83.57173157,16.42000008,0.000876074
-0.027441407,-83.86241913,16.5,0.000884615
-0.02758789,-84.13912964,16.57999992,0.000878039
-0.027685546,-84.74341583,16.65999985,0.000871213
-0.027832031,-85.16664886,16.73999977,0.000894655
-0.027978516,-85.60122681,16.81999969,0.000903468
-0.028125,-85.98449707,16.89999962,0.00090407
-0.028222656,-86.32418823,16.97999954,0.000912881
-0.028369141,-86.94425201,17.05999947,0.000912446
-0.028515626,-87.45656586,17.13999939,0.000928735
-0.028662109,-87.89146423,17.21999931,0.000944748
-0.028808594,-88.33956909,17.29999924,0.000945635
-0.028955079,-88.69515991,17.37999916,0.000944688
-0.029101562,-89.32817078,17.45999908,0.000953662
-0.029248047,-89.92459106,17.54000092,0.000967851
-0.029345703,-90.34937286,17.62000084,0.000974422
-0.029492188,-90.70442963,17.70000076,0.000979911
-0.029638672,-91.14925385,17.78000069,0.000981527
-0.029785157,-91.73578644,17.86000061,0.000991703
-0.02993164,-92.24326324,17.94000053,0.000999715
-0.030078125,-92.68354797,18.02000046,0.001015658
-0.03022461,-93.01498413,18.10000038,0.001014996
-0.030322266,-93.55086517,18.18000031,0.001027198
-0.030468749,-94.06278229,18.26000023,0.001042098
-0.030615236,-94.54990387,18.34000015,0.001054242
-0.030761719,-95.02391815,18.42000008,0.001055443
-0.030859374,-95.38606262,18.5,0.001062315
-0.03100586,-95.80696869,18.57999992,0.001072905
-0.031152344,-96.4580307,18.65999985,0.001092919
-0.031298827,-96.78304291,18.73999977,0.001098249
-0.031396485,-97.3143158,18.81999969,0.00110465
-0.031542968,-97.62107086,18.89999962,0.001112236
-0.031689455,-98.10453796,18.97999954,0.00111792
-0.031787109,-98.7035675,19.05999947,0.001130245
-0.031933592,-99.30392456,19.13999939,0.0011567
-0.032080079,-99.5109024,19.21999931,0.001157433
-0.032177733,-99.91320801,19.29999924,0.001161574
-0.03232422,-100.4504471,19.37999916,0.001169754
-0.032421874,-100.9829407,19.45999908,0.001184348
-0.032568358,-101.3123856,19.54000092,0.001193174
-0.032714845,-101.7158279,19.62000084,0.001203994
-0.032812499,-102.1622849,19.70000076,0.001203716
-0.032958986,-102.7604294,19.78000069,0.001228219
-0.033105469,-103.2303848,19.86000061,0.001235295
-0.033203127,-103.6891022,19.94000053,0.001253872
-0.03334961,-103.9620667,20.02000046,0.001263711
-0.033447264,-104.4483109,20.10000038,0.00126362
-0.033593751,-104.9348221,20.18000031,0.001271601
-0.033691405,-105.473259,20.26000023,0.001293757
-0.033837892,-105.8052063,20.34000015,0.001291571
-0.033935547,-106.1659088,20.42000008,0.001312875
-0.03408203,-106.7552719,20.5,0.001319055
-0.034228517,-107.325676,20.57999992,0.00133325
-0.034326171,-107.774025,20.65999985,0.001343537
-0.034472658,-108.2238235,20.73999977,0.001366508
-0.034619141,-108.6238403,20.81999969,0.001370901
-0.034716795,-109.1683731,20.89999962,0.001380988
-0.034863282,-109.7225723,20.97999954,0.00139157
-0.035009765,-110.2580948,21.05999947,0.001402255
-0.035156248,-110.7754669,21.13999939,0.001411116
-0.035302735,-111.1223297,21.21999931,0.001416453
-0.03540039,-111.8487244,21.29999924,0.001430555
-0.035546876,-112.4659195,21.37999916,0.00143478
-0.03569336,-112.9592819,21.45999908,0.001466144
-0.035839843,-113.407074,21.54000092,0.001473746
-0.03598633,-113.9777756,21.62000084,0.001481263
-0.036132813,-114.6322403,21.70000076,0.001502588
-0.036279296,-115.3059006,21.78000069,0.001519618
-0.036425783,-115.6902313,21.86000061,0.001534696
-0.036572266,-116.2718658,21.94000053,0.001552834
-0.036718749,-116.6920853,22.02000046,0.001553096
-0.036865233,-117.2950058,22.10000038,0.001570781
-0.03701172,-117.8378372,22.18000031,0.001598688
-0.037158203,-118.3957367,22.26000023,0.001616318
-0.037255861,-118.8454819,22.34000015,0.001620775
-0.037402344,-119.259491,22.42000008,0.001649048
-0.037548827,-119.8092041,22.5,0.001665096
-0.037695314,-120.4639206,22.57999992,0.001689131
-0.037792968,-120.8417664,22.65999985,0.001706404
-0.037939451,-121.3672256,22.73999977,0.001727536
-0.038085938,-121.9433899,22.81999969,0.001727275
-0.038232422,-122.5331345,22.89999962,0.001766608
-0.038330079,-123.0563507,22.97999954,0.001779439
-0.038476563,-123.564209,23.05999947,0.001804836
-0.038623046,-123.8774414,23.13999939,0.001811465
-0.038720704,-124.3932037,23.21999931,0.001831121
-0.038867187,-124.9865189,23.29999924,0.001857821
-0.03901367,-125.5759811,23.37999916,0.001867678
-0.039111328,-125.9825134,23.45999908,0.001882676
-0.039257811,-126.5330124,23.54000092,0.001904238
-0.039404298,-126.9706497,23.62000084,0.001918059
-0.039550781,-127.6215439,23.70000076,0.001943757
-0.039648439,-128.2796783,23.78000069,0.001971432
-0.039794922,-128.5761566,23.86000061,0.001988364
-0.039892577,-129.0439453,23.94000053,0.002005683
-0.040039064,-129.5640869,24.02000046,0.002019692
-0.040136718,-130.1705933,24.10000038,0.00204821
-0.040283205,-130.738327,24.18000031,0.002076175
-0.040429688,-131.2735596,24.26000023,0.002086052
-0.040527342,-131.6064911,24.34000015,0.002101918
-0.040673829,-132.3036957,24.42000008,0.002132669
-0.040820312,-132.8701935,24.5,0.002158836
-0.04091797,-133.4304352,24.57999992,0.002178005
-0.041064453,-133.9687347,24.65999985,0.002197631
-0.041210937,-134.4425507,24.73999977,0.002216729
-0.041308595,-135.0952148,24.81999969,0.002248083
-0.041455078,-135.9099579,24.89999962,0.002273747
-0.041601561,-136.3334808,24.97999954,0.002297118
-0.041748048,-136.5606232,25.05999947,0.002332943
-0.041894531,-137.0542603,25.13999939,0.002380788
-0.041992189,-137.7384338,25.21999931,0.002419264
-0.042138672,-138.3598022,25.29999924,0.002454698
-0.042333984,-139.0366974,25.37999916,0.002496612
-0.042431642,-139.4252625,25.45999908,0.002521806
-0.042578125,-140.2598724,25.54000092,0.00257271
-0.042724609,-140.825119,25.62000084,0.002614175
-0.042871096,-141.4658051,25.70000076,0.002662491
-0.043017579,-141.8466797,25.78000069,0.002694454
-0.043164062,-142.5554657,25.86000061,0.002742021
-0.043310545,-142.8541412,25.94000053,0.0027805
-0.043408203,-143.6453094,26.02000046,0.002822408
-0.043554686,-144.2346802,26.10000038,0.0028701
-0.043701173,-144.710434,26.18000031,0.002897484
-0.043847656,-145.1446838,26.26000023,0.002937149
-0.043945314,-145.8305054,26.34000015,0.002977372
-0.044091797,-146.5368347,26.42000008,0.003023733
-0.044238281,-147.2205963,26.5,0.003045551
-0.044384764,-147.7163239,26.57999992,0.003076201
-0.044531251,-148.301239,26.65999985,0.003121785
-0.044628905,-149.0739288,26.73999977,0.003157515
-0.044775392,-149.785614,26.81999969,0.003194336
-0.044921875,-150.4938202,26.89999962,0.003234039
-0.045068358,-151.0010376,26.97999954,0.003244578
-0.045166016,-151.5866699,27.05999947,0.003287658
-0.045312499,-152.1283264,27.13999939,0.003325
-0.045410157,-152.9496002,27.21999931,0.003354384
-0.045556641,-153.5780334,27.29999924,0.003382504
-0.045703124,-154.1750641,27.37999916,0.003404601
-0.045849611,-154.7717896,27.45999908,0.003425845
-0.045947265,-155.6222839,27.54000092,0.003478246
-0.046093752,-156.1444702,27.62000084,0.003512057
-0.046191406,-156.6712341,27.70000076,0.003530239
-0.046337889,-157.0998688,27.78000069,0.003549457
-0.046435547,-157.8761139,27.86000061,0.003582855
-0.04658203,-158.4523315,27.94000053,0.003619556
-0.046679688,-159.2088013,28.02000046,0.003648182
-0.046826171,-159.6530762,28.10000038,0.003666901
-0.046923829,-160.2277069,28.18000031,0.003711857
-0.047070313,-160.7988739,28.26000023,0.00374203
-0.04716797,-161.4567871,28.34000015,0.003776374
-0.047314454,-162.2616119,28.42000008,0.00380751
-0.047460937,-162.8602448,28.5,0.003840744
-0.047558595,-163.3027344,28.57999992,0.003871367
-0.047705078,-164.0715027,28.65999985,0.003910005
-0.047851561,-164.4382019,28.73999977,0.003959973
-0.047949219,-164.9351807,28.81999969,0.003999943
-0.048095702,-165.4893799,28.89999962,0.004058423
-0.048242189,-165.9543152,28.97999954,0.004104454
-0.048388672,-166.5004578,29.05999947,0.004141723
-0.048486327,-167.4069061,29.13999939,0.004185775
-0.048632814,-167.961319,29.21999931,0.004231659
-0.048779297,-168.5270386,29.29999924,0.004282241
-0.04892578,-169.1633911,29.37999916,0.004320904
-0.049072267,-169.8871002,29.45999908,0.004365915
-0.04921875,-170.5495758,29.54000092,0.004411344
-0.049316408,-171.1947021,29.62000084,0.004449463
-0.049462891,-171.8656311,29.70000076,0.004497255
-0.049609374,-172.2942657,29.78000069,0.004550175
-0.049755858,-173.0059204,29.86000061,0.004599302
-0.049902344,-173.6235962,29.94000053,0.004656323
-0.050048828,-174.1776123,30.02000046,0.004702565
-0.050195311,-174.5790558,30.10000038,0.004757249
-0.050292969,-175.1433716,30.18000031,0.004810376
-0.050439452,-175.85289,30.26000023,0.004857278
-0.050585939,-176.4376373,30.34000015,0.004901997
-0.050732422,-176.8785095,30.42000008,0.004960299
-0.050830076,-177.3859406,30.5,0.005000434
-0.050976563,-178.1119843,30.57999992,0.00505357
-0.051123046,-178.7542725,30.65999985,0.005104864
-0.05126953,-179.195282,30.73999977,0.005155751
-0.051367188,-179.7600861,30.81999969,0.005209143
-0.051513671,-180.2549744,30.89999962,0.005258454
-0.051660158,-180.7949371,30.97999954,0.005304079
-0.051757812,-181.3352051,31.05999947,0.0053508
-0.051904295,-182.0069427,31.13999939,0.005397058
-0.052050782,-182.3940887,31.21999931,0.005450369
-0.052148436,-182.9596558,31.29999924,0.005506591
-0.052294923,-183.4317932,31.37999916,0.0055614
-0.052441406,-183.9690094,31.45999908,0.005623463
-0.052539064,-184.417572,31.54000092,0.005676951
-0.052685547,-184.7492371,31.62000084,0.005729843
-0.052783202,-185.1350555,31.70000076,0.005786641
-0.052929689,-185.6168518,31.78000069,0.005839418
-0.053076172,-185.9097595,31.86000061,0.00590377
-0.05317383,-186.1962738,31.94000053,0.00597985
-0.053320313,-186.3600616,32.02000046,0.006061819
-0.053417967,-186.4812622,32.09999847,0.006145583
-0.053564454,-186.734375,32.18000031,0.00621987
-0.053710937,-187.01474,32.25999832,0.006298756
-0.053808595,-187.2715912,32.34000015,0.006381977
-0.053955078,-187.288559,32.41999817,0.006445421
-0.054052733,-187.771225,32.5,0.006516366
-0.054199219,-188.0836334,32.58000183,0.006591096
-0.054345703,-188.5841827,32.65999985,0.006656706
-0.054443361,-188.8424072,32.74000168,0.006732657
-0.054589844,-189.1624146,32.81999969,0.006804863
-0.054736327,-189.4474182,32.90000153,0.006881135
-0.054882814,-189.9745636,32.97999954,0.006963267
-0.054980468,-190.3539734,33.06000137,0.007041172
-0.055126951,-190.8723145,33.13999939,0.0071114
-0.055273438,-191.0593414,33.22000122,0.00718192
-0.055419921,-191.1408691,33.29999924,0.007348512
-0.055566405,-190.8753204,33.38000107,0.007484352
-0.055712891,-191.1295319,33.45999908,0.007605625
-0.055859375,-191.4164124,33.54000092,0.007691571
-0.056005858,-191.8765259,33.61999893,0.007766453
-0.056152345,-192.3803406,33.70000076,0.007842957
-0.056298828,-193.2108917,33.77999878,0.007919007
-0.056445311,-193.5926514,33.86000061,0.007990567
-0.056591798,-194.1118774,33.93999863,0.008053965
-0.056738281,-194.7225952,34.02000046,0.008135666
-0.056884764,-195.2675781,34.09999847,0.008197559
-0.056982422,-195.8776855,34.18000031,0.00827516
-0.057128906,-196.2553253,34.25999832,0.008347385
-0.057275389,-196.6540527,34.34000015,0.00842141
-0.057421876,-197.001236,34.41999817,0.008491085
-0.057568359,-197.4142914,34.5,0.008568131
-0.057666017,-198.1182861,34.58000183,0.008635633
-0.0578125,-198.5871582,34.65999985,0.008697745
-0.057958983,-198.9488678,34.74000168,0.00876683
-0.05810547,-199.3383331,34.81999969,0.00882552
-0.058203124,-199.8371277,34.90000153,0.008905849
-0.058349608,-200.2291718,34.97999954,0.008991403
-0.058496094,-200.5188446,35.06000137,0.009050666
-0.058642578,-200.8572693,35.13999939,0.00912938
-0.058740236,-201.1899109,35.22000122,0.00921262
-0.058886719,-201.6264954,35.29999924,0.009279351
-0.059033202,-201.9320374,35.38000107,0.009360653
-0.05913086,-202.2802582,35.45999908,0.009431354
-0.059277343,-202.3920593,35.54000092,0.009504522
-0.059423826,-202.8197632,35.61999893,0.009585555
-0.059521484,-203.1008148,35.70000076,0.009662601
-0.059667967,-203.3330688,35.77999878,0.009741188
-0.059765625,-203.5624847,35.86000061,0.009821003
-0.059912109,-203.8529053,35.93999863,0.009905821
-0.060009766,-204.0878143,36.02000046,0.009971755
-0.06015625,-204.6189575,36.09999847,0.010056642
-0.060302733,-204.8253326,36.18000031,0.010139493
-0.060400391,-205.0470276,36.25999832,0.010208419
-0.060546874,-205.3730316,36.34000015,0.010271801
-0.060644532,-205.7601624,36.41999817,0.010343525
-0.060791015,-206.2524872,36.5,0.010411782
-0.060937498,-206.5257263,36.58000183,0.010484634
-0.061035156,-206.9058838,36.65999985,0.010546955
-0.061181643,-207.3261414,36.74000168,0.010622318
-0.061328123,-207.674408,36.81999969,0.010696331
-0.06147461,-208.2515259,36.90000153,0.010769783
-0.061572267,-208.6221924,36.97999954,0.010846118
-0.061718747,-209.0053101,37.06000137,0.010916763
-0.061865234,-209.3393555,37.13999939,0.010983727
-0.062011721,-209.8419037,37.22000122,0.011060366
-0.0621582,-210.4067688,37.29999924,0.011148734
-0.062304687,-210.6751251,37.38000107,0.011231838
-0.062451174,-210.9901276,37.45999908,0.011307351
-0.062597654,-211.4255371,37.54000092,0.011392826
-0.062695311,-211.7931213,37.61999893,0.011482921
-0.062841798,-212.0537262,37.70000076,0.011568875
-0.062988278,-212.0794525,37.77999878,0.011660934
-0.063134765,-212.0987701,37.86000061,0.011750999
-0.063281252,-212.5279236,37.93999863,0.011840599
-0.063427731,-212.7623291,38.02000046,0.011942416
-0.063525389,-212.8019257,38.09999847,0.012044708
-0.063671876,-212.8014832,38.18000031,0.012151463
-0.063818363,-212.7100677,38.25999832,0.012243096
-0.063964842,-212.8746948,38.34000015,0.012346405
-0.064111329,-212.9895172,38.41999817,0.012452039
-0.064208987,-212.9977417,38.5,0.012552105
-0.064355467,-212.9262848,38.58000183,0.012661263
-0.064501954,-212.7246094,38.65999985,0.012770467
-0.064599612,-212.3298187,38.74000168,0.012896801
-0.064746091,-212.0394592,38.81999969,0.013032639
-0.064892578,-211.4947205,38.90000153,0.013186044
-0.065039065,-210.9471588,38.97999954,0.013297511
-0.065136715,-210.7611084,39.06000137,0.01342901
-0.065283202,-210.523468,39.13999939,0.013557505
-0.06538086,-209.9774475,39.22000122,0.01368639
-0.065527347,-209.4253082,39.29999924,0.013819352
-0.065673827,-208.8256073,39.38000107,0.013952923
-0.065771485,-208.5131378,39.45999908,0.014074012
-0.065917971,-208.470047,39.54000092,0.014194142
-0.066064451,-208.15979,39.61999893,0.014328134
-0.066162109,-207.939682,39.70000076,0.014444702
-0.066308596,-207.5969391,39.77999878,0.014548506
-0.066406254,-207.3812256,39.86000061,0.014682218
-0.066552733,-207.3974152,39.93999863,0.014785764
-0.06669922,-207.0838623,40.02000046,0.01490788
-0.066796878,-206.7593689,40.09999847,0.015024564
-0.066943358,-206.4259033,40.18000031,0.015152876
-0.067041015,-205.9855652,40.25999832,0.015282176
-0.067187502,-205.4972839,40.34000015,0.01541958
-0.067285153,-205.055603,40.41999817,0.01556574
-0.06743164,-204.367218,40.5,0.01569732
-0.067529298,-204.1470032,40.58000183,0.015821681
-0.067675785,-203.8847351,40.65999985,0.015962929
-0.067822264,-203.6065369,40.74000168,0.01608584
-0.067968751,-203.0616913,40.81999969,0.016230257
-0.068066409,-202.5901489,40.90000153,0.016376427
-0.068212888,-202.2796326,40.97999954,0.016507813
-0.068359375,-202.234848,41.06000137,0.016637479
-0.068505862,-202.3130646,41.13999939,0.016750135
-0.068652342,-202.2732544,41.22000122,0.016860153
-0.068798829,-202.2343903,41.29999924,0.016964741
-0.068896486,-202.4023438,41.38000107,0.01707501
-0.069042966,-202.6983795,41.45999908,0.017193137
-0.069189453,-202.8070679,41.54000092,0.017312574
-0.06933594,-202.789917,41.61999893,0.017413318
-0.069482419,-202.8695526,41.70000076,0.017518247
-0.069628906,-202.9606171,41.77999878,0.01762731
-0.069775393,-203.1857605,41.86000061,0.017743907
-0.069921873,-203.3508911,41.93999863,0.017846898
-0.070068359,-203.5158234,42.02000046,0.017955785
-0.070214846,-203.577179,42.09999847,0.018055742
-0.070312497,-203.9739532,42.18000031,0.018157081
-0.070458984,-204.1381073,42.25999832,0.018257439
-0.070605471,-204.274231,42.34000015,0.018363455
-0.07075195,-204.4403229,42.41999817,0.018460069
-0.070898437,-204.5346375,42.5,0.018568622
-0.070996095,-204.7830505,42.58000183,0.018660186
-0.071142575,-205.1259766,42.65999985,0.018777304
-0.071289061,-205.1081543,42.74000168,0.018882914
-0.071435548,-205.0199738,42.81999969,0.01897766
-0.071533206,-205.11763,42.90000153,0.019073885
-0.071679686,-205.3713837,42.97999954,0.01918769
-0.071826173,-205.5266266,43.06000137,0.019281957
-0.071972659,-205.4678192,43.13999939,0.019390453
-0.07207031,-205.4707184,43.22000122,0.019498233
-0.072216797,-205.4630432,43.29999924,0.019608255
-0.072363284,-205.4619904,43.38000107,0.01972579
-0.072460934,-205.4828339,43.45999908,0.0198405
-0.072607421,-205.3888245,43.54000092,0.019953019
-0.072753908,-204.6639557,43.61999893,0.020080688
-0.072851566,-204.2733307,43.70000076,0.020234729
-0.072998046,-203.3496246,43.77999878,0.020411306
-0.073095704,-202.5242615,43.86000061,0.020582147
-0.07324219,-201.1125488,43.93999863,0.020778789
-0.073339841,-199.8733063,44.02000046,0.020975393
-0.073486328,-198.6181946,44.09999847,0.021178301
-0.073632815,-197.0061646,44.18000031,0.021426289
-0.073730465,-195.0249329,44.25999832,0.021672235
-0.073876952,-193.0889435,44.34000015,0.021936296
-0.07397461,-191.0392761,44.41999817,0.022183161
-0.074121097,-189.3951263,44.5,0.022433216
-0.074267577,-188.0873108,44.58000183,0.022659351
-0.074365234,-187.2176208,44.65999985,0.022862307
-0.074511721,-186.362793,44.74000168,0.023032544
-0.074658201,-185.5541687,44.81999969,0.023206836
-0.074755859,-185.2983551,44.90000153,0.02336999
-0.074902346,-185.0993042,44.97999954,0.023515129
-0.075048825,-184.8408813,45.06000137,0.023655746
-0.075195312,-184.7274323,45.13999939,0.023791081
-0.075341799,-184.6811981,45.22000122,0.023918616
-0.075488279,-184.5483398,45.29999924,0.024081199
-0.075585936,-184.2164154,45.38000107,0.024228651
-0.075732423,-183.701004,45.45999908,0.024407787
-0.075878903,-183.1652985,45.54000092,0.024573346
-0.07602539,-182.9372101,45.61999893,0.024721829
-0.076171877,-182.931488,45.70000076,0.024876923
-0.076318356,-182.8029633,45.77999878,0.025027637
-0.076464843,-182.8648834,45.86000061,0.025170535
-0.07661133,-181.8824463,45.93999863,0.025355779
-0.076757809,-181.4281616,46.02000046,0.025553225
-0.076904296,-180.8640594,46.09999847,0.025734626
-0.077001954,-180.6000214,46.18000031,0.025899823
-0.077148441,-179.9435272,46.25999832,0.0260693
-0.077294921,-179.5011749,46.34000015,0.026225009
-0.077441407,-179.249649,46.41999817,0.02637638
-0.077539065,-179.2229462,46.5,0.026527088
-0.077685545,-178.9289398,46.58000183,0.026671281
-0.077832032,-178.8518982,46.65999985,0.026812164
-0.077978519,-178.5683594,46.74000168,0.026948494
-0.078076169,-178.6336823,46.81999969,0.027094879
-0.078222656,-178.6452942,46.90000153,0.027224867
-0.078369143,-178.6533508,46.97999954,0.027364118
-0.078515623,-178.2507172,47.06000137,0.027509544
-0.078662109,-177.9260559,47.13999939,0.027664668
-0.078759767,-177.4272614,47.22000122,0.027840337
-0.078906247,-176.8757172,47.29999924,0.028019382
-0.079003905,-176.3832397,47.38000107,0.028174654
-0.079150392,-175.9483032,47.45999908,0.028337532
-0.07924805,-175.5007324,47.54000092,0.028498534
-0.079394529,-175.2733917,47.61999893,0.028648717
-0.079541016,-174.9777374,47.70000076,0.028808327
-0.079638674,-174.5167847,47.77999878,0.028956088
-0.079785154,-174.221817,47.86000061,0.029099494
-0.079882811,-173.8525391,47.93999863,0.029258801
-0.080029298,-173.6321106,48.02000046,0.029415931
-0.080175778,-173.0246582,48.09999847,0.029569877
-0.080273436,-172.3775177,48.18000031,0.029772928
-0.080419923,-171.483902,48.25999832,0.029965136
-0.08051758,-170.9368286,48.34000015,0.030140296
-0.08066406,-170.5332794,48.41999817,0.030311605
-0.080761718,-169.9759674,48.5,0.030491286
-0.080908205,-169.3618927,48.58000183,0.03065449
-0.081054684,-168.9063568,48.65999985,0.030832449
-0.081152342,-168.2932281,48.74000168,0.031026568
-0.081298829,-166.2816925,48.81999969,0.031355907
-0.081445316,-164.519043,48.90000153,0.031634223
-0.081542967,-163.2505188,48.97999954,0.031894262
-0.081689454,-162.0938416,49.06000137,0.032139385
-0.08183594,-161.0493011,49.13999939,0.032377709
-0.08198242,-160.0175476,49.22000122,0.032626889
-0.082128907,-158.8904419,49.29999924,0.032882272
-0.082226565,-157.4932556,49.38000107,0.033145392
-0.082373044,-156.2066345,49.45999908,0.033422151
-0.082519531,-154.9755096,49.54000092,0.033715962
-0.082666018,-153.6976013,49.61999893,0.034011184
-0.082812498,-152.2787323,49.70000076,0.034277524
-0.082958984,-151.2348022,49.77999878,0.034528388
-0.083105471,-150.5767365,49.86000061,0.034744684
-0.083251951,-150.0905609,49.93999863,0.034943689
-0.083349609,-149.639267,50.02000046,0.035127425
-0.083496096,-149.1404572,50.09999847,0.035313984
-0.083642575,-148.5189362,50.18000031,0.035496869
-0.083789062,-148.1265717,50.25999832,0.035687201
-0.083935549,-147.8909607,50.34000015,0.035870358
-0.0840332,-147.5064087,50.41999817,0.036041558
-0.084179686,-147.2584839,50.5,0.036206315
-0.084326173,-146.9674225,50.58000183,0.036360652
-0.084472653,-146.794281,50.65999985,0.03651499
-0.084570311,-146.778244,50.74000168,0.03668548
-0.084716798,-146.4388733,50.81999969,0.036845482
-0.084863284,-146.0478821,50.90000153,0.036996662
-0.085009764,-145.6883698,50.97999954,0.037164104
-0.085107422,-145.6229095,51.06000137,0.037337086
-0.085253909,-145.4370575,51.13999939,0.037503887
-0.085400388,-145.0183716,51.22000122,0.037649377
-0.085498046,-144.8842316,51.29999924,0.037790636
-0.085644533,-144.8042145,51.38000107,0.037912901
-0.085791013,-144.8666534,51.45999908,0.038069134
-0.085888671,-144.7252197,51.54000092,0.038227015
-0.086035157,-144.3163757,51.61999893,0.038379247
-0.086132815,-143.8078613,51.70000076,0.038545571
-0.086279295,-143.7030487,51.77999878,0.038712329
-0.086425782,-143.4028473,51.86000061,0.038858372
-0.08652344,-143.3253937,51.93999863,0.039034039
-0.086669919,-142.8687134,52.02000046,0.03918865
-0.086767577,-142.4500732,52.09999847,0.039336246
-0.086914064,-142.1671448,52.18000031,0.039504324
-0.087011722,-142.1083832,52.25999832,0.03966095
-0.087158201,-141.8834839,52.34000015,0.039806593
-0.087304688,-141.6608582,52.41999817,0.039958588
-0.087451175,-141.4264984,52.5,0.040102299
-0.087548826,-141.0415344,52.58000183,0.040294442
-0.087695313,-107.5081787,52.65999985,0.044911314
-0.0878418,-103.1658096,52.74000168,0.045885183
-0.08793945,-100.4461288,52.81999969,0.046569094
-0.088085937,-98.7119751,52.90000153,0.047124398
-0.088232424,-97.40603638,52.97999954,0.047566959
-0.088330075,-96.19054413,53.06000137,0.047989164
-0.088476561,-95.08312225,53.13999939,0.04838836
-0.088623048,-93.97363281,53.22000122,0.048779872
-0.088769528,-92.95702362,53.29999924,0.049172955
-0.088916015,-92.17308044,53.38000107,0.049545029
-0.089062502,-91.24727631,53.45999908,0.049910399
-0.089208981,-90.25186157,53.54000092,0.050316739
-0.089355468,-89.11928558,53.61999893,0.050675604
-0.089501955,-88.31926727,53.70000076,0.051035735
-0.089648434,-87.47234344,53.77999878,0.051417028
-0.089794921,-86.6283493,53.86000061,0.051779596
-0.089892579,-85.78957367,53.93999863,0.052128209
-0.090039066,-84.82707977,54.02000046,0.052468975
-0.090185546,-84.21700287,54.09999847,0.052811469
-0.090332032,-83.40364075,54.18000031,0.053174921
-0.090478512,-82.42635345,54.25999832,0.053569231
-0.090624999,-81.50933075,54.34000015,0.053907312
-0.090771486,-80.83998871,54.41999817,0.054220851
-0.090869144,-80.25054932,54.5,0.054531938
-0.091015623,-79.75370789,54.58000183,0.054860553
-0.09116211,-78.74512482,54.65999985,0.055219996
-0.091308597,-77.41618347,54.74000168,0.055645633
-0.091406248,-76.09471893,54.81999969,0.056096218
-0.091552734,-75.12921906,54.90000153,0.056526791
-0.091699221,-74.07954407,54.97999954,0.056945813
-0.091796872,-72.71930695,55.06000137,0.057382986
-0.091943359,-71.49869537,55.13999939,0.05779857
-0.092089846,-70.47771454,55.22000122,0.058174584
-0.092187503,-69.77563477,55.29999924,0.058530401
-0.092333983,-69.02588654,55.38000107,0.05888435
-0.09248047,-68.13382721,55.45999908,0.059221547
-0.092578128,-67.20708466,55.54000092,0.059568792
-0.092724607,-66.58689117,55.61999893,0.05991149
-0.092871094,-65.84574127,55.70000076,0.060269482
-0.092968752,-64.94617462,55.77999878,0.0606414
-0.093115232,-63.94962692,55.86000061,0.061045488
-0.09321289,-62.93690491,55.93999863,0.061450672
-0.093359376,-62.14797974,56.02000046,0.061847662
-0.093505856,-61.39929199,56.09999847,0.062249892
-0.093603514,-60.54027939,56.18000031,0.062630104
-0.093750001,-59.4402771,56.25999832,0.06306154
-0.093847659,-58.5627594,56.34000015,0.063470143
-0.093994138,-57.85784912,56.41999817,0.063873107
-0.094091796,-57.11042786,56.5,0.064277549
-0.094238283,-56.39651489,56.58000183,0.064665001
-0.094384763,-55.49927902,56.65999985,0.065046304
-0.094482421,-54.80594635,56.74000168,0.065435022
-0.094628907,-54.05410004,56.81999969,0.065839362
-0.094775394,-53.4310379,56.90000153,0.066230423
-0.094921874,-52.51298141,56.97999954,0.066617358
-0.095019532,-51.93328094,57.06000137,0.067001092
-0.095166019,-51.31924057,57.13999939,0.067341571
-0.095312498,-50.86222839,57.22000122,0.067708192
-0.095458985,-50.35630417,57.29999924,0.068075111
-0.095605472,-49.74614716,57.38000107,0.068421024
-0.095751951,-48.96956635,57.45999908,0.06875502
-0.095898438,-48.69018173,57.54000092,0.069110363
-0.096044925,-48.3167572,57.61999893,0.069434449
-0.096191405,-47.87066269,57.70000076,0.069753893
-0.096289063,-47.30322266,57.77999878,0.070066453
-0.096435549,-46.94603348,57.86000061,0.070371018
-0.096582029,-46.54154205,57.93999863,0.070669594
-0.096728516,-46.28210068,58.02000046,0.070979382
-0.096875003,-45.78185654,58.09999847,0.071290655
-0.097021482,-45.27674103,58.18000031,0.071604649
-0.09711914,-44.75109863,58.25999832,0.071917209
-0.097265627,-44.38796616,58.34000015,0.072235634
-0.097412107,-44.14112854,58.41999817,0.072540432
-0.097558594,-43.6806488,58.5,0.072840368
-0.097656251,-43.13394928,58.58000183,0.073124516
-0.097802731,-42.82409286,58.65999985,0.073425246
-0.097949218,-42.49869156,58.74000168,0.0737386
-0.098095705,-42.17416382,58.81999969,0.074043019
-0.098193363,-41.76567841,58.90000153,0.074336305
-0.098339842,-41.24815369,58.97999954,0.074630894
-0.098486329,-40.97600555,59.06000137,0.074920339
-0.098632816,-40.63859558,59.13999939,0.07521885
-0.098730467,-40.43917847,59.22000122,0.075515847
-0.098876953,-39.92511368,59.29999924,0.075789896
-0.09902344,-39.56780624,59.38000107,0.076078206
-0.099121091,-39.24497986,59.45999908,0.07636287
-0.099267578,-39.08621979,59.54000092,0.076631848
-0.099365236,-38.83255005,59.61999893,0.076903212
-0.099511715,-38.47805023,59.70000076,0.077140496
-0.099609373,-38.02568436,59.77999878,0.077384168
-0.09975586,-37.91588974,59.86000061,0.077658435
-0.099902347,-37.71326828,59.93999863,0.077916739
-0.099999997,-37.43505478,60.02000046,0.078171062
-0.100146484,-37.02283859,60.09999847,0.078398589
-0.100244142,-36.84438324,60.18000031,0.078633617
-0.100390622,-36.60655975,60.25999832,0.078877783
-0.100537109,-36.51985931,60.34000015,0.079108897
-0.100634767,-36.3090744,60.41999817,0.079333717
-0.100781253,-36.06553268,60.5,0.079567486
-0.100878904,-35.79209518,60.58000183,0.079802237
-0.101025391,-35.60339737,60.65999985,0.080055455
-0.101171878,-35.47999954,60.74000168,0.080275211
-0.101269528,-35.18464279,60.81999969,0.080532183
-0.101416015,-34.94023132,60.90000153,0.080774233
-0.101562502,-34.71808243,60.97999954,0.081004138
-0.101708982,-34.56257629,61.06000137,0.081267033
-0.101855469,-34.31994247,61.13999939,0.081535196
-0.101953126,-33.95750809,61.22000122,0.081800426
-0.102099606,-33.62691498,61.29999924,0.082079379
-0.102246093,-33.45751953,61.38000107,0.08234955
-0.10239258,-33.28347015,61.45999908,0.082639133
-0.102539059,-32.98176575,61.54000092,0.082917715
-0.102685546,-32.68505478,61.61999893,0.083188301
-0.102832033,-32.47602844,61.70000076,0.083456194
-0.102978513,-32.18182755,61.77999878,0.08373204
-0.103124999,-32.07913589,61.86000061,0.084017745
-0.103271486,-31.75551796,61.93999863,0.084296502
-0.103417966,-31.42394829,62.02000046,0.084569088
-0.103515624,-31.09796715,62.09999847,0.084837062
-0.103662111,-30.98147202,62.18000031,0.085111838
-0.10380859,-30.73586655,62.25999832,0.085398446
-0.103955077,-30.39538956,62.34000015,0.085669977
-0.104101564,-30.12916756,62.41999817,0.085916508
-0.104199222,-29.92272377,62.5,0.086179854
-0.104345701,-29.78051376,62.58000183,0.086450302
-0.104492188,-29.67719269,62.65999985,0.086715139
-0.104638675,-29.15380096,62.74000168,0.087032575
-0.104785155,-28.76226234,62.81999969,0.087307941
-0.104882813,-28.54005814,62.90000153,0.087592707
-0.105029299,-28.41412544,62.97999954,0.087886045
-0.105175779,-28.10982704,63.06000137,0.088145702
-0.105322266,-27.91699409,63.13999939,0.088398709
-0.105419924,-27.5008049,63.22000122,0.088656117
-0.105566403,-27.42666626,63.29999924,0.088908215
-0.105664061,-27.30727959,63.38000107,0.089145462
-0.105810548,-27.18251038,63.45999908,0.089388966
-0.105957028,-26.92414856,63.54000092,0.089619214
-0.106054686,-26.6586628,63.61999893,0.089837362
-0.106201172,-26.64458847,63.70000076,0.090082518
-0.106347659,-26.56339836,63.77999878,0.090303707
-0.10644531,-26.39912605,63.86000061,0.09052582
-0.106591797,-26.15412521,63.93999863,0.090746842
-0.106689455,-25.98228455,64.01999664,0.090961556
-0.106835934,-25.83666229,64.09999847,0.091208502
-0.106982421,-25.82878494,64.18000031,0.091431211
-0.107080079,-25.56972694,64.26000214,0.091669404
-0.107226566,-25.3382206,64.33999634,0.091893999
-0.107324217,-25.10531425,64.41999817,0.09214173
-0.107470703,-25.01699448,64.5,0.092374547
-0.10761719,-24.9484787,64.58000183,0.092611364
-0.107714841,-24.69189835,64.66000366,0.092852919
-0.107861328,-24.45409966,64.73999786,0.093079245
-0.108007815,-22.36227798,64.81999969,0.09431252
-0.108105465,-22.09601021,64.90000153,0.094606272
-0.108251952,-21.96369171,64.98000336,0.094882642
-0.108398439,-21.76973534,65.05999756,0.095126787
-0.108544918,-21.5176487,65.13999939,0.095352771
-0.108691405,-21.46609306,65.22000122,0.095579169
-0.108837892,-21.52415848,65.30000305,0.095814794
-0.10893555,-21.40775681,65.37999725,0.096041047
-0.10908203,-21.29615974,65.45999908,0.096264739
-0.109228517,-21.01499176,65.54000092,0.096472722
-0.109375003,-21.06536865,65.62000275,0.096702184
-0.109521483,-21.08161926,65.69999695,0.096932235
-0.10966797,-20.20418358,65.77999878,0.097393749
-0.109814457,-19.04106903,65.86000061,0.098059769
-0.109960936,-18.84744644,65.94000244,0.098319782
-0.110058594,-18.79467964,66.01999664,0.098579905
-0.110205081,-18.19726944,66.09999847,0.099021549
-0.110351561,-17.68101883,66.18000031,0.099462959
-0.110498047,-17.39923286,66.26000214,0.099712743
-0.110644534,-16.73464012,66.33999634,0.100167315
-0.110742185,-16.64287376,66.41999817,0.10044995
-0.110888672,-16.35455513,66.5,0.10077576
-0.111035159,-15.98756695,66.58000183,0.101112659
-0.111181638,-15.73993397,66.66000366,0.101351259
-0.111279296,-15.30490017,66.73999786,0.10173762
-0.111425783,-15.44525051,66.81999969,0.101990867
-0.111572263,-14.99449635,66.90000153,0.102343263
-0.11166992,-14.81644058,66.98000336,0.102607133
-0.111816407,-14.29252529,67.05999756,0.102944534
-0.111962894,-14.26524448,67.13999939,0.103210099
-0.112060545,-14.09161472,67.22000122,0.10352565
-0.112207032,-13.91921139,67.30000305,0.103787177
-0.11230469,-13.52479362,67.37999725,0.104108141
-0.112451169,-13.18871784,67.45999908,0.104417377
-0.112597656,-12.96181011,67.54000092,0.104721483
-0.112695314,-12.81164646,67.62000275,0.105095096
-0.112841793,-12.49020195,67.69999695,0.105399697
-0.11298828,-12.21639824,67.77999878,0.105706909
-0.113085938,-11.93826199,67.86000061,0.105995394
-0.113232425,-11.83138561,67.94000244,0.106291751
-0.113330076,-11.6958437,68.01999664,0.106577099
-0.113476563,-11.44211006,68.09999847,0.106847496
-0.11357422,-11.19439125,68.18000031,0.107106462
-0.1137207,-10.97096157,68.26000214,0.107366104
-0.113818358,-10.82055759,68.33999634,0.107621672
-0.113964845,-10.82488441,68.41999817,0.107881358
-0.114111332,-10.64095116,68.5,0.108110959
-0.114208982,-10.37270069,68.58000183,0.108349057
-0.114355469,-10.3038187,68.66000366,0.108592358
-0.114453127,-7.853268147,68.73999786,0.110232657
-0.114599607,-7.466980457,68.81999969,0.110614958
-0.114746093,-7.145348072,68.90000153,0.110944478
-0.11489258,-6.727189064,68.98000336,0.111262605
-0.114990231,-6.589013577,69.05999756,0.111575479
-0.115136718,-6.49288559,69.13999939,0.11188518
-0.115283205,-6.237016201,69.22000122,0.112196125
-0.115429684,-6.039894581,69.30000305,0.112478905
-0.115576171,-5.694126129,69.37999725,0.112753703
-0.115673829,-5.618224621,69.45999908,0.113047172
-0.115820316,-5.559698105,69.54000092,0.113321075
-0.115966795,-5.346739769,69.62000275,0.113595779
-0.116113282,-5.17139864,69.69999695,0.113871538
-0.116259769,-4.944743156,69.77999878,0.114149007
-0.116406249,-4.811170101,69.86000061,0.11442673
-0.116552736,-4.83763504,69.94000244,0.114707553
-0.116699215,-4.508039474,70.01999664,0.114987444
-0.116845702,-4.295385838,70.09999847,0.115255709
-0.116992189,-4.047397137,70.18000031,0.115521347
-0.117089847,-4.125938892,70.26000214,0.115785799
-0.117236326,-4.022007942,70.33999634,0.116057017
-0.117382813,-3.90786767,70.41999817,0.116295269
-0.1175293,-3.686109304,70.5,0.11654316
-0.117626951,-3.552399397,70.58000183,0.116805451
-0.117773438,-3.50774312,70.66000366,0.117058211
-0.117919924,-3.451847076,70.73999786,0.117300086
-0.118066404,-3.263876438,70.81999969,0.117541531
-0.118212891,-3.035258055,70.90000153,0.117789641
-0.118310549,-2.979391336,70.98000336,0.118043805
-0.118457028,-2.965597868,71.05999756,0.118289587
-0.118554686,-2.848584175,71.13999939,0.118516429
-0.118701173,-2.706403255,71.22000122,0.118761098
-0.118847653,-2.62771225,71.30000305,0.119002325
-0.118994139,-2.542092323,71.37999725,0.11924994
-0.119091797,-2.531899214,71.45999908,0.119494922
-0.119238284,-2.374883175,71.54000092,0.11972362
-0.119335935,-2.227823734,71.62000275,0.119946519
-0.119482422,-2.129319191,71.69999695,0.120184588
-0.119628909,-2.129957676,71.77999878,0.120401317
-0.119726559,-2.166212082,71.86000061,0.120629586
-0.119873046,-1.960929751,71.94000244,0.120864046
-0.120019533,-1.836281776,72.01999664,0.121067998
-0.120117191,-1.709705591,72.09999847,0.121302808
-0.12026367,-1.710212231,72.18000031,0.12153342
-0.120361328,-1.704777122,72.26000214,0.1217506
-0.120507815,-1.527541161,72.33999634,0.121974146
-0.120654295,-1.346470237,72.41999817,0.122202851
-0.120751953,-1.282215118,72.5,0.122422993
-0.120898439,-1.329052687,72.58000183,0.122648678
-0.121044919,-1.329217196,72.66000366,0.122876198
-0.121142577,-1.034626365,72.73999786,0.123205682
-0.121289064,-0.789788187,72.81999969,0.123479229
-0.121435543,-0.781255782,72.90000153,0.123737947
-0.121533201,-0.733375788,72.98000336,0.124002137
-0.121679688,-0.645474017,73.05999756,0.124265498
-0.121826175,-0.500997007,73.13999939,0.124522325
-0.121972655,-0.418472648,73.22000122,0.124792685
-0.122119134,-0.338413984,73.30000305,0.125054808
-0.122265628,-0.385555416,73.37999725,0.12533016
-0.122412108,-0.223202437,73.45999908,0.125632883
-0.122558587,-0.013303468,73.54000092,0.125935447
-0.122705082,0.203934625,73.62000275,0.126256826
-0.122851561,0.210688442,73.69999695,0.126566621
-0.122998041,0.196623877,73.77999878,0.126911109
-0.123095699,0.434628844,73.86000061,0.127269377
-0.123242193,0.646673858,73.94000244,0.127666674
-0.123388672,0.676712751,74.01999664,0.128170737
-0.123535152,0.705315173,74.09999847,0.128941538
-0.123681646,0.668891668,74.18000031,0.130144457
-0.123828126,0.738769829,74.26000214,0.13252499
-0.123974605,0.854850769,74.33999634,5.287639797
-0.124121099,0.846551001,74.41999817,5.484893452
-0.124218757,0.792010307,74.5,5.483986344
-0.124365237,0.60232985,74.58000183,5.484106485
-0.124511716,0.746915162,74.66000366,5.481151398
-0.124609374,0.874449134,74.73999786,5.484207999
-0.124755854,0.827233613,74.81999969,5.484209396
-0.124902348,0.686072111,74.90000153,5.484212656
-0.125000006,0.708798409,74.98000336,5.484213121
-0.125146486,0.620360017,75.05999756,5.484214984
-0.125292965,0.877513468,75.13999939,5.484216381
-0.125439459,0.775878549,75.22000122,5.484218244
-0.125537103,0.76344198,75.30000305,5.484217778
-0.125683597,0.674261272,75.37999725,5.484219175
-0.125830076,0.83957082,75.45999908,5.484222434
-0.125927734,0.815720022,75.54000092,5.484223831
-0.126074214,0.760805845,75.62000275,5.484222434
-0.126171872,0.672156811,75.69999695,5.484221503
-0.126318366,0.801182508,75.77999878,5.4842229
-0.126416009,0.836266994,75.86000061,5.484226625
-0.126562503,0.861376524,75.94000244,5.484223366
-0.126708983,0.762987256,76.01999664,5.484225228
-0.126806641,0.696554542,76.09999847,5.484225228
-0.12695312,0.732726693,76.18000031,5.48422616
-0.127050778,0.80437088,76.26000214,5.484225694
-0.127197272,0.838574529,76.33999634,5.48422616
-0.127343752,0.763799608,76.41999817,5.484225228
-0.12744141,0.718863547,76.5,5.484225228
-0.127587889,0.812502086,76.58000183,5.484225694
-0.127734369,0.861480236,76.66000366,5.484224297
-0.127832027,0.803122997,76.73999786,5.484226625
-0.127978521,0.745038271,76.81999969,5.484225694
-0.128125001,0.73083353,76.90000153,5.484227091
-0.128222659,0.68206203,76.98000336,5.484227557
-0.128369138,0.78215009,77.05999756,5.48422616
-0.128515632,0.735354483,77.13999939,5.484224763
-0.128662112,0.739993095,77.22000122,5.484224297
-0.128808591,0.669637501,77.30000305,5.484227091
-0.128955071,0.803582191,77.37999725,5.484223831
-0.129101565,0.887625039,77.45999908,5.484224763
-0.129248045,0.694722772,77.54000092,5.484225694
-0.129345703,0.689036608,77.62000275,5.484227091
-0.129492182,0.695402861,77.69999695,5.484225694
-0.129638676,0.781516969,77.77999878,5.484227091
-0.129785156,0.798000515,77.86000061,5.484227557
-0.129931635,0.78103435,77.94000244,5.484225228
-0.13007813,0.678956628,78.01999664,5.484228022
-0.130224609,0.747526526,78.09999847,5.48422616
-0.130322267,0.752084553,78.18000031,5.484225228
-0.130468747,0.769589841,78.26000214,5.484224763
-0.130615241,0.792568207,78.33999634,5.484223831
-0.13076172,0.763519049,78.41999817,5.484225694
-0.13076172,0.727890611,78.44000244,5.484225228