File: Data/Thesis_Samples_Data/Notched_Solid_4/Notched_Solid_4.csv
"File Path: C:\Users\Lab User\Desktop\Will\Thesis Tests\Test Run 2 04-8-22 16 00 04 PM\DAQ- Crosshead, … - (Timed).csv   ",,,
Test: MTS EM Tension (Extensometer) - Will 1,,,
Test Run: Test Run 2,,,
Date: 4/8/2022 3:55:41 PM,,,
,,,
,,,
Crosshead ,Load ,Time ,Extensometer
mm,N,sec,mm
0,-2.860416651,0.02,-8.37E-06
-9.77E-05,-2.820498943,0.200000003,4.93E-06
-0.000292969,-3.097290277,0.379999995,-1.21E-07
-0.000634766,-3.827520847,0.560000002,1.19E-05
-0.000976563,-4.501769543,0.74000001,2.33E-05
-0.001367187,-5.201424122,0.920000017,1.61E-05
-0.001708984,-5.921417713,1.100000024,2.69E-05
-0.002001953,-6.679661274,1.279999971,5.22E-05
-0.00234375,-7.59348011,1.460000038,6.59E-05
-0.002685547,-8.128322601,1.639999986,7.51E-05
-0.002978516,-8.8100214,1.820000052,8.21E-05
-0.003320313,-9.482715607,2,9.45E-05
-0.003613281,-10.53334427,2.180000067,9.87E-05
-0.00390625,-11.11284065,2.359999895,0.000117859
-0.004199219,-11.68588924,2.539999962,0.000119786
-0.004492188,-12.29921818,2.720000029,0.000128369
-0.004785156,-13.10035896,2.900000095,0.000138732
-0.005078125,-13.89928913,3.079999924,0.000161057
-0.005371094,-14.453475,3.25999999,0.000161627
-0.005664062,-14.95617008,3.440000057,0.000169235
-0.005957031,-15.80068684,3.619999886,0.000169715
-0.00625,-16.4822216,3.799999952,0.000184229
-0.006542969,-17.23880959,3.980000019,0.000194339
-0.006884766,-17.80857086,4.159999847,0.000192672
-0.007177734,-18.52070427,4.340000153,0.000211565
-0.007470703,-19.43315315,4.519999981,0.000221377
-0.0078125,-20.2197876,4.699999809,0.000231266
-0.008154297,-20.97372246,4.880000114,0.000228886
-0.008447266,-21.55815315,5.059999943,0.000251021
-0.008740234,-22.50603485,5.239999771,0.000258741
-0.009082031,-23.45362473,5.420000076,0.000282237
-0.009375,-24.04780579,5.599999905,0.000293706
-0.009667969,-24.79531288,5.78000021,0.000290016
-0.009960938,-25.56702232,5.960000038,0.000304957
-0.010253906,-26.36928368,6.139999866,0.000306108
-0.010546875,-27.22595024,6.320000172,0.000318534
-0.010839844,-27.88031197,6.5,0.000320554
-0.011132813,-28.58938217,6.679999828,0.00032395
-0.011425781,-29.39613724,6.860000134,0.00033029
-0.01171875,-30.20929146,7.039999962,0.000340033
-0.01196289,-30.89928436,7.21999979,0.000336659
-0.012255859,-31.56532097,7.400000095,0.000362911
-0.012548828,-32.41382599,7.579999924,0.000351068
-0.012841797,-33.27713776,7.760000229,0.000361345
-0.013134766,-34.20184326,7.940000057,0.000373543
-0.013427734,-34.82064056,8.119999886,0.000377509
-0.013720703,-35.57048035,8.300000191,0.000384844
-0.0140625,-36.64326477,8.479999542,0.000387084
-0.014404297,-37.5418663,8.659999847,0.000398848
-0.014697265,-38.38279724,8.840000153,0.000397215
-0.015039062,-39.10810471,9.020000458,0.000403357
-0.015332031,-40.09326172,9.199999809,0.00041527
-0.015673828,-40.90857315,9.380000114,0.000421962
-0.015966796,-41.67775345,9.56000042,0.000421298
-0.016259766,-42.40755844,9.739999771,0.000438731
-0.016601563,-43.13162613,9.920000076,0.000446871
-0.016894532,-44.0797081,10.10000038,0.000451848
-0.0171875,-44.87285233,10.27999973,0.000455897
-0.017480468,-45.56249237,10.46000004,0.00046436
-0.017773438,-46.14201736,10.64000034,0.000469181
-0.018066406,-46.94147873,10.81999969,0.000478193
-0.018310548,-47.85528946,11,0.00048472
-0.018603516,-48.49339294,11.18000031,0.000503195
-0.018896484,-49.16584396,11.35999966,0.000501436
-0.019189452,-49.81663895,11.53999996,0.000517774
-0.019482422,-50.61536789,11.72000027,0.000516736
-0.019775391,-51.50138474,11.89999962,0.000523587
-0.020068359,-52.19231033,12.07999992,0.000528121
-0.020361329,-52.89093781,12.26000023,0.000538764
-0.020703124,-53.75775146,12.43999958,0.000550895
-0.020996094,-54.83811188,12.61999989,0.000564091
-0.02133789,-55.63577652,12.80000019,0.000568603
-0.021679687,-56.36949539,12.97999954,0.00058222
-0.021972657,-57.33141327,13.15999985,0.000581816
-0.022265625,-58.19612885,13.34000015,0.000595192
-0.022607423,-58.97265244,13.52000046,0.000601104
-0.022900391,-59.74620819,13.69999981,0.00061179
-0.023193359,-60.59571457,13.88000011,0.000612856
-0.023486327,-61.40449524,14.06000042,0.000620998
-0.023779297,-62.30687714,14.23999977,0.000639054
-0.024072266,-63.0655632,14.42000008,0.00065303
-0.024365234,-63.83829117,14.60000038,0.000656176
-0.024658204,-64.65399933,14.77999973,0.000654855
-0.024951172,-65.51773834,14.96000004,0.000665356
-0.025195313,-66.33059692,15.14000034,0.000681126
-0.025488282,-67.03674316,15.31999969,0.000687231
-0.02578125,-67.84485626,15.5,0.000702549
-0.026074218,-68.80162048,15.68000031,0.000706266
-0.026367188,-69.82495117,15.85999966,0.000715962
-0.026660156,-70.5539093,16.04000092,0.000716606
-0.026953125,-71.5350647,16.21999931,0.00073017
-0.027246093,-72.4105835,16.39999962,0.000740483
-0.02758789,-73.52426147,16.57999992,0.000762936
-0.027929687,-74.49564362,16.76000023,0.000765549
-0.028222656,-75.50257111,16.94000053,0.000778932
-0.028515626,-76.43157959,17.12000084,0.00079414
-0.028857421,-77.41734314,17.29999924,0.000806271
-0.029150391,-78.57839966,17.47999954,0.000823117
-0.029443359,-79.48612213,17.65999985,0.000823992
-0.029736328,-80.31243896,17.84000015,0.000838452
-0.030078125,-81.40734863,18.02000046,0.000842445
-0.030371093,-82.56317902,18.20000076,0.000864461
-0.030664061,-83.48621368,18.37999916,0.000877808
-0.030957031,-84.32261658,18.55999947,0.000879963
-0.031250001,-85.275383,18.73999977,0.000887025
-0.031494139,-86.42531586,18.92000008,0.000911477
-0.031787109,-87.38058472,19.10000038,0.000914383
-0.032080079,-88.22884369,19.28000069,0.000922869
-0.032373046,-89.11530304,19.45999908,0.000934128
-0.032666016,-90.28275299,19.63999939,0.000938682
-0.032958986,-91.37660217,19.81999969,0.000967344
-0.033251952,-92.44742584,20,0.000980254
-0.033544922,-93.47885895,20.18000031,0.000997047
-0.033886718,-94.5166626,20.36000061,0.00099868
-0.034179688,-95.84976959,20.54000092,0.001022644
-0.034521483,-97.07006836,20.71999931,0.00103723
-0.034863282,-98.12418365,20.89999962,0.00104351
-0.035156248,-99.22817993,21.07999992,0.001053661
-0.035449219,-100.4542084,21.26000023,0.001077389
-0.035791014,-101.8084335,21.44000053,0.001089414
-0.036083984,-102.8690262,21.62000084,0.001111089
-0.036376954,-103.8608932,21.79999924,0.001119245
-0.036718749,-104.9912109,21.97999954,0.001135089
-0.03701172,-106.1147003,22.15999985,0.001153512
-0.037304686,-107.3777618,22.34000015,0.001159322
-0.037597656,-108.3301239,22.52000046,0.001182118
-0.037890626,-109.4553223,22.70000076,0.001189415
-0.038134767,-110.5859375,22.87999916,0.001203908
-0.038427734,-111.7813492,23.05999947,0.001235903
-0.038720704,-112.8479767,23.23999977,0.001253044
-0.03901367,-113.8016281,23.42000008,0.001265107
-0.03930664,-115.0147629,23.60000038,0.001280815
-0.039550781,-116.2429733,23.78000069,0.001298235
-0.039843751,-117.3826447,23.95999908,0.001311396
-0.040185547,-118.5812454,24.13999939,0.001342435
-0.040478517,-119.7528763,24.31999969,0.001363454
-0.040771483,-121.317009,24.5,0.001379506
-0.041113282,-122.7108917,24.68000031,0.001396333
-0.041455078,-124.015625,24.86000061,0.001420349
-0.041748048,-125.3536606,25.04000092,0.001445856
-0.042089843,-126.6620178,25.21999931,0.001471403
-0.042382813,-128.096817,25.39999962,0.001496161
-0.04267578,-129.3504333,25.57999992,0.001535603
-0.04296875,-130.5651093,25.76000023,0.00155638
-0.043310545,-131.776474,25.94000053,0.001566291
-0.043603515,-133.1041565,26.12000084,0.001609004
-0.043896485,-134.4715576,26.29999924,0.001630828
-0.044189452,-135.6831207,26.47999954,0.001658557
-0.044482422,-136.8977203,26.65999985,0.001682237
-0.044726563,-138.1937866,26.84000015,0.001705728
-0.045019533,-139.5323334,27.02000046,0.001742332
-0.045312499,-140.8369904,27.20000076,0.001779213
-0.045605469,-141.7992401,27.37999916,0.001805662
-0.045898436,-143.1941681,27.55999947,0.001833652
-0.046191406,-144.5579071,27.73999977,0.001868385
-0.046484376,-146.1593018,27.92000008,0.001912408
-0.046777343,-147.4243622,28.10000038,0.001939065
-0.047070313,-148.8583374,28.28000069,0.001965372
-0.047412108,-150.4134521,28.45999908,0.002005432
-0.047705078,-152.2430573,28.63999939,0.002045171
-0.048046873,-153.7965698,28.81999969,0.002072528
-0.048388672,-155.3668823,29,0.002110245
-0.048681639,-157.07164,29.18000031,0.002139322
-0.048974609,-158.937561,29.36000061,0.002185705
-0.049267579,-160.4690857,29.54000092,0.002221281
-0.049609374,-162.1018066,29.71999931,0.002253803
-0.049902344,-163.9563751,29.89999962,0.002304128
-0.050195311,-165.6189117,30.07999992,0.002338956
-0.050488281,-167.3779297,30.26000023,0.002382683
-0.050781251,-168.9135895,30.44000053,0.002435064
-0.051074217,-170.4638214,30.62000084,0.002479353
-0.051367188,-172.0237732,30.79999924,0.002517527
-0.051660158,-173.5396729,30.97999954,0.002583357
-0.051953124,-174.9664307,31.15999985,0.002650744
-0.052246094,-176.2351227,31.34000015,0.002716069
-0.052539064,-177.5079498,31.52000046,0.00279849
-0.052783202,-178.8273926,31.70000076,0.002886344
-0.053076172,-180.13974,31.87999916,0.00299827
-0.053369142,-180.8096161,32.06000137,0.003139463
-0.053710937,-181.9245605,32.24000168,0.003271076
-0.054003907,-182.9318542,32.41999817,0.00340765
-0.054345703,-183.9135742,32.59999847,0.00357357
-0.054638673,-184.9901886,32.77999878,0.003730399
-0.054980468,-186.0761566,32.95999908,0.003877014
-0.055273438,-187.1587982,33.13999939,0.004028366
-0.055566405,-188.2575226,33.31999969,0.004169552
-0.055908204,-189.3689575,33.5,0.00431023
-0.05620117,-190.592865,33.68000031,0.004448421
-0.05649414,-191.4758301,33.86000061,0.004605839
-0.05678711,-192.2231445,34.04000092,0.004768423
-0.057080077,-193.1902924,34.22000122,0.004949196
-0.057373047,-193.9397583,34.40000153,0.005114071
-0.057666017,-195.1047821,34.58000183,0.005228791
-0.057958983,-196.3126068,34.75999832,0.00536695
-0.058203124,-197.4493408,34.93999863,0.005512927
-0.058496094,-198.1529541,35.11999893,0.00569564
-0.058789061,-198.2490997,35.29999924,0.005908937
-0.059082031,-197.7575531,35.47999954,0.00616384
-0.059375001,-197.9366608,35.65999985,0.006396835
-0.059667967,-198.4120789,35.84000015,0.006631639
-0.059960938,-198.8265381,36.02000046,0.00684393
-0.060253908,-199.6266479,36.20000076,0.007024292
-0.060546874,-201.0054932,36.38000107,0.007192513
-0.060839844,-201.7774048,36.56000137,0.007412543
-0.061181643,-202.7171783,36.74000168,0.007632558
-0.061523438,-203.225708,36.91999817,0.007867936
-0.061816405,-203.6385345,37.09999847,0.008090306
-0.0621582,-204.6745148,37.27999878,0.008286182
-0.062451174,-205.766571,37.45999908,0.008464178
-0.06274414,-207.0375214,37.63999939,0.00863038
-0.063037107,-208.2242737,37.81999969,0.008776294
-0.063330081,-209.2059326,38,0.008932809
-0.063671876,-210.2120819,38.18000031,0.00910518
-0.063964842,-210.7410431,38.36000061,0.009309671
-0.064257816,-211.0135956,38.54000092,0.00952455
-0.064550783,-211.2454224,38.72000122,0.009737397
-0.064843749,-211.1054382,38.90000153,0.010001564
-0.065087894,-211.3249664,39.08000183,0.010245487
-0.06538086,-211.5702972,39.25999832,0.010468574
-0.065673827,-211.476593,39.43999863,0.010704752
-0.0659668,-211.8197937,39.61999893,0.010914147
-0.066259767,-212.4283447,39.79999924,0.011137386
-0.066552733,-213.3370972,39.97999954,0.011355242
-0.0668457,-214.118454,40.15999985,0.011544744
-0.067187502,-213.7902985,40.34000015,0.01170023
-0.067480469,-215.0316315,40.52000046,0.011862703
-0.067822264,-216.0503387,40.70000076,0.012086512
-0.068164059,-216.4723053,40.88000107,0.012318801
-0.068457033,-216.6535034,41.06000137,0.012572742
-0.068798829,-216.9263153,41.24000168,0.012803442
-0.069091795,-217.0895691,41.41999817,0.013055492
-0.069384769,-216.9299622,41.59999847,0.013345105
-0.069677735,-216.0948486,41.77999878,0.013658819
-0.069970702,-214.9073181,41.95999908,0.013993925
-0.070312497,-212.775177,42.13999939,0.014414062
-0.070605471,-209.729538,42.31999969,0.014893476
-0.070898437,-207.5014801,42.5,0.015315531
-0.071191404,-206.3358002,42.68000031,0.015660571
-0.071435548,-205.0106964,42.86000061,0.016016855
-0.071728515,-203.7649231,43.04000092,0.016381739
-0.072021481,-202.4639282,43.22000122,0.016756892
-0.072314455,-201.0480042,43.40000153,0.01713016
-0.072607421,-200.2627563,43.58000183,0.017461556
-0.072900388,-199.7327728,43.75999832,0.017807801
-0.073193361,-198.391571,43.93999863,0.018196175
-0.073486328,-196.4031067,44.11999893,0.018624423
-0.073779294,-194.9427643,44.29999924,0.019041214
-0.074121097,-193.8900299,44.47999954,0.01942593
-0.074414063,-193.2009125,44.65999985,0.019815294
-0.074755859,-192.1453705,44.84000015,0.02020715
-0.075048825,-190.9616699,45.02000046,0.020583
-0.075390628,-188.863266,45.20000076,0.021056583
-0.075683594,-187.2418823,45.38000107,0.021481339
-0.075976561,-185.7098694,45.56000137,0.02195307
-0.076318356,-183.9315491,45.74000168,0.022388871
-0.07661133,-182.2768402,45.91999817,0.022811344
-0.076904296,-180.3050232,46.09999847,0.02327286
-0.077197263,-178.883194,46.27999878,0.023700552
-0.077490236,-177.5043793,46.45999908,0.024124283
-0.077783203,-175.5393066,46.63999939,0.024682749
-0.07802734,-174.1320648,46.81999969,0.025141293
-0.078320314,-173.2897644,47,0.025536714
-0.07861328,-172.8107147,47.18000031,0.025896436
-0.078906247,-172.4577332,47.36000061,0.02623279
-0.079199221,-171.9465179,47.54000092,0.02655589
-0.079443358,-171.8052521,47.72000122,0.026893706
-0.079785154,-171.3457336,47.90000153,0.027266802
-0.080078127,-170.5980835,48.08000183,0.027676746
-0.080371094,-169.6270752,48.25999832,0.028103588
-0.08066406,-167.2594452,48.43999863,0.028650684
-0.081005863,-164.9811096,48.61999893,0.029243387
-0.081347658,-163.1607208,48.79999924,0.029801173
-0.081640625,-160.9135895,48.97999954,0.030406234
-0.08198242,-157.7514343,49.15999985,0.03109402
-0.082275394,-154.9842987,49.34000015,0.031760239
-0.08256836,-153.3968048,49.52000046,0.032307296
-0.082910155,-152.0096741,49.70000076,0.032836953
-0.083203122,-133.2453613,49.88000107,0.035155655
-0.083496096,-122.1293488,50.06000137,0.037098613
-0.083789062,-116.4214478,50.24000168,0.038329952
-0.084082028,-110.5307922,50.41999817,0.039681348
-0.084375002,-103.2098923,50.59999847,0.041372747
-0.084667969,-96.76563263,50.77999878,0.043029406
-0.084960935,-93.73760223,50.95999908,0.044042903
-0.085253909,-91.30033875,51.13999939,0.04494665
-0.085546875,-89.11638641,51.31999969,0.045813362
-0.085839842,-87.31891632,51.5,0.046569894
-0.086083986,-85.82907104,51.68000031,0.047272239
-0.086376953,-84.47110748,51.86000061,0.047939586
-0.086669919,-82.93471527,52.04000092,0.048696911
-0.087011722,-81.24140167,52.22000122,0.049489456
-0.087304688,-79.45417786,52.40000153,0.050265677
-0.087646484,-78.067276,52.58000183,0.05101255
-0.08793945,-77.061203,52.75999832,0.051670577
-0.088281253,-76.34122467,52.93999863,0.052252552
-0.088574219,-75.50693512,53.11999893,0.052816715
-0.088867186,-74.5216217,53.29999924,0.053368018
-0.089208981,-73.32015228,53.47999954,0.054040796
-0.089501955,-71.28020477,53.65999985,0.054914522
-0.089794921,-69.37497711,53.84000015,0.055790271
-0.090087888,-67.12184906,54.02000046,0.056715991
-0.090380861,-65.26087952,54.20000076,0.057573299
-0.090673828,-63.87339401,54.38000107,0.05832535
-0.090966794,-62.76452637,54.56000137,0.059010832
-0.091259768,-61.61509323,54.74000168,0.059675476
-0.091552734,-60.48366547,54.91999817,0.060316484
-0.091845701,-59.72826004,55.09999847,0.060889139
-0.092089846,-59.08076096,55.27999878,0.061430379
-0.092382812,-58.43661499,55.45999908,0.061960091
-0.092675778,-57.82491302,55.63999939,0.062456871
-0.092968752,-57.34968185,55.81999969,0.062943989
-0.093261719,-56.96666336,56,0.063424777
-0.093554685,-56.66867065,56.18000031,0.063894819
-0.093847659,-56.20641327,56.36000061,0.064371598
-0.094189454,-55.80572891,56.54000092,0.064848842
-0.094482421,-55.22896576,56.72000122,0.065364657
-0.094824216,-54.78728485,56.90000153,0.065884196
-0.09511719,-54.26737595,57.08000183,0.066433618
-0.095458985,-53.48408508,57.25999832,0.066976325
-0.095751951,-52.94307709,57.43999863,0.067501707
-0.096044925,-52.50348282,57.61999893,0.068013731
-0.096337892,-52.0161438,57.79999924,0.068547735
-0.096630858,-51.46388626,57.97999954,0.069063688
-0.096972653,-50.88487244,58.15999985,0.069568567
-0.097265627,-50.3181839,58.34000015,0.07009683
-0.097509765,-49.73134232,58.52000046,0.070614959
-0.097802731,-49.36225128,58.70000076,0.071134178
-0.098095705,-48.77259827,58.88000107,0.071612551
-0.098388671,-48.21374893,59.06000137,0.07207934
-0.098681638,-47.9259758,59.24000168,0.072561015
-0.098974611,-47.56554413,59.41999817,0.073041665
-0.099218749,-47.13729095,59.59999847,0.073517309
-0.099511715,-46.51568222,59.77999878,0.073989235
-0.099804689,-46.039814,59.95999908,0.074473937
-0.100097655,-45.84220886,60.13999939,0.07496796
-0.100439451,-45.4899559,60.31999969,0.07547014
-0.100781253,-45.02008438,60.5,0.075975426
-0.10107422,-44.52725983,60.68000031,0.07649936
-0.101416015,-44.12870789,60.86000061,0.077014898
-0.101708982,-43.77425385,61.04000092,0.077541357
-0.102050784,-43.34379196,61.22000122,0.078049125
-0.102343751,-42.8924675,61.40000153,0.07855695
-0.102685546,-42.36303329,61.58000183,0.07904903
-0.102978513,-42.0957489,61.75999832,0.079558129
-0.103271486,-41.75803757,61.93999863,0.080070327
-0.103564453,-41.17032623,62.11999893,0.080573554
-0.103857419,-40.67591858,62.29999924,0.081078906
-0.104150393,-40.17287827,62.47999954,0.081583414
-0.104443359,-39.78178406,62.65999985,0.082126251
-0.104736326,-39.2056694,62.84000015,0.082651597
-0.105029299,-38.72182465,63.02000046,0.083175612
-0.105322266,-38.20042801,63.20000076,0.083674728
-0.105615232,-37.79367828,63.38000107,0.084163519
-0.105908206,-37.43572235,63.56000137,0.084695646
-0.106201172,-36.87210083,63.74000168,0.085213382
-0.106494139,-35.34465408,63.91999817,0.085931686
-0.106787113,-34.66212463,64.09999847,0.086469445
-0.107080079,-34.32049942,64.27999878,0.086983346
-0.107421874,-33.95691681,64.45999908,0.087472639
-0.107714841,-33.60123825,64.63999939,0.087977991
-0.108056644,-33.19752502,64.81999969,0.088466993
-0.10834961,-33.00210571,65,0.088937995
-0.108691405,-32.1801796,65.18000031,0.089592228
-0.108984372,-31.80550957,65.36000061,0.090075766
-0.109277345,-31.24213982,65.54000092,0.090545895
-0.109570312,-31.03447342,65.72000122,0.091006688
-0.109912107,-30.77360725,65.90000153,0.091471273
-0.110205081,-30.18727493,66.08000183,0.092037291
-0.110498047,-29.73145866,66.26000214,0.092534312
-0.110791014,-29.21533585,66.44000244,0.092989983
-0.111083988,-29.06946754,66.62000275,0.09343867
-0.111376954,-28.56699181,66.80000305,0.093976334
-0.111621091,-28.04046631,66.98000336,0.094446252
-0.111914065,-27.71584702,67.16000366,0.094907067
-0.112207032,-27.29796219,67.33999634,0.095381729
-0.112499998,-27.05860329,67.51999664,0.095853495
-0.112792972,-26.76267624,67.69999695,0.096325573
-0.113085938,-26.41707611,67.87999725,0.09677418
-0.113378905,-26.00584221,68.05999756,0.097219214
-0.113671878,-25.84362984,68.23999786,0.097686156
-0.114013674,-25.77284241,68.41999817,0.098147764
-0.11430664,-25.36297798,68.59999847,0.098624951
-0.114648436,-24.95345497,68.77999878,0.0991161
-0.114941409,-24.36991882,68.95999908,0.09971219
-0.115283205,-24.11106682,69.13999939,0.100247773
-0.115576171,-23.74654579,69.31999969,0.100782287
-0.115917966,-23.26391411,69.5,0.101285885
-0.11621094,-22.89710999,69.68000031,0.101787817
-0.116503907,-22.62685966,69.86000061,0.102266473
-0.116796873,-22.44909286,70.04000092,0.102732418
-0.117089847,-22.216959,70.22000122,0.103205923
-0.117382813,-21.80128479,70.40000153,0.10364312
-0.11767578,-21.50755501,70.58000183,0.104097038
-0.117968753,-21.31082916,70.76000214,0.104544561
-0.11826172,-19.03486633,70.94000244,0.10599626
-0.118554686,-18.66552925,71.12000275,0.106489402
-0.118798831,-18.43562508,71.30000305,0.10689153
-0.119091797,-18.48062134,71.48000336,0.107291431
-0.119384764,-18.45107841,71.66000366,0.107685548
-0.119677738,-17.6297226,71.83999634,0.108401669
-0.119970704,-17.28600502,72.01999664,0.108837929
-0.12026367,-16.90850449,72.19999695,0.109370631
-0.120605466,-16.65519905,72.37999725,0.109925692
-0.120898439,-16.42605019,72.55999756,0.110458837
-0.121240235,-16.17431831,72.73999786,0.11099274
-0.121533201,-15.72578621,72.91999817,0.111502421
-0.121874997,-15.49577522,73.09999847,0.112019225
-0.12216797,-15.38998985,73.27999878,0.112516442
-0.122509766,-15.14055157,73.45999908,0.113009679
-0.122802739,-14.84893894,73.63999939,0.113470691
-0.123095699,-14.59414005,73.81999969,0.113938637
-0.123388672,-14.46312618,74,0.114393275
-0.123681646,-14.37760067,74.18000031,0.114837771
-0.123974605,-14.16643238,74.36000061,0.115277027
-0.124267579,-13.99014091,74.54000092,0.115721246
-0.124560553,-13.79827881,74.72000122,0.116139723
-0.124853512,-13.70174122,74.90000153,0.11657182
-0.125146486,-13.61731243,75.08000183,0.116990515
-0.125439459,-13.33302593,75.26000214,0.117395015
-0.125683597,-13.16373158,75.44000244,0.117811636
-0.125976556,-13.0788002,75.62000275,0.118211603
-0.12626953,-12.99681664,75.80000305,0.118637268
-0.126562503,-12.82634068,75.98000336,0.11905776
-0.126855462,-12.63291359,76.16000366,0.119483208
-0.127197272,-12.5651722,76.33999634,0.119905635
-0.127490232,-12.4799614,76.51999664,0.120335637
-0.127832027,-12.46665668,76.69999695,0.120796765
-0.128125001,-12.17443085,76.87999725,0.121241494
-0.128466796,-12.03112793,77.05999756,0.121679652
-0.12875977,-11.98703289,77.23999786,0.122116617
-0.129052729,-12.00344563,77.41999817,0.122538768
-0.129345703,-11.9074173,77.59999847,0.122950674
-0.129638676,-11.67616653,77.77999878,0.123359947
-0.129980472,-11.63243198,77.95999908,0.123757258
-0.130273431,-11.57649422,78.13999939,0.124165264
-0.130566405,-11.54035091,78.31999969,0.124570128
-0.130859378,-11.36533642,78.5,0.1249864
-0.131152337,-11.04819775,78.68000031,0.125400722
-0.131396489,-11.11052704,78.86000061,0.12580739
-0.131689449,-11.05907345,79.04000092,0.126202882
-0.131982422,-10.96151161,79.22000122,0.126598767
-0.132275396,-10.73085117,79.40000153,0.126981293
-0.132519534,-10.50875282,79.58000183,0.127362335
-0.132812507,-10.62992382,79.76000214,0.127755076
-0.133154303,-10.59278679,79.94000244,0.128142012
-0.133447262,-10.11098862,80.12000275,0.128636108
-0.133740235,-9.925350189,80.30000305,0.129066946
-0.134082031,-9.82269001,80.48000336,0.129486652
-0.134375005,-9.897136688,80.66000366,0.129912616
-0.1347168,-9.851599693,80.83999634,0.13033241
-0.135009759,-9.683304787,81.01999664,0.130746761
-0.135351569,-9.586527824,81.19999695,0.1311667
-0.135644528,-9.538347244,81.37999725,0.131573004
-0.135937502,-9.55649662,81.55999756,0.131983048
-0.136279297,-9.386000633,81.73999786,0.132375804
-0.136572271,-9.22851181,81.91999817,0.132766902
-0.13686523,-9.218185425,82.09999847,0.133152033
-0.137158204,-9.272537231,82.27999878,0.133551934
-0.137451178,-9.085720062,82.45999908,0.134008442
-0.137744137,-8.836046219,82.63999939,0.134413553
-0.13803711,-8.563284874,82.81999969,0.134832415
-0.138330084,-8.498722076,83,0.135258786
-0.138623043,-8.562418938,83.18000031,0.135654496
-0.138867181,-8.405200958,83.36000061,0.136060728
-0.139160155,-8.154102325,83.54000092,0.136435832
-0.139453128,-8.019571304,83.72000122,0.136815404
-0.139746087,-8.057234764,83.90000153,0.137225608
-0.140039061,-7.986073971,84.08000183,0.137640396
-0.140380856,-7.903168678,84.26000214,0.13806911
-0.14067383,-7.656064987,84.44000244,0.138499236
-0.141015626,-7.686789513,84.62000275,0.138911098
-0.141308599,-7.753175735,84.80000305,0.139327414
-0.141650395,-7.628917217,84.98000336,0.139741736
-0.14199219,-7.519084454,85.16000366,0.140135744
-0.142285149,-7.36921072,85.33999634,0.140531018
-0.142578123,-7.445374012,85.51999664,0.140938311
-0.142871097,-7.360060215,85.69999695,0.14136947
-0.143212892,-7.178564072,85.87999725,0.141767639
-0.143505866,-7.135424137,86.05999756,0.142148026
-0.143798825,-7.010975361,86.23999786,0.142525605
-0.144042962,-7.034874916,86.41999817,0.142909747
-0.144335936,-6.968550205,86.59999847,0.14329268
-0.14462891,-6.838576794,86.77999878,0.143676967
-0.144921869,-6.678647041,86.95999908,0.144060818
-0.145214843,-6.707310677,87.13999939,0.144451988
-0.145507816,-6.700847149,87.31999969,0.144829799
-0.145800775,-6.545127869,87.5,0.145206344
-0.146093749,-6.531797886,87.68000031,0.145582366
-0.146386723,-6.360760689,87.86000061,0.145953498
-0.146679682,-6.356603146,88.04000092,0.146328442
-0.146972656,-6.44281292,88.22000122,0.146723993
-0.147314451,-6.316146374,88.40000153,0.147143553
-0.147607425,-6.120076656,88.58000183,0.147566068
-0.14794922,-6.046039104,88.76000214,0.147991246
-0.148242194,-6.119565487,88.94000244,0.148400999
-0.148583989,-6.049333096,89.12000275,0.148807536
-0.148876949,-5.971887589,89.30000305,0.149213549
-0.149169922,-5.826117039,89.48000336,0.14958976
-0.149462896,-5.84371376,89.66000366,0.149989995
-0.149804691,-5.872362614,89.83999634,0.150368796
-0.15009765,-5.788384914,90.01999664,0.150749722
-0.150390624,-5.605620861,90.19999695,0.151146087
-0.150683598,-5.707266331,90.37999725,0.151520697
-0.150976557,-5.679908276,90.55999756,0.151891611
-0.151269531,-5.626067162,90.73999786,0.152295572
-0.151562504,-5.479019165,90.91999817,0.152643741
-0.151855464,-5.373611927,91.09999847,0.153015062
-0.152099616,-5.505484581,91.27999878,0.153374305
-0.152392575,-5.542359352,91.45999908,0.153737768
-0.152685549,-5.501049995,91.63999939,0.154110516
-0.152978522,-5.301506996,91.81999969,0.154490292
-0.153271481,-5.129543781,92,0.154858048
-0.153564455,-5.285186768,92.18000031,0.15523177
-0.15390625,-5.352584839,92.36000061,0.155619127
-0.154248046,-5.333518982,92.54000092,0.156010516
-0.15454102,-5.162631512,92.72000122,0.156413793
-0.154882815,-5.076393604,92.90000153,0.156805632
-0.155175774,-5.215545177,93.08000183,0.157202667
-0.155517584,-5.194665432,93.26000214,0.15758675
-0.155810543,-5.131705284,93.44000244,0.157967937
-0.156103517,-4.969782829,93.62000275,0.158346098
-0.156396491,-4.940282822,93.80000305,0.158735042
-0.15668945,-5.041152,93.98000336,0.15911652
-0.156982424,-4.934028625,94.16000366,0.159491625
-0.157275397,-4.865915775,94.33999634,0.159850009
-0.157568356,-4.745069981,94.51999664,0.160229014
-0.15786133,-4.813271999,94.69999695,0.160595693
-0.158154304,-4.857514381,94.87999725,0.160984157
-0.158447263,-4.738853931,95.05999756,0.161333533
-0.1586914,-4.568765163,95.23999786,0.161689008
-0.158984374,-4.600618362,95.41999817,0.162048076
-0.159277348,-4.64454031,95.59999847,0.162404103
-0.159570307,-4.676460743,95.77999878,0.162767319
-0.159863281,-4.58903265,95.95999908,0.163119505
-0.160156254,-4.475151539,96.13999939,0.163498073
-0.160449214,-4.47755146,96.31999969,0.163876437
-0.160791009,-4.645767212,96.5,0.16425889
-0.161083983,-4.527528763,96.68000031,0.164655066
-0.161425778,-4.429815769,96.86000061,0.16503493
-0.161718752,-4.459270954,97.04000092,0.165425095
-0.162060547,-4.365417957,97.22000122,0.165822872
-0.162353521,-4.488070965,97.40000153,0.166202852
-0.16264648,-4.358190536,97.58000183,0.166580139
-0.162939454,-4.268202782,97.76000214,0.166956423
-0.163232427,-4.306494236,97.94000244,0.167327715
-0.163525387,-4.413075447,98.12000275,0.167686361
-0.163867182,-4.311066151,98.30000305,0.168058352
-0.164160156,-4.17921257,98.48000336,0.168438084
-0.164404293,-4.126882553,98.66000366,0.168796323
-0.164697267,-4.206632137,98.83999634,0.169165345
-0.164990241,-4.206658363,99.01999664,0.169541177
-0.1652832,-4.118273735,99.19999695,0.16991036
-0.165576173,-3.923139811,99.37999725,0.170257816
-0.165869147,-4.001714706,99.55999756,0.170615924
-0.166162106,-4.006216049,99.73999786,0.170979765
-0.16645508,-4.068069458,99.91999817,0.171341526
-0.166748054,-3.936789036,100.0999985,0.171727981
-0.167041013,-3.816380739,100.2799988,0.172110391
-0.167333987,-3.845613956,100.4599991,0.172498883
-0.167675782,-3.771399975,100.6399994,0.172982051
-0.168017577,-3.705231667,100.8199997,0.173399239
-0.168359373,-3.67385006,101,0.173789769
-0.168652346,-3.507395744,101.1800003,0.174195811
-0.168945306,-3.667259693,101.3600006,0.17457355
-0.169238279,-3.683998585,101.5400009,0.174962799
-0.169580075,-3.604674101,101.7200012,0.175357825
-0.169873048,-3.416840076,101.9000015,0.175752808
-0.170166022,-3.401918888,102.0800018,0.176124682
-0.170458981,-3.571290016,102.2600021,0.17651204
-0.170751955,-3.527899504,102.4400024,0.176882706
-0.17109375,-3.326170444,102.6200027,0.177251364
-0.171386724,-3.26382494,102.8000031,0.17764185
-0.171630862,-3.204697609,102.9800034,0.177990005
-0.171923835,-3.427082777,103.1600037,0.178363189
-0.172216794,-3.256972313,103.3399963,0.178718619
-0.172509768,-3.205990314,103.5199966,0.179077804
-0.172802727,-3.075366497,103.6999969,0.179455106
-0.173095701,-3.248810053,103.8799973,0.179816125
-0.173388675,-3.308163881,104.0599976,0.180203089
-0.173681634,-3.118129015,104.2399979,0.18056824
-0.173974608,-3.114807129,104.4199982,0.180956005
-0.174316403,-3.101609945,104.5999985,0.18135432
-0.174658198,-3.150651455,104.7799988,0.181753057
-0.174951172,-3.256478071,104.9599991,0.182169446
-0.175244146,-3.008795023,105.1399994,0.182539021
-0.175585941,-2.939367533,105.3199997,0.182928445
-0.1758789,-2.991277933,105.5,0.183312164
-0.176171874,-3.087918043,105.6800003,0.183697222
-0.176464848,-3.062071085,105.8600006,0.184078846
-0.176806643,-2.81311965,106.0400009,0.184451084
-0.177099602,-2.859016895,106.2200012,0.184830264
-0.177343754,-2.773421764,106.4000015,0.185205252
-0.177636713,-2.816483259,106.5800018,0.185596393
-0.177929687,-2.703791142,106.7600021,0.18595958
-0.178222661,-2.589068174,106.9400024,0.18632086
-0.17851562,-2.676274776,107.1200027,0.186689751
-0.178808594,-2.637562037,107.3000031,0.187060272
-0.179052731,-2.658937216,107.4800034,0.187425263
-0.179345705,-2.608666897,107.6600037,0.187772384
-0.179638679,-2.422217131,107.8399963,0.188146121
-0.179931638,-2.569699526,108.0199966,0.188520833
-0.180224612,-2.546251297,108.1999969,0.188898121
-0.180566407,-2.545133829,108.3799973,0.189289349
-0.180859381,-2.400170803,108.5599976,0.189682542
-0.181201176,-2.463845015,108.7399979,0.190097082
-0.181542971,-2.485405445,108.9199982,0.190502673
-0.181835931,-2.484745026,109.0999985,0.19090806
-0.18217774,-2.368020296,109.2799988,0.191307583
-0.1824707,-2.31543684,109.4599991,0.191706655
-0.182763673,-2.309001923,109.6399994,0.192090884
-0.183105469,-2.425867319,109.8199997,0.192484353
-0.183398442,-2.354335785,110,0.192867199
-0.183691402,-2.250653505,110.1800003,0.193262953
-0.183984375,-2.191866636,110.3600006,0.193627333
-0.184277349,-2.262667418,110.5400009,0.19399148
-0.184570308,-2.259331226,110.7200012,0.194348191
-0.184863282,-2.188815594,110.9000015,0.194730412
-0.185156256,-2.12489152,111.0800018,0.195100889
-0.185449215,-2.163100958,111.2600021,0.195460118
-0.185693352,-2.122303486,111.4400024,0.195841771
-0.185986326,-2.181238413,111.6200027,0.196215056
-0.1862793,-2.034386396,111.8000031,0.196588691
-0.186621095,-1.91250968,111.9800034,0.197000481
-0.186914069,-1.957895875,112.1600037,0.197390604
-0.187207028,-1.938220382,112.3399963,0.197800968
-0.187548823,-1.842200637,112.5199966,0.198214198
-0.187841797,-1.753014565,112.6999969,0.19862011
-0.188183592,-1.776089907,112.8799973,0.19902912
-0.188476566,-1.777839184,113.0599976,0.199424991
-0.188818361,-1.882954717,113.2399979,0.199824644
-0.189111335,-1.740975618,113.4199982,0.200194452
-0.189404294,-1.617714047,113.5999985,0.200579103
-0.189697268,-1.703606963,113.7799988,0.200984607
-0.189990227,-1.734550476,113.9599991,0.201363742
-0.190332037,-1.751053452,114.1399994,0.201736984
-0.190576175,-1.57548964,114.3199997,0.202095136
-0.190869134,-1.486884713,114.5,0.202466399
-0.191162108,-1.542494178,114.6800003,0.202837648
-0.191455081,-1.651703596,114.8600006,0.203193384
-0.19174804,-1.586852431,115.0400009,0.2035629
-0.192041014,-1.436364532,115.2200012,0.203912117
-0.192285152,-1.464899063,115.4000015,0.204274038
-0.192578125,-1.489914298,115.5800018,0.204642638
-0.192871099,-1.528900862,115.7600021,0.205001954
-0.193164058,-1.448884726,115.9400024,0.205370496
-0.193457032,-1.38616538,116.1200027,0.205736025
-0.193750006,-1.365933537,116.3000031,0.206118741
-0.194091801,-1.479374886,116.4800034,0.206513927
-0.19438476,-1.401793003,116.6600037,0.206923447
-0.194726555,-1.36827147,116.8399963,0.207309728
-0.195019529,-1.333304524,117.0199966,0.207691381
-0.195361325,-1.331290603,117.1999969,0.208091806
-0.195654298,-1.3687644,117.3799973,0.208478465
-0.195947272,-1.345179915,117.5599976,0.20887451
-0.196240231,-1.117087245,117.7399979,0.209251026
-0.196582027,-1.155189991,117.9199982,0.209619058
-0.196875,-1.265008926,118.0999985,0.210008919
-0.197167974,-1.310768008,118.2799988,0.21038494
-0.197412111,-1.179029584,118.4599991,0.210746526
-0.197705085,-1.069758534,118.6399994,0.211116159
-0.197998044,-1.084690809,118.8199997,0.211476596
-0.198291018,-1.196957231,119,0.211859864
-0.198583977,-1.120900035,119.1800003,0.212203537
-0.198876951,-1.040766954,119.3600006,0.212557876
-0.199121088,-1.039836884,119.5400009,0.212924569
-0.199414062,-1.000658751,119.7200012,0.213300213
-0.199707036,-1.253076911,119.9000015,0.213684834
-0.200048831,-0.984561265,120.0800018,0.214062093
-0.20034179,-0.993320882,120.2600021,0.214448432
-0.200634764,-0.963911474,120.4400024,0.214847649
-0.200976559,-1.003232718,120.6200027,0.215262116
-0.201318355,-1.083202004,120.8000031,0.215689346
-0.201611329,-0.93307513,120.9800034,0.216107044
-0.201953124,-0.810647845,121.1600037,0.216660119
-0.202246098,-0.632486761,121.3399963,0.217137014
-0.202587893,-0.659421027,121.5199966,0.217602021
-0.202880852,-0.576422691,121.6999969,0.218029192
-0.203173826,-0.449833155,121.8799973,0.218457382
-0.203515621,-0.442367345,122.0599976,0.218870962
-0.203808595,-0.452711195,122.2399979,0.219277223
-0.204101569,-0.398109376,122.4199982,0.21968341
-0.204394528,-0.386695832,122.5999985,0.220071757
-0.204687502,-0.252447367,122.7799988,0.220461952
-0.204980475,-0.396404088,122.9599991,0.220847534
-0.205224613,-0.331688762,123.1399994,0.22122715
-0.205517572,-0.372209609,123.3199997,0.221609065
-0.205810546,-0.203125179,123.5,0.221985581
-0.206103519,-0.202381372,123.6800003,0.222349248
-0.206396478,-0.257858366,123.8600006,0.222716553
-0.206689452,-0.27451092,124.0400009,0.223108
-0.206982426,-0.226100817,124.2200012,0.223501833
-0.207324221,-0.092436925,124.4000015,0.223904804
-0.20761718,-0.205850363,124.5800018,0.224307849
-0.20795899,-0.30050993,124.7600021,0.22473339
-0.20825195,-0.207158372,124.9400024,0.225123906
-0.208593745,-0.151670694,125.1200027,0.22552193
-0.208886719,-0.021453412,125.3000031,0.225920652
-0.209179692,-0.15897508,125.4800034,0.22631367
-0.209472651,-0.282602966,125.6600037,0.22671395
-0.209765625,-0.099290073,125.8399963,0.227090452
-0.210107421,-0.081988849,126.0199966,0.227465061
-0.210400394,0.047020596,126.1999969,0.227873694
-0.210693353,-0.108152784,126.3799973,0.228245248
-0.210986327,-0.068332411,126.5599976,0.228624238
-0.211230465,-0.009487049,126.7399979,0.228996505
-0.211523438,0.153545812,126.9199982,0.229384139
-0.211816412,0.137193024,127.0999985,0.22975482
-0.212109371,0.073644303,127.2799988,0.230128077
-0.212402345,0.135825112,127.4599991,0.230543636
-0.212646482,0.23932974,127.6399994,0.230937861
-0.212939456,0.303271413,127.8199997,0.2313554
-0.213281251,0.267676651,128,0.23177774
-0.213574225,0.224650875,128.1799927,0.232189283
-0.213867184,0.520632446,128.3600006,0.23295774
-0.21420898,0.740068555,128.5399933,0.233958781
-0.214501953,0.632778704,128.7200012,0.234755193
-0.214843749,0.575165808,128.8999939,0.235465675
-0.215136723,0.508969426,129.0800018,0.236119609
-0.215478518,0.621206641,129.2599945,0.23672833
-0.215771492,0.706994116,129.4400024,0.237321932
-0.216064451,0.639295816,129.6199951,0.237914282
-0.216406246,0.593396723,129.8000031,0.238516062
-0.21669922,0.644348741,129.9799957,0.239076398
-0.216992194,0.660621166,130.1600037,0.239636589
-0.217285153,0.768497765,130.3399963,0.240190901
-0.217578126,0.724472642,130.5200043,0.240770576
-0.2178711,0.592849672,130.6999969,0.241319925
-0.218164059,0.600841105,130.8800049,0.241871196
-0.218457033,0.713355422,131.0599976,0.242417227
-0.218701171,0.834645748,131.2400055,0.242949653
-0.218994144,0.707538486,131.4199982,0.243481685
-0.219287103,0.786624134,131.6000061,0.244016162
-0.219580077,0.736599267,131.7799988,0.244537718
-0.219873051,0.899014056,131.9600067,0.245095289
-0.22016601,0.746073842,132.1399994,0.245686097
-0.220507805,0.699881673,132.3200073,0.246267417
-0.220800779,0.772167206,132.5,0.246814976
-0.221142574,0.788874388,132.6799927,0.247333315
-0.22148437,0.810357869,132.8600006,0.247862044
-0.221777344,0.740641296,133.0399933,0.248394994
-0.222070317,0.634139121,133.2200012,0.248925789
-0.222412113,0.804006577,133.3999939,0.249456178
-0.222705072,0.799043,133.5800018,0.250001147
-0.222998046,0.869573414,133.7599945,0.250541081
-0.223291019,0.779297411,133.9400024,0.25111498
-0.223583978,0.773784041,134.1199951,0.25167939
-0.223925788,0.874685347,134.3000031,0.252257945
-0.224169926,0.893460631,134.4799957,0.252835453
-0.224462885,0.783627331,134.6600037,0.253409526
-0.224755859,0.697276056,134.8399963,0.254003913
-0.225048832,0.777777851,135.0200043,0.254578219
-0.225341792,0.878315747,135.1999969,0.255158782
-0.225585944,0.863192797,135.3800049,0.255755003
-0.225878903,0.800980628,135.5599976,0.256382977
-0.226171876,0.677820742,135.7400055,0.257004518
-0.22646485,0.774020672,135.9199982,0.257645472
-0.226757809,0.794496417,136.1000061,0.258282817
-0.227050783,0.691238999,136.2799988,0.258930784
-0.227392578,0.687574029,136.4600067,0.259588851
-0.227685552,0.679280162,136.6399994,0.260260829
-0.228027347,0.873551309,136.8200073,0.260930799
-0.228320307,0.821647704,137,0.261628447
-0.228662117,0.746233344,137.1799927,0.262307236
-0.228955076,0.645792425,137.3600006,0.26299461
-0.229248049,0.735370576,137.5399933,0.263694121
-0.229541009,0.865980506,137.7200012,0.264458824
-0.229833982,0.858047128,137.8999939,0.265623472
-0.230175778,0.714846611,138.0800018,0.266684045
-0.230468751,0.66795063,138.2599945,0.267623982
-0.230761725,0.784763396,138.4400024,0.268422649
-0.231054684,0.892320633,138.6199951,0.269215321
-0.231347658,0.708666861,138.8000031,0.269995158
-0.231591795,0.683727264,138.9799957,0.270806166
-0.231884769,0.752692044,139.1600037,0.271664438
-0.232177728,0.69565767,139.3399963,0.272561359
-0.232470702,0.92108357,139.5200043,0.273427257
-0.232763676,0.770652771,139.6999969,0.274301245
-0.233056635,0.775428116,139.8800049,0.275687693
-0.233349609,0.755524397,140.0599976,0.277183281
-0.233642582,0.810207784,140.2400055,0.278642576
-0.233984378,0.850622892,140.4199982,0.28040522
-0.234277337,0.734053016,140.6000061,0.281914778
-0.234619147,0.744955301,140.7799988,0.283759611
-0.234960942,0.819199741,140.9600067,0.2850811
-0.235253901,0.874814212,141.1399994,0.286281953
-0.235546875,0.897614777,141.3200073,0.287478033
-0.23588867,0.705790162,141.5,0.288628449
-0.236181644,0.731955647,141.6799927,0.289762451
-0.236474603,0.795411527,141.8600006,0.290827185
-0.236816413,0.820201218,142.0399933,0.291906559
-0.237109372,0.74981755,142.2200012,0.292990735
-0.237402346,0.701852202,142.3999939,0.294050114
-0.237646484,0.669473648,142.5800018,0.295094738
-0.237939457,0.813604712,142.7599945,0.296143873
-0.238232416,0.79679805,142.9400024,0.297153689
-0.23852539,0.695239127,143.1199951,0.2981711
-0.238818364,0.62785542,143.3000031,0.299173553
-0.239062501,0.692747712,143.4799957,0.300172542
-0.239355475,0.793224692,143.6600037,0.301145046
-0.23969727,0.765533745,143.8399963,0.302133209
-0.239941408,0.723432124,144.0200043,0.303161592
-0.240283203,0.796954393,144.1999969,0.304217829
-0.240576177,0.777196884,144.3800049,0.305430935
-0.240917972,0.759321034,144.5599976,0.306934293
-0.241210932,0.779967666,144.7400055,0.308198767
-0.241552741,0.6935215,144.9199982,0.309326046
-0.241845701,0.673901677,145.1000061,0.310376956
-0.242187496,0.787077963,145.2799988,0.311416923
-0.24248047,0.724796534,145.4600067,0.312510412
-0.242773443,0.694373369,145.6399994,0.313562428
-0.243066403,0.631476045,145.8200073,0.314548932
-0.243359376,0.706502914,146,0.315521203
-0.24365235,0.809727967,146.1799927,0.316445075
-0.243945309,0.689941645,146.3600006,0.317371538
-0.244238268,0.724942803,146.5399933,0.318291597
-0.244531257,0.634782672,146.7200012,0.319266634
-0.244824216,0.769608974,146.8999939,0.320300256
-0.245117175,0.737522602,147.0800018,0.321469211
-0.245410163,0.678119063,147.2599945,0.322791573
-0.245703122,0.676351964,147.4400024,0.324284425
-0.245996082,0.636098444,147.6199951,0.325708708
-0.24628907,0.784558296,147.8000031,0.327093003
-0.246582029,0.764208496,147.9799957,0.328430237
-0.246874988,0.603305519,148.1600037,0.329760078
-0.247167976,0.63501364,148.3399963,0.331079646
-0.247509772,0.712154686,148.5200043,0.332631287
-0.247802731,0.866986692,148.6999969,0.3347155
-0.248144526,0.784257352,148.8800049,0.336982455
-0.248437515,0.590747416,149.0599976,0.33882109
-0.24877931,0.709513724,149.2400055,0.3403624
-0.249072269,0.728090763,149.4199982,0.341738341
-0.249414064,0.831119478,149.6000061,0.343045715
-0.249707024,0.681917489,149.7799988,0.344305794
-0.250000012,0.685617864,149.9600067,0.345563749
-0.250292971,0.706210077,150.1399994,0.346846442
-0.25058593,0.901349127,150.3200073,0.347984052
-0.250878918,0.758808136,150.5,0.349100941
-0.251171878,0.751059949,150.6799927,0.350221701
-0.251464837,0.635088921,150.8600006,0.351295224
-0.251757825,0.720740259,151.0399933,0.352306291
-0.252050784,0.783629715,151.2200012,0.353270152
-0.252294936,0.704390407,151.3999939,0.354197895
-0.252587895,0.668146133,151.5800018,0.355134776
-0.252880855,0.606619477,151.7599945,0.356055127
-0.253173814,0.767755985,151.9400024,0.356953096
-0.253466802,0.841907442,152.1199951,0.35785549
-0.253808597,0.749574065,152.3000031,0.358803489
-0.254150393,0.684265792,152.4799957,0.359739788
-0.254443352,0.73731637,152.6600037,0.3606588
-0.254785147,0.80289495,152.8399963,0.36155089
-0.255078136,0.7864272,153.0200043,0.362392573
-0.255371095,0.687722862,153.1999969,0.363218045
-0.255664054,0.601696491,153.3800049,0.36399893
-0.256005849,0.733986855,153.5599976,0.364773208
-0.256298837,0.837796807,153.7400055,0.365571206
-0.256591797,0.822835922,153.9199982,0.366377499
-0.256884756,0.657339394,154.1000061,0.367191446
-0.257177744,0.589392304,154.2799988,0.368039764
-0.257470703,0.745092571,154.4600067,0.368898443
-0.257763662,0.861070573,154.6399994,0.369726418
-0.258056651,0.763534367,154.8200073,0.370537746
-0.258300774,0.683796823,155,0.371378177
-0.258593762,0.638199866,155.1799927,0.372214738
-0.258886721,0.799980342,155.3600006,0.373052026
-0.25917968,0.698126256,155.5399933,0.373868388
-0.259423832,0.670553386,155.7200012,0.374704949
-0.259716791,0.541789532,155.8999939,0.375541335
-0.260058587,0.660973251,156.0800018,0.37637318
-0.260351575,0.783010423,156.2599945,0.377197692
-0.260644534,0.680303931,156.4400024,0.378046534
-0.26098633,0.624996245,156.6199951,0.378902128
-0.261279289,0.66199255,156.8000031,0.379730016
-0.261621084,0.678276539,156.9799957,0.380526326
-0.261914072,0.797838569,157.1600037,0.381325983
-0.262255868,0.701272428,157.3399963,0.382140512
-0.262548827,0.613836586,157.5200043,0.383001403
-0.262841786,0.754580915,157.6999969,0.383848295
-0.263134774,0.757190466,157.8800049,0.384662038
-0.263427733,0.737616301,158.0599976,0.38545407
-0.263769529,0.635683239,158.2400055,0.386289525
-0.264062488,0.65075177,158.4199982,0.38716069
-0.264355476,0.640926182,158.6000061,0.388066546
-0.264648435,0.798158348,158.7799988,0.389015826
-0.264892587,0.735566258,158.9600067,0.389943336
-0.265185547,0.523347974,159.1399994,0.390879839
-0.265478506,0.647634804,159.3200073,0.39180601
-0.265771494,0.776913881,159.5,0.392679154
-0.266064453,0.763639927,159.6799927,0.393532304
-0.266357412,0.685203731,159.8600006,0.394378323
-0.266650401,0.658421755,160.0399933,0.395200041
-0.26694336,0.720648527,160.2200012,0.396019372
-0.267285155,0.727686942,160.3999939,0.396867574
-0.267578114,0.743328452,160.5800018,0.397708965
-0.26791991,0.680359364,160.7599945,0.398547796
-0.268261705,0.610044479,160.9400024,0.399410172
-0.268554693,0.693932474,161.1199951,0.40030331
-0.268896489,0.783441305,161.3000031,0.401223195
-0.269189448,0.773724079,161.4799957,0.40225382
-0.269482436,0.581275344,161.6600037,0.403314625
-0.269775395,0.616645336,161.8399963,0.404262042
-0.270068354,0.737617552,162.0200043,0.405192404
-0.27041015,0.752916992,162.1999969,0.4061379
-0.270703138,0.740027964,162.3800049,0.407110696
-0.270947261,0.668171823,162.5599976,0.408041611
-0.27124022,0.723411024,162.7400055,0.408938417
-0.271533208,0.749690056,162.9199982,0.409842702
-0.271826168,0.746622086,163.1000061,0.410824403
-0.272119127,0.715229094,163.2799988,0.411880115
-0.272412115,0.594632983,163.4600067,0.412925961
-0.272705074,0.705977201,163.6399994,0.413899194
-0.272998033,0.794767261,163.8200073,0.414889946
-0.273291022,0.751064181,164,0.415911898
-0.273583981,0.660537362,164.1799927,0.416959549
-0.27387694,0.691127539,164.3600006,0.418140029
-0.274218764,0.712862015,164.5399933,0.419885095
-0.274511724,0.804050148,164.7200012,0.425360602
-0.274853519,0.678367138,164.8999939,0.430090004
-0.275146478,0.654025435,165.0800018,0.433398673
-0.275488273,0.689803779,165.2599945,0.435960916
-0.275781262,0.828252256,165.4400024,0.438549119
-0.276074221,0.864322662,165.6199951,0.441660493
-0.27636718,0.659468651,165.8000031,0.444596488
-0.276660168,0.660544693,165.9799957,0.447660073
-0.277001964,-6.338160992,166.1600037,1.347944839
-0.277294923,-2.86942029,166.3399963,3.984972369
-0.277539075,-0.550513387,166.5200043,5.441030022
-0.277832034,0.121286705,166.6999969,5.667852703
-0.278124993,0.231224552,166.8800049,5.699481815
-0.278417981,0.408129483,167.0599976,5.709332414
-0.278710941,0.471442074,167.2400055,5.71728684
-0.2790039,0.41444543,167.4199982,5.72369108
-0.279296888,0.361325771,167.6000061,5.732854828
-0.279589847,0.423798263,167.7799988,5.744764581
-0.279882806,0.496066183,167.9600067,5.752034485
-0.280175795,0.509188831,168.1399994,5.752922036
-0.280468754,0.399252921,168.3200073,5.758862011
-0.280810549,0.439492673,168.5,5.762417335
-0.281103508,0.534471095,168.6799927,5.767203402
-0.281445304,0.484672338,168.8600006,5.76884253
-0.281738292,0.521549761,169.0399933,5.773891695
-0.282080087,0.427256584,169.2200012,5.776930135
-0.282373047,0.420109928,169.3999939,5.77846868
-0.282714842,0.603168607,169.5800018,5.779781379
-0.283007801,0.574797332,169.7599945,5.786932539
-0.283300789,0.542207479,169.9400024,5.787712988
-0.283593748,0.436070681,170.1199951,5.788112991
-0.283886708,0.60969013,170.3000031,5.789787509
-0.284179696,0.562475145,170.4799957,5.793803837
-0.284472655,0.576459169,170.6600037,5.796225742
-0.284765614,0.482745737,170.8399963,5.797792226
-0.285058602,0.545538366,171.0200043,5.800345913
-0.285351562,0.599058986,171.1999969,5.802918226
-0.285644521,0.70067209,171.3800049,5.804090761
-0.285888673,0.505008698,171.5599976,5.804835353
-0.286181632,0.516721249,171.7400055,5.805420224
-0.28647462,0.547964215,171.9199982,5.80621697
-0.286767579,0.683636665,172.1000061,5.80707239
-0.287109375,0.575646281,172.2799988,5.807623733
-0.287402334,0.543503642,172.4600067,5.808448885
-0.287744129,0.537925959,172.6399994,5.809193943
-0.288037118,0.508759975,172.8200073,5.809963681
-0.288378913,0.641702533,173,5.811200012
-0.288671872,0.590282857,173.1799927,5.811797455
-0.288964831,0.451660573,173.3600006,5.81270922
-0.289306627,0.56651336,173.5399933,5.813607015