File: Data/Thesis_Samples_Data/Notched_Layered_4/Notched_Layered_4.csv
"File Path: C:\Users\Lab User\Desktop\Will\Thesis Tests\Test Run 1 04-8-22 15 46 49 PM\DAQ- Crosshead, … - (Timed).csv   ",,,
Test: MTS EM Tension (Extensometer) - Will 1,,,
Test Run: Test Run 1,,,
Date: 4/8/2022 3:31:48 PM,,,
,,,
,,,
Crosshead ,Load ,Time ,Extensometer
mm,N,sec,mm
-4.88E-05,-2.018614769,0.108000003,5.40E-05
-0.0015625,-2.697912931,0.927999973,9.77E-05
-0.003417969,-3.677893162,1.748000026,0.000161296
-0.005126953,-4.55403614,2.568000078,0.00022973
-0.006689453,-5.210933208,3.388000011,0.000291859
-0.008251953,-6.094023228,4.208000183,0.000348229
-0.010009766,-6.907351494,5.027999878,0.000419479
-0.01171875,-7.7351017,5.84800005,0.000488221
-0.013330078,-8.480853081,6.668000221,0.000554299
-0.01484375,-9.314339638,7.487999916,0.000614438
-0.016601563,-10.23103619,8.307999611,0.000680215
-0.018261719,-11.01927757,9.128000259,0.000740834
-0.01982422,-11.93255329,9.947999954,0.000801538
-0.021386719,-12.60255623,10.76799965,0.000856284
-0.023046876,-13.31488037,11.5880003,0.000918311
-0.024804687,-14.10792828,12.40799999,0.001004919
-0.026367188,-14.77882195,13.22799969,0.001062173
-0.027929687,-15.66633129,14.04800034,0.001121155
-0.029687501,-16.53622437,14.86800003,0.001186749
-0.031396485,-17.3477993,15.68799973,0.00125515
-0.033007811,-18.20258713,16.50799942,0.001316628
-0.034521483,-19.03966331,17.32799911,0.001383065
-0.036230467,-19.70307159,18.14800072,0.001438648
-0.037939451,-20.51576614,18.96800041,0.001524457
-0.039550781,-21.21852684,19.78800011,0.001595415
-0.041113282,-22.00870514,20.6079998,0.001666857
-0.042773438,-22.89364815,21.4279995,0.00174327
-0.044531251,-23.86154366,22.24799919,0.001818531
-0.046142577,-24.61728859,23.06800079,0.001909055
-0.047705078,-25.36642838,23.88800049,0.00194493
-0.049365233,-26.16527557,24.70800018,0.002022862
-0.051074217,-26.91460228,25.52799988,0.002109257
-0.052685547,-27.65505219,26.34799957,0.002176742
-0.054248048,-28.34482193,27.16799927,0.002269042
-0.055859375,-29.22815514,27.98800087,0.002344482
-0.057617188,-30.22420311,28.80800056,0.002411279
-0.059228514,-31.0596714,29.62800026,0.002499996
-0.060742186,-31.92698479,30.44799995,0.002558361
-0.062402345,-32.79671097,31.26799965,0.002637052
-0.064160158,-33.63267899,32.08800125,0.002724233
-0.065820313,-34.45206833,32.90800095,0.002827025
-0.067382811,-35.28144455,33.72800064,0.002902201
-0.068994137,-36.30412292,34.54800034,0.002999989
-0.07075195,-37.28441238,35.36800003,0.00310046
-0.072412113,-38.26458359,36.18799973,0.003224792
-0.07397461,-39.07474136,37.00799942,0.003314689
-0.075537107,-39.95320511,37.82799911,0.003447241
-0.077294921,-40.83454514,38.64799881,0.00355966
-0.078955076,-41.75710297,39.4679985,0.003671496
-0.08051758,-42.59757233,40.2879982,0.003776405
-0.082080078,-43.45115662,41.10800171,0.003893136
-0.08388672,-44.52356339,41.9280014,0.004007058
-0.085546875,-45.50646591,42.7480011,0.004115921
-0.087109373,-46.3603363,43.56800079,0.004273025
-0.088671877,-47.16688538,44.38800049,0.004420323
-0.090380861,-47.0450592,45.20800018,0.004884844
-0.092041017,-46.84375763,46.02799988,0.00544135
-0.093603514,-46.84072113,46.84799957,0.005909308
-0.095166019,-46.64808655,47.66799927,0.006453341
-0.096923832,-46.0620079,48.48799896,0.00726988
-0.098632816,-44.15940094,49.30799866,0.008638703
-0.100195313,-18.87290955,50.12799835,0.03617955
-0.101757811,-19.02449417,50.94800186,0.037884067
-0.103515624,-19.62068748,51.76800156,0.03894051
-0.105224608,-20.0885849,52.58800125,0.039774612
-0.106787113,-20.51339722,53.40800095,0.040539788
-0.10834961,-20.85153008,54.22800064,0.041249805
-0.110107423,-21.35106659,55.04800034,0.04198468
-0.111767578,-21.86259842,55.86800003,0.04267801
-0.113378905,-22.35385895,56.68799973,0.043316591
-0.114941409,-22.76656342,57.50799942,0.043887569
-0.116650393,-23.39375687,58.32799911,0.044509699
-0.118359378,-23.94246864,59.14799881,0.045119534
-0.119921875,-24.39051056,59.9679985,0.045679284
-0.121484372,-24.47607613,60.7879982,0.046374687
-0.123144535,-24.90507698,61.60800171,0.046962487
-0.124853512,-25.34984398,62.4280014,0.047550806
-0.126464845,-25.67522812,63.2480011,0.048150014
-0.127978521,-26.07882309,64.06800079,0.04875283
-0.129687498,-26.58877754,64.88800049,0.049386948
-0.131396489,-26.98275757,65.70800018,0.050133785
-0.133056645,-27.22348595,66.52799988,0.050910832
-0.134619142,-25.90254402,67.34799957,0.052533531
-0.136279297,-25.64373589,68.16799927,0.053648058
-0.137988274,-26.1556282,68.98799896,0.05429432
-0.139599608,-26.46168137,69.80799866,0.054914464
-0.141113283,-26.75061035,70.62799835,0.055539975
-0.142773439,-27.26290321,71.44799805,0.056146495
-0.144580074,-27.84107018,72.26799774,0.056763896
-0.146191407,-28.21162415,73.08799744,0.057349542
-0.147753904,-28.75734138,73.90799713,0.057890091
-0.14941406,-29.22992706,74.72799683,0.058459867
-0.151123051,-29.686409,75.54799652,0.059049249
-0.152783206,-30.13865089,76.36799622,0.059619324
-0.154296882,-30.37210846,77.18800354,0.060143346
-0.155908201,-30.87615967,78.00800323,0.06070127
-0.157617193,-31.31933594,78.82800293,0.061307808
-0.159228512,-31.79340363,79.64800262,0.061910083
-0.160791009,-32.12657547,80.46800232,0.062565734
-0.162402343,-32.44576645,81.28800201,0.063283442
-0.164208977,-32.72816849,82.10800171,0.064030239
-0.165869147,-33.0581665,82.9280014,0.06471487
-0.167431645,-32.98122025,83.7480011,0.065536078
-0.169042964,-33.05005646,84.56800079,0.066307606
-0.170751955,-33.43097305,85.38800049,0.067113258
-0.17241211,-33.83259583,86.20800018,0.067832567
-0.173974608,-34.1556015,87.02799988,0.06849083
-0.175537105,-34.55083084,87.84799957,0.069181238
-0.177294918,-34.85093689,88.66799927,0.069896858
-0.17900391,-35.21572495,89.48799896,0.07055742
-0.180566407,-35.47345734,90.30799866,0.071215109
-0.18217774,-35.8094635,91.12799835,0.071879796
-0.183886717,-36.28731155,91.94799805,0.072624549
-0.185546873,-36.69009781,92.76799774,0.073329422
-0.18710937,-37.11629105,93.58799744,0.074033633
-0.188671882,-37.47867966,94.40799713,0.074712465
-0.190429681,-37.8950882,95.22799683,0.075442702
-0.192041014,-38.14997864,96.04799652,0.076161647
-0.193652348,-38.41453171,96.86799622,0.076839817
-0.195214845,-38.74101257,97.68800354,0.0775433
-0.196972658,-39.12138367,98.50800323,0.07836143
-0.198681635,-39.54477692,99.32800293,0.079240577
-0.200244147,-39.82102203,100.1480026,0.080049729
-0.201806644,-40.21007156,100.9680023,0.08085055
-0.203515621,-40.53667068,101.788002,0.08177125
-0.205224613,-40.707798,102.6080017,0.082635503
-0.20678711,-41.02137375,103.4280014,0.083472973
-0.208398444,-41.1533699,104.2480011,0.084416868
-0.210107421,-41.30090332,105.0680008,0.085409709
-0.211767576,-41.62909317,105.8880005,0.086455882
-0.213427731,-41.65159988,106.7080002,0.087643719
-0.214941407,-41.94873428,107.5279999,0.08865937
-0.216650384,-42.31106949,108.3479996,0.089578309
-0.218359375,-42.59601212,109.1679993,0.090465917
-0.219921872,-42.69837189,109.987999,0.091310125
-0.221435548,-43.08665466,110.8079987,0.09212298
-0.223144525,-43.41126633,111.6279984,0.092966948
-0.224902338,-43.88546753,112.447998,0.093835355
-0.22646485,-44.08210754,113.2679977,0.094718533
-0.228027347,-44.1275177,114.0879974,0.095961121
-0.229785161,-44.08766556,114.9079971,0.09707726
-0.231445316,-36.65077591,115.7279968,0.114671762
-0.233056635,-36.90885544,116.5479965,0.115924391
-0.234619147,-37.27892303,117.3679962,0.116975854
-0.236328124,-37.61014175,118.1880035,0.118061187
-0.238037115,-38.10303879,119.0080032,0.11915317
-0.239648434,-38.58047485,119.8280029,0.120193217
-0.24116211,-38.92243958,120.6480026,0.121185782
-0.242822265,-39.00445557,121.4680023,0.12221979
-0.244580064,-39.13608551,122.288002,0.123348655
-0.246240234,-39.23278427,123.1080017,0.124367987
-0.247753895,-39.39012527,123.9280014,0.12535257
-0.249462901,-39.51431274,124.7480011,0.126436265
-0.251171878,-39.65699387,125.5680008,0.127572755
-0.252783211,-40.01367569,126.3880005,0.128580621
-0.254296872,-40.10874557,127.2080002,0.129568056
-0.255957042,-40.34704971,128.0279999,0.130568209
-0.257666019,-40.49795532,128.8480072,0.131626177
-0.259277353,-40.721241,129.6679993,0.132657777
-0.26083985,-41.13371658,130.4880066,0.133661801
-0.262451184,-41.40847015,131.3079987,0.134715156
-0.264257804,-41.46128082,132.128006,0.13586061
-0.265917974,-41.02721024,132.947998,0.136848306
-0.267431635,-40.88612366,133.7680054,0.13791144
-0.269091805,-41.14541626,134.5879974,0.138970005
-0.270849618,-41.08502579,135.4080048,0.14003308
-0.272460951,-40.9119606,136.2279968,0.140867356
-0.274023449,-41.04889297,137.0480042,0.14181163
-0.275634753,-41.20123672,137.8679962,0.142776014
-0.277392566,-41.37314606,138.6880035,0.143818776
-0.279052736,-41.4330101,139.5079956,0.144780744
-0.280566397,-41.57489395,140.3280029,0.145747879
-0.282177731,-41.7441864,141.147995,0.14673284
-0.283935544,-41.90103149,141.9680023,0.147804152
-0.285595714,-42.17205048,142.7879944,0.148819599
-0.287158211,-42.42799377,143.6080017,0.149818807
-0.288720708,-42.56681824,144.4279938,0.150818349
-0.290478521,-42.70231628,145.2480011,0.151961009
-0.292138662,-33.8960762,146.0679932,0.163291741
-0.29370116,-34.23327637,146.8880005,0.164501718
-0.295263686,-34.4630928,147.7079926,0.165555466
-0.296972663,-34.94885254,148.5279999,0.166649072
-0.29868164,-35.36306763,149.3480072,0.167728329
-0.300292973,-35.67702866,150.1679993,0.168740196
-0.301855471,-35.96339798,150.9880066,0.169697538
-0.303613284,-36.43574524,151.8079987,0.170797735
-0.305273425,-31.37275887,152.628006,0.176790971
-0.306835951,-19.2904129,153.447998,0.19074489
-0.308398448,-19.15937233,154.2680054,0.193600557
-0.310156262,-19.29801941,155.0879974,0.195681059
-0.311865238,-19.35118294,155.9080048,0.198032314
-0.313427736,-19.64517212,156.7279968,0.199535905
-0.315039069,-19.93161583,157.5480042,0.200927563
-0.316748046,-20.16525269,158.3679962,0.202468844
-0.318408216,-20.14894867,159.1880035,0.204138734
-0.320019521,-20.36248779,160.0079956,0.205706077
-0.321533211,-20.45981216,160.8280029,0.207101286
-0.323242188,-20.64855385,161.647995,0.20852391
-0.324951165,-20.82133293,162.4680023,0.209958656
-0.326513662,-21.06949615,163.2879944,0.211242223
-0.328027352,-21.24062347,164.1080017,0.212433297
-0.329785165,-21.56966591,164.9279938,0.213634194
-0.331494142,-21.76860619,165.7480011,0.21485574
-0.333105476,-21.57781029,166.5679932,0.216688655
-0.334667973,-21.72899437,167.3880005,0.21791787
-0.336328114,-21.76832199,168.2079926,0.219303474
-0.33803712,-21.95652771,169.0279999,0.22069877
-0.339648424,-22.03807449,169.8480072,0.222014656
-0.341210951,-22.34321594,170.6679993,0.22325902
-0.342871092,-22.58823776,171.4880066,0.224553063
-0.344628905,-22.81892967,172.3079987,0.225894531
-0.346240238,-22.89684105,173.128006,0.227189361
-0.347802736,-23.01319122,173.947998,0.228438352
-0.349511713,-23.15785027,174.7680054,0.229768906
-0.351220689,-23.47556496,175.5879974,0.231116486
-0.352832023,-23.66754913,176.4080048,0.232431281
-0.35439452,-23.86597252,177.2279968,0.233735016
-0.356005854,-24.10477448,178.0480042,0.234946259
-0.357714831,-24.35654831,178.8679962,0.236186388
-0.359326164,-24.48700523,179.6880035,0.237387401
-0.360888662,-24.43582344,180.5079956,0.238979643
-0.362499995,-24.66082573,181.3280029,0.240271693
-0.364306645,-24.99706078,182.147995,0.241661604
-0.365966785,-25.23219681,182.9680023,0.243031347
-0.367529283,-25.46197891,183.7879944,0.244353228
-0.369140616,-25.60602188,184.6080017,0.245768955
-0.370849622,-21.71600151,185.4279938,0.253892678
-0.372509763,-22.03798294,186.2480011,0.255518447
-0.374023424,-22.10621452,187.0679932,0.256940548
-0.375634758,-22.3459053,187.8880005,0.258330576
-0.377392571,-22.62312889,188.7079926,0.259797904
-0.379052741,-22.84397316,189.5279999,0.261189911
-0.380615238,-23.0779171,190.3480072,0.262619957
-0.382226572,-23.16213989,191.1679993,0.263943075
-0.383984385,-23.30197716,191.9880066,0.265333074
-0.385644526,-23.47106743,192.8079987,0.26667476
-0.387207023,-23.58622932,193.628006,0.268013799
-0.38876952,-23.525877,194.447998,0.269968354
-0.390527333,-23.71489334,195.2680054,0.271412544
-0.392138667,-23.92725945,196.0879974,0.272801757
-0.393750001,-23.9118557,196.9080048,0.274230842
-0.395312498,-23.99635506,197.7279968,0.27562055
-0.397070311,-24.04090309,198.5480042,0.277164945
-0.398779288,-24.12552834,199.3679962,0.278737978
-0.400341785,-24.18034935,200.1880035,0.280214765
-0.401904283,-24.24926186,201.0079956,0.281751069
-0.403613289,-24.53429413,201.8280029,0.283267174
-0.405322266,-24.69699287,202.647995,0.284838112
-0.406884763,-24.72354126,203.4680023,0.286581868
-0.40844726,-24.40912819,204.2879944,0.288734183
-0.410205073,-24.65279198,205.1080017,0.29047209
-0.411865243,-24.76178741,205.9279938,0.292058015
-0.413476577,-24.92192268,206.7480011,0.293702382
-0.415039074,-25.04884148,207.5679932,0.295094651
-0.416748051,-25.24019051,208.3880005,0.29653628
-0.418408192,-25.37233925,209.2079926,0.297979481
-0.420019525,-25.43772697,210.0279999,0.299648236
-0.421533216,-25.5530262,210.8480072,0.301005261
-0.423242192,-25.54056931,211.6679993,0.302437431
-0.424951169,-25.81259918,212.4880066,0.30393622
-0.426562503,-25.90820503,213.3079987,0.305345486
-0.428125,-26.13853645,214.128006,0.306616043
-0.429833977,-26.35384369,214.947998,0.307979382
-0.431542983,-26.28658485,215.7680054,0.309806026
-0.433154288,-26.36442566,216.5879974,0.311265176
-0.434716785,-26.42145538,217.4080048,0.312661985
-0.436425791,-26.47821999,218.2279968,0.314168836
-0.438134768,-26.65957069,219.0480042,0.31567362
-0.439746102,-26.92833328,219.8679962,0.316990569
-0.441259763,-27.0239048,220.6880035,0.318226957
-0.442919933,-26.99739456,221.5079956,0.320075342
-0.444677746,-27.16400719,222.3280029,0.321576459
-0.44628905,-27.27778244,223.147995,0.323052227
-0.447851577,-27.38138962,223.9680023,0.324361434
-0.449511717,-27.47475052,224.7879944,0.325868576
-0.451220694,-27.72440529,225.6080017,0.327414746
-0.452832028,-27.76716614,226.4279938,0.328797963
-0.454394525,-27.98628616,227.2480011,0.33021823
-0.456005859,-28.00995827,228.0679932,0.331948686
-0.457763672,-28.04239082,228.8880005,0.333493866
-0.459375005,-28.15686417,229.7079926,0.334931246
-0.460888667,-28.25916862,230.5279999,0.336313795
-0.462597643,-28.37456894,231.3480072,0.337834004
-0.464355457,-28.59407425,232.1679993,0.339322258
-0.46596679,-28.70387268,232.9880066,0.340703875
-0.467529288,-28.45658684,233.8079987,0.342525018
-0.469189457,-28.08115768,234.628006,0.344279775
-0.470898434,-28.22089005,235.447998,0.345829554
-0.472558604,-28.30641747,236.2680054,0.347238878
-0.474072265,-28.40883636,237.0879974,0.348597212
-0.475732435,-28.66595078,237.9080048,0.349969574
-0.477441412,-28.69591904,238.7279968,0.351568888
-0.479101553,-28.85356903,239.5480042,0.352953648
-0.48066405,-28.92715645,240.3679962,0.354243122
-0.482275384,-28.97757912,241.1880035,0.355560565
-0.484033197,-29.10756111,242.0079956,0.356924196
-0.485693366,-29.16601753,242.8280029,0.358236575
-0.487255864,-29.25665665,243.647995,0.3595163
-0.488769554,-29.40350533,244.4680023,0.360780483
-0.490527367,-28.96151733,245.2879944,0.363483414
-0.492187508,-29.19342613,246.1080017,0.365175656
-0.493749976,-29.16590881,246.9279938,0.366625027
-0.495312503,-29.27343178,247.7480011,0.368083769
-0.497070316,-29.2942009,248.5679932,0.369623769
-0.498779293,-29.43392754,249.3880005,0.371133588
-0.500341819,-29.50813866,250.2079926,0.372629438
-0.501904287,-29.69357109,251.0279999,0.374012481
-0.503710937,-29.84194183,251.8480072,0.375426462
-0.505371077,-30.06331825,252.6679993,0.376815995
-0.506933604,-29.95247269,253.4880066,0.378194964
-0.508496072,-29.94676399,254.3079987,0.379502744
-0.510253885,-29.99006844,255.128006,0.380913407
-0.511914084,-30.00214767,255.947998,0.382287195
-0.513525389,-30.02954102,256.7680054,0.38360781
-0.515087915,-30.18553162,257.5880127,0.384940999
-0.516796892,-28.80524826,258.4079895,0.387412292
-0.518505869,-22.68894005,259.2279968,0.393794209
-0.520068337,-22.80522919,260.0480042,0.395056792
-0.521630864,-22.71543503,260.8680115,0.396388321
-0.523291004,-22.75885582,261.6879883,0.397857802
-0.524999981,-22.83542252,262.5079956,0.399324956
-0.526562508,-22.96568871,263.3280029,0.400710589
-0.528173812,-23.05005836,264.1480103,0.402064587
-0.529882789,-23.30452919,264.9679871,0.40343657
-0.531591824,-23.38497925,265.7879944,0.404844322
-0.533203129,-23.19794464,266.6080017,0.406741456
-0.534765597,-19.92517662,267.428009,0.412353344
-0.536474632,-19.91932678,268.2479858,0.414029666
-0.538134773,-19.9119873,269.0679932,0.415795454
-0.539746077,-19.86719322,269.8880005,0.417416741
-0.541259767,-19.9389801,270.7080078,0.418877346
-0.542968744,-20.04178238,271.5280151,0.420389813
-0.544726558,-19.94740295,272.3479919,0.422357698
-0.546337862,-19.87154579,273.1679993,0.424084283
-0.547900388,-20.03391075,273.9880066,0.425549573
-0.549609365,-20.12697792,274.8080139,0.427120773
-0.551269506,-20.12125587,275.6279907,0.428748172
-0.552929705,-20.0496788,276.447998,0.430218264
-0.554443337,-20.18435097,277.2680054,0.43166164
-0.5560547,-19.74313736,278.0880127,0.434210786
-0.557812513,-19.37160492,278.9079895,0.436396251
-0.559374981,-19.24901009,279.7279968,0.438601157
-0.560937508,-19.16135406,280.5480042,0.440135744
-0.562597648,-19.27289391,281.3680115,0.441776123
-0.564355461,-19.32415199,282.1879883,0.443391618
-0.566015602,-19.43608093,283.0079956,0.44497865
-0.567578129,-19.3086586,283.8280029,0.446480146
-0.569189433,-19.30171013,284.6480103,0.447956263
-0.570947246,-19.34847641,285.4679871,0.44951131
-0.572558609,-19.16685295,286.2879944,0.451535714
-0.574121077,-19.28656769,287.1080017,0.453128159
-0.57573244,-19.34852791,287.928009,0.454701978
-0.577490253,-19.49461555,288.7479858,0.456313661
-0.579150394,-19.60035896,289.5679932,0.457860151
-0.580712862,-19.51647568,290.3880005,0.459311443
-0.582324225,-19.53481293,291.2080078,0.460831448
-0.584082038,-19.60804558,292.0280151,0.462309137
-0.585693342,-19.70876503,292.8479919,0.463775534
-0.587255869,-19.57349968,293.6679993,0.465659221
-0.588867173,-19.76634407,294.4880066,0.467083795
-0.59057615,-19.95523453,295.3080139,0.468647078
-0.592236349,-20.00981903,296.1279907,0.470174738
-0.593798817,-19.94927597,296.947998,0.471608684
-0.595361344,-19.96909714,297.7680054,0.472985703
-0.597167993,-19.93021584,298.5880127,0.474539207
-0.59887697,-20.07327271,299.4079895,0.475896348
-0.600390602,-20.08727074,300.2279968,0.477233698
-0.601953128,-20.00937843,301.0480042,0.479015172
-0.603759778,-20.22299957,301.8680115,0.480627787
-0.605419918,-20.33452606,302.6879883,0.482133502
-0.606933609,-20.38952446,303.5079956,0.483624957
-0.608544913,-20.38155937,304.3280029,0.485102792
-0.610302726,-20.46342659,305.1480103,0.486653211
-0.611962867,-20.49149132,305.9679871,0.488121004
-0.61357423,-20.38261604,306.7879944,0.489939121
-0.615136698,-20.49283791,307.6080017,0.491350947
-0.616845675,-20.72491646,308.428009,0.492838328
-0.618505874,-20.76353264,309.2479858,0.494382635
-0.620068342,-20.84669876,310.0679932,0.495787477
-0.621630868,-20.73501015,310.8880005,0.497181842
-0.623339845,-20.82533646,311.7080078,0.498613808
-0.625048822,-20.81445885,312.5280151,0.500066439
-0.626611349,-20.95817757,313.3479919,0.501449278
-0.628173817,-21.04720879,314.1679993,0.502787007
-0.62993163,-21.15773773,314.9880066,0.504238764
-0.631640607,-21.02992249,315.8080139,0.506227487
-0.63325197,-21.03794098,316.6279907,0.507696299
-0.634765602,-21.11124802,317.447998,0.509100792
-0.636474637,-21.09372139,318.2680054,0.510595855
-0.638183614,-21.22813797,319.0880127,0.512163097
-0.639794918,-21.31778908,319.9079895,0.513631501
-0.641357445,-21.47710991,320.7279968,0.515049323
-0.643017585,-21.60266113,321.5480042,0.516507833
-0.644775399,-21.72369576,322.3680115,0.518013316
-0.646386703,-21.63492203,323.1879883,0.51940704
-0.647949229,-21.61187363,324.0079956,0.520751113
-0.64960937,-21.40799904,324.8280029,0.522720045
-0.651318347,-21.53371048,325.6480103,0.524295028
-0.65292971,-21.54870415,326.4679871,0.525748124
-0.654443342,-21.7495594,327.2879944,0.527134223
-0.656103541,-21.93472862,328.1080017,0.528587901
-0.657812518,-21.95633316,328.928009,0.530142337
-0.659423822,-21.97094154,329.7479858,0.531509286
-0.660986349,-21.9708271,330.5679932,0.532885198
-0.662646489,-21.9797039,331.3880005,0.534306688
-0.664404302,-22.10050392,332.2080078,0.535797619
-0.666064443,-19.132967,333.0280151,0.537591579
-0.667578133,-19.22363281,333.8479919,0.538932101
-0.669238274,-19.41133308,334.6679993,0.54028834
-0.670996087,-19.57714462,335.4880066,0.541717978
-0.672656228,-19.29476547,336.3080139,0.54396491
-0.674169918,-19.34374619,337.1279907,0.545260846
-0.675781223,-19.47522545,337.947998,0.546621566
-0.677587872,-19.6776638,338.7680054,0.548128213
-0.679199235,-19.87199211,339.5880127,0.549519609
-0.680761703,-19.86210442,340.4079895,0.550918281
-0.682373066,-20.05701256,341.2279968,0.552323647
-0.684082042,-20.1102314,342.0480042,0.553790189
-0.685742183,-20.11759377,342.8680115,0.555231061
-0.687353488,-12.92331123,343.6879883,0.568782096
-0.688867178,-12.98395252,344.5079956,0.570460164
-0.690624991,-13.21794701,345.3280029,0.572184625
-0.692285132,-13.37784004,346.1480103,0.573840283
-0.693798822,-13.45776749,346.9679871,0.575445825
-0.695410185,-13.39682007,347.7879944,0.577125291
-0.697167998,-13.39850426,348.6080017,0.578787178
-0.698828138,-13.44865799,349.428009,0.580342137
-0.700439443,-13.49700832,350.2479858,0.581805711
-0.702001969,-13.60928631,351.0679932,0.58329606
-0.703759782,-13.60947704,351.8880005,0.584935246
-0.705419923,-13.58051968,352.7080078,0.586679613
-0.70698245,-13.72537613,353.5280151,0.588094466
-0.708544918,-13.71611404,354.3479919,0.589465781
-0.710351567,-13.72082901,355.1679993,0.590977317
-0.712011708,-13.71090317,355.9880066,0.592445431
-0.713574234,-13.79528522,356.8080139,0.593874545
-0.715185539,-13.82463741,357.6279907,0.595252437
-0.716894516,-13.88949394,358.447998,0.596751983
-0.718554715,-14.06183243,359.2680054,0.59822388
-0.720117183,-14.17146015,360.0880127,0.599633437
-0.721679709,-14.17621613,360.9079895,0.600979663
-0.723388686,-14.26692295,361.7279968,0.602459942
-0.725048827,-14.28403091,362.5480042,0.603934343
-0.726660131,-14.29694939,363.3680115,0.605370442
-0.728222658,-14.32495785,364.1879883,0.606761314
-0.729931635,-14.40480042,365.0079956,0.608277856
-0.731689448,-14.41310978,365.8280029,0.609795738
-0.733300752,-14.57366371,366.6480103,0.61122881
-0.734814443,-14.71803951,367.4679871,0.612585864
-0.73652342,-14.47264957,368.2879944,0.614942168
-0.738232397,-14.57279301,369.1080017,0.616534497
-0.739794923,-14.52739429,369.928009,0.618051155
-0.741357449,-14.59378052,370.7479858,0.619511644
-0.743066426,-14.58707905,371.5679932,0.621070794
-0.744775403,-14.57003403,372.3880005,0.622544496
-0.746435544,-14.71509933,373.2080078,0.624022388
-0.747949234,-14.6864624,374.0280151,0.625822227
-0.749707047,-14.79535294,374.8479919,0.627424743
-0.751367188,-14.93685818,375.6679993,0.629024114
-0.752978493,-15.01846313,376.4880066,0.630502647
-0.754492183,-14.95830822,377.3080139,0.631933799
-0.756152323,-14.93696499,378.1279907,0.633360818
-0.7578613,-14.87615013,378.947998,0.634886557
-0.759472663,-14.98620892,379.7680054,0.636292272
-0.761035131,-15.01255894,380.5880127,0.637634192
-0.76269533,-15.09046364,381.4079895,0.639054808
-0.764453143,-15.1559763,382.2279968,0.640570244
-0.766113284,-15.30307102,383.0480042,0.641991326
-0.767675752,-15.36263084,383.8680115,0.643365667
-0.769287115,-15.40572929,384.6879883,0.644803571
-0.771044928,-15.22902298,385.5079956,0.646949688
-0.772656233,-15.27050781,386.3280029,0.648501038
-0.774218759,-15.22538948,387.1480103,0.649947324
-0.775830064,-15.26071262,387.9679871,0.651451992
-0.777587877,-15.39723969,388.7879944,0.653035881
-0.779248076,-15.34409523,389.6080017,0.654505799
-0.780761708,-15.52149391,390.428009,0.655909709
-0.782421848,-15.5926075,391.2479858,0.65733731
-0.784179661,-15.63419342,392.0679932,0.658874807
-0.785791024,-15.67412853,392.8880005,0.660340302
-0.787353492,-15.78223228,393.7080078,0.661724887
-0.788916019,-15.69490719,394.5280151,0.663135143
-0.790673832,-15.73877525,395.3479919,0.664644933
-0.792333973,-15.73367882,396.1679993,0.666122709
-0.793896499,-15.70929909,396.9880066,0.667567714
-0.795507804,-15.65453053,397.8080139,0.669633853
-0.797265617,-15.59837532,398.6279907,0.671368849
-0.798925757,-15.79422188,399.447998,0.672979862
-0.800488284,-15.79502773,400.2680054,0.674547977
-0.80205081,-15.9236412,401.0880127,0.676127209
-0.803808565,-15.99298382,401.9079895,0.677788863
-0.805468764,-15.98446083,402.7279968,0.679358258
-0.807031232,-15.95175362,403.5480042,0.680834928
-0.808642595,-15.81612778,404.3680115,0.682540936
-0.810400408,-15.88102818,405.1879883,0.684428087
-0.812060549,-15.98227024,406.0079956,0.686063664
-0.813623075,-16.13230515,406.8280029,0.687644351
-0.815185544,-16.10101318,407.6480103,0.689167879
-0.816943357,-16.31948471,408.4679871,0.690750428
-0.818603497,-16.18784904,409.2879944,0.69258787
-0.820166024,-16.22476387,410.1080017,0.694260059
-0.821679714,-16.20473289,410.928009,0.695859722
-0.823437527,-16.06518364,411.7479858,0.698685704
-0.825146504,-15.9666605,412.5679932,0.700551493
-0.826708972,-16.03630066,413.3880005,0.702134974
-0.828271499,-16.04985046,414.2080078,0.703674741
-0.830029312,-16.25667191,415.0280151,0.705317419
-0.831738289,-16.25943756,415.8479919,0.70688338
-0.833300757,-16.24527931,416.6679993,0.708573963
-0.834863284,-16.38876724,417.4880066,0.710107677
-0.836572261,-16.32016182,418.3080139,0.711751636
-0.838281238,-16.36284828,419.1279907,0.713359448
-0.8398926,-16.28560448,419.947998,0.714826398
-0.841406232,-16.3049736,420.7680054,0.71620167
-0.843115209,-16.33582687,421.5880127,0.717704766
-0.844824244,-16.38545799,422.4079895,0.719239295
-0.846484385,-16.53902054,423.2279968,0.720700365
-0.847998075,-16.51717758,424.0480042,0.722115044
-0.849707052,-16.45667648,424.8680115,0.724071113
-0.851416029,-16.66062546,425.6879883,0.725588121
-0.852978497,-16.64491272,426.5079956,0.727069273
-0.854541024,-16.64054108,427.3280029,0.728512066
-0.856201164,-16.65348816,428.1480103,0.729980413
-0.857910141,-16.52544212,428.9679871,0.731494918
-0.859521504,-16.60744858,429.7879944,0.732843648
-0.861035136,-16.66919327,430.6080017,0.734211411
-0.862744113,-16.71154213,431.428009,0.735686335
-0.864501926,-16.699543,432.2479858,0.737661903
-0.866113289,-16.8467083,433.0679932,0.739165116
-0.867675757,-16.82596397,433.8880005,0.740596792
-0.869335956,-16.86861229,434.7080078,0.742114556
-0.871093769,-16.8485508,435.5280151,0.743693206
-0.872705074,-16.84385109,436.3479919,0.745160796
-0.8742676,-16.83863068,437.1679993,0.746580481
-0.875927741,-16.8502903,437.9880066,0.748039572
-0.877636718,-16.93554497,438.8080139,0.749568397
-0.879296858,-17.03284073,439.6279907,0.751064799
-0.880810549,-17.02709961,440.447998,0.752673019
-0.882421853,-17.08739853,441.2680054,0.754333218
-0.884179666,-17.20251846,442.0880127,0.75589522
-0.885839865,-17.15374947,442.9079895,0.757392612
-0.887402333,-17.23238182,443.7279968,0.758837385
-0.88896486,-17.14009285,444.5480042,0.76027168
-0.890722673,-17.13323593,445.3680115,0.761798932
-0.892333977,-17.18258286,446.1879883,0.763290387
-0.893896504,-17.29004478,447.0079956,0.764695928
-0.895507808,-17.32515907,447.8280029,0.766080688
-0.897265621,-17.47293854,448.6480103,0.767599442
-0.898925762,-17.57203484,449.4679871,0.769075588
-0.900488289,-17.53474998,450.2879944,0.770483399
-0.902099593,-17.54265213,451.1080017,0.771880616
-0.903857406,-17.45049858,451.928009,0.773505191
-0.905517605,-17.42570686,452.7479858,0.775389315
-0.907080073,-17.48651886,453.5679932,0.776772504
-0.9086426,-17.46209717,454.3880005,0.778193353
-0.910400413,-17.64167213,455.2080078,0.779712922
-0.91210939,-17.69618988,456.0280151,0.781210023
-0.913671858,-17.74425125,456.8479919,0.782618241
-0.915234385,-17.78894424,457.6679993,0.783985306
-0.916992198,-17.81950188,458.4880066,0.785470998
-0.918652338,-17.7436924,459.3080139,0.787030847
-0.920214865,-17.64513206,460.1279907,0.788759033
-0.921777333,-17.71583176,460.947998,0.790146529
-0.92348631,-17.74695587,461.7680054,0.791653001
-0.925146509,-17.9072628,462.5880127,0.793159707
-0.926757813,-18.02430916,463.4079895,0.794543652
-0.928271504,-18.06124496,464.2279968,0.795903266
-0.930029317,-18.11587715,465.0480042,0.79733989
-0.931738294,-18.01057434,465.8680115,0.798803172
-0.933349598,-18.05992126,466.6879883,0.800185138
-0.934912125,-17.85169601,467.5079956,0.801827875
-0.936621102,-17.94750786,468.3280029,0.803473464
-0.938281242,-18.08830833,469.1480103,0.804954499
-0.939892605,-18.15144157,469.9679871,0.80634834
-0.941455073,-18.30058861,470.7879944,0.807732809
-0.94316405,-18.40925217,471.6080017,0.809178222
-0.944873027,-18.43788147,472.428009,0.810663565
-0.94648439,-18.43410301,473.2479858,0.812043319
-0.948046858,-18.36016464,474.0679932,0.813375926
-0.949755835,-18.34405708,474.8880005,0.814802304
-0.95146487,-18.49992371,475.7080078,0.816260173
-0.953076174,-18.34445381,476.5280151,0.818099419
-0.954589865,-18.47027779,477.3479919,0.819596928
-0.956250005,-18.55662155,478.1679993,0.821097405
-0.957958982,-18.59860229,478.9880066,0.822802423
-0.959570287,-18.61344147,479.8080139,0.824616756
-0.961083977,-18.57616997,480.6279907,0.82654017
-0.962744118,-18.5284977,481.447998,0.828390475
-0.964550767,-18.45671844,482.2680054,0.830354518
-0.966210966,-18.43792534,483.0880127,0.832049991
-0.967724598,-18.4713707,483.9079895,0.833701808
-0.969384739,-18.55150604,484.7279968,0.835302344
-0.971093774,-18.61089134,485.5480042,0.836984196
-0.972753915,-18.72382164,486.3680115,0.838603359
-0.974267605,-18.75731087,487.1879883,0.840153196
-0.975878909,-18.80542946,488.0079956,0.842500303
-0.977685559,-18.52028084,488.8280029,0.84427197
-0.979296863,-18.67897415,489.6480103,0.845797244
-0.98085939,-18.68002319,490.4679871,0.847307383
-0.982519588,-18.74112701,491.2879944,0.848851167
-0.984228565,-18.87134171,492.1080017,0.850505952
-0.98583987,-18.89935875,492.928009,0.852073135
-0.987402396,-18.87553787,493.7479858,0.853586418
-0.989013701,-18.95137405,494.5679932,0.855046499
-0.990722678,-19.02418709,495.3880005,0.856602623
-0.99238276,-19.07556725,496.2080078,0.858125917
-0.993945287,-19.09127998,497.0280151,0.859547697
-0.995556591,-18.98228836,497.8479919,0.86103013
-0.997314462,-18.9958744,498.6679993,0.862630957
-0.998974661,-19.00059509,499.4880066,0.864215428
-1.000537071,-19.09529495,500.3080139,0.865667593
-1.002148492,-19.19705582,501.1279907,0.867102237
-1.003857469,-19.31260109,501.947998,0.868634437
-1.005566446,-19.31875992,502.7680054,0.870142947
-1.007128856,-19.16576576,503.5880127,0.872502394
-1.008691383,-19.18605995,504.4079895,0.874014455
-1.010449254,-19.20538902,505.2279968,0.875570928
-1.012158231,-19.24405479,506.0480042,0.877146318
-1.013720757,-19.12953758,506.8680115,0.878666702
-1.015283167,-19.31221581,507.6879883,0.88015513
-1.016992144,-19.4947834,508.5079956,0.881778949
-1.018652343,-19.48829079,509.3280029,0.883365457
-1.02021487,-19.57326508,510.1480103,0.884859066
-1.021777396,-19.6499176,510.9679871,0.88630605
-1.023486373,-19.69501877,511.7879944,0.887865026
-1.02519535,-19.65068817,512.6079712,0.88939257
-1.026806654,-19.61072731,513.4279785,0.890868134
-1.028369181,-19.62379074,514.2479858,0.892310345
-1.030078158,-19.59339142,515.0679932,0.893853721
-1.031787135,-19.71245384,515.8880005,0.89538371
-1.033398439,-19.77695084,516.7080078,0.896790065
-1.034960966,-19.80080986,517.5280151,0.898202648
-1.036621048,-19.92618752,518.3480225,0.899698003
-1.038378919,-19.6571312,519.1680298,0.902142609
-1.039941446,-19.67590141,519.9879761,0.90372382
-1.041455078,-19.77100754,520.8079834,0.90509461
-1.043212833,-19.73203087,521.6279907,0.906630768
-1.044921926,-19.76989365,522.447998,0.908183167
-1.046533231,-19.91265488,523.2680054,0.909632363
-1.048095757,-19.9808197,524.0880127,0.911085284
-1.049804734,-20.06581497,524.90802,0.912641
-1.051464817,-20.07416725,525.7280273,0.914171862
-1.053076121,-20.05246735,526.5479736,0.915667275
-1.054589869,-20.02766609,527.367981,0.917155237
-1.056298846,-19.99606323,528.1879883,0.918762526
-1.057958929,-20.05267334,529.0079956,0.920431863
-1.059619128,-20.04833794,529.8280029,0.921984029
-1.06113276,-20.18540382,530.6480103,0.923445856
-1.062792959,-20.32283211,531.4680176,0.924951106
-1.06455083,-20.43344307,532.2880249,0.926553563
-1.066210913,-20.03273392,533.1079712,0.928998168
-1.067773439,-20.05589867,533.9279785,0.930764189
-1.069433638,-20.10422707,534.7479858,0.932405994
-1.071142615,-20.07665634,535.5679932,0.934144598
-1.072802697,-20.23177719,536.3880005,0.935744552
-1.074316446,-20.25326538,537.2080078,0.937269535
-1.075976528,-20.45021057,538.0280151,0.938881363
-1.0777344,-20.39834404,538.8480225,0.940597733
-1.079345704,-20.50476646,539.6680298,0.942247105
-1.080908231,-20.43459511,540.4879761,0.943898631
-1.082519535,-20.43660164,541.3079834,0.94554614
-1.08427729,-20.42321396,542.1279907,0.947274268
-1.085937489,-20.21997261,542.947998,0.949976093
-1.087451121,-20.27399254,543.7680054,0.951730355
-1.089062542,-20.39110947,544.5880127,0.953296898
-1.090771519,-20.48906136,545.40802,0.954951684
-1.092431601,-20.58963394,546.2280273,0.956614094
-1.093994128,-20.511549,547.0479736,0.9581669
-1.095556654,-20.43992996,547.867981,0.959713187
-1.097363303,-20.39607811,548.6879883,0.961555401
-1.098974608,-20.38255882,549.5079956,0.963740807
-1.100585912,-20.4868412,550.3280029,0.965321378
-1.102148439,-20.60559464,551.1480103,0.966868014
-1.103955088,-20.69338417,551.9680176,0.96853578
-1.105615287,-20.77791405,552.7880249,0.970144582
-1.107128919,-20.76258469,553.6079712,0.971655245
-1.108740224,-20.68154335,554.4279785,0.973147049
-1.110546873,-20.67220879,555.2479858,0.974718889
-1.112158177,-20.66858673,556.0679932,0.97620039
-1.113720704,-20.79776764,556.8880005,0.977638992
-1.115332008,-20.79669571,557.7080078,0.979093602
-1.11708988,-20.75574493,558.5280151,0.98162808
-1.118749962,-20.76509857,559.3480225,0.9833941
-1.120263711,-20.76784134,560.1680298,0.984863611
-1.121826121,-20.79764748,560.9879761,0.986344647
-1.123583992,-20.84296036,561.8079834,0.987928943
-1.125244191,-20.8561306,562.6279907,0.989532215
-1.126806601,-20.91952324,563.447998,0.991073903
-1.128369127,-21.00908279,564.2680054,0.992570072
-1.130126999,-21.08733368,565.0880127,0.994099653
-1.131835976,-21.14093208,565.90802,0.99566672
-1.13344728,-20.89717293,566.7280273,0.99816022
-1.134960912,-20.92108917,567.5479736,0.999793177
-1.136718784,-20.95987892,568.367981,1.001418568
-1.138378866,-20.93248177,569.1879883,1.003003097
-1.139990287,-20.98415565,570.0079956,1.004567952
-1.141503919,-21.13233566,570.8280029,1.006039092
-1.143261674,-21.24192429,571.6480103,1.007581712
-1.144970651,-21.33633423,572.4680176,1.00915134
-1.146582072,-21.33465195,573.2880249,1.010987558
-1.148144482,-21.26854897,574.1079712,1.012398629
-1.149853459,-20.98742867,574.9279785,1.014689682
-1.151562552,-21.07937622,575.7479858,1.016377006
-1.153124962,-21.06310272,576.5679932,1.017909381
-1.15463871,-21.23174858,577.3880005,1.019340008
-1.156347687,-21.33364487,578.2080078,1.020897878
-1.158056664,-21.35042572,579.0280151,1.022476936
-1.159619191,-21.46767235,579.8480225,1.023951801
-1.161181601,-21.48099899,580.6680298,1.02538499
-1.1628418,-21.4753418,581.4879761,1.026941929
-1.164648449,-21.4785862,582.3079834,1.028849976
-1.166259754,-21.51527786,583.1279907,1.030354411
-1.16782228,-21.52440071,583.947998,1.031813677
-1.169482479,-21.75907135,584.7680054,1.033283304
-1.171191456,-21.69334221,585.5880127,1.034800895
-1.17280276,-21.81738091,586.40802,1.036276808
-1.174365287,-21.83919334,587.2280273,1.037643757
-1.175976591,-21.76812172,588.0479736,1.039084629
-1.177734346,-21.87326813,588.867981,1.040613628
-1.179394545,-21.76637268,589.6879883,1.042111311
-1.180908177,-21.84222603,590.5079956,1.043554978
-1.182568376,-21.92084885,591.3280029,1.045042067
-1.184326131,-22.01385117,592.1480103,1.04663719
-1.185937552,-22.01832962,592.9680176,1.048156875
-1.187499962,-22.19259453,593.7880249,1.049611368
-1.189111383,-22.09934235,594.6079712,1.051039668
-1.19082036,-22.2005024,595.4279785,1.052575652
-1.192480442,-22.18463898,596.2479858,1.054058899
-1.194042969,-22.06251335,597.0679932,1.056220615
-1.195654273,-21.91819,597.8880005,1.057966845
-1.197412144,-22.03359795,598.7080078,1.059560687
-1.199072227,-22.20324135,599.5280151,1.061073155
-1.200634753,-22.15765953,600.3480225,1.062544761
-1.20219728,-22.36539268,601.1680298,1.063989126
-1.203955035,-22.37075424,601.9879761,1.065538381
-1.205615234,-22.44950294,602.8079834,1.067032921
-1.20717776,-22.35706711,603.6279907,1.06840604
-1.208789065,-22.36584282,604.447998,1.069746213
-1.210546819,-22.36532211,605.2680054,1.071143313
-1.212207018,-22.49759865,606.0880127,1.072535175
-1.213769545,-22.56829643,606.90802,1.073888503
-1.215332071,-22.52715111,607.7280273,1.075238921
-1.217089826,-22.62630463,608.5479736,1.076710294
-1.218750025,-22.68169403,609.367981,1.078165602
-1.220312552,-22.65740204,610.1879883,1.079565031
-1.221826184,-22.66149902,611.0079956,1.080921502
-1.223583939,-22.6401844,611.8280029,1.082404051
-1.225292915,-22.74898911,612.6480103,1.083916752
-1.226855442,-22.73055077,613.4680176,1.085331198
-1.228417968,-22.86487007,614.2880249,1.086747739
-1.230224618,-22.62880707,615.1079712,1.08948315
-1.231884817,-22.71375656,615.9279785,1.091339276
-1.233447227,-22.81521225,616.7479858,1.092755119
-1.235009753,-22.89150047,617.5679932,1.094138133
-1.23671873,-22.86366463,618.3880005,1.095653861
-1.238427707,-22.82827377,619.2080078,1.097178436
-1.240039011,-22.87505531,620.0280151,1.09860464
-1.24155276,-22.87992096,620.8480225,1.100004767
-1.243310515,-23.1862812,621.6680298,1.101440168
-1.245019492,-23.17871857,622.4879761,1.10287033
-1.246630913,-23.13929939,623.3079834,1.104590949
-1.248144545,-23.16786957,624.1279907,1.106174313
-1.2499023,-23.23381805,624.947998,1.107657794
-1.251562499,-23.22082329,625.7680054,1.109203789
-1.253173803,-23.24656296,626.5880127,1.1106733
-1.254687551,-23.22068024,627.40802,1.112069585
-1.256347634,-23.28280449,628.2280273,1.11354515
-1.258056611,-23.37058067,629.0479736,1.114997896
-1.259667915,-23.45567131,629.867981,1.116358559
-1.261230442,-23.50399208,630.6879883,1.117663225
-1.262890641,-23.61422729,631.5079956,1.119033201
-1.264648396,-23.63258934,632.3280029,1.120444387
-1.266259816,-23.52288818,633.1480103,1.12177548
-1.267822227,-23.60710716,633.9680176,1.123037306
-1.269531203,-23.59015465,634.7880249,1.124410657
-1.27124018,-23.62997818,635.6079712,1.12582196
-1.272851601,-23.72628021,636.4279785,1.127150608
-1.274414011,-23.59126472,637.2479858,1.129232231
-1.27607421,-23.63707733,638.0679932,1.131156692
-1.277832082,-23.72771835,638.8880005,1.132837264
-1.279443386,-23.72534943,639.7080078,1.134427963
-1.280957018,-23.7482872,640.5280151,1.135903411
-1.282617217,-23.78359032,641.3480225,1.137417043
-1.284374972,-23.75914764,642.1680298,1.139007509
-1.285986276,-23.90786171,642.9879761,1.140575041
-1.287548803,-23.92588997,643.8079834,1.142024412
-1.289160107,-24.16935539,644.6279907,1.143485191
-1.290869084,-24.26864052,645.447998,1.145047718
-1.292529283,-24.11530113,646.2680054,1.14691339
-1.294042915,-24.03031731,647.0880127,1.148682903
-1.295654336,-24.13929367,647.90802,1.150250551
-1.297412091,-24.03416443,648.7280273,1.151884557
-1.29907229,-24.22272491,649.5479736,1.153492136
-1.300634816,-24.2716198,650.367981,1.154996105
-1.302246121,-24.36116791,651.1879883,1.156466315
-1.304003876,-24.42573929,652.0079956,1.157998107
-1.305664075,-24.50520134,652.8280029,1.159428735
-1.307226601,-24.42652512,653.6480103,1.160749118
-1.308837906,-24.4185257,654.4680176,1.162114786
-1.31059566,-24.36051941,655.2880249,1.163580222
-1.312255859,-24.46306229,656.1079712,1.164964167
-1.313818386,-24.54784393,656.9279785,1.166278031
-1.315380912,-24.63415718,657.7479858,1.167546143
-1.317138667,-24.73673439,658.5679932,1.168916118
-1.318798866,-24.6126442,659.3880005,1.170596108
-1.320361276,-24.51467896,660.2080078,1.172719523
-1.321923803,-24.4842701,661.0280151,1.174171572
-1.32363278,-24.58710289,661.8480225,1.175636426
-1.325292978,-24.61054039,662.6680298,1.177057042
-1.326904283,-24.67099762,663.4879761,1.178444945
-1.328466809,-24.84838676,664.3079834,1.179854968
-1.330224564,-24.99179268,665.1279907,1.181340311
-1.331884763,-25.02612877,665.947998,1.182839856
-1.333496068,-24.99674797,666.7680054,1.184712746
-1.335058594,-24.85685921,667.5880127,1.186414738
-1.336767571,-24.95038605,668.40802,1.187991817
-1.338476548,-24.96075249,669.2280273,1.189481933
-1.340039074,-24.97301102,670.0479736,1.190805226
-1.341552706,-25.05132103,670.867981,1.192090334
-1.343310578,-25.21182823,671.6879883,1.193512348
-1.345019555,-25.3165493,672.5079956,1.194970799
-1.346630859,-25.3449173,673.3280029,1.196339377
-1.348193386,-25.3650074,674.1480103,1.197660575
-1.349951141,-25.32361794,674.9680176,1.199100516
-1.351611339,-25.08060455,675.7880249,1.201682491
-1.353222644,-25.01504517,676.6079712,1.203376683
-1.354736276,-25.13789177,677.4279785,1.204829081
-1.356396475,-25.17441177,678.2479858,1.206261222
-1.358105452,-25.36263847,679.0679932,1.207786961
-1.359716756,-25.4117794,679.8880005,1.209254027
-1.361230505,-25.42823029,680.7080078,1.210713526
-1.362939482,-25.44211388,681.5280151,1.212220523
-1.364697237,-25.45804596,682.3480225,1.213799114
-1.366308541,-25.44667244,683.1680298,1.215251861
-1.367871067,-25.36589622,683.9879761,1.216592966
-1.369580044,-25.48314857,684.8079834,1.217926969
-1.371240243,-25.56432724,685.6279907,1.219303347
-1.372851548,-25.58332634,686.447998,1.220545149
-1.374414074,-25.59723282,687.2680054,1.221772283
-1.376074273,-25.65619278,688.0880127,1.223075669
-1.377832028,-25.61855698,688.90802,1.224495354
-1.379443333,-25.59391212,689.7280273,1.225873828
-1.381005859,-25.63225555,690.5479736,1.227190369
-1.382666058,-25.67124939,691.367981,1.228556386
-1.384423813,-25.75687981,692.1879883,1.230014605
-1.386035117,-25.82553673,693.0079956,1.231414382
-1.387548866,-25.8214016,693.8280029,1.232755953
-1.38916017,-25.92713165,694.6480103,1.234066673
-1.390917925,-25.89694405,695.4680176,1.235482865
-1.392529346,-25.84165192,696.2880249,1.236879732
-1.394091756,-25.87645721,697.1079712,1.238226658
-1.395703177,-25.94967461,697.9279785,1.239660429
-1.39750971,-25.69093895,698.7479858,1.242190483
-1.399169909,-25.74590683,699.5679932,1.244188752
-1.400683541,-25.86011505,700.3880005,1.24565966
-1.402294962,-25.92216682,701.2080078,1.247031265
-1.404052717,-25.93539429,702.0280151,1.248513814
-1.405712916,-25.90340042,702.8480225,1.249977853
-1.407275442,-25.93939781,703.6680298,1.251454232
-1.408837852,-26.12482071,704.4879761,1.252933871
-1.410644501,-26.13408852,705.3079834,1.254498377
-1.412255806,-26.22642899,706.1279907,1.255994546
-1.413867227,-26.17553329,706.947998,1.257391647
-1.415429637,-26.13791084,707.7680054,1.25878898
-1.417187508,-26.10925102,708.5880127,1.260240912
-1.418847707,-26.04365921,709.40802,1.261664787
-1.420361339,-26.19366837,710.2280273,1.262988895
-1.421923866,-26.31879997,711.0479736,1.264296239
-1.423681621,-26.29368782,711.867981,1.265743747
-1.425341819,-26.32474136,712.6879883,1.267171348
-1.426953124,-26.25132179,713.5079956,1.268514083
-1.42851565,-26.27224541,714.3280029,1.269851928
-1.430273405,-26.3330555,715.1480103,1.271284185
-1.431982382,-26.47873688,715.9680176,1.272764639
-1.433544909,-26.50329399,716.7880249,1.27420749
-1.435107435,-26.59498787,717.6079712,1.275611226
-1.436816412,-26.58492851,718.4279785,1.277109492
-1.438525389,-26.55199814,719.2479858,1.278646174
-1.440087915,-26.55892372,720.0679932,1.280104625
-1.441650442,-26.48742676,720.8880005,1.281522214
-1.443359419,-26.6670475,721.7080078,1.283068792
-1.445117174,-26.60946655,722.5280151,1.284620375
-1.4466797,-26.72565842,723.3480225,1.286090002
-1.448242227,-26.73934174,724.1680298,1.287443098
-1.449951204,-26.70260048,724.9879761,1.288922387
-1.45166018,-26.62260818,725.8079834,1.29037234
-1.453222707,-26.63795662,726.6279907,1.291764085
-1.454736339,-26.57369041,727.447998,1.293126261
-1.456445316,-26.65459633,728.2680054,1.294633257
-1.458154293,-26.6482563,729.0880127,1.29620207
-1.459765597,-26.80267525,729.90802,1.297700685
-1.461279346,-26.82523346,730.7280273,1.299191732
-1.462988323,-26.80334091,731.5479736,1.300727949
-1.464746078,-26.77134895,732.367981,1.302274293
-1.466357382,-26.72520828,733.1879883,1.303740777
-1.467919908,-26.75578308,734.0079956,1.305124955
-1.469628885,-26.82247162,734.8280029,1.306638122
-1.471337862,-26.96698761,735.6480103,1.308154664
-1.472949167,-27.02021027,736.4680176,1.309655723
-1.474462915,-27.02791023,737.2880249,1.311119646
-1.476171892,-27.02212906,738.1079712,1.312646898
-1.477880869,-27.09897995,738.9279785,1.314289286
-1.479492174,-26.95105934,739.7479858,1.315920381
-1.4810547,-27.02238464,740.5679932,1.317548682
-1.482714899,-27.01187706,741.3880005,1.319223084
-1.484423876,-27.0957222,742.2080078,1.320930896
-1.486083958,-27.06561661,743.0280151,1.322569558
-1.487597707,-27.20424271,743.8480225,1.324131503
-1.489209011,-27.18602943,744.6680298,1.325710793
-1.490966766,-27.12879562,745.4879761,1.327406149
-1.492578071,-26.91543961,746.3079834,1.329823979
-1.494140597,-26.90360069,747.1279907,1.331480918
-1.495751902,-27.01408768,747.947998,1.332980115
-1.497509773,-27.18618011,748.7680054,1.334642759
-1.499169972,-27.27522659,749.5880127,1.336359303
-1.500732382,-27.27483559,750.40802,1.338001457
-1.502294908,-27.21433449,751.2280273,1.33950368
-1.504101558,-27.09001923,752.0479736,1.341065741
-1.505761757,-26.98658371,752.867981,1.342528965
-1.507324167,-26.82347107,753.6879883,1.34404772
-1.508886693,-26.76927567,754.5079956,1.345683821
-1.510693342,-26.91363907,755.3280029,1.347422483
-1.512304647,-26.98046494,756.1480103,1.34917465
-1.513867173,-27.07462692,756.9680176,1.350948471
-1.515478478,-27.07531929,757.7880249,1.352752559
-1.517236349,-27.01888847,758.6079712,1.35461404
-1.518896432,-27.04958534,759.4279785,1.356418128
-1.520458958,-26.93057823,760.2479858,1.35806785
-1.521972707,-26.94511604,761.0679932,1.359693822
-1.523730461,-27.07731819,761.8880005,1.361404546
-1.52539066,-27.05624962,762.7080078,1.36307627
-1.52695307,-27.12564659,763.5280151,1.364664291
-1.528564491,-27.19221687,764.3480225,1.366245211
-1.530273468,-27.27214241,765.1680298,1.367927413
-1.531982445,-27.21918106,765.9879761,1.36959285
-1.53359375,-26.96556664,766.8079834,1.372068073
-1.535156276,-26.95645714,767.6279907,1.374194864
-1.536865253,-27.02885246,768.447998,1.375873922
-1.538525335,-27.0510788,769.2680054,1.377463108
-1.540087862,-27.18914795,770.0880127,1.379066263
-1.541650388,-27.15427208,770.90802,1.380894799
-1.543359365,-27.10251808,771.7280273,1.383835566
-1.545117237,-27.0195961,772.5479736,1.386804623
-1.546728541,-26.72759438,773.367981,1.390338992
-1.548291068,-26.64353943,774.1879883,1.39208429
-1.550000045,-26.38823318,775.0079956,1.39406079
-1.551709021,-26.3541069,775.8280029,1.39608304
-1.553271431,-26.39295006,776.6480103,1.397966524
-1.554833958,-26.51195526,777.4680176,1.399791683
-1.556494157,-26.60766602,778.2880249,1.401591231
-1.558203134,-26.65374756,779.1079712,1.403401257
-1.559814438,-26.72486877,779.9279785,1.40519999
-1.56132807,-26.60908508,780.7479858,1.406983822
-1.563037164,-26.39529419,781.5679932,1.410258119
-1.564794919,-26.43204308,782.3880005,1.411964884
-1.566406223,-26.55098724,783.2080078,1.413548132
-1.567968749,-26.65673256,784.0280151,1.415179344
-1.569628948,-26.68250465,784.8480225,1.416977379
-1.571337925,-26.78561211,785.6680298,1.418865635
-1.57294923,-26.69921303,786.4879761,1.420951681
-1.574511756,-26.69410324,787.3079834,1.422912115
-1.576171839,-26.43076324,788.1279907,1.425562776
-1.577880816,-26.32654572,788.947998,1.428247779
-1.579541015,-26.43023872,789.7680054,1.429716358
-1.581054647,-26.43848419,790.5880127,1.43115886
-1.582763623,-26.63159752,791.40802,1.432650606
-1.5844726,-26.77539635,792.2280273,1.434213482
-1.586084021,-26.75733757,793.0479736,1.435714192
-1.587646431,-26.78608131,793.867981,1.437244704
-1.589257852,-26.72948647,794.6879883,1.438837731
-1.591015607,-26.86165047,795.5079956,1.440597698
-1.592626912,-26.85907173,796.3280029,1.442323672
-1.594189438,-26.81506538,797.1480103,1.443979447
-1.595800743,-26.76645088,797.9680176,1.445587259
-1.597558614,-26.79233742,798.7880249,1.448155614
-1.599218696,-26.84779167,799.6079712,1.449907548
-1.600781223,-26.76983643,800.4279785,1.451464952
-1.602392527,-26.71303368,801.2479858,1.453164616
-1.604101621,-26.7804184,802.0679932,1.454984187
-1.605761703,-26.83215904,802.8880005,1.456730068
-1.60732423,-26.85057831,803.7080078,1.458390732
-1.608935534,-26.86183167,804.5280151,1.460013213
-1.610693405,-26.94314003,805.3480225,1.461666427
-1.612353488,-27.02459717,806.1680298,1.463148743
-1.613916014,-27.0056057,806.9879761,1.464574714
-1.615527319,-27.05068398,807.8079834,1.466088928
-1.61728519,-26.93696213,808.6279907,1.467716997
-1.618896495,-26.94923401,809.447998,1.469292329
-1.620459021,-26.98989296,810.2680054,1.47078291
-1.622021431,-27.08972168,811.0880127,1.472292701
-1.623779302,-27.19729233,811.90802,1.47396198
-1.625439501,-27.22491264,812.7280273,1.47565885
-1.627001911,-27.20845413,813.5479736,1.477326034
-1.628613332,-27.19760323,814.367981,1.479034778
-1.630371087,-27.21426773,815.1879883,1.480958192
-1.632031286,-27.21145821,816.0079956,1.482832944
-1.633593696,-27.17573357,816.8280029,1.484518987
-1.635156223,-27.26189804,817.6480103,1.486116089
-1.636914094,-27.27420616,818.4680176,1.48777978
-1.638574176,-27.34179688,819.2880249,1.489450224
-1.640185597,-27.3567543,820.1079712,1.491026953
-1.641699229,-27.40852165,820.9279785,1.492529642
-1.643456984,-27.50601578,821.7479858,1.494179829
-1.645165961,-27.34835434,822.5679932,1.495919772
-1.646777382,-27.20398903,823.3880005,1.497671008
-1.647460973,-27.36917496,823.7479858,1.498457277