File: Data/Thesis_Samples_Data/Notched_Cast_4/Notched_Cast_4.csv
"File Path: C:\Users\Lab User\Desktop\Will\Thesis Tests\Test Run 11 04-9-22 14 19 42 PM\DAQ- Crosshead, … - (Timed).csv   ",,,
Test: MTS EM Tension (Extensometer) - Will 1,,,
Test Run: Test Run 11,,,
Date: 4/9/2022 2:18:25 PM,,,
,,,
,,,
Crosshead ,Load ,Time ,Extensometer
mm,N,sec,mm
0,-4.131319523,0.075999998,-2.75E-05
-4.88E-05,-4.330916882,0.136000007,-1.03E-05
-4.88E-05,-4.226331234,0.195999995,-1.30E-05
-0.000146484,-4.351292133,0.256000012,-1.73E-05
-0.000195312,-4.373741627,0.316000015,-9.92E-06
-0.000244141,-4.401217461,0.375999987,-2.21E-05
-0.000292969,-4.684539318,0.43599999,-1.30E-05
-0.000390625,-4.650333405,0.495999992,-9.26E-06
-0.000488281,-4.884547234,0.555999994,-9.87E-06
-0.000585938,-5.096344948,0.615999997,-1.35E-05
-0.000732422,-5.222126961,0.675999999,-1.29E-05
-0.000878906,-5.810784817,0.736000001,1.35E-06
-0.001025391,-6.015852928,0.796000004,-8.85E-06
-0.001171875,-6.575732231,0.856000006,3.02E-06
-0.001318359,-6.906863213,0.916000009,7.46E-06
-0.001416016,-7.184689999,0.976000011,1.17E-05
-0.0015625,-7.644908905,1.036000013,1.59E-05
-0.001708984,-7.763445377,1.095999956,1.37E-05
-0.001806641,-8.272711754,1.156000018,1.78E-05
-0.001904297,-8.53168869,1.215999961,1.66E-05
-0.002050781,-8.861536026,1.276000023,2.49E-05
-0.002148437,-9.285973549,1.335999966,2.85E-05
-0.002246094,-9.308376312,1.396000028,2.35E-05
-0.00234375,-9.828364372,1.45599997,3.95E-05
-0.002441406,-9.986991882,1.516000032,3.02E-05
-0.002539063,-10.27032661,1.575999975,3.62E-05
-0.002685547,-10.52394772,1.636000037,3.42E-05
-0.002783203,-10.77835083,1.69599998,3.60E-05
-0.002880859,-11.25194168,1.756000042,4.26E-05
-0.002978516,-11.37238693,1.815999985,4.43E-05
-0.003076172,-11.66149426,1.876000047,5.58E-05
-0.003173828,-12.04036236,1.93599999,6.42E-05
-0.003271484,-12.16054916,1.996000051,5.78E-05
-0.003369141,-12.59252071,2.055999994,5.42E-05
-0.003466797,-12.7611208,2.115999937,5.58E-05
-0.003564453,-12.98744106,2.176000118,6.65E-05
-0.003662109,-13.33102989,2.236000061,7.25E-05
-0.003759766,-13.53362465,2.296000004,6.09E-05
-0.003857422,-13.93534279,2.355999947,7.48E-05
-0.003955078,-14.03019905,2.415999889,6.41E-05
-0.004052734,-14.34742737,2.476000071,6.93E-05
-0.004150391,-14.60926914,2.536000013,8.06E-05
-0.004248047,-14.87902832,2.595999956,7.24E-05
-0.004345703,-15.35918427,2.655999899,7.84E-05
-0.00444336,-15.36962032,2.71600008,7.20E-05
-0.004541016,-15.74044609,2.776000023,8.76E-05
-0.004638672,-15.97021198,2.835999966,9.71E-05
-0.004736328,-16.27142906,2.895999908,8.65E-05
-0.004833984,-16.63178062,2.95600009,9.31E-05
-0.00493164,-16.80329704,3.016000032,8.87E-05
-0.005029297,-17.23994637,3.075999975,8.97E-05
-0.005126953,-17.36219406,3.135999918,9.59E-05
-0.00522461,-17.61736679,3.196000099,9.29E-05
-0.005322266,-17.97725868,3.256000042,0.000107205
-0.005419922,-18.05719566,3.315999985,9.68E-05
-0.005517578,-18.48132515,3.375999928,0.000110366
-0.005615234,-18.68219948,3.436000109,0.000106341
-0.00571289,-19.02638435,3.496000051,0.000105657
-0.005810547,-19.31804466,3.555999994,0.000118107
-0.005908203,-19.39556503,3.615999937,0.000123891
-0.006005859,-19.85359192,3.676000118,0.000120658
-0.006103516,-20.09939957,3.736000061,0.000123486
-0.006201172,-20.37277794,3.796000004,0.000119637
-0.006298828,-20.74670792,3.855999947,0.000132901
-0.006396484,-20.94841766,3.915999889,0.000121183
-0.006494141,-21.38505173,3.976000071,0.000134814
-0.006591797,-21.49717712,4.035999775,0.000130831
-0.006689453,-21.82780266,4.096000195,0.000144664
-0.006787109,-22.13090324,4.156000137,0.000149905
-0.006884766,-22.2852211,4.21600008,0.000142418
-0.00703125,-22.73721504,4.276000023,0.000144643
-0.007128906,-23.00956154,4.335999966,0.000150153
-0.007226563,-23.24880028,4.395999908,0.000149897
-0.007324219,-23.64005852,4.455999851,0.000159573
-0.007421875,-23.74383163,4.515999794,0.000150497
-0.007568359,-24.12416267,4.576000214,0.000159861
-0.007666015,-24.36519241,4.636000156,0.000159801
-0.007763672,-24.67439842,4.696000099,0.000171464
-0.007861328,-25.04380608,4.756000042,0.000180148
-0.007958984,-25.21066666,4.815999985,0.000166119
-0.008056641,-25.67085648,4.875999928,0.000176144
-0.008154297,-25.82601357,4.93599987,0.000173457
-0.008300782,-26.18797684,4.995999813,0.000185922
-0.008398438,-26.44306755,5.056000233,0.000187579
-0.008496094,-26.66594887,5.116000175,0.000180641
-0.00859375,-27.10133553,5.176000118,0.000198795
-0.008691406,-27.13240814,5.236000061,0.000184899
-0.008789062,-27.65276146,5.296000004,0.00019939
-0.008886719,-27.80072784,5.355999947,0.000203
-0.008984375,-27.99977112,5.415999889,0.000198049
-0.009082031,-28.39336967,5.475999832,0.000208247
-0.009179687,-28.49168587,5.535999775,0.000196602
-0.009277343,-28.91775322,5.596000195,0.000204685
-0.009375,-29.17354202,5.656000137,0.000213625
-0.009472657,-29.36277199,5.71600008,0.000206803
-0.009570313,-29.77882385,5.776000023,0.000226225
-0.009667969,-29.86484718,5.835999966,0.000217331
-0.009765625,-30.26085472,5.895999908,0.00022508
-0.00991211,-30.40542221,5.955999851,0.000219455
-0.010009766,-30.81990814,6.015999794,0.000220506
-0.010107422,-31.07736969,6.076000214,0.000225799
-0.01015625,-31.19743538,6.136000156,0.000220723
-0.010253906,-31.63206863,6.196000099,0.000226919
-0.01040039,-31.85728264,6.256000042,0.000227658
-0.010449219,-32.05247498,6.315999985,0.000228332
-0.010546875,-32.32947159,6.375999928,0.000245495
-0.010644531,-32.47956467,6.43599987,0.000235835
-0.010742187,-32.96421051,6.495999813,0.000243193
-0.010839844,-33.12411118,6.556000233,0.000241308
-0.0109375,-33.36129761,6.616000175,0.000243173
-0.011035157,-33.66729736,6.676000118,0.000254107
-0.011132813,-33.84273529,6.736000061,0.000248137
-0.011230469,-34.24792099,6.796000004,0.000253684
-0.011328125,-34.33744049,6.855999947,0.000256233
-0.011425781,-34.716465,6.915999889,0.000263749
-0.011523438,-34.87440872,6.975999832,0.000263568
-0.011621094,-35.09859467,7.035999775,0.000262438
-0.01171875,-35.4827919,7.096000195,0.000268987
-0.011816406,-35.63378525,7.156000137,0.000273405
-0.011914062,-35.99232483,7.21600008,0.000272072
-0.01196289,-36.07183838,7.276000023,0.000286254
-0.012060547,-36.38781357,7.335999966,0.000271959
-0.012207031,-36.7992363,7.395999908,0.000288493
-0.012255859,-36.75703812,7.455999851,0.000280829
-0.012353516,-37.22849655,7.515999794,0.000281247
-0.012451172,-37.40153503,7.576000214,0.000290327
-0.012548828,-37.63271713,7.636000156,0.000274059
-0.012646485,-38.0357666,7.696000099,0.000294359
-0.012744141,-38.17140198,7.756000042,0.000284854
-0.012890625,-38.52348328,7.815999985,0.000289759
-0.012988281,-38.77950287,7.875999928,0.000296984
-0.013085937,-39.01226807,7.93599987,0.000298607
-0.013183594,-39.48793411,7.995999813,0.000308095
-0.01328125,-39.47302246,8.055999756,0.000302601
-0.013378906,-39.93477631,8.116000175,0.000315373
-0.013476562,-40.15451813,8.175999641,0.000311095
-0.013623046,-40.46147919,8.236000061,0.000308923
-0.013720703,-40.78414536,8.295999527,0.000324237
-0.01381836,-40.96549225,8.355999947,0.00032641
-0.013916016,-41.40575027,8.416000366,0.000326373
-0.014013672,-41.61187744,8.475999832,0.00032435
-0.014160156,-41.99501419,8.536000252,0.000326729
-0.014257813,-42.2334671,8.595999718,0.000331137
-0.014355469,-42.3579216,8.656000137,0.000329548
-0.014453125,-42.87246704,8.715999603,0.000332567
-0.014599609,-43.04688644,8.776000023,0.000337032
-0.014697265,-43.32478714,8.836000443,0.000334782
-0.014794922,-43.66340637,8.895999908,0.000350156
-0.014892578,-43.88271332,8.956000328,0.000342869
-0.014990234,-44.26883316,9.015999794,0.000349648
-0.01508789,-44.45631027,9.076000214,0.000355086
-0.015234375,-44.80526352,9.13599968,0.000353116
-0.015332031,-45.11299896,9.196000099,0.000368298
-0.015429687,-45.28076935,9.255999565,0.000358669
-0.015527345,-45.78660202,9.315999985,0.000364219
-0.015625001,-45.79030228,9.376000404,0.000353071
-0.015722657,-46.17579651,9.43599987,0.000371514
-0.015820313,-46.41154099,9.49600029,0.000370452
-0.015917969,-46.68214798,9.555999756,0.000370665
-0.016064454,-47.10154343,9.616000175,0.000383977
-0.01616211,-47.19923401,9.675999641,0.000383838
-0.016259766,-47.60157013,9.736000061,0.000383776
-0.016357422,-47.83749771,9.795999527,0.000390508
-0.016455078,-47.94213104,9.855999947,0.00039046
-0.016552734,-48.37727737,9.916000366,0.000394182
-0.016650391,-48.45381546,9.975999832,0.00039361
-0.016748047,-48.96538544,10.03600025,0.000400246
-0.016845703,-49.14161682,10.09599972,0.000414557
-0.016943359,-49.36381531,10.15600014,0.000406238
-0.017041015,-49.69639969,10.2159996,0.000409621
-0.017138673,-49.85444641,10.27600002,0.000409658
-0.017236329,-50.23740005,10.33600044,0.00041347
-0.017333985,-50.33292389,10.39599991,0.000420522
-0.017431641,-50.65503311,10.45600033,0.000411493
-0.017529297,-51.0684967,10.51599979,0.000421043
-0.017626953,-51.13789368,10.57600021,0.000417905
-0.017724609,-51.48607635,10.63599968,0.000427111
-0.017773438,-51.70466614,10.6960001,0.000433501
-0.017871094,-51.92681885,10.75599957,0.000431494
-0.01796875,-52.26520157,10.81599998,0.000431564
-0.018066406,-52.26713562,10.8760004,0.000431681
-0.018164063,-52.89933014,10.93599987,0.000441908
-0.018261719,-53.04018402,10.99600029,0.000450653
-0.018359375,-53.23944473,11.05599976,0.00044569
-0.018457031,-53.57079315,11.11600018,0.000454355
-0.018554687,-53.72206116,11.17599964,0.000440822
-0.018652343,-54.12569427,11.23600006,0.000461875
-0.018750001,-54.30604172,11.29599953,0.000455911
-0.018847657,-54.62630844,11.35599995,0.00045967
-0.018945313,-54.92531967,11.41600037,0.000464652
-0.019042969,-55.065979,11.47599983,0.000458039
-0.019140625,-55.41506577,11.53600025,0.000469279
-0.019238281,-55.540802,11.59599972,0.000473951
-0.019335937,-55.81398773,11.65600014,0.00047361
-0.019433593,-56.13357925,11.7159996,0.000472545
-0.01953125,-56.36492538,11.77600002,0.00048046
-0.019628906,-56.8392334,11.83600044,0.000495687
-0.019726562,-56.92777252,11.89599991,0.000491795
-0.01982422,-57.32117081,11.95600033,0.000493721
-0.019921876,-57.55117416,12.01599979,0.000493972
-0.020068359,-57.82823563,12.07600021,0.000495907
-0.020166015,-58.19553757,12.13599968,0.000499181
-0.020263671,-58.30574417,12.1960001,0.000501986
-0.020361329,-58.7561264,12.25599957,0.000509705
-0.020458985,-59.11228561,12.31599998,0.000519074
-0.020556641,-59.29370117,12.3760004,0.000511633
-0.020703124,-59.67155838,12.43599987,0.000529334
-0.02080078,-59.80291367,12.49600029,0.00052116
-0.020898438,-60.20658493,12.55599976,0.000532666
-0.020996094,-60.49348831,12.61600018,0.000538313
-0.021093751,-60.69159698,12.67599964,0.000530487
-0.021191407,-61.13599777,12.73600006,0.000542912
-0.021289063,-61.2108345,12.79599953,0.000539406
-0.021386719,-61.55537033,12.85599995,0.000544494
-0.021484375,-61.81650925,12.91600037,0.000556463
-0.021582031,-62.02651978,12.97599983,0.000546366
-0.021728516,-62.35580826,13.03600025,0.000559466
-0.021826172,-62.58104706,13.09599972,0.000553734
-0.021923828,-63.03568268,13.15600014,0.000564145
-0.022021484,-63.27633286,13.2159996,0.000563797
-0.02211914,-63.496418,13.27600002,0.000567994
-0.022216796,-63.8211937,13.33600044,0.000580799
-0.022314453,-63.96590424,13.39599991,0.000579657
-0.022412109,-64.38168335,13.45600033,0.000586773
-0.022509766,-64.56373596,13.51599979,0.000585778
-0.022607423,-64.86569214,13.57600021,0.000590448
-0.022705079,-65.14319611,13.63599968,0.000605487
-0.022802735,-65.30649567,13.6960001,0.000603581
-0.022900391,-65.74454498,13.75599957,0.000597816
-0.022998047,-65.86087036,13.81599998,0.000604772
-0.023144532,-66.18017578,13.8760004,0.000608439
-0.023242188,-66.57766724,13.93599987,0.000619868
-0.023339844,-66.70201874,13.99600029,0.000602611
-0.0234375,-67.12609863,14.05599976,0.000618569
-0.023535156,-67.20113373,14.11600018,0.000624262
-0.023632812,-67.5508194,14.17599964,0.000618567
-0.023730468,-67.81907654,14.23600006,0.000636562
-0.023828125,-67.93986511,14.29599953,0.000632252
-0.023876953,-68.36391449,14.35599995,0.000645959
-0.02397461,-68.4822998,14.41600037,0.000650667
-0.024072266,-68.82049561,14.47599983,0.000641594
-0.024218751,-69.11847687,14.53600025,0.000652331
-0.024316407,-69.37215424,14.59599972,0.000648652
-0.024365234,-69.73461914,14.65600014,0.000665507
-0.02446289,-69.78970337,14.7159996,0.000669636
-0.024560546,-70.20136261,14.77600002,0.000671473
-0.024658204,-70.3924942,14.83600044,0.00067305
-0.02475586,-70.57698059,14.89599991,0.000672958
-0.024853516,-70.94936371,14.95600033,0.000685867
-0.024951172,-71.01237488,15.01599979,0.000685381
-0.025048828,-71.36099243,15.07600021,0.000689485
-0.025146484,-71.55448914,15.13599968,0.00069075
-0.02524414,-71.76305389,15.1960001,0.000690968
-0.025341797,-72.17524719,15.25599957,0.000696874
-0.025439453,-72.29724121,15.31599998,0.000688182
-0.025537109,-72.64972687,15.3760004,0.000708278
-0.025634765,-72.99445343,15.43599987,0.000712417
-0.025732423,-73.15729523,15.49600029,0.000701878
-0.025830079,-73.51198578,15.55599976,0.000720747
-0.025927735,-73.55857849,15.61600018,0.000711365
-0.026025391,-73.9658432,15.67599964,0.000718831
-0.026123047,-74.16926575,15.73600006,0.000729438
-0.026220703,-74.41207123,15.79599953,0.000729552
-0.026318359,-74.9134903,15.85599995,0.000737615
-0.026416015,-74.97789764,15.91600037,0.00073668
-0.026513671,-75.40605927,15.97599983,0.000732919
-0.026611327,-75.59877014,16.0359993,0.000744013
-0.026708984,-75.86450958,16.09600067,0.000735881
-0.026806641,-76.33531952,16.15600014,0.000757353
-0.026904298,-76.37867737,16.2159996,0.000746139
-0.027050781,-76.82231903,16.27599907,0.000748859
-0.027148437,-77.08838654,16.33600044,0.000764181
-0.027246093,-77.38008118,16.39599991,0.000762189
-0.027343751,-77.65647888,16.45599937,0.000768407
-0.027490234,-77.85144043,16.51600075,0.000762979
-0.02758789,-78.39015961,16.57600021,0.000770215
-0.027685546,-78.48206329,16.63599968,0.000783947
-0.027783202,-78.81137848,16.69599915,0.000778968
-0.02788086,-79.12669373,16.75600052,0.000795456
-0.027978516,-79.31594086,16.81599998,0.000793829
-0.028076172,-79.70188904,16.87599945,0.000795477
-0.028222656,-79.81434631,16.93600082,0.000795268
-0.028320312,-80.26039124,16.99600029,0.000801155
-0.02841797,-80.49863434,17.05599976,0.000804777
-0.028515626,-80.6469574,17.11599922,0.00079856
-0.028613282,-81.1436615,17.1760006,0.000820293
-0.028710938,-81.27258301,17.23600006,0.000817059
-0.028808594,-81.64016724,17.29599953,0.000825106
-0.02890625,-81.79624939,17.3560009,0.000834716
-0.029003906,-81.94850922,17.41600037,0.000829355
-0.029150391,-82.31509399,17.47599983,0.000847984
-0.029248047,-82.47092438,17.5359993,0.000840844
-0.029345703,-82.90390015,17.59600067,0.000843346
-0.029443359,-83.06723785,17.65600014,0.000845821
-0.029541015,-83.29745483,17.7159996,0.000857142
-0.029638672,-83.69676971,17.77599907,0.000864583
-0.029736328,-83.78901672,17.83600044,0.000858539
-0.029833984,-84.19721222,17.89599991,0.000864812
-0.02993164,-84.39807892,17.95599937,0.000871048
-0.030029298,-84.67246246,18.01600075,0.000868293
-0.030126954,-85.03455353,18.07600021,0.000880041
-0.03022461,-85.17409515,18.13599968,0.000887082
-0.030322266,-85.49877167,18.19599915,0.000887351
-0.030419922,-85.60152435,18.25600052,0.00089259
-0.030517578,-85.84630585,18.31599998,0.000894776
-0.030615236,-86.22605133,18.37599945,0.00091192
-0.03071289,-86.28644562,18.43600082,0.000898233
-0.030810548,-86.68302917,18.49600029,0.00091943
-0.030908202,-86.87508392,18.55599976,0.000912741
-0.03100586,-87.12680054,18.61599922,0.000918437
-0.031103515,-87.36499786,18.6760006,0.000928719
-0.031201173,-87.40081787,18.73600006,0.000915968
-0.031298827,-87.81719971,18.79599953,0.000931856
-0.031396485,-88.00566101,18.8560009,0.000942676
-0.031494139,-88.30950928,18.91600037,0.000939071
-0.031591797,-88.52407074,18.97599983,0.000950218
-0.031689455,-88.74993896,19.0359993,0.000943762
-0.031787109,-89.11566925,19.09600067,0.000962582
-0.031884767,-89.09882355,19.15600014,0.000951114
-0.031933592,-89.45766449,19.2159996,0.000954468
-0.03203125,-89.74015045,19.27599907,0.000966543
-0.032128908,-89.95083618,19.33600044,0.000965954
-0.032226562,-90.35062408,19.39599991,0.00097153
-0.03232422,-90.45185089,19.45599937,0.000982509
-0.032421874,-90.79318237,19.51600075,0.000979846
-0.032519532,-91.02179718,19.57600021,0.000990024
-0.032617187,-91.16269684,19.63599968,0.000982529
-0.032714845,-91.64753723,19.69599915,0.000992135
-0.032812499,-91.68101501,19.75600052,0.000993761
-0.032910157,-92.06790161,19.81599998,0.000998853
-0.033007811,-92.30104828,19.87599945,0.001011033
-0.033154298,-92.59677124,19.93600082,0.001002809
-0.033251952,-92.92753601,19.99600029,0.001024626
-0.03334961,-93.04727173,20.05599976,0.001022553
-0.033447264,-93.59230042,20.11599922,0.001021006
-0.033544922,-93.77342224,20.1760006,0.001033348
-0.033642576,-94.01464844,20.23600006,0.001032539
-0.033789063,-94.31235504,20.29599953,0.001040434
-0.033886718,-94.51290894,20.3560009,0.001030424
-0.033984375,-95.02426147,20.41600037,0.001051886
-0.03408203,-95.16503143,20.47599983,0.001048044
-0.034179688,-95.48735046,20.5359993,0.001054398
-0.034326171,-95.88092041,20.59600067,0.00106683
-0.034423829,-95.99291229,20.65600014,0.001071527
-0.034521483,-96.38054657,20.7159996,0.001072935
-0.034619141,-96.6363678,20.77599907,0.001075169
-0.034716795,-96.93344116,20.83600044,0.001072418
-0.034814453,-97.17543793,20.89599991,0.001097698
-0.034960936,-97.36457825,20.95599937,0.001078277
-0.035058594,-97.72338104,21.01600075,0.00109641
-0.035156248,-97.86886597,21.07600021,0.001101448
-0.035253906,-98.1811142,21.13599968,0.001099083
-0.035351564,-98.49245453,21.19599915,0.001120092
-0.035449219,-98.66950989,21.25600052,0.001105832
-0.035546876,-99.13214111,21.31599998,0.001120027
-0.035644531,-99.1354599,21.37599945,0.001115535
-0.035742189,-99.41109467,21.43600082,0.001128416
-0.035839843,-99.9131546,21.49600029,0.001139036
-0.035937501,-99.9307785,21.55599976,0.0011323
-0.036035155,-100.372818,21.61599922,0.001147323
-0.036132813,-100.3901062,21.6760006,0.001143664
-0.036230467,-100.7064514,21.73600006,0.001155452
-0.036328125,-100.9490662,21.79599953,0.001154092
-0.036425783,-101.1033478,21.8560009,0.001153005
-0.036523437,-101.5519333,21.91600037,0.001163967
-0.036621095,-101.6007538,21.97599983,0.001172168
-0.036718749,-102.0788269,22.0359993,0.001170729
-0.036816407,-102.2878265,22.09600067,0.001177522
-0.036914062,-102.4694595,22.15600014,0.001164022
-0.03701172,-102.805809,22.2159996,0.00119326
-0.037109374,-102.8816147,22.27599907,0.001180483
-0.037207032,-103.2490158,22.33600044,0.001191793
-0.037304686,-103.4679489,22.39599991,0.001201273
-0.037402344,-103.6682205,22.45599937,0.001188606
-0.037500002,-104.0255814,22.51600075,0.001204344
-0.037597656,-104.0979385,22.57600021,0.001196381
-0.037695314,-104.4499969,22.63599968,0.001198258
-0.037792968,-104.631485,22.69599915,0.00122339
-0.037890626,-104.842247,22.75600052,0.001210823
-0.03798828,-105.2144165,22.81599998,0.001228866
-0.038085938,-105.3232193,22.87599945,0.001224119
-0.038183593,-105.5851974,22.93600082,0.001233959
-0.03828125,-105.7841949,22.99600029,0.001245237
-0.038378905,-106.0503082,23.05599976,0.001238928
-0.038427734,-103.7174301,23.11599922,0.001184615
-0.038525392,-103.6240234,23.1760006,0.001116278
-0.038623046,-103.9417953,23.23600006,0.001117865
-0.038720704,-104.0401154,23.29599953,0.001109373
-0.038818358,-104.3442383,23.3560009,0.001106267
-0.038916016,-104.7086182,23.41600037,0.00111703
-0.03901367,-104.9659653,23.47599983,0.001119468
-0.039111328,-105.3945236,23.5359993,0.001115539
-0.039208986,-105.669487,23.59600067,0.00111881
-0.03930664,-105.9899368,23.65600014,0.001116912
-0.039404298,-106.3700867,23.7159996,0.001129981
-0.039501952,-106.6261597,23.77599907,0.001128268
-0.03959961,-107.1160965,23.83600044,0.001136471
-0.039697265,-107.2977905,23.89599991,0.001131847
-0.039794922,-107.6759949,23.95599937,0.001142239
-0.039892577,-108.0455933,24.01600075,0.001143375
-0.039990235,-108.3091888,24.07600021,0.001139265
-0.040136718,-108.7331467,24.13599968,0.001149933
-0.040234376,-108.991127,24.19599915,0.001155304
-0.04033203,-109.4076843,24.25600052,0.001151392
-0.040429688,-109.7528839,24.31599998,0.001170143
-0.040527342,-110.0291138,24.37599945,0.001165476
-0.040625,-110.4547806,24.43600082,0.001171215
-0.040771483,-110.5802994,24.49600029,0.001168857
-0.040869141,-110.9986877,24.55599976,0.001177463
-0.040966795,-111.3197403,24.61599922,0.001190476
-0.041064453,-111.6528091,24.6760006,0.001181566
-0.041162108,-112.0477676,24.73600006,0.001198616
-0.041259766,-112.13694,24.79599953,0.001193208
-0.041406249,-112.4789276,24.8560009,0.001198598
-0.041503907,-112.7566376,24.91600037,0.001197187
-0.041601561,-112.9721069,24.97599983,0.001197106
-0.041699219,-113.4531021,25.0359993,0.001208686
-0.041796877,-113.6264496,25.09600067,0.001205504
-0.041894531,-114.0411758,25.15600014,0.001213922
-0.041992189,-114.1811142,25.2159996,0.001221136
-0.042089843,-114.4612885,25.27599907,0.001210826
-0.042187501,-114.8061981,25.33600044,0.001229133
-0.042285155,-114.8426514,25.39599991,0.001228705
-0.042382813,-115.3146591,25.45599937,0.001241693
-0.042529296,-115.5391388,25.51600075,0.001244449
-0.042626954,-115.8668976,25.57600021,0.001235188
-0.042724609,-116.0889511,25.63599968,0.001244849
-0.042822267,-116.1906586,25.69599915,0.001244461
-0.042919921,-116.6412582,25.75600052,0.001253128
-0.043017579,-116.8586884,25.81599998,0.001262179
-0.043115233,-117.1498795,25.87599945,0.001256335
-0.043212891,-117.4559631,25.93600082,0.001270331
-0.043310545,-117.6700516,25.99600029,0.001261522
-0.043408203,-118.1896133,26.05599976,0.001273274
-0.043505861,-118.1650009,26.11599922,0.001271139
-0.043603515,-118.4522858,26.1760006,0.001271251
-0.043701173,-118.7307053,26.23600006,0.001282554
-0.043798827,-118.9009705,26.29599953,0.001274453
-0.043896485,-119.2980728,26.3560009,0.001287757
-0.04399414,-119.3776627,26.41600037,0.001289926
-0.044091797,-119.7364197,26.47599983,0.001293829
-0.044189452,-120.0065384,26.5359993,0.00129985
-0.04428711,-120.1655045,26.59600067,0.001294314
-0.044384764,-120.4478378,26.65600014,0.001302333
-0.044482422,-120.6226807,26.7159996,0.001306069
-0.04458008,-120.857193,26.77599907,0.00130842
-0.044628905,-121.2305298,26.83600044,0.0013146
-0.044726563,-121.4974594,26.89599991,0.001313357
-0.044824217,-121.7979202,26.95599937,0.001324902
-0.044921875,-121.9164734,27.01600075,0.001321739
-0.045019533,-122.3001633,27.07600021,0.001330455
-0.045117187,-122.5502701,27.13599968,0.001330356
-0.045214845,-122.6997299,27.19599915,0.001335892
-0.045312499,-122.9981308,27.25600052,0.001341329
-0.045410157,-123.2649231,27.31599998,0.0013407
-0.045507812,-123.6520996,27.37599945,0.001348118
-0.045605469,-123.8420639,27.43600082,0.001355672
-0.045703124,-124.164032,27.49600029,0.001349655
-0.045800782,-124.5713196,27.55599976,0.001367742
-0.045898436,-124.654068,27.61599922,0.001371229
-0.045996094,-125.0985565,27.6760006,0.001370357
-0.046093752,-125.2845688,27.73600006,0.001372169
-0.046191406,-125.5974045,27.79599953,0.001370401
-0.046289064,-126.04216,27.8560009,0.001380189
-0.046386718,-126.0491104,27.91600037,0.001381467
-0.046484376,-126.5193405,27.97599983,0.001390831
-0.046630859,-126.7551804,28.0359993,0.001391717
-0.046728517,-127.0642929,28.09600067,0.001399818
-0.046826171,-127.6325989,28.15600014,0.001406911
-0.046923829,-127.66642,28.2159996,0.001403054
-0.047021484,-128.1747589,28.27599907,0.001416566
-0.04716797,-128.3756714,28.33600044,0.001415047
-0.047265625,-128.7264557,28.39599991,0.001417708
-0.047363283,-129.1271515,28.45599937,0.001436407
-0.047460937,-129.317627,28.51600075,0.001427611
-0.047558595,-129.7723236,28.57600021,0.001437747
-0.047705078,-129.9019623,28.63599968,0.001432508
-0.047802736,-130.2929382,28.69599915,0.001441362
-0.04790039,-130.6607666,28.75600052,0.001449468
-0.047998048,-130.8989563,28.81599998,0.001454575
-0.048095702,-131.3017273,28.87599945,0.001462367
-0.04819336,-131.4319,28.93600082,0.001463337
-0.048339843,-131.8266907,28.99600029,0.001459953
-0.048437501,-132.0762939,29.05599976,0.001474185
-0.048535156,-132.347168,29.11599922,0.001464993
-0.048632814,-132.8640594,29.1760006,0.001479615
-0.048730468,-132.9771271,29.23600006,0.001482728
-0.048828126,-133.3434143,29.29599953,0.001485014
-0.04892578,-133.5972137,29.3560009,0.001499689
-0.049023438,-133.8603973,29.41600037,0.001483854
-0.049121092,-134.2210846,29.47599983,0.001508033
-0.04921875,-134.3683777,29.5359993,0.001511078
-0.049316408,-134.7947998,29.59600067,0.001503231
-0.049462891,-134.9795685,29.65600014,0.001517928
-0.049560545,-135.2545319,29.7159996,0.001517041
-0.049658203,-135.7095642,29.77599907,0.001520569
-0.049755858,-135.7967834,29.83600044,0.001535643
-0.049853516,-136.2848969,29.89599991,0.001537537
-0.049951173,-136.4587097,29.95599937,0.001539904
-0.050048828,-136.6754608,30.01600075,0.001539396
-0.050146486,-137.0829926,30.07600021,0.001556256
-0.05024414,-137.0937653,30.13599968,0.001546943
-0.050341798,-137.5348358,30.19599915,0.001546218
-0.050439452,-137.8122101,30.25600052,0.001564789
-0.05053711,-138.0532227,30.31599998,0.001556514
-0.050634764,-138.3898163,30.37599945,0.001561393
-0.050732422,-138.5557556,30.43600082,0.001557616
-0.050830076,-138.9847107,30.49600029,0.001576602
-0.050927734,-139.1627655,30.55599976,0.001583319
-0.050976563,-139.4369812,30.61599922,0.001582986
-0.051074217,-139.7155609,30.6760006,0.001581281
-0.051171875,-139.8331451,30.73600006,0.001586021
-0.05126953,-140.3398438,30.79599953,0.001597607
-0.051367188,-140.5419006,30.8560009,0.001606873
-0.051464845,-140.7760468,30.91600037,0.001603218
-0.0515625,-141.1272736,30.97599983,0.001625044
-0.051660158,-141.2889252,31.0359993,0.001616492
-0.051757812,-141.6833191,31.09600067,0.001626008
-0.05185547,-141.8930969,31.15600014,0.001628762
-0.051953124,-142.2134094,31.2159996,0.001627699
-0.052050782,-142.3709106,31.27599907,0.00164032
-0.052148436,-142.6633759,31.33600044,0.001640945
-0.052246094,-143.1700592,31.39599991,0.00164816
-0.052294923,-143.3140259,31.45599937,0.001648651
-0.052441406,-143.6027527,31.51600075,0.001648596
-0.052490235,-143.9177246,31.57600021,0.001657722
-0.05258789,-144.1483002,31.63599968,0.001651872
-0.052685547,-144.5665283,31.69599915,0.001664217
-0.052783202,-144.6690521,31.75600052,0.001665927
-0.05288086,-145.1664734,31.81599998,0.001683738
-0.052978514,-145.5652771,31.87599945,0.001681987
-0.053125001,-145.7406769,31.93600082,0.001676292
-0.053222655,-146.1562195,31.99600029,0.001694057
-0.053320313,-146.3666077,32.05599976,0.001691947
-0.053417967,-146.9001312,32.11600113,0.001699833
-0.053515625,-147.1616669,32.17599869,0.001705109
-0.053613283,-147.430603,32.23600006,0.001703738
-0.053759766,-147.9496307,32.29600143,0.001722019
-0.05385742,-148.1051941,32.35599899,0.001719488
-0.053955078,-148.5950317,32.41600037,0.001728895
-0.054052733,-148.8874054,32.47600174,0.001725426
-0.054199219,-149.2469635,32.5359993,0.001726449
-0.054296874,-149.6217194,32.59600067,0.001740159
-0.054394532,-149.8969269,32.65599823,0.001742491
-0.054492186,-150.334259,32.7159996,0.001754886
-0.054589844,-150.5559387,32.77600098,0.001756979
-0.054687502,-150.9138947,32.83599854,0.001758526
-0.054833985,-151.2863922,32.89599991,0.001769777
-0.054931639,-151.484024,32.95600128,0.00178485
-0.055029297,-151.879776,33.01599884,0.001787296
-0.055126951,-152.1050873,33.07600021,0.001779155
-0.055224609,-152.4920044,33.13600159,0.001790099
-0.055322267,-152.8342438,33.19599915,0.001803109
-0.055419921,-152.9884644,33.25600052,0.001781788
-0.055517579,-153.4657745,33.31600189,0.001804932
-0.055615234,-153.571228,33.37599945,0.001808069
-0.055712891,-153.9613953,33.43600082,0.001805255
-0.055810546,-154.2656708,33.49599838,0.00182601
-0.055957033,-154.5424194,33.55599976,0.001809673
-0.056054687,-154.980545,33.61600113,0.0018248
-0.056152345,-155.1471863,33.67599869,0.001827869
-0.056249999,-155.3445435,33.73600006,0.001842481
-0.056347657,-155.6412659,33.79600143,0.001845024
-0.056445311,-155.8349762,33.85599899,0.001848167
-0.056542969,-156.3274689,33.91600037,0.001853329
-0.056640623,-156.4597931,33.97600174,0.001852898
-0.056738281,-156.8407135,34.0359993,0.001859609
-0.056835939,-157.2124786,34.09600067,0.001871945
-0.056933593,-157.383316,34.15599823,0.001870622
-0.057031251,-157.797699,34.2159996,0.00188051
-0.057128906,-157.8924561,34.27600098,0.001881597
-0.057226564,-158.3000183,34.33599854,0.001896405
-0.057324218,-158.5817871,34.39599991,0.001901508
-0.057421876,-158.8600006,34.45600128,0.001891164
-0.05751953,-159.2741852,34.51599884,0.001905856
-0.057617188,-159.3368683,34.57600021,0.001893664
-0.057714842,-159.7326813,34.63600159,0.001904508
-0.057763671,-160.0104065,34.69599915,0.001923499
-0.057861329,-160.2027283,34.75600052,0.001923404
-0.057958983,-160.5979614,34.81600189,0.001936852
-0.058056641,-160.7533875,34.87599945,0.001930272
-0.058154295,-161.275528,34.93600082,0.001938122
-0.058251953,-161.4566498,34.99599838,0.001947393
-0.058349608,-161.6945343,35.05599976,0.001957003
-0.058447265,-162.0300293,35.11600113,0.001961481
-0.058544923,-162.2623291,35.17599869,0.001950957
-0.058642578,-162.6405945,35.23600006,0.001970677
-0.058740236,-162.8244171,35.29600143,0.001972175
-0.05883789,-163.0698547,35.35599899,0.00197515
-0.058935548,-163.4380951,35.41600037,0.001987219
-0.059033202,-163.5479431,35.47600174,0.001980384
-0.05913086,-164.0760956,35.5359993,0.00199514
-0.059228514,-164.2481079,35.59600067,0.001991626
-0.059326172,-164.6792297,35.65599823,0.002001306
-0.059423826,-165.0309448,35.7159996,0.002010271
-0.059521484,-165.2957764,35.77600098,0.00201563
-0.059619142,-165.7841644,35.83599854,0.002032273
-0.059716796,-165.9482269,35.89599991,0.002030721
-0.059814454,-166.3580475,35.95600128,0.002025677
-0.059912109,-166.6257782,36.01599884,0.00204303
-0.060009766,-166.9439545,36.07600021,0.002037889
-0.06015625,-167.3866882,36.13600159,0.002052201
-0.060253908,-167.5440063,36.19599915,0.002052371
-0.060351562,-168.0413513,36.25600052,0.002058142
-0.06044922,-168.3499298,36.31600189,0.002073865
-0.060546874,-168.7052002,36.37599945,0.002078071
-0.060693361,-169.042984,36.43600082,0.002087427
-0.060791015,-169.2815247,36.49599838,0.002101103
-0.060888673,-169.7937317,36.55599976,0.002099453
-0.060986327,-170.0935059,36.61600113,0.002115409
-0.061083985,-170.4654999,36.67599869,0.002111889
-0.061230472,-170.8889008,36.73600006,0.002132627
-0.061328123,-171.0593719,36.79600143,0.002131215
-0.061425781,-171.504715,36.85599899,0.002139722
-0.061523438,-171.7858887,36.91600037,0.002143817
-0.061621096,-172.0290985,36.97600174,0.002147681
-0.061718747,-172.3991241,37.0359993,0.0021824
-0.061816405,-172.5138855,37.09600067,0.002165981
-0.061914063,-172.9277802,37.15599823,0.002175436
-0.062011721,-173.1919708,37.2159996,0.002185639
-0.062109379,-173.4884338,37.27600098,0.002191149
-0.062255858,-173.7833252,37.33599854,0.002205332
-0.062353516,-173.9727478,37.39599991,0.002203924
-0.062451174,-174.4435272,37.45600128,0.002213169
-0.062548825,-174.7125092,37.51599884,0.002219329
-0.062646483,-175.0377655,37.57600021,0.002228195
-0.06274414,-175.40979,37.63600159,0.002238071
-0.062841798,-175.5783539,37.69599915,0.002235633
-0.062939456,-176.0611877,37.75600052,0.002258381
-0.063037107,-176.2019196,37.81600189,0.002257998
-0.063134765,-176.4509277,37.87599945,0.002264525
-0.063232423,-176.8174286,37.93600082,0.002277408
-0.063330081,-177.0451965,37.99599838,0.002284528
-0.063427731,-177.4232025,38.05599976,0.002297093
-0.063525389,-177.4944305,38.11600113,0.002304217
-0.063623047,-177.9472656,38.17599869,0.002317962
-0.063720705,-178.1826477,38.23600006,0.002326325
-0.063818363,-178.3168945,38.29600143,0.002323114
-0.063916013,-178.7995148,38.35599899,0.002343751
-0.064013671,-178.9285736,38.41600037,0.002333119
-0.064111329,-179.3114166,38.47600174,0.002345273
-0.064208987,-179.5495453,38.5359993,0.002360433
-0.064306638,-179.8322296,38.59600067,0.002370068
-0.064404296,-180.1281891,38.65599823,0.002395176
-0.064501954,-180.2881317,38.7159996,0.002388016
-0.064599612,-180.6360321,38.77600098,0.002394129
-0.064697262,-180.9280853,38.83599854,0.002408799
-0.06479492,-181.1643219,38.89599991,0.002411042
-0.064892578,-181.5345154,38.95600128,0.002427794
-0.064990236,-181.7073822,39.01599884,0.002421935
-0.065087894,-182.1129913,39.07600021,0.002433252
-0.065185544,-182.2020569,39.13600159,0.002442935
-0.065234373,-182.5321655,39.19599915,0.002449929
-0.06538086,-182.8463898,39.25600052,0.002463632
-0.065429689,-183.0151672,39.31600189,0.0024668
-0.065527347,-183.569931,39.37599945,0.002479574
-0.065624998,-183.6936188,39.43600082,0.002480695
-0.065722656,-184.0764923,39.49599838,0.002480833
-0.065820313,-184.3828735,39.55599976,0.002512484
-0.065917971,-184.5514984,39.61600113,0.002505599
-0.066015622,-185.0275116,39.67599869,0.002524233
-0.066162109,-185.2591553,39.73600006,0.002540375
-0.066259767,-185.5851746,39.79600143,0.002542384
-0.066357425,-185.8937836,39.85599899,0.002571479
-0.066455075,-186.0355835,39.91600037,0.002575528
-0.066552733,-186.5816803,39.97600174,0.002604176
-0.066650391,-186.6481476,40.0359993,0.002618126
-0.066748049,-187.1450043,40.09600067,0.002627573
-0.0668457,-187.3826294,40.15599823,0.002649573
-0.066943358,-187.7220459,40.2159996,0.002647764
-0.067089844,-188.1216125,40.27600098,0.002678968
-0.067187502,-188.4116364,40.33599854,0.00268203
-0.067285153,-188.7511597,40.39599991,0.002695988
-0.067382811,-189.0901184,40.45600128,0.002720829
-0.067480469,-189.3288116,40.51599884,0.002727419
-0.067578127,-189.6904449,40.57600021,0.002754068
-0.067724606,-189.8975372,40.63600159,0.00276395
-0.067822264,-190.2716827,40.69599915,0.002778188
-0.067919922,-190.4707336,40.75600052,0.002792058
-0.06801758,-190.8473206,40.81600189,0.00279277
-0.068115238,-191.1916046,40.87599945,0.002815703
-0.068212888,-191.3622589,40.93600082,0.002827479
-0.068310546,-191.749527,40.99599838,0.002830169
-0.068408204,-192.0571747,41.05599976,0.002850503
-0.068505862,-192.3875275,41.11600113,0.002865251
-0.068652342,-192.8176575,41.17599869,0.002883464
-0.06875,-192.9696655,41.23600006,0.002893242
-0.068847658,-193.4045563,41.29600143,0.002904432
-0.068945315,-193.6532745,41.35599899,0.002918265
-0.069042966,-193.8680878,41.41600037,0.00292186
-0.069140624,-194.1844788,41.47600174,0.002944899
-0.069238282,-194.500946,41.5359993,0.00295144
-0.06933594,-194.8834534,41.59600067,0.002963054
-0.06943359,-195.0214996,41.65599823,0.002974944
-0.069531248,-195.3585052,41.7159996,0.002979543
-0.069628906,-195.6170349,41.77600098,0.003000594
-0.069726564,-195.7846832,41.83599854,0.003008448
-0.069824222,-196.2259216,41.89599991,0.00302498
-0.069921873,-196.4152374,41.95600128,0.003027077
-0.070019531,-196.6700439,42.01599884,0.003038935
-0.070117188,-197.0299683,42.07600021,0.003058055
-0.070214846,-197.1967926,42.13600159,0.0030636
-0.070312497,-197.5534058,42.19599915,0.003079116
-0.070410155,-197.7258911,42.25600052,0.003096125
-0.070507813,-197.9555359,42.31600189,0.003110075
-0.070605471,-198.3034668,42.37599945,0.003125932
-0.070703129,-198.6625519,42.43600082,0.003127604
-0.070800779,-198.953186,42.49599838,0.003147899
-0.070898437,-199.0157471,42.55599976,0.003155079
-0.070996095,-199.3506012,42.61600113,0.003180316
-0.071093753,-199.5641785,42.67599869,0.003186788
-0.071142575,-199.8318481,42.73600006,0.003182891
-0.071240233,-200.1486816,42.79600143,0.003210751
-0.07133789,-200.1286316,42.85599899,0.00323462
-0.071435548,-200.6455231,42.91600037,0.003257592
-0.071533206,-200.6135254,42.97600174,0.003281707
-0.071630857,-200.8108368,43.0359993,0.003295521
-0.071728515,-201.1255035,43.09600067,0.003329496
-0.071826173,-201.1517792,43.15599823,0.00333515
-0.071923831,-201.5006104,43.2159996,0.003368395
-0.072021481,-201.5702362,43.27600098,0.003387317
-0.072119139,-201.9407196,43.33599854,0.003401383
-0.072216797,-202.2639923,43.39599991,0.003419111
-0.072265626,-202.3015442,43.45600128,0.003433997
-0.072412113,-202.8066254,43.51599884,0.003454541
-0.072509763,-203.0959015,43.57600021,0.003464764
-0.072607421,-203.3850098,43.63600159,0.003486691
-0.072705079,-203.7788849,43.69599915,0.00349531
-0.072802737,-203.9316559,43.75600052,0.003500454
-0.072900388,-204.4941559,43.81600189,0.003523734
-0.072998046,-204.6685944,43.87599945,0.003534081
-0.073095704,-204.9998627,43.93600082,0.00355006
-0.073193361,-205.4480743,43.99599838,0.003563436
-0.073291012,-205.6753998,44.05599976,0.003569431
-0.07338867,-206.1830444,44.11600113,0.003585113
-0.073486328,-206.4430695,44.17599869,0.003598472
-0.073583986,-206.9025269,44.23600006,0.003616417
-0.073681644,-207.3946228,44.29600143,0.003634395
-0.073828123,-207.5243835,44.35599899,0.0036347
-0.073925781,-208.050415,44.41600037,0.003668448
-0.074023439,-208.3352814,44.47600174,0.00367738
-0.074121097,-208.8117523,44.5359993,0.003702334
-0.074267577,-209.1668854,44.59600067,0.003719364
-0.074365234,-209.5148315,44.65599823,0.003718161
-0.074462892,-210.0437927,44.7159996,0.003748694
-0.07456055,-210.1148224,44.77600098,0.003763824
-0.074658201,-210.6274261,44.83599854,0.003775025
-0.074804688,-210.9587708,44.89599991,0.003795947
-0.074902346,-211.2586212,44.95600128,0.0038112
-0.075000004,-211.6282043,45.01599884,0.003837447
-0.075097654,-211.796875,45.07600021,0.003847505
-0.075195312,-212.3869476,45.13600159,0.003874263
-0.07529297,-212.6925201,45.19599915,0.003890679
-0.075390628,-212.8151855,45.25600052,0.003891295
-0.075488279,-213.2327271,45.31600189,0.003915819
-0.075585936,-213.4431915,45.37599945,0.003921765
-0.075683594,-213.8167114,45.43600082,0.003938463
-0.075781252,-214.1446381,45.49599838,0.003964522
-0.075878903,-214.5038757,45.55599976,0.003967291
-0.07602539,-214.7775574,45.61600113,0.003999024
-0.076123048,-215.0378876,45.67599869,0.004003357
-0.076220706,-215.4445953,45.73600006,0.004026474
-0.076318356,-215.6824799,45.79600143,0.004044514
-0.076416014,-216.0965881,45.85599899,0.004059282
-0.076513672,-216.4105682,45.91600037,0.004074468
-0.07661133,-216.6977386,45.97600174,0.004085914
-0.076708988,-217.2528229,46.0359993,0.004109183
-0.076806638,-217.369751,46.09600067,0.004126784
-0.076904296,-217.7580261,46.15599823,0.004137092
-0.077001954,-218.038681,46.2159996,0.004159607
-0.077099612,-218.3738861,46.27600098,0.004173445
-0.077197263,-218.8324127,46.33599854,0.004195166
-0.077294921,-219.0821991,46.39599991,0.004200711
-0.077392579,-219.4705658,46.45600128,0.00422102
-0.077490236,-219.6194458,46.51599884,0.004253395
-0.077587887,-219.9926147,46.57600021,0.00426193
-0.077685545,-220.4380188,46.63600159,0.004297869
-0.077783203,-220.497406,46.69599915,0.004321274
-0.077832032,-220.9019165,46.75600052,0.004341899
-0.077978519,-221.2005463,46.81600189,0.004364093
-0.078076169,-221.5210571,46.87599945,0.004379103
-0.078124998,-221.9033661,46.93600082,0.004421714
-0.078222656,-221.8986206,46.99599838,0.004431757
-0.078320314,-222.3393097,47.05599976,0.004452455
-0.078417972,-222.5262604,47.11600113,0.004483815
-0.078515623,-222.6885834,47.17599869,0.004510605
-0.07861328,-223.0691071,47.23600006,0.004547941
-0.078710938,-223.1669159,47.29600143,0.00458156
-0.078808596,-223.6130524,47.35599899,0.004609074
-0.078906247,-223.7229919,47.41600037,0.004647181
-0.079003905,-223.8759766,47.47600174,0.004678269
-0.079101563,-224.16362,47.5359993,0.00472749
-0.079199221,-224.274704,47.59600067,0.004767204
-0.079296879,-224.4397278,47.65599823,0.004843232
-0.079394529,-223.9558258,47.7159996,0.004938963
-0.079492187,-223.7916565,47.77600098,0.005037506
-0.079589845,-223.7362671,47.83599854,0.005118593
-0.079687503,-223.3694153,47.89599991,0.005215211
-0.079785154,-223.2812347,47.95600128,0.005317464
-0.07993164,-222.9996185,48.01599884,0.005406574
-0.080029298,-222.8808289,48.07600021,0.005512661
-0.080126956,-222.547287,48.13600159,0.005639629
-0.080224607,-221.940033,48.19599915,0.005767843
-0.080322265,-221.3129272,48.25600052,0.005936998
-0.080468752,-220.312561,48.31600189,0.006109975
-0.080566409,-219.5831909,48.37599945,0.006281884
-0.08066406,-218.6503906,48.43600082,0.006472093
-0.080761718,-218.0158539,48.49599838,0.00660528
-0.080908205,-217.7792053,48.55599976,0.006747674
-0.081005863,-217.2617188,48.61600113,0.006868695
-0.081103513,-217.1267853,48.67599869,0.006989366
-0.081201171,-216.9673004,48.73600006,0.007098727
-0.081298829,-216.954834,48.79600143,0.007173233
-0.081396487,-217.2008362,48.85599899,0.007260125
-0.081542967,-217.0662689,48.91600037,0.007325988
-0.081640625,-217.3343658,48.97600174,0.007415726
-0.081738282,-217.2244568,49.0359993,0.007502136
-0.08183594,-217.2540588,49.09600067,0.007589435
-0.081933591,-217.4165955,49.15599823,0.007668957
-0.082031249,-217.3911743,49.2159996,0.007742866
-0.082128907,-217.5814056,49.27600098,0.007830511
-0.082226565,-217.4580383,49.33599854,0.00790876
-0.082324215,-217.4468689,49.39599991,0.007990481
-0.082421873,-217.3818207,49.45600128,0.008098817
-0.082519531,-217.2036896,49.51599884,0.008189727
-0.082617189,-217.2863007,49.57600021,0.008297225
-0.082714847,-216.9970398,49.63600159,0.008397316
-0.082812498,-216.9182129,49.69599915,0.008504095
-0.082910155,-216.5589142,49.75600052,0.008614677
-0.083056642,-215.9681396,49.81600189,0.008754304
-0.0831543,-215.4947357,49.87599945,0.008942026
-0.083251951,-214.6486969,49.93600082,0.009086183
-0.083349609,-214.1855621,49.99599838,0.009236076
-0.083447267,-213.578186,50.05599976,0.009375691
-0.083544925,-213.001358,50.11600113,0.009509327
-0.083642575,-212.4434052,50.17599869,0.009662337
-0.083740233,-211.6841888,50.23600006,0.009798038
-0.083837891,-211.1902618,50.29600143,0.009944872
-0.083935549,-210.3773651,50.35599899,0.010109366
-0.0840332,-209.838089,50.41600037,0.010255982
-0.084082028,-209.1748657,50.47600174,0.0104155
-0.084179686,-208.2572479,50.5359993,0.010564872
-0.084277344,-207.5431671,50.59600067,0.010718347
-0.084375002,-206.6344147,50.65599823,0.010901431
-0.084472653,-205.1849213,50.7159996,0.011124775
-0.084570311,-203.9492493,50.77600098,0.011357763
-0.084667969,-202.5292664,50.83599854,0.011570276
-0.084765627,-201.4104614,50.89599991,0.011783216
-0.084863284,-199.626709,50.95600128,0.012049895
-0.084960935,-197.5196991,51.01599884,0.012339827
-0.085058593,-194.6220093,51.07600021,0.012745234
-0.085156251,-190.1025238,51.13600159,0.013239301
-0.085253909,-185.0008698,51.19599915,0.013887196
-0.085351559,-177.1727905,51.25600052,0.01478945
-0.085449217,-167.3108063,51.31600189,0.015981333
-0.085546875,-158.521286,51.37599945,0.017113123
-0.085644533,-147.6495972,51.43600082,0.018548384
-0.085742191,-135.3286743,51.49599838,0.020351848
-0.085839842,-127.8765488,51.55599976,0.021535245
-0.0859375,-118.1608124,51.61600113,0.0231878
-0.086035157,-107.4256134,51.67599869,0.025185602
-0.086132815,-97.51702118,51.73600006,0.027182605
-0.086230466,-87.4002533,51.79600143,0.029496958
-0.086328124,-74.35135651,51.85599899,0.032662399
-0.086425782,-61.61598206,51.91600037,0.036587295
-0.08652344,-50.52240372,51.97600174,0.040643306
-0.08662109,-39.02230835,52.0359993,0.045401044
-0.086767577,-15.62078476,52.09600067,0.056770248
-0.086865235,0.471936792,52.15599823,5.259003025
-0.086962893,0.423845679,52.2159996,5.268218461
-0.087060544,0.39995715,52.27600098,5.268870853
-0.087158201,0.473788887,52.33599854,5.2686329
-0.087255859,0.400512099,52.39599991,5.26884757
-0.087402346,0.575586975,52.45600128,5.268793087
-0.087499997,0.318507344,52.51599884,5.268895999
-0.087597655,0.400759786,52.57600021,5.267739296
-0.087695313,0.449218392,52.63600159,5.268900655
-0.087792971,0.397203594,52.69599915,5.268904846
-0.087890628,0.435612082,52.75600052,5.268907174
-0.087988279,0.268788874,52.81600189,5.268909037
-0.088134766,0.409463823,52.87599945,5.268908571
-0.088232424,0.448874444,52.93600082,5.268911831
-0.088330075,0.354943603,52.99599838,5.268912762
-0.088427732,0.442267865,53.05599976,5.268911831
-0.08852539,0.262222856,53.11600113,5.268912297
-0.088623048,0.490638107,53.17599869,5.268915091
-0.088720706,0.350757092,53.23600006,5.268915091
-0.088818357,0.31193465,53.29600143,5.268916488
-0.088916015,0.424189806,53.35599899,5.268914625
-0.089013673,0.213010401,53.41600037,5.268918816
-0.08911133,0.462821543,53.47600174,5.268919282
-0.08925781,0.400093287,53.5359993,5.268920213
-0.089355468,0.354707956,53.59600067,5.268919747
-0.089453126,0.371292263,53.65599823,5.268919282
-0.089550784,0.302814305,53.7159996,5.268918816
-0.089648434,0.473079294,53.77600098,5.268918816
-0.089746092,0.368247837,53.83599854,5.268920213
-0.08984375,0.393894464,53.89599991,5.268921144
-0.089941408,0.448977441,53.95600128,5.268922541
-0.090039066,0.273121536,54.01599884,5.268916953
-0.090136717,0.460177749,54.07600021,5.268920679
-0.090234375,0.29214105,54.13600159,5.268920213
-0.090332032,0.337195903,54.19599915,5.268921144
-0.09042969,0.394881487,54.25600052,5.268919747
-0.090527341,0.291406721,54.31600189,5.268919282
-0.090624999,0.472401589,54.37599945,5.268921144
-0.090722657,0.332188338,54.43600082,5.26891835
-0.090771486,0.402584016,54.49599838,5.268922076
-0.090869144,0.350675553,54.55599976,5.268921144
-0.090966794,0.316063464,54.61600113,5.26892161
-0.091064452,0.418494105,54.67599869,5.268919282
-0.09116211,0.333728582,54.73600006,5.268920679
-0.091259768,0.336882383,54.79600143,5.268921144
-0.091357419,0.312315851,54.85599899,5.268920679
-0.091455076,0.328013539,54.91600037,5.268919747
-0.091552734,0.460370094,54.97600174,5.268917885
-0.091650392,0.295945436,55.0359993,5.268917419
-0.09174805,0.375847161,55.09600067,5.268921144
-0.091845701,0.343696207,55.15599823,5.268921144
-0.091943359,0.283552051,55.2159996,5.268920213
-0.092041017,0.400761873,55.27600098,5.268920679
-0.092138675,0.290549874,55.33599854,5.268919282
-0.092236325,0.478002429,55.39599991,5.268920213
-0.092285154,0.388214141,55.45600128,5.268920679
-0.092382812,0.407225549,55.51599884,5.268923473
-0.09248047,0.376685739,55.57600021,5.268918816
-0.092578128,0.35202992,55.63600159,5.268918816
-0.092724607,0.440792322,55.69599915,5.268919282
-0.092822265,0.345083356,55.75600052,5.268921144
-0.092919923,0.364397049,55.81600189,5.268920213
-0.093017581,0.396939725,55.87599945,5.268921144
-0.093115232,0.306364805,55.93600082,5.268920213
-0.09321289,0.494779646,55.99599838,5.268917885
-0.093310548,0.305011094,56.05599976,5.268919747
-0.093408205,0.379451215,56.11600113,5.268919282
-0.093505856,0.375244528,56.17599869,5.268919747
-0.093652343,0.301856339,56.23600006,5.26891835